Workbook
Name estatus: #REF!
Name estatus21: #REF!
Name STATUS: #REF!
Name STATUS2: #REF!
Name status20: #REF!
Name turnos: '[1]16'!$BV$10:$BV$19

Sheet Pala 4100 XPCAC
B3: PALA ELÉCTRICA P&H 4100 XPC AC (KOMATSU)
P9: Especificaciones técnicas del equipo

Sheet Pala 203 Filtrado
A1: Equipo | B1: Flota | C1: Año | D1: Mes | E1: Fecha | F1: Hora | G1: Duration | H1: DURACIÓN DEC. | I1: Fecha Inicio | J1: Fecha Fin | K1: Días | L1: Hrs Opera | M1: Estado | N1: Codigo | O1: Categoria | P1: Razon | Q1: CODIGO COMPONENTE | R1: DESCRIPCIÓN | S1: OT | T1: SISTEMA | U1: SUBSISTEMA | V1: COMPONENTE ASOCIADO
A2: 203 | B2: 4100 | C2: 2019 | D2: October | E2: 43739 | F2: 0.2971875 | G2: 0.036145833 | H2: 0.8675 | I2: =E2+F2 -> 43739.297 | J2: =I2+G2 -> 43739.333 | M2: Pane | N2: 937 | O2: Averia | P2: FALLA ALIMENTACION ELECTRICA | R2: EQUIPO QUEDA SIN JanRGIA | T2: SIN INFORMACIÓN | U2: SIN INFORMACIÓN | V2: SIN INFORMACIÓN
A3: 203 | B3: 4100 | C3: 2019 | D3: October | E3: 43740 | F3: 0.73869213 | G3: 0.030428241 | H3: 0.73027778 | I3: =E3+F3 -> 43740.739 | J3: =I3+G3 -> 43740.769 | K3: =I3-J2 -> 1.4053588 | L3: =K3*24 -> 33.728611 | M3: Pane | N3: 607 | O3: Averia | P3: ESTRUCTURAS | Q3: 160 | R3: CAMBIO DE PUNTAS DE BALDE | S3: A200047070 | T3: ESTRUCTURAS | U3: Elemento Desgaste | V3: ELEMENTOS DESGASTE
A4: 203 | B4: 4100 | C4: 2019 | D4: October | E4: 43742 | F4: 12:15:40 | G4: 00:16:08 | H4: 0.26888889 | I4: =E4+F4 -> 43742.511 | J4: =I4+G4 -> 43742.522 | K4: =I4-J3 -> 1.7417593 | L4: =K4*24 -> 41.802222 | M4: Pane | N4: 719 | O4: Averia | P4: CABINA | Q4: 60 | R4: CAMBIO DE FILTROS DE AIRE CABINA | S4: A200047539 | T4: CABINA | U4: Aire aconDecionado | V4: FILTRO CABINA
A5: 203 | B5: 4100 | C5: 2019 | D5: October | E5: 43745 | F5: 09:51:32 | G5: 01:56:07 | H5: 1.9352778 | I5: =E5+F5 -> 43745.411 | J5: =I5+G5 -> 43745.491 | K5: =I5-J4 -> 2.8887037 | L5: =K5*24 -> 69.328889 | M5: Pane | N5: 601 | O5: Averia | P5: SISTEMA PROPULSION (TRASLADO) | Q5: 1268 | R5: SE REPOSICIONA BLOWER EN BASE | S5: A200047999 | T5: SISTEMA PROPULSION (TRASLADO) | U5: Motor propel | V5: MOTOR PROPEL DERECHO
A6: 203 | B6: 4100 | C6: 2019 | D6: October | E6: 43746 | F6: 18:05:11 | G6: 00:37:04 | H6: 0.61777778 | I6: =E6+F6 -> 43746.754 | J6: =I6+G6 -> 43746.779 | K6: =I6-J5 -> 1.2621759 | L6: =K6*24 -> 30.292222 | M6: Pane | N6: 602 | O6: Averia | P6: SISTEMA HOIST (LEVANTE) | Q6: 1155 | R6: SE AJUSTA SENSOR DE SLACK | S6: A200048532 | T6: SISTEMA HOIST (LEVANTE) | U6: Frenos hoist | V6: FRENOS HOIST DELANTERO
A7: 203 | B7: 4100 | C7: 2019 | D7: October | E7: 43748 | F7: 22:02:41 | G7: 03:28:20 | H7: 3.4722222 | I7: =E7+F7 -> 43748.919 | J7: =I7+G7 -> 43749.063 | K7: =I7-J6 -> 2.1391898 | L7: =K7*24 -> 51.340556 | M7: Pane | N7: 606 | O7: Averia | P7: SISTEMA ELECTRICO | Q7: 186 | R7: PROBLEMAS CON SENSOR ESCALERA PRINCIPAL-CAMBIO SWITCH SENSOR ESCALERA | S7: 200049089 | T7: ESTRUCTURAS | U7: Estructuras | V7: PLATAFORMAS Y ESCALERAS
A8: 203 | B8: 4100 | C8: 2019 | D8: October | E8: 43749 | F8: 08:55:00 | G8: 00:15:30 | H8: 0.25833333 | I8: =E8+F8 -> 43749.372 | J8: =I8+G8 -> 43749.382 | K8: =I8-J7 -> 0.30832176 | L8: =K8*24 -> 7.3997222 | M8: Pane | N8: 603 | O8: Averia | P8: SISTEMA CROWD | Q8: 704 | R8: NO LIBERA FRENO CROWD, DA CONDecION SI INTERVENCIONDE TECNICO | T8: SISTEMA CROWD | U8: Freno crowd | V8: FRENO CROWD
A9: 203 | B9: 4100 | C9: 2019 | D9: October | E9: 43752 | F9: 21:39:08 | G9: 00:20:52 | H9: 0.34777778 | I9: =E9+F9 -> 43752.902 | J9: =I9+G9 -> 43752.917 | K9: =I9-J8 -> 3.5198843 | L9: =K9*24 -> 84.477222 | M9: Pane | N9: 605 | O9: Averia | P9: SISTEMA LUBRICACION | Q9: 1189 | R9: FALLA LUBRICACION INFERIOR-MANTENCION V/V DIRECCIONAL LUBRICACION ABIERTA | S9: 200049919 | T9: SISTEMA LUBRICACION | U9: Sistema lubricacion | V9: LUBRICACION
A10: 203 | B10: 4100 | C10: 2019 | D10: October | E10: 43754 | F10: 0.23364583 | G10: 00:31:14 | H10: 0.52055556 | I10: =E10+F10 -> 43754.234 | J10: =I10+G10 -> 43754.255 | K10: =I10-J9 -> 1.3169792 | L10: =K10*24 -> 31.6075 | M10: Pane | N10: 606 | O10: Averia | P10: SISTEMA ELECTRICO | Q10: 890 | R10: SOPLADO DE FILTROS DE FAN ISO SWING | S10: A200050651 | T10: SISTEMA ELECTRICO | U10: Swing | V10: SWING
A11: 203 | B11: 4100 | C11: 2019 | D11: October | E11: 43756 | F11: 11:04:56 | G11: 00:43:34 | H11: 0.72611111 | I11: =E11+F11 -> 43756.462 | J11: =I11+G11 -> 43756.492 | K11: =I11-J10 -> 2.2064236 | L11: =K11*24 -> 52.954167 | M11: Pane | N11: 607 | O11: Averia | P11: ESTRUCTURAS | Q11: 122 | R11: PROBLEMAS CON BIELA DE BALDE, SE NORMALIZA BIELA, CHEQUEO ELEMENTOS DE DESGASTE | S11: 200051140 | T11: ESTRUCTURAS | U11: Balde | V11: BALANCIN BALDE, LEVER LATCH
A12: 203 | B12: 4100 | C12: 2019 | D12: October | E12: 43756 | F12: 20:03:53 | G12: 0.1118287 | H12: 2.0911111 | I12: =E12+F12 -> 43756.836 | J12: =I12+G12 -> 43756.948 | K12: =I12-J11 -> 0.3440162 | L12: =K12*24 -> 8.2563889 | M12: Pane | N12: 607 | O12: Averia | P12: ESTRUCTURAS | Q12: 160 | R12: CHEQUEO DE PUNTAS PARA CAMBIO | S12: A200051167 | T12: ESTRUCTURAS | U12: Elemento Desgaste | V12: ELEMENTOS DESGASTE
A13: 203 | B13: 4100 | C13: 2019 | D13: October | E13: 43757 | F13: 05:59:47 | G13: 02:00:13 | H13: 2.0036111 | I13: =E13+F13 -> 43757.25 | J13: =I13+G13 -> 43757.333 | K13: =I13-J12 -> 0.30199074 | L13: =K13*24 -> 7.2477778 | M13: Pane | N13: 606 | O13: Averia | P13: SISTEMA ELECTRICO | Q13: 0 | R13: SIN JanRGIA PROBLEMAS CON HILO PILOTO | S13: A200051385 | T13: SIN INFORMACIÓN | U13: SIN INFORMACION | V13: SIN INFORMACIÓN
A14: 203 | B14: 4100 | C14: 2019 | D14: October | E14: 43757 | F14: 08:09:40 | G14: 01:23:50 | H14: 1.3972222 | I14: =E14+F14 -> 43757.34 | J14: =I14+G14 -> 43757.398 | K14: =I14-J13 -> 0.006712963 | L14: =K14*24 -> 0.16111111 | M14: Pane | N14: 607 | O14: Averia | P14: ESTRUCTURAS | Q14: 120 | R14: OREJA TAPA SNUBER DE BALDE POR CAER, SE NORMALIZA SNUBER | S14: 200051294 | T14: ESTRUCTURAS | U14: Balde | V14: ARO BALDE
A15: 203 | B15: 4100 | C15: 2019 | D15: October | E15: 43757 | F15: 16:24:58 | G15: 01:28:40 | H15: 1.4777778 | I15: =E15+F15 -> 43757.684 | J15: =I15+G15 -> 43757.746 | K15: =I15-J14 -> 0.28574074 | L15: =K15*24 -> 6.8577778 | M15: Pane | N15: 604 | O15: Averia | P15: SISTEMA NEUMATICO | Q15: 1234 | R15: CAMBIO FITTING DE LUBRICACION DE LA CORREDERA | S15: 200051317 | T15: SISTEMA NEUMATICO | U15: Compresor aire | V15: COMPRESOR DE AIRE
A16: 203 | B16: 4100 | C16: 2019 | D16: October | E16: 43757 | F16: 23:05:02 | G16: 00:45:46 | H16: 0.76277778 | I16: =E16+F16 -> 43757.962 | J16: =I16+G16 -> 43757.994 | K16: =I16-J15 -> 0.21625 | L16: =K16*24 -> 5.19 | M16: Pane | N16: 719 | O16: Averia | P16: CABINA | Q16: 60 | R16: CAMBIO DE FILTROS DE CABINA | S16: A200051340 | T16: CABINA | U16: Aire aconDecionado | V16: FILTRO CABINA
A17: 203 | B17: 4100 | C17: 2019 | D17: October | E17: 43758 | F17: 06:40:12 | G17: 00:26:34 | H17: 0.44277778 | I17: =E17+F17 -> 43758.278 | J17: =I17+G17 -> 43758.296 | K17: =I17-J16 -> 0.28430556 | L17: =K17*24 -> 6.8233333 | M17: Pane | N17: 606 | O17: Averia | P17: SISTEMA ELECTRICO | Q17: 704 | R17: SE LIMPIA CUERPO DE VALVULA DEL FRENO CROWD | S17: A200051518 | T17: SISTEMA CROWD | U17: Freno crowd | V17: FRENO CROWD
A18: 203 | B18: 4100 | C18: 2019 | D18: October | E18: 43758 | F18: 08:00:00 | G18: 03:55:14 | H18: 3.9205556 | I18: =E18+F18 -> 43758.333 | J18: =I18+G18 -> 43758.497 | K18: =I18-J17 -> 0.036967593 | L18: =K18*24 -> 0.88722222 | M18: Pane | N18: 606 | O18: Averia | P18: SISTEMA ELECTRICO | Q18: 0 | R18: SIN JanRGIA PROBLEMAS CON HILO PILOTO | S18: A200051385 | T18: SIN INFORMACIÓN | U18: SIN INFORMACION | V18: SIN INFORMACIÓN
A19: 203 | B19: 4100 | C19: 2019 | D19: October | E19: 43758 | F19: 13:50:38 | G19: 02:00:13 | H19: 2.0036111 | I19: =E19+F19 -> 43758.577 | J19: =I19+G19 -> 43758.66 | K19: =I19-J18 -> 0.080138889 | L19: =K19*24 -> 1.9233333 | M19: Pane | N19: 607 | O19: Averia | P19: ESTRUCTURAS | Q19: 113 | R19: PASADOR VIELA DE BALDE SE DESPLAZA | S19: 200051410 | T19: #N/A | U19: #N/A | V19: #N/A
A20: 203 | B20: 4100 | C20: 2019 | D20: October | E20: 43758 | F20: 17:50:25 | G20: 02:09:35 | H20: 2.1597222 | I20: =E20+F20 -> 43758.743 | J20: 43759.257 | K20: =I20-J19 -> 0.083032407 | L20: =K20*24 -> 1.9927778 | M20: Pane | N20: 607 | O20: Averia | P20: ESTRUCTURAS | Q20: 123 | R20: SE CORTAN AMBAS OREJAS SNUBBER BALDE LADO IZQUIERDO | S20: 200051422 | T20: ESTRUCTURAS | U20: Balde | V20: BALDE
A21: 203 | B21: 4100 | C21: 2019 | D21: October | E21: 43759 | F21: 16:03:16 | G21: 03:08:33 | H21: 3.1425 | I21: =E21+F21 -> 43759.669 | J21: =I21+G21 -> 43759.8 | K21: =I21-J20 -> 0.4121875 | L21: =K21*24 -> 9.8925 | M21: Pane | N21: 605 | O21: Averia | P21: SISTEMA LUBRICACION | Q21: 1194 | R21: FALLA DDE GRASA SUOERIO | S21: 200051715 | T21: SISTEMA LUBRICACION | U21: Tanque lubricacion | V21: ESTANQUE DE GRASA
A22: 203 | B22: 4100 | C22: 2019 | D22: October | E22: 43759 | F22: 20:59:33 | G22: 01:00:21 | H22: 1.0058333 | I22: =E22+F22 -> 43759.875 | J22: =I22+G22 -> 43759.917 | K22: =I22-J21 -> 0.074814815 | L22: =K22*24 -> 1.7955556 | M22: Pane | N22: 605 | O22: Averia | P22: SISTEMA LUBRICACION | Q22: 1189 | R22: SE REGULAN PRESIONES DE SISTEMA CERRADO DE LUBRICACION Y SE REGULAN TIEMPOS | S22: A2000517 | T22: SISTEMA LUBRICACION | U22: Sistema lubricacion | V22: LUBRICACION
A23: 203 | B23: 4100 | C23: 2019 | D23: October | E23: 43760 | F23: 07:39:17 | G23: 00:20:43 | H23: 0.34527778 | I23: =E23+F23 -> 43760.319 | J23: =I23+G23 -> 43760.333 | K23: =I23-J22 -> 0.40234954 | L23: =K23*24 -> 9.6563889 | M23: Pane | N23: 607 | O23: Averia | P23: ESTRUCTURAS | Q23: 123 | R23: SE CAE PUNTA DEL BALDE-REPOSICION DE PUNTA POSICION 7 MAS WEARCAP | S23: 200052262 | T23: ESTRUCTURAS | U23: Balde | V23: BALDE
A24: 203 | B24: 4100 | C24: 2019 | D24: October | E24: 43761 | F24: 08:00:00 | G24: 02:52:17 | H24: 2.8713889 | I24: =E24+F24 -> 43761.333 | J24: =I24+G24 -> 43761.453 | K24: =I24-J23 -> 1 | L24: =K24*24 -> 24 | M24: Pane | N24: 607 | O24: Averia | P24: ESTRUCTURAS | Q24: 123 | R24: SE CAE PUNTA DEL BALDE-REPOSICION DE PUNTA POSICION 7 MAS WEARCAP | S24: 200052262 | T24: ESTRUCTURAS | U24: Balde | V24: BALDE
A25: 203 | B25: 4100 | C25: 2019 | D25: October | E25: 43762 | F25: 01:40:00 | G25: 01:50:00 | H25: 1.8333333 | I25: =E25+F25 -> 43762.069 | J25: 43763.601 | K25: =I25-J24 -> 0.61646991 | L25: =K25*24 -> 14.795278 | M25: Pane | N25: 602 | O25: Averia | P25: SISTEMA HOIST (LEVANTE) | Q25: 1154 | R25: CAMBIO DE CABLES DE LEVANTE | S25: 200052592 | T25: SISTEMA HOIST (LEVANTE) | U25: Cables levante | V25: CABLES LEVANTE
A26: 203 | B26: 4100 | C26: 2019 | D26: October | E26: 43763 | F26: 16:08:33 | G26: 00:37:49 | H26: 0.63027778 | I26: =E26+F26 -> 43763.673 | J26: =I26+G26 -> 43763.699 | K26: =I26-J25 -> 0.071712963 | L26: =K26*24 -> 1.7211111 | M26: Pane | N26: 606 | O26: Averia | P26: SISTEMA ELECTRICO | Q26: 894 | R26: DIFERENCIA TEMPERATURA LADO IZQUIERDO-CAMBIO FAN ISU 3 LADO IZQUIERDO | S26: 200052863 | T26: SISTEMA ELECTRICO | U26: Ventilador sala maquina | V26: VENTILADOR SALA MAQUINA IZQUIERDO
A27: 203 | B27: 4100 | C27: 2019 | D27: October | E27: 43764 | F27: 01:10:00 | G27: 00:32:46 | H27: 0.54611111 | I27: =E27+F27 -> 43764.049 | J27: =I27+G27 -> 43764.071 | K27: =I27-J26 -> 0.34974537 | L27: =K27*24 -> 8.3938889 | M27: Pane | N27: 509 | O27: Averia | P27: ESPERA RECURSO | Q27: 0 | R27: EQUIPO SE ENTREGA OPERATIVO, COMIENZA TRASLADO LARGO A POSTURA | T27: SIN INFORMACIÓN | U27: SIN INFORMACION | V27: SIN INFORMACIÓN
A28: 203 | B28: 4100 | C28: 2019 | D28: October | E28: 43765 | F28: 03:06:56 | G28: 02:36:12 | H28: 2.6033333 | I28: =E28+F28 -> 43765.13 | J28: =I28+G28 -> 43765.238 | K28: =I28-J27 -> 1.0584491 | L28: =K28*24 -> 25.402778 | M28: Pane | N28: 605 | O28: Averia | P28: SISTEMA LUBRICACION | Q28: 1189 | R28: FALLA BAJA Pº LUBRICACION-CAMBIO BB LUBRICACION A POSICION BB AUXILIAR | S28: 200053171 | T28: SISTEMA LUBRICACION | U28: Sistema lubricacion | V28: LUBRICACION
A29: 203 | B29: 4100 | C29: 2019 | D29: October | E29: 43765 | F29: 11:53:03 | G29: 00:41:50 | H29: 0.69722222 | I29: =E29+F29 -> 43765.495 | J29: =I29+G29 -> 43765.524 | K29: =I29-J28 -> 0.25688657 | L29: =K29*24 -> 6.1652778 | M29: Pane | N29: 606 | O29: Averia | P29: SISTEMA ELECTRICO | Q29: 894 | R29: FALLA AMBOS SOPLADORES SALA MAQUINA-SE NORMALIZA DRIVE SALA MAQUINA IZQUIE | S29: 200053077 | T29: SISTEMA ELECTRICO | U29: Ventilador sala maquina | V29: VENTILADOR SALA MAQUINA IZQUIERDO
A30: 203 | B30: 4100 | C30: 2019 | D30: October | E30: 43765 | F30: 13:09:47 | G30: 00:52:25 | H30: 0.87361111 | I30: =E30+F30 -> 43765.548 | J30: =I30+G30 -> 43765.585 | K30: =I30-J29 -> 0.024236111 | L30: =K30*24 -> 0.58166667 | M30: Pane | N30: 605 | O30: Averia | P30: SISTEMA LUBRICACION | Q30: 1189 | R30: FALLA LUBRICACION-SE NORMALIZA VASTAGO DE BOMBA LUBRICACION SISTEMA LOWER | S30: 200053090 | T30: SISTEMA LUBRICACION | U30: Sistema lubricacion | V30: LUBRICACION
A31: 203 | B31: 4100 | C31: 2019 | D31: October | E31: 43768 | F31: 14:33:21 | G31: 00:39:59 | H31: 0.66638889 | I31: =E31+F31 -> 43768.606 | J31: =I31+G31 -> 43768.634 | K31: =I31-J30 -> 3.0216319 | L31: =K31*24 -> 72.519167 | M31: Pane | N31: 509 | O31: Averia | P31: ESPERA RECURSO | Q31: 0 | R31: NO SE PUEDE INGRESAR AL SECTOR POR TRONADURA | S31: S OT | T31: SIN INFORMACIÓN | U31: SIN INFORMACION | V31: SIN INFORMACIÓN
A32: 203 | B32: 4100 | C32: 2019 | D32: October | E32: 43769 | F32: 10:30:20 | G32: 00:26:55 | H32: 0.44861111 | I32: =E32+F32 -> 43769.438 | J32: =I32+G32 -> 43769.456 | K32: =I32-J31 -> 0.80347222 | L32: =K32*24 -> 19.283333 | M32: Pane | N32: 606 | O32: Averia | P32: SISTEMA ELECTRICO | Q32: 704 | R32: REAPRITE DE TENSOR DE SLACK ROPE | S32: A200054293 | T32: SISTEMA CROWD | U32: Freno crowd | V32: FRENO CROWD
A33: 203 | B33: =VLOOKUP(A33,'[2]Flota Mina '!$C$5:$D$105,2,FALSE) -> 4100 | C33: 2019 | D33: =TEXT(E33,"MMMM") -> noviembre | E33: 43772 | F33: 15:22:19 | G33: 01:21:19 | H33: =G33*24 -> 1.3552778 | I33: =E33+F33 -> 43772.64 | J33: =I33+G33 -> 43772.697 | K33: =I33-J32 -> 3.1840741 | L33: =K33*24 -> 76.417778 | M33: Pane | N33: 604 | O33: Averia | P33: SISTEMA NEUMATICO | Q33: 1233 | R33: SE REGULA PRESIONES DE BOMBA Y VALVULA SPRAY Y SE NORMALIZAN TIEMPOS | S33: A200054920 | T33: =VLOOKUP(Q33,[2]CÓDIGOS!$A$2:$C$2024,3,) -> SISTEMA NEUMATICO | U33: =VLOOKUP(Q33,[2]CÓDIGOS!$A$2:$D$2024,4,) -> Valvula reguladora presion | V33: =VLOOKUP(Q33,[2]CÓDIGOS!$A$2:$B$2024,2,) -> VALVULA REGULADORA PRESION
A34: 203 | B34: =VLOOKUP(A34,'[2]Flota Mina '!$C$5:$D$105,2,FALSE) -> 4100 | C34: 2019 | D34: =TEXT(E34,"MMMM") -> noviembre | E34: 43777 | F34: 03:58:43 | G34: 00:35:12 | H34: =G34*24 -> 0.58666667 | I34: =E34+F34 -> 43777.166 | J34: =I34+G34 -> 43777.19 | K34: =I34-J33 -> 4.4688079 | L34: =K34*24 -> 107.25139 | M34: Pane | N34: 606 | O34: Averia | P34: SISTEMA ELECTRICO | Q34: 0 | R34: FALLA DRIVE VENTILADOR SALA MAQUINA IZQUIERDO | S34: 200056511 | T34: =VLOOKUP(Q34,[2]CÓDIGOS!$A$2:$C$2024,3,) -> SIN INFORMACIÓN | U34: =VLOOKUP(Q34,[2]CÓDIGOS!$A$2:$D$2024,4,) -> SIN INFORMACION | V34: =VLOOKUP(Q34,[2]CÓDIGOS!$A$2:$B$2024,2,) -> SIN INFORMACIÓN
A35: 203 | B35: =VLOOKUP(A35,'[2]Flota Mina '!$C$5:$D$105,2,FALSE) -> 4100 | C35: 2019 | D35: =TEXT(E35,"MMMM") -> noviembre | E35: 43777 | F35: 16:56:10 | G35: 01:49:38 | H35: =G35*24 -> 1.8272222 | I35: =E35+F35 -> 43777.706 | J35: =I35+G35 -> 43777.782 | K35: =I35-J34 -> 0.51545139 | L35: =K35*24 -> 12.370833 | M35: Pane | N35: 937 | O35: Averia | P35: FALLA ALIMENTACION ELECTRICA | Q35: 0 | R35: EQUIPO EN TRASLADO QUEDA SIN JanRGIA | T35: =VLOOKUP(Q35,[2]CÓDIGOS!$A$2:$C$2024,3,) -> SIN INFORMACIÓN | U35: =VLOOKUP(Q35,[2]CÓDIGOS!$A$2:$D$2024,4,) -> SIN INFORMACION | V35: =VLOOKUP(Q35,[2]CÓDIGOS!$A$2:$B$2024,2,) -> SIN INFORMACIÓN
A36: 203 | B36: =VLOOKUP(A36,'[2]Flota Mina '!$C$5:$D$105,2,FALSE) -> 4100 | C36: 2019 | D36: =TEXT(E36,"MMMM") -> noviembre | E36: 43778 | F36: 12:46:12 | G36: 01:14:23 | H36: =G36*24 -> 1.2397222 | I36: =E36+F36 -> 43778.532 | J36: =I36+G36 -> 43778.584 | K36: =I36-J35 -> 0.75027778 | L36: =K36*24 -> 18.006667 | M36: Pane | N36: 605 | O36: Averia | P36: SISTEMA LUBRICACION | T36: =VLOOKUP(Q36,[2]CÓDIGOS!$A$2:$C$2024,3,) -> SIN INFORMACIÓN | U36: =VLOOKUP(Q36,[2]CÓDIGOS!$A$2:$D$2024,4,) -> SIN INFORMACION | V36: =VLOOKUP(Q36,[2]CÓDIGOS!$A$2:$B$2024,2,) -> SIN INFORMACIÓN
A37: 203 | B37: =VLOOKUP(A37,'[2]Flota Mina '!$C$5:$D$105,2,FALSE) -> 4100 | C37: 2019 | D37: =TEXT(E37,"MMMM") -> noviembre | E37: 43779 | F37: 03:17:10 | G37: 04:13:09 | H37: =G37*24 -> 4.2191667 | I37: =E37+F37 -> 43779.137 | J37: =I37+G37 -> 43779.313 | K37: =I37-J36 -> 0.55318287 | L37: =K37*24 -> 13.276389 | M37: Pane | N37: 607 | O37: Averia | P37: ESTRUCTURAS | Q37: 186 | R37: PROBLEMAS CON ESCALA PRINCIPAL-SE CAMBIAN AMBOS CILINDROS DE ESCALERA | S37: 200056803 | T37: =VLOOKUP(Q37,[2]CÓDIGOS!$A$2:$C$2024,3,) -> ESTRUCTURAS | U37: =VLOOKUP(Q37,[2]CÓDIGOS!$A$2:$D$2024,4,) -> Estructuras | V37: =VLOOKUP(Q37,[2]CÓDIGOS!$A$2:$B$2024,2,) -> PLATAFORMAS Y ESCALERAS
A38: 203 | B38: =VLOOKUP(A38,'[2]Flota Mina '!$C$5:$D$105,2,FALSE) -> 4100 | C38: 2019 | D38: =TEXT(E38,"MMMM") -> noviembre | E38: 43779 | F38: 23:55:00 | G38: 00:55:52 | H38: =G38*24 -> 0.93111111 | I38: =E38+F38 -> 43779.997 | J38: =I38+G38 -> 43780.035 | K38: =I38-J37 -> 0.68380787 | L38: =K38*24 -> 16.411389 | M38: Pane | N38: 719 | O38: Averia | P38: CABINA | Q38: 77 | R38: PROBLEMAS CON BOCINA | S38: 200056731 | T38: =VLOOKUP(Q38,[2]CÓDIGOS!$A$2:$C$2024,3,) -> CABINA | U38: =VLOOKUP(Q38,[2]CÓDIGOS!$A$2:$D$2024,4,) -> Bocina | V38: =VLOOKUP(Q38,[2]CÓDIGOS!$A$2:$B$2024,2,) -> BOCINA
A39: 203 | B39: =VLOOKUP(A39,'[2]Flota Mina '!$C$5:$D$105,2,FALSE) -> 4100 | C39: 2019 | D39: =TEXT(E39,"MMMM") -> noviembre | E39: 43781 | F39: 10:36:50 | G39: 00:56:03 | H39: =G39*24 -> 0.93416667 | I39: =E39+F39 -> 43781.442 | J39: =I39+G39 -> 43781.481 | K39: =I39-J38 -> 1.4069213 | L39: =K39*24 -> 33.766111 | M39: Pane | N39: 605 | O39: Averia | P39: SISTEMA LUBRICACION | Q39: 1213 | R39: AUMENTO DE PRESION DE GRASA INFERIOR | S39: 200057188 | T39: =VLOOKUP(Q39,[2]CÓDIGOS!$A$2:$C$2024,3,) -> SISTEMA LUBRICACION | U39: =VLOOKUP(Q39,[2]CÓDIGOS!$A$2:$D$2024,4,) -> Valvula lubricacion open gear | V39: =VLOOKUP(Q39,[2]CÓDIGOS!$A$2:$B$2024,2,) -> VALVULAS LUBRICACION ABIERTA
A40: 203 | B40: =VLOOKUP(A40,'[2]Flota Mina '!$C$5:$D$105,2,FALSE) -> 4100 | C40: 2019 | D40: =TEXT(E40,"MMMM") -> noviembre | E40: 43781 | F40: 20:47:58 | G40: 01:08:38 | H40: =G40*24 -> 1.1438889 | I40: =E40+F40 -> 43781.867 | J40: =I40+G40 -> 43781.914 | K40: =I40-J39 -> 0.38547454 | L40: =K40*24 -> 9.2513889 | M40: Pane | N40: 605 | O40: Averia | P40: SISTEMA LUBRICACION | Q40: 1192 | R40: BAJA Pº AIRE-SE NORMALIZA BOMBA DE LUBRICACION ABIERTA | S40: 200057288 | T40: =VLOOKUP(Q40,[2]CÓDIGOS!$A$2:$C$2024,3,) -> SISTEMA LUBRICACION | U40: =VLOOKUP(Q40,[2]CÓDIGOS!$A$2:$D$2024,4,) -> bombas lubricacion | V40: =VLOOKUP(Q40,[2]CÓDIGOS!$A$2:$B$2024,2,) -> BOMBAS LUBRICACION ABIERTA
...

Sheet Nelson Aalen
A2: BASE DATOS PALA 203 p&h 4100XPC AC, OCT-NOV-DIC 2019
A4: N de Fallas | B4: Tiempo entre Fallas (Hrs) | C4: Tiempo Calendario (Hrs)
A5: 1 | B5: 33.728611 | C5: =B5 -> 33.728611 | N5: Test de Tendencia de Laplace
A6: 2 | B6: 41.802222 | C6: =B6+C5 -> 75.530833
A7: 3 | B7: 69.328889 | C7: =B7+C6 -> 144.85972 | N7: Suma ti = | O7: =SUM(C5:C95) -> 96975.201
A8: 4 | B8: 30.292222 | C8: =B8+C7 -> 175.15194 | N8: n = | O8: 91
A9: 5 | B9: 51.340556 | C9: =B9+C8 -> 226.4925 | N9: to = | O9: =C95 -> 1960.0897
A10: 6 | B10: 7.3997222 | C10: =B10+C9 -> 233.89222
A11: 7 | B11: 84.477222 | C11: =B11+C10 -> 318.36944 | N11: U = | O11: =(O7/O8-O9/2)/(O9*SQRT(1/(12*O8))) -> 1.4434235
A12: 8 | B12: 31.6075 | C12: =B12+C11 -> 349.97694
A13: 9 | B13: 52.954167 | C13: =B13+C12 -> 402.93111 | M13: 1.- | N13: Nivel de significancia:
A14: 10 | B14: 8.2563889 | C14: =B14+C13 -> 411.1875 | N14: α = | O14: 0.5
A15: 11 | B15: 7.2477778 | C15: =B15+C14 -> 418.43528 | N15: => -0,674 < U < 0,674
A16: 12 | B16: 0.16111111 | C16: =B16+C15 -> 418.59639
A17: 13 | B17: 6.8577778 | C17: =B17+C16 -> 425.45417 | N17: Sistema triste, dregradación de la confiabilidad.
A18: 14 | B18: 5.19 | C18: =B18+C17 -> 430.64417
A19: 15 | B19: 6.8233333 | C19: =B19+C18 -> 437.4675 | M19: 2.- | N19: Nivel de significancia:
A20: 16 | B20: 0.88722222 | C20: =B20+C19 -> 438.35472 | N20: α = | O20: 0.1
A21: 17 | B21: 1.9233333 | C21: =B21+C20 -> 440.27806 | N21: => -1,645 < U < 1,645
A22: 18 | B22: 1.9927778 | C22: =B22+C21 -> 442.27083
A23: 19 | B23: 9.8925 | C23: =B23+C22 -> 452.16333 | N23: Sistema neutro (iid).
A24: 20 | B24: 1.7955556 | C24: =B24+C23 -> 453.95889
A25: 21 | B25: 9.6563889 | C25: =B25+C24 -> 463.61528
A26: 22 | B26: 24 | C26: =B26+C25 -> 487.61528
A27: 23 | B27: 14.795278 | C27: =B27+C26 -> 502.41056
A28: 24 | B28: 1.7211111 | C28: =B28+C27 -> 504.13167
A29: 25 | B29: 8.3938889 | C29: =B29+C28 -> 512.52556
A30: 26 | B30: 25.402778 | C30: =B30+C29 -> 537.92833
A31: 27 | B31: 6.1652778 | C31: =B31+C30 -> 544.09361
A32: 28 | B32: 0.58166667 | C32: =B32+C31 -> 544.67528
A33: 29 | B33: 72.519167 | C33: =B33+C32 -> 617.19444
A34: 30 | B34: 19.283333 | C34: =B34+C33 -> 636.47778
A35: 31 | B35: 76.417778 | C35: =B35+C34 -> 712.89556
... A95: 91 | B95: 48.297222 | C95: =B95+C94 -> 1960.0897

Sheet Crow Aansa
A2: BASE DATOS PALA 203 p&h 4100XPC AC, OCT-NOV-DIC 2019 | V2: Proyección 1 año después de las 1960,1 hrs: | Z2: Costo MC = | AA2: 3000 | AB2: USD/falla
V3: 17 hrs operacionales al día | Z3: Mantenimiento correctivo
A4: N de Fallas | B4: Tiempo entre Fallas (Hrs) | C4: Tiempo Calendario (Hrs) | D4: Ln(Tq/Xi) | E4: W(t) | O4: Modelo de Crow Aansa | V4: Tiempo Calendario (Hrs) | W4: W(t) | X4: Incremento de falla cada 250 hrs | Y4: Costos | Z4: Acumulado Costo | AA4: Confiabilidad | AB4: Tasa de Falla | AC4: MTBF Inst.
A5: 1 | B5: 33.728611 | C5: =B5 -> 33.728611 | D5: =LN($P$7/C5) -> 4.0623991 | E5: =$P$12*C5^$P$11 -> 0.63353584 | U5: Cada 250 hrs | V5: =P7 -> 1960.0897 | W5: =$P$12*V5^($P$11) -> 91 | AA5: =EXP(-1*$P$12*V5^($P$11)) -> 3.0144088e-40 | AB5: =$P$12*$P$11*V5^($P$11-1) -> 0.056767934 | AC5: =1/AB5 -> 17.615578
A6: 2 | B6: 41.802222 | C6: =B6+C5 -> 75.530833 | D6: =LN($P$7/C6) -> 3.2562046 | E6: =$P$12*C6^$P$11 -> 1.6978038 | O6: Nq = | P6: =H36 -> 91 | V6: =V5+250 -> 2210.0897 | W6: =$P$12*V6^($P$11) -> 105.38728 | X6: =W6-W5 -> 14.387276 | Y6: =X6*$AA$2 -> 43161.829 | Z6: =Y6 -> 43161.829 | AA6: =EXP(-1*$P$12*V6^($P$11)) -> 1.7017172e-46 | AB6: =$P$12*$P$11*V6^($P$11-1) -> 0.05830636 | AC6: =1/AB6 -> 17.150788
A7: 3 | B7: 69.328889 | C7: =B7+C6 -> 144.85972 | D7: =LN($P$7/C7) -> 2.6049797 | E7: =$P$12*C7^$P$11 -> 3.7645214 | O7: Tq = | P7: =H37 -> 1960.0897 | V7: =V6+250 -> 2460.0897 | W7: =$P$12*V7^($P$11) -> 120.14238 | X7: =W7-W6 -> 14.755105 | Y7: =X7*$AA$2 -> 44265.316 | Z7: =Y7+Z6 -> 87427.145 | AA7: =EXP(-1*$P$12*V7^($P$11)) -> 6.6500758e-53 | AB7: =$P$12*$P$11*V7^($P$11-1) -> 0.059714932 | AC7: =1/AB7 -> 16.74623
A8: 4 | B8: 30.292222 | C8: =B8+C7 -> 175.15194 | D8: =LN($P$7/C8) -> 2.4150917 | E8: =$P$12*C8^$P$11 -> 4.7483932 | V8: =V7+250 -> 2710.0897 | W8: =$P$12*V8^($P$11) -> 135.23582 | X8: =W8-W7 -> 15.093441 | Y8: =X8*$AA$2 -> 45280.322 | Z8: =Y8+Z7 -> 132707.47 | AA8: =EXP(-1*$P$12*V8^($P$11)) -> 1.8528002e-59 | AB8: =$P$12*$P$11*V8^($P$11-1) -> 0.06101628 | AC8: =1/AB8 -> 16.389069
A9: 5 | B9: 51.340556 | C9: =B9+C8 -> 226.4925 | D9: =LN($P$7/C9) -> 2.1580337 | E9: =$P$12*C9^$P$11 -> 6.5020917 | O9: Suma Ln(Tq/Xi) = | P9: =SUM(D5:D95) -> 74.422412 | V9: =V8+250 -> 2960.0897 | W9: =$P$12*V9^($P$11) -> 150.64301 | X9: =W9-W8 -> 15.407192 | Y9: =X9*$AA$2 -> 46221.577 | Z9: =Y9+Z8 -> 178929.04 | AA9: =EXP(-1*$P$12*V9^($P$11)) -> 3.7719849e-66 | AB9: =$P$12*$P$11*V9^($P$11-1) -> 0.062227417 | AC9: =1/AB9 -> 16.070087
A10: 6 | B10: 7.3997222 | C10: =B10+C9 -> 233.89222 | D10: =LN($P$7/C10) -> 2.1258851 | E10: =$P$12*C10^$P$11 -> 6.762777 | N10: 1.- | O10: Parámetros: | V10: =V9+250 -> 3210.0897 | W10: =$P$12*V10^($P$11) -> 166.34312 | X10: =W10-W9 -> 15.700101 | Y10: =X10*$AA$2 -> 47100.303 | Z10: =Y10+Z9 -> 226029.35 | AA10: =EXP(-1*$P$12*V10^($P$11)) -> 5.7293161e-73 | AB10: =$P$12*$P$11*V10^($P$11-1) -> 0.06336148 | AC10: =1/AB10 -> 15.78246
A11: 7 | B11: 84.477222 | C11: =B11+C10 -> 318.36944 | D11: =LN($P$7/C11) -> 1.817533 | E11: =$P$12*C11^$P$11 -> 9.8598512 | O11: Beta = | P11: =P6/P9 -> 1.2227499 | V11: =V10+250 -> 3460.0897 | W11: =$P$12*V11^($P$11) -> 182.3182 | X11: =W11-W10 -> 15.975086 | Y11: =X11*$AA$2 -> 47925.259 | Z11: =Y11+Z10 -> 273954.61 | AA11: =EXP(-1*$P$12*V11^($P$11)) -> 6.6101454e-80 | AB11: =$P$12*$P$11*V11^($P$11-1) -> 0.064428841 | AC11: =1/AB11 -> 15.520999
A12: 8 | B12: 31.6075 | C12: =B12+C11 -> 349.97694 | D12: =LN($P$7/C12) -> 1.7228782 | E12: =$P$12*C12^$P$11 -> 11.069684 | O12: Lamda = | P12: =P6/P7^P11 -> 0.0085784961 | V12: =V11+250 -> 3710.0897 | W12: =$P$12*V12^($P$11) -> 198.55268 | X12: =W12-W11 -> 16.234475 | Y12: =X12*$AA$2 -> 48703.426 | Z12: =Y12+Z11 -> 322658.03 | AA12: =EXP(-1*$P$12*V12^($P$11)) -> 5.8839357e-87 | AB12: =$P$12*$P$11*V12^($P$11-1) -> 0.065437845 | AC12: =1/AB12 -> 15.281677
A13: 9 | B13: 52.954167 | C13: =B13+C12 -> 402.93111 | D13: =LN($P$7/C13) -> 1.5819799 | E13: =$P$12*C13^$P$11 -> 13.150945 | V13: =V12+250 -> 3960.0897 | W13: =$P$12*V13^($P$11) -> 215.03283 | X13: =W13-W12 -> 16.480155 | Y13: =X13*$AA$2 -> 49440.466 | Z13: =Y13+Z12 -> 372098.5 | AA13: =EXP(-1*$P$12*V13^($P$11)) -> 4.0966365e-94 | AB13: =$P$12*$P$11*V13^($P$11-1) -> 0.06639531 | AC13: =1/AB13 -> 15.061305
A14: 10 | B14: 8.2563889 | C14: =B14+C13 -> 411.1875 | D14: =LN($P$7/C14) -> 1.5616962 | E14: =$P$12*C14^$P$11 -> 13.481192 | N14: 2.- | O14: N° esperado de fallas: | V14: =V13+250 -> 4210.0897 | W14: =$P$12*V14^($P$11) -> 231.74651 | X14: =W14-W13 -> 16.713678 | Y14: =X14*$AA$2 -> 50141.034 | Z14: =Y14+Z13 -> 422239.53 | AA14: =EXP(-1*$P$12*V14^($P$11)) -> 2.2582356e-101 | AB14: =$P$12*$P$11*V14^($P$11-1) -> 0.067306887 | AC14: =1/AB14 -> 14.857321
A15: 11 | B15: 7.2477778 | C15: =B15+C14 -> 418.43528 | D15: =LN($P$7/C15) -> 1.5442233 | E15: =$P$12*C15^$P$11 -> 13.772317 | V15: =V14+250 -> 4460.0897 | W15: =$P$12*V15^($P$11) -> 248.68285 | X15: =W15-W14 -> 16.936338 | Y15: =X15*$AA$2 -> 50809.014 | Z15: =Y15+Z14 -> 473048.55 | AA15: =EXP(-1*$P$12*V15^($P$11)) -> 9.9634796e-109 | AB15: =$P$12*$P$11*V15^($P$11-1) -> 0.068177314 | AC15: =1/AB15 -> 14.667636
A16: 12 | B16: 0.16111111 | C16: =B16+C15 -> 418.59639 | D16: =LN($P$7/C16) -> 1.5438383 | E16: =$P$12*C16^$P$11 -> 13.778801 | V16: =V15+250 -> 4710.0897 | W16: =$P$12*V16^($P$11) -> 265.83207 | X16: =W16-W15 -> 17.149226 | Y16: =X16*$AA$2 -> 51447.678 | Z16: =Y16+Z15 -> 524496.22 | AA16: =EXP(-1*$P$12*V16^($P$11)) -> 3.5530127e-116 | AB16: =$P$12*$P$11*V16^($P$11-1) -> 0.069010608 | AC16: =1/AB16 -> 14.490526
A17: 13 | B17: 6.8577778 | C17: =B17+C16 -> 425.45417 | D17: =LN($P$7/C17) -> 1.5275883 | E17: =$P$12*C17^$P$11 -> 14.05532 | V17: =V16+250 -> 4960.0897 | W17: =$P$12*V17^($P$11) -> 283.18535 | X17: =W17-W16 -> 17.353271 | Y17: =X17*$AA$2 -> 52059.812 | Z17: =Y17+Z16 -> 576556.04 | AA17: =EXP(-1*$P$12*V17^($P$11)) -> 1.0331586e-123 | AB17: =$P$12*$P$11*V17^($P$11-1) -> 0.069810202 | AC17: =1/AB17 -> 14.324554
A18: 14 | B18: 5.19 | C18: =B18+C17 -> 430.64417 | D18: =LN($P$7/C18) -> 1.5154634 | E18: =$P$12*C18^$P$11 -> 14.265253 | N18: 3.- | O18: Predicción siguiente fallo futuro: | V18: =V17+250 -> 5210.0897 | W18: =$P$12*V18^($P$11) -> 300.73462 | X18: =W18-W17 -> 17.54927 | Y18: =X18*$AA$2 -> 52647.81 | Z18: =Y18+Z17 -> 629203.85 | AA18: =EXP(-1*$P$12*V18^($P$11)) -> 2.4695392e-131 | AB18: =$P$12*$P$11*V18^($P$11-1) -> 0.07057906 | AC18: =1/AB18 -> 14.168508
A19: 15 | B19: 6.8233333 | C19: =B19+C18 -> 437.4675 | D19: =LN($P$7/C19) -> 1.4997431 | E19: =$P$12*C19^$P$11 -> 14.542112 | O19: Ultima falla N = | P19: 91 | V19: =V18+250 -> 5460.0897 | W19: =$P$12*V19^($P$11) -> 318.47253 | X19: =W19-W18 -> 17.737914 | Y19: =X19*$AA$2 -> 53213.742 | Z19: =Y19+Z18 -> 682417.59 | AA19: =EXP(-1*$P$12*V19^($P$11)) -> 4.8880732e-139 | AB19: =$P$12*$P$11*V19^($P$11-1) -> 0.071319756 | AC19: =1/AB19 -> 14.02136
A20: 16 | B20: 0.88722222 | C20: =B20+C19 -> 438.35472 | D20: =LN($P$7/C20) -> 1.4977171 | E20: =$P$12*C20^$P$11 -> 14.578182 | O20: T92 = | P20: =(92/P12)^(1/P11) -> 1977.6877 | V20: =V19+250 -> 5710.0897 | W20: =$P$12*V20^($P$11) -> 336.39234 | X20: =W20-W19 -> 17.919806 | Y20: =X20*$AA$2 -> 53759.417 | Z20: =Y20+Z19 -> 736177.01 | AA20: =EXP(-1*$P$12*V20^($P$11)) -> 8.0661256e-147 | AB20: =$P$12*$P$11*V20^($P$11-1) -> 0.072034544 | AC20: =1/AB20 -> 13.882229
A21: 17 | B21: 1.9233333 | C21: =B21+C20 -> 440.27806 | D21: =LN($P$7/C21) -> 1.4933391 | E21: =$P$12*C21^$P$11 -> 14.656432 | O21: Delta t ultima falla | P21: =P20-P7 -> 17.598022 | V21: =V20+250 -> 5960.0897 | W21: =$P$12*V21^($P$11) -> 354.48781 | X21: =W21-W20 -> 18.095473 | Y21: =X21*$AA$2 -> 54286.419 | Z21: =Y21+Z20 -> 790463.43 | AA21: =EXP(-1*$P$12*V21^($P$11)) -> 1.1166083e-154 | AB21: =$P$12*$P$11*V21^($P$11-1) -> 0.072725407 | AC21: =1/AB21 -> 13.750353
A22: 18 | B22: 1.9927778 | C22: =B22+C21 -> 442.27083 | D22: =LN($P$7/C22) -> 1.4888231 | E22: =$P$12*C22^$P$11 -> 14.737587 | V22: =V21+250 -> 6210.0897 | W22: =$P$12*V22^($P$11) -> 372.75319 | X22: =W22-W21 -> 18.265383 | Y22: =X22*$AA$2 -> 54796.15 | Z22: =Y22+Z21 -> 845259.58 | AA22: =EXP(-1*$P$12*V22^($P$11)) -> 1.3042046e-162 | AB22: =$P$12*$P$11*V22^($P$11-1) -> 0.0733941 | AC22: =1/AB22 -> 13.625073
A23: 19 | B23: 9.8925 | C23: =B23+C22 -> 452.16333 | D23: =LN($P$7/C23) -> 1.4667021 | E23: =$P$12*C23^$P$11 -> 15.141656
A24: 20 | B24: 1.7955556 | C24: =B24+C23 -> 453.95889 | D24: =LN($P$7/C24) -> 1.4627389 | E24: =$P$12*C24^$P$11 -> 15.21521 | N24: 4.- | O24: Confiabilidad:
A25: 21 | B25: 9.6563889 | C25: =B25+C24 -> 463.61528 | D25: =LN($P$7/C25) -> 1.4416905 | E25: =$P$12*C25^$P$11 -> 15.611886
A26: 22 | B26: 24 | C26: =B26+C25 -> 487.61528 | D26: =LN($P$7/C26) -> 1.3912188 | E26: =$P$12*C26^$P$11 -> 16.605713 | V26: T | W26: Confiabilidad | X26: Rocof | Y26: MTBF | AF26: Nota: T = 0 es cuando comienza el análisi, inicio de los 3 meses.
A27: 23 | B27: 14.795278 | C27: =B27+C26 -> 502.41056 | D27: =LN($P$7/C27) -> 1.3613279 | E27: =$P$12*C27^$P$11 -> 17.223864 | V27: 0 | W27: =EXP(-1*$P$12*V27^($P$11)) -> 1 | X27: =$P$12*$P$11*V27^($P$11-1) -> 0
A28: 24 | B28: 1.7211111 | C28: =B28+C27 -> 504.13167 | D28: =LN($P$7/C28) -> 1.3579081 | E28: =$P$12*C28^$P$11 -> 17.296039 | V28: =V27+250 -> 250 | W28: =EXP(-1*$P$12*V28^($P$11)) -> 0.00065129045 | X28: =$P$12*$P$11*V28^($P$11-1) -> 0.035883088 | Y28: =1/X28 -> 27.868281
A29: 25 | B29: 8.3938889 | C29: =B29+C28 -> 512.52556 | D29: =LN($P$7/C29) -> 1.341395 | E29: =$P$12*C29^$P$11 -> 17.64882 | V29: =V28+250 -> 500 | W29: =EXP(-1*$P$12*V29^($P$11)) -> 3.6612696e-08 | X29: =$P$12*$P$11*V29^($P$11-1) -> 0.041873979 | Y29: =1/X29 -> 23.88118
A30: 26 | B30: 25.402778 | C30: =B30+C29 -> 537.92833 | D30: =LN($P$7/C30) -> 1.2930202 | E30: =$P$12*C30^$P$11 -> 18.724244 | V30: =V29+250 -> 750 | W30: =EXP(-1*$P$12*V30^($P$11)) -> 6.1816149e-13 | X30: =$P$12*$P$11*V30^($P$11-1) -> 0.045831972 | Y30: =1/X30 -> 21.81883
A31: 27 | B31: 6.1652778 | C31: =B31+C30 -> 544.09361 | D31: =LN($P$7/C31) -> 1.2816242 | E31: =$P$12*C31^$P$11 -> 18.986982 | G31: MTBF = | H31: 16 hrs (histórico 3 meses) | V31: =V30+250 -> 1000 | W31: =EXP(-1*$P$12*V31^($P$11)) -> 4.4073088e-18 | X31: =$P$12*$P$11*V31^($P$11-1) -> 0.048865083 | Y31: =1/X31 -> 20.46451
A32: 28 | B32: 0.58166667 | C32: =B32+C31 -> 544.67528 | D32: =LN($P$7/C32) -> 1.2805557 | E32: =$P$12*C32^$P$11 -> 19.011804 | V32: =V31+250 -> 1250 | W32: =EXP(-1*$P$12*V32^($P$11)) -> 1.5835208e-23 | X32: =$P$12*$P$11*V32^($P$11-1) -> 0.051355308 | Y32: =1/X32 -> 19.472184
A33: 29 | B33: 72.519167 | C33: =B33+C32 -> 617.19444 | D33: =LN($P$7/C33) -> 1.1555614 | E33: =$P$12*C33^$P$11 -> 22.151315 | G33: Test de Tendencia de Laplace | V33: =V32+250 -> 1500 | W33: =EXP(-1*$P$12*V33^($P$11)) -> 3.202659e-29 | X33: =$P$12*$P$11*V33^($P$11-1) -> 0.053483887 | Y33: =1/X33 -> 18.69722
A34: 30 | B34: 19.283333 | C34: =B34+C33 -> 636.47778 | D34: =LN($P$7/C34) -> 1.124796 | E34: =$P$12*C34^$P$11 -> 23.000483 | V34: =V33+250 -> 1750 | W34: =EXP(-1*$P$12*V34^($P$11)) -> 3.9365787e-35 | X34: =$P$12*$P$11*V34^($P$11-1) -> 0.055352259 | Y34: =1/X34 -> 18.06611
A35: 31 | B35: 76.417778 | C35: =B35+C34 -> 712.89556 | D35: =LN($P$7/C35) -> 1.0114106 | E35: =$P$12*C35^$P$11 -> 26.42095 | G35: Suma ti = | H35: =SUM(C5:C95) -> 96975.201 | V35: =V34+250 -> 2000 | W35: =EXP(-1*$P$12*V35^($P$11)) -> 3.1119631e-41 | X35: =$P$12*$P$11*V35^($P$11-1) -> 0.057023393 | Y35: =1/X35 -> 17.536663
A36: 32 | B36: 107.25139 | C36: =B36+C35 -> 820.14694 | D36: =LN($P$7/C36) -> 0.871262 | E36: =$P$12*C36^$P$11 -> 31.35971 | G36: n = | H36: 91 | V36: =V35+250 -> 2250 | W36: =EXP(-1*$P$12*V36^($P$11)) -> 1.6529168e-47 | X36: =$P$12*$P$11*V36^($P$11-1) -> 0.058539267 | Y36: =1/X36 -> 17.082551
A37: 33 | B37: 12.370833 | C37: =B37+C36 -> 832.51778 | D37: =LN($P$7/C37) -> 0.85629095 | E37: =$P$12*C37^$P$11 -> 31.939063 | G37: to = | H37: =C95 -> 1960.0897 | V37: =V36+250 -> 2500 | W37: =EXP(-1*$P$12*V37^($P$11)) -> 6.1085269e-54 | X37: =$P$12*$P$11*V37^($P$11-1) -> 0.059929376 | Y37: =1/X37 -> 16.686308
A38: 34 | B38: 18.006667 | C38: =B38+C37 -> 850.52444 | D38: =LN($P$7/C38) -> 0.83489238 | E38: =$P$12*C38^$P$11 -> 32.785781 | V38: =V37+250 -> 2750 | W38: =EXP(-1*$P$12*V38^($P$11)) -> 1.6162806e-60 | X38: =$P$12*$P$11*V38^($P$11-1) -> 0.061215299 | Y38: =1/X38 -> 16.335786
A39: 35 | B39: 13.276389 | C39: =B39+C38 -> 863.80083 | D39: =LN($P$7/C39) -> 0.8194033 | E39: =$P$12*C39^$P$11 -> 33.412636 | G39: U = | H39: =(H35/H36-H37/2)/(H37*SQRT(1/(12*H36))) -> 1.4434235 | V39: =V38+250 -> 3000 | W39: =EXP(-1*$P$12*V39^($P$11)) -> 3.1360265e-67 | X39: =$P$12*$P$11*V39^($P$11-1) -> 0.062413333 | Y39: =1/X39 -> 16.022218
A40: 36 | B40: 16.411389 | C40: =B40+C39 -> 880.21222 | D40: =LN($P$7/C40) -> 0.80058249 | E40: =$P$12*C40^$P$11 -> 34.190482 | V40: =V39+250 -> 3250 | W40: =EXP(-1*$P$12*V40^($P$11)) -> 4.5535932e-74 | X40: =$P$12*$P$11*V40^($P$11-1) -> 0.063536111 | Y40: =1/X40 -> 15.739081
A41: 37 | B41: 33.766111 | C41: =B41+C40 -> 913.97833 | D41: =LN($P$7/C41) -> 0.76293866 | E41: =$P$12*C41^$P$11 -> 35.801017 | G41: Nivel de significancia: | V41: =V40+250 -> 3500 | W41: =EXP(-1*$P$12*V41^($P$11)) -> 5.0355578e-81 | X41: =$P$12*$P$11*V41^($P$11-1) -> 0.064593641 | Y41: =1/X41 -> 15.4814
...
