Workbook

Sheet ANALISIS RIESGOS
A1: MATRIZ DE RIESGOS Y OPORTUNIDADES
A3: Ítem | B3: Identificación | C3: ESPECIALIDAD | D3: Análisis | E3: Rubro | F3: Gravedad | G3: Monto S/. | H3: Amenazas | I3: Oportunidad | J3: Observaciones | K3: ESTATUS RO | L3: Responsable | M3: Soluciones
A4: 01 | B4: Debido a la modalidad del contrato (suma alzada): se tenga que ejecutar mayores prestaciones adicionales sin que necesariamente sean reconocidos por la Entidad. Mov. De Tierras | C4: MOV. DE TIERRAS | D4: Gestionar ante la Entidad adicionales y deductivos vinculantes, no obstante sean rechazados se deberá dejar antecedes para un posterior reconocimiento mediante la via que corresponda. | E4: METRADO | F4: MUY BAJA | G4: 15000 | H4: =+IF(G4>0,G4,0) -> 15000 | J4: Costo total que se podria presentar en cualquier momento | K4: No Considerado en RO | L4: Obra | M4: Elaboración del presupuesto compromiso con metrados reales lo que permitirá determinar la brecha entre lo considerado en el Expediente Técnico y lo realmente a ejecutar. | AE4: ALTA
A5: =+A4+1 -> 2 | B5: Debido a la modalidad del contrato (suma alzada): se tenga que ejecutar mayores prestaciones adicionales sin que necesariamente sean reconocidos por la Entidad. Estructuras | C5: ESTRUCTURAS | D5: Gestionar ante la Entidad adicionales y deductivos vinculantes, no obstante sean rechazados se deberá dejar antecedes para un posterior reconocimiento mediante la via que corresponda. | E5: METRADO | F5: MUY BAJA | G5: 25000 | H5: =+IF(G5>0,G5,0) -> 25000 | J5: Costo total que se podria presentar en cualquier momento | K5: No Considerado en RO | L5: Obra | M5: Elaboración del presupuesto compromiso con metrados reales lo que permitirá determinar la brecha entre lo considerado en el Expediente Técnico y lo realmente a ejecutar. | AE5: ALTA
A6: =+A5+1 -> 3 | B6: Adecuaciones | C6: GG | D6: Adecuaciones de instalaciones de obra. | E6: EXTERNO | F6: ALTA | G6: 5000 | H6: =+IF(G6>0,G6,0) -> 5000 | J6: Costo mensual que se podria considerar en el mes de octubre y noviembre | K6: Costo Considerado en RO | L6: Área legal | M6: Se solicita apoyo al área legal
A7: =+A6+1 -> 4 | B7: Paralizaciones varias,: gremios sindicales, paro de transportistas, etc. | C7: GG | D7: Costos Stand by asociados a paralizaciones | E7: EXTERNO | F7: MUY BAJA | G7: 5000 | H7: =+IF(G7>0,G7,0) -> 5000 | J7: Costo mensual que se podria presentar en cada mes de la obra | K7: No Considerado en RO | L7: Externo | M7: Se realizará una contingencia ante estos eventos días antes. Envío de comunicación ante la entidad comunicando evento.
A8: =+A7+1 -> 5 | B8: Alquiler de GE para suministro de energía de obra | C8: ELÉCTRICAS | D8: Se puede dar si se corta la Energia Eléctrica | E8: EXTERNO | F8: ALTA | G8: 3000 | H8: =+IF(G8>0,G8,0) -> 3000 | J8: Costo mensual de combustible y alquiler de GE por si se corta la energia electrica | K8: No Considerado en RO | L8: Area Legal | M8: Enviar costo de adicional a Entidad. Revisar contingencia de órganos de control de contratos, de revisar GE defintivos de acuerdo a rpta de entidad.
A9: =+A8+1 -> 6 | B9: Sobre costo de Agregados (Estructuras) | C9: ESTRUCTURAS | D9: Podria darse debido a la inaccesibilidad de la cantera actual por lluvias | E9: EXTERNO | F9: MUY BAJA | H9: =+IF(G9>0,G9,0) -> 0 | J9: Suministro de agregados en el mes de septiembre, podría ser un 20% al estimado inciialmente debido a la lejanía de las canteras | K9: No Considerado en RO | L9: Obra | M9: Encontrar proveedores con lleguen al costo considerando viaje puesto en obra.
A10: =+A9+1 -> 7 | F10: MUY BAJA | H10: =+IF(G10>0,G10,0) -> 0
A11: =+A10+1 -> 8 | F11: MUY BAJA | H11: =+IF(G11>0,G11,0) -> 0
G12: =SUM(G4:G11) -> 53000 | H12: =SUM(H4:H11) -> 53000 | I12: =SUM(I4:I11) -> 0
B19: Etiquetas de fila | C19: Suma de Amenazas | D19: Suma de Oportunidad
B20: METRADO | C20: 0
B21: PANDEMIA | C21: 0 | D21: 1958414.8
B22: PLAZO | D22: 3779808.1
B23: ALCANCE | C23: -7095143.5 | D23: 681215.99
B24: EXTERNO | C24: -210000
B25: SUPERVISION | C25: -1514650 | D25: 20586
B26: CONTRATO | C26: 0
B27: ENTIDAD | C27: -1087010.2
B28: INGENIERIA | C28: -3582801.2 | D28: 0
B29: Total general | C29: -13489605 | D29: 6440024.9

Sheet PRESUPUESTOS
A1: ANALISIS DE PRESUPUESTOS
A3: PROYECTO: | B3: I.E. N° 1182 "EL BOSQUE" - CERCO + INGRESOS Y CASETAS
A5: PC | B5: ITEM | C5: DESCRIPCION | D5: UND | E5: CONTRACTUAL - VENTA | I5: META INICIAL -MES ANTERIOR | M5: META ACTUALIZADO
E6: METRADO | F6: P.U. (S/.) | G6: PARCIAL (S/.) | I6: METRADO | J6: P.U. (S/.) | K6: PARCIAL (S/.) | M6: METRADO | N6: P.U. (S/.) | O6: MANO DE OBRA | P6: MATERIALES | Q6: EQUIPOS | R6: SERVICIOS | S6: SUBCONTRATOS | T6: PARCIAL (S/.)
B7: 01 | C7: OBRAS PROVISIONALES, TRABAJOS PRELIMINARES, SEGURIDAD Y SALUD
B8: 01.02 | C8: Trabajos Preliminares
B9: 01.02.04 | C9: Trazo, Niveles y Replanteo
A10: 100 | B10: 01.02.04.01 | C10: TRAZO Y REPLANTEO PRELIMINAR | D10: M2 | E10: 897.34 | F10: 2.04 | G10: =ROUND(E10*F10,2) -> 1830.57 | I10: 942.21 | J10: 1.33 | K10: =ROUND(I10*J10,2) -> 1253.14 | M10: 942.21 | N10: =SUM(O10:S10) -> 1.33 | O10: 1.03 | Q10: 0.3 | T10: =ROUND(M10*N10,2) -> 1253.14
A11: 100 | B11: 01.02.04.02 | C11: TRAZO Y REPLANTEO DURANTE EL PROCESO | D11: m2 | E11: 897.34 | F11: 2.04 | G11: =ROUND(E11*F11,2) -> 1830.57 | I11: 942.21 | J11: 1.33 | K11: =ROUND(I11*J11,2) -> 1253.14 | M11: 942.21 | N11: =SUM(O11:S11) -> 1.33 | O11: 1.03 | Q11: 0.3 | T11: =ROUND(M11*N11,2) -> 1253.14
B12: 02 | C12: ESTRUCTURAS | T12: =ROUND(M12*N12,2) -> 0
B13: 02.01 | C13: Movimiento de Tierras | T13: =ROUND(M13*N13,2) -> 0
B14: 02.01.01 | C14: Excavaciones | T14: =ROUND(M14*N14,2) -> 0
A15: 200 | B15: 02.01.01.01 | C15: EXCAV.ZANJAS Y ZAPATA RT>2kg/cm2 H=1.5m | D15: m3 | E15: 41.9 | F15: 46.74 | G15: =ROUND(E15*F15,2) -> 1958.41 | I15: 39.81 | J15: 29.22 | K15: =ROUND(I15*J15,2) -> 1163.25 | M15: 39.81 | N15: =SUM(O15:S15) -> 29.22 | O15: 10.22 | S15: 19 | T15: =ROUND(M15*N15,2) -> 1163.25
A16: 200 | B16: 02.01.01.02 | C16: EXCAV.ZANJAS Y ZAPATA RT>2kg/cm2 H=2.0m | D16: m3 | E16: 1975.16 | F16: 50.99 | G16: =ROUND(E16*F16,2) -> 100713.41 | I16: 1876.4 | J16: 33.36 | K16: =ROUND(I16*J16,2) -> 62596.7 | M16: 1876.4 | N16: =SUM(O16:S16) -> 33.36 | O16: 12.26 | S16: 21.1 | T16: =ROUND(M16*N16,2) -> 62596.7
B17: 02.01.03 | C17: Rellenos | T17: =ROUND(M17*N17,2) -> 0
A18: 200 | B18: 02.01.03.01 | C18: RELLENO COMPACTADO C/EQUIPO MAT/PROPIO | D18: m3 | E18: 1197.91 | F18: 26.01 | G18: =ROUND(E18*F18,2) -> 31157.64 | I18: 1138.01 | J18: 15 | K18: =ROUND(I18*J18,2) -> 17070.15 | M18: 1138.01 | N18: =SUM(O18:S18) -> 15 | S18: 15 | T18: =ROUND(M18*N18,2) -> 17070.15
B19: 02.01.04 | C19: Eliminacion de Material Excedente | T19: =ROUND(M19*N19,2) -> 0
A20: 200 | B20: 02.01.04.01 | C20: ACARREO INTERNO, MATERIAL PROCEDENTE DE EXCAVACIONES | D20: m3 | E20: 68.91 | F20: 17.53 | G20: =ROUND(E20*F20,2) -> 1207.99 | T20: =ROUND(M20*N20,2) -> 0
A21: 200 | B21: 02.01.04.02 | C21: ELIMINACION MATERIAL EXCEDENTE ACARREADO | D21: M3 | E21: 68.91 | F21: 16.02 | G21: =ROUND(E21*F21,2) -> 1103.94 | T21: =ROUND(M21*N21,2) -> 0
A22: 200 | B22: 02.01.04.03 | C22: ELIMINACION MATERIAL EXCEDENTE C/MAQUINA | D22: m3 | E22: 995.9 | F22: 21.84 | G22: =ROUND(E22*F22,2) -> 21750.46 | I22: 1118.06 | J22: 18.27 | K22: =ROUND(I22*J22,2) -> 20426.96 | M22: 1118.06 | N22: =SUM(O22:S22) -> 18.27 | S22: 18.27 | T22: =ROUND(M22*N22,2) -> 20426.96
B23: 02.01.05 | C23: Nivelacion Interior y Apisonado | T23: =ROUND(M23*N23,2) -> 0
A24: 200 | B24: 02.01.05.01 | C24: ESCARIFICADO Y COMPACTACION CON PLANCHA COMPACTADORA e = 30 cm | D24: m2 | E24: 68.95 | F24: 4.72 | G24: =ROUND(E24*F24,2) -> 325.44 | I24: 70.33 | J24: 4.36 | K24: =ROUND(I24*J24,2) -> 306.64 | M24: 70.33 | N24: =SUM(O24:S24) -> 4.36 | O24: 2.39 | Q24: 1.97 | T24: =ROUND(M24*N24,2) -> 306.64
A25: 200 | B25: 02.01.05.02 | C25: ESCARIFICADO Y COMPACTACION CON PLANCHA COMPACTADORA H=0.60m (02 CAPAS 30cm c/u) | D25: m2 | E25: 8.56 | F25: 7.85 | G25: =ROUND(E25*F25,2) -> 67.2 | I25: 8.73 | J25: 7.37 | K25: =ROUND(I25*J25,2) -> 64.34 | M25: 8.73 | N25: =SUM(O25:S25) -> 7.37 | O25: 4.04 | Q25: 3.33 | T25: =ROUND(M25*N25,2) -> 64.34
A26: 200 | B26: 02.01.05.05 | C26: AFIRMADO DE 8" PARA PISOS,PATIOS Y VEREDAS,COMPACTADO. | D26: m2 | E26: 68.95 | F26: 15.19 | G26: =ROUND(E26*F26,2) -> 1047.35 | I26: 70.33 | J26: 11.5 | K26: =ROUND(I26*J26,2) -> 808.8 | M26: 70.33 | N26: =SUM(O26:S26) -> 11.5 | S26: 11.5 | T26: =ROUND(M26*N26,2) -> 808.8
A27: 200 | B27: 02.01.05.06 | C27: AFIRMADO DE 12" EN PISOS INTERIOR/EXTERIOR,COMPACTADO. | D27: m2 | E27: 8.56 | F27: 21.79 | G27: =ROUND(E27*F27,2) -> 186.52 | I27: 8.73 | J27: 14.5 | K27: =ROUND(I27*J27,2) -> 126.59 | M27: 8.73 | N27: =SUM(O27:S27) -> 14.5 | S27: 14.5 | T27: =ROUND(M27*N27,2) -> 126.59
B28: 02.02 | C28: Obras de Concreto Simple | T28: =ROUND(M28*N28,2) -> 0
B29: 02.02.01 | C29: Falsos Cimientos | T29: =ROUND(M29*N29,2) -> 0
A30: 300 | B30: 02.02.01.01 | C30: SUBCIMIENTO, SUBZAPATA MEZCLA 1:12 + 30 % P.G. | D30: m3 | E30: 323.69 | F30: 173.72 | G30: =ROUND(E30*F30,2) -> 56231.43 | I30: 330.16 | J30: 184.1 | K30: =ROUND(I30*J30,2) -> 60782.46 | M30: 330.16 | N30: =SUM(O30:S30) -> 184.1 | O30: 23.88 | P30: 17.82 | Q30: 0.72 | S30: 141.68 | T30: =ROUND(M30*N30,2) -> 60782.46
B31: 02.02.02 | C31: Cimientos | T31: =ROUND(M31*N31,2) -> 0
A32: 300 | B32: 02.02.02.02 | C32: CIMIENTOS CORRIDOS 1:10 + 30 % P.G. f'c >=100Kg/cm2 | D32: m3 | E32: 24.73 | F32: 179.78 | G32: =ROUND(E32*F32,2) -> 4445.96 | I32: 24.24 | J32: 182.46 | K32: =ROUND(I32*J32,2) -> 4422.83 | M32: 24.24 | N32: =SUM(O32:S32) -> 182.46 | O32: 22.29 | P32: 17.82 | Q32: 0.67 | S32: 141.68 | T32: =ROUND(M32*N32,2) -> 4422.83
A33: 400 | B33: 02.02.02.03 | C33: CIMIENTO CORRIDO - ENCOFRADO Y DESENCOFRADO | D33: m2 | E33: 23.09 | F33: 46.17 | G33: =ROUND(E33*F33,2) -> 1066.07 | I33: 22.63 | J33: 23.83 | K33: =ROUND(I33*J33,2) -> 539.27 | M33: 22.63 | N33: =SUM(O33:S33) -> 23.83 | O33: 16.71 | P33: 6.62 | Q33: 0.5 | T33: =ROUND(M33*N33,2) -> 539.27
A34: 300 | B34: 02.02.02.04 | C34: CALZADURA: CONCRETO C:H 1:10 + 30 % P.G. | D34: m3 | E34: 163.82 | F34: 179.78 | G34: =ROUND(E34*F34,2) -> 29451.56 | I34: 160.54 | J34: 207.85 | K34: =ROUND(I34*J34,2) -> 33368.24 | M34: 160.54 | N34: =SUM(O34:S34) -> 207.85 | O34: 42.36 | P34: 17.82 | Q34: 5.99 | S34: 141.68 | T34: =ROUND(M34*N34,2) -> 33368.24
A35: 400 | B35: 02.02.02.05 | C35: CALZADURA: ENCOFRADO Y DESENCOFRADO | D35: m2 | E35: 327.63 | F35: 37.47 | G35: =ROUND(E35*F35,2) -> 12276.3 | I35: 321.08 | J35: 26.53 | K35: =ROUND(I35*J35,2) -> 8518.25 | M35: 321.08 | N35: =SUM(O35:S35) -> 26.53 | O35: 20.06 | P35: 5.87 | Q35: 0.6 | T35: =ROUND(M35*N35,2) -> 8518.25
B36: 02.02.03 | C36: Sobrecimientos | T36: =ROUND(M36*N36,2) -> 0
A37: 300 | B37: 02.02.03.01 | C37: SOBRECIMIENTO, CONCRETO 1:8 + 25% P.M. f'c >=100Kg/cm2 | D37: m3 | E37: 3.21 | F37: 260.59 | G37: =ROUND(E37*F37,2) -> 836.49 | I37: 3.15 | J37: 201.22 | K37: =ROUND(I37*J37,2) -> 633.84 | M37: 3.15 | N37: =SUM(O37:S37) -> 201.22 | O37: 30.77 | P37: 14.58 | Q37: 4.07 | S37: 151.8 | T37: =ROUND(M37*N37,2) -> 633.84
A38: 400 | B38: 02.02.03.02 | C38: SOBRECIMIENTO, ENCOFRADO Y DESENCOFRADO | D38: m2 | E38: 43.95 | F38: 37.7 | G38: =ROUND(E38*F38,2) -> 1656.92 | I38: 43.07 | J38: 24.18 | K38: =ROUND(I38*J38,2) -> 1041.43 | M38: 43.07 | N38: =SUM(O38:S38) -> 24.18 | O38: 17.22 | P38: 6.44 | Q38: 0.52 | T38: =ROUND(M38*N38,2) -> 1041.43
B39: 02.03 | C39: Obras de Concreto Armado | T39: =ROUND(M39*N39,2) -> 0
B40: 02.03.02 | C40: Zapatas | T40: =ROUND(M40*N40,2) -> 0
A41: 300 | B41: 02.03.02.01 | C41: ZAPATAS.- CONCRETO 210 kg/cm2 | D41: m3 | E41: 396.75 | F41: 292.79 | G41: =ROUND(E41*F41,2) -> 116164.43 | I41: 412.62 | J41: 286.6 | K41: =ROUND(I41*J41,2) -> 118256.89 | M41: 412.62 | N41: =SUM(O41:S41) -> 286.6 | O41: 30.77 | Q41: 2.49 | S41: 253.34 | T41: =ROUND(M41*N41,2) -> 118256.89
A42: 500 | B42: 02.03.02.03 | C42: ZAPATAS.- ACERO Fy=4200 kg/cm2 | D42: KG | E42: 17534.91 | F42: 4.02 | G42: =ROUND(E42*F42,2) -> 70490.34 | I42: 17359.56 | J42: 3.4 | K42: =ROUND(I42*J42,2) -> 59022.5 | M42: 17359.56 | N42: =SUM(O42:S42) -> 3.4 | P42: 2.66 | S42: 0.74 | T42: =ROUND(M42*N42,2) -> 59022.5
...

Sheet COSTO DIRECTO
A1: ANALISIS DE AVANCE
A3: PROYECTO: | B3: I.E. N° 1182 "EL BOSQUE" - CERCO + INGRESOS Y CASETAS
E4: ANALISIS DE PRECIOS VENTA | L4: COSTO PREVISTO
A5: PC | B5: ITEM | C5: DESCRIPCION | D5: UND | E5: CONTRACTUAL | F5: VENTA ACTUAL | H5: VENTA PENDIENTE | J5: VENTA TOTAL | L5: PREVISTO | M5: PREVISTO ACTUAL | O5: PREVISTO PENDIENTE | Q5: PREVISTO TOTAL
E6: P.U. (S/.) | F6: METRADO EJECUTADO | G6: PARCIAL (S/.) | H6: METRADO POR EJECUT | I6: PARCIAL (S/.) | J6: METRADO CONTRATO | K6: PARCIAL (S/.) | L6: P.U. (S/.) | M6: METRADO EJECUTADO REAL | N6: PARCIAL (S/.) | O6: METRADO POR EJECUT | P6: PARCIAL (S/.) | Q6: METRADO TOTAL REAL | R6: PARCIAL (S/.)
B7: 01 | C7: OBRAS PROVISIONALES, TRABAJOS PRELIMINARES, SEGURIDAD Y SALUD
B8: 01.02 | C8: Trabajos Preliminares
B9: 01.02.04 | C9: Trazo, Niveles y Replanteo
A10: 100 | B10: 01.02.04.01 | C10: TRAZO Y REPLANTEO PRELIMINAR | D10: M2 | E10: =PRESUPUESTOS!F10 -> 2.04 | F10: =IF(Q10=0,0,((M10/Q10)*J10)) -> 0 | G10: =ROUND(E10*F10,2) -> 0 | H10: =J10-F10 -> 897.34 | I10: =ROUND(E10*H10,2) -> 1830.57 | J10: =PRESUPUESTOS!E10 -> 897.34 | K10: =ROUND(E10*J10,2) -> 1830.57 | L10: =PRESUPUESTOS!N10 -> 1.33 | M10: 0 | N10: =ROUND(M10*L10,2) -> 0 | O10: =Q10-M10 -> 942.21 | P10: =ROUND(O10*L10,2) -> 1253.14 | Q10: =PRESUPUESTOS!M10 -> 942.21 | R10: =ROUND(Q10*L10,2) -> 1253.14
A11: 100 | B11: 01.02.04.02 | C11: TRAZO Y REPLANTEO DURANTE EL PROCESO | D11: m2 | E11: =PRESUPUESTOS!F11 -> 2.04 | F11: =IF(Q11=0,0,((M11/Q11)*J11)) -> 224.335 | G11: =ROUND(E11*F11,2) -> 457.64 | H11: =J11-F11 -> 673.005 | I11: =ROUND(E11*H11,2) -> 1372.93 | J11: =PRESUPUESTOS!E11 -> 897.34 | K11: =ROUND(E11*J11,2) -> 1830.57 | L11: =PRESUPUESTOS!N11 -> 1.33 | M11: 235.5525 | N11: =ROUND(M11*L11,2) -> 313.28 | O11: =Q11-M11 -> 706.6575 | P11: =ROUND(O11*L11,2) -> 939.85 | Q11: =PRESUPUESTOS!M11 -> 942.21 | R11: =ROUND(Q11*L11,2) -> 1253.14
B12: 02 | C12: ESTRUCTURAS
B13: 02.01 | C13: Movimiento de Tierras
B14: 02.01.01 | C14: Excavaciones
A15: 200 | B15: 02.01.01.01 | C15: EXCAV.ZANJAS Y ZAPATA RT>2kg/cm2 H=1.5m | D15: m3 | E15: =PRESUPUESTOS!F15 -> 46.74 | F15: =IF(Q15=0,0,((M15/Q15)*J15)) -> 0 | G15: =ROUND(E15*F15,2) -> 0 | H15: =J15-F15 -> 41.9 | I15: =ROUND(E15*H15,2) -> 1958.41 | J15: =PRESUPUESTOS!E15 -> 41.9 | K15: =ROUND(E15*J15,2) -> 1958.41 | L15: =PRESUPUESTOS!N15 -> 29.22 | M15: 0 | N15: =ROUND(M15*L15,2) -> 0 | O15: =Q15-M15 -> 39.81 | P15: =ROUND(O15*L15,2) -> 1163.25 | Q15: =PRESUPUESTOS!M15 -> 39.81 | R15: =ROUND(Q15*L15,2) -> 1163.25
A16: 200 | B16: 02.01.01.02 | C16: EXCAV.ZANJAS Y ZAPATA RT>2kg/cm2 H=2.0m | D16: m3 | E16: =PRESUPUESTOS!F16 -> 50.99 | F16: =IF(Q16=0,0,((M16/Q16)*J16)) -> 0 | G16: =ROUND(E16*F16,2) -> 0 | H16: =J16-F16 -> 1975.16 | I16: =ROUND(E16*H16,2) -> 100713.41 | J16: =PRESUPUESTOS!E16 -> 1975.16 | K16: =ROUND(E16*J16,2) -> 100713.41 | L16: =PRESUPUESTOS!N16 -> 33.36 | M16: 0 | N16: =ROUND(M16*L16,2) -> 0 | O16: =Q16-M16 -> 1876.4 | P16: =ROUND(O16*L16,2) -> 62596.7 | Q16: =PRESUPUESTOS!M16 -> 1876.4 | R16: =ROUND(Q16*L16,2) -> 62596.7
B17: 02.01.03 | C17: Rellenos
A18: 200 | B18: 02.01.03.01 | C18: RELLENO COMPACTADO C/EQUIPO MAT/PROPIO | D18: m3 | E18: =PRESUPUESTOS!F18 -> 26.01 | F18: =IF(Q18=0,0,((M18/Q18)*J18)) -> 838.537 | G18: =ROUND(E18*F18,2) -> 21810.35 | H18: =J18-F18 -> 359.373 | I18: =ROUND(E18*H18,2) -> 9347.29 | J18: =PRESUPUESTOS!E18 -> 1197.91 | K18: =ROUND(E18*J18,2) -> 31157.64 | L18: =PRESUPUESTOS!N18 -> 15 | M18: 796.607 | N18: =ROUND(M18*L18,2) -> 11949.11 | O18: =Q18-M18 -> 341.403 | P18: =ROUND(O18*L18,2) -> 5121.05 | Q18: =PRESUPUESTOS!M18 -> 1138.01 | R18: =ROUND(Q18*L18,2) -> 17070.15
B19: 02.01.04 | C19: Eliminacion de Material Excedente
A20: 200 | B20: 02.01.04.01 | C20: ACARREO INTERNO, MATERIAL PROCEDENTE DE EXCAVACIONES | D20: m3 | E20: =PRESUPUESTOS!F20 -> 17.53 | F20: =IF(Q20=0,0,((M20/Q20)*J20)) -> 0 | G20: =ROUND(E20*F20,2) -> 0 | H20: =J20-F20 -> 68.91 | I20: =ROUND(E20*H20,2) -> 1207.99 | J20: =PRESUPUESTOS!E20 -> 68.91 | K20: =ROUND(E20*J20,2) -> 1207.99 | L20: =PRESUPUESTOS!N20 -> 0 | M20: 0 | N20: =ROUND(M20*L20,2) -> 0 | O20: =Q20-M20 -> 0 | P20: =ROUND(O20*L20,2) -> 0 | Q20: =PRESUPUESTOS!M20 -> 0 | R20: =ROUND(Q20*L20,2) -> 0
A21: 200 | B21: 02.01.04.02 | C21: ELIMINACION MATERIAL EXCEDENTE ACARREADO | D21: M3 | E21: =PRESUPUESTOS!F21 -> 16.02 | F21: =IF(Q21=0,0,((M21/Q21)*J21)) -> 0 | G21: =ROUND(E21*F21,2) -> 0 | H21: =J21-F21 -> 68.91 | I21: =ROUND(E21*H21,2) -> 1103.94 | J21: =PRESUPUESTOS!E21 -> 68.91 | K21: =ROUND(E21*J21,2) -> 1103.94 | L21: =PRESUPUESTOS!N21 -> 0 | M21: 0 | N21: =ROUND(M21*L21,2) -> 0 | O21: =Q21-M21 -> 0 | P21: =ROUND(O21*L21,2) -> 0 | Q21: =PRESUPUESTOS!M21 -> 0 | R21: =ROUND(Q21*L21,2) -> 0
A22: 200 | B22: 02.01.04.03 | C22: ELIMINACION MATERIAL EXCEDENTE C/MAQUINA | D22: m3 | E22: =PRESUPUESTOS!F22 -> 21.84 | F22: =IF(Q22=0,0,((M22/Q22)*J22)) -> 0 | G22: =ROUND(E22*F22,2) -> 0 | H22: =J22-F22 -> 995.9 | I22: =ROUND(E22*H22,2) -> 21750.46 | J22: =PRESUPUESTOS!E22 -> 995.9 | K22: =ROUND(E22*J22,2) -> 21750.46 | L22: =PRESUPUESTOS!N22 -> 18.27 | M22: 0 | N22: =ROUND(M22*L22,2) -> 0 | O22: =Q22-M22 -> 1118.06 | P22: =ROUND(O22*L22,2) -> 20426.96 | Q22: =PRESUPUESTOS!M22 -> 1118.06 | R22: =ROUND(Q22*L22,2) -> 20426.96
B23: 02.01.05 | C23: Nivelacion Interior y Apisonado | E23: =PRESUPUESTOS!F23 -> 0 | F23: =IF(Q23=0,0,((M23/Q23)*J23)) -> 0 | G23: =ROUND(E23*F23,2) -> 0 | H23: =J23-F23 -> 0 | I23: =ROUND(E23*H23,2) -> 0 | J23: =PRESUPUESTOS!E23 -> 0 | K23: =ROUND(E23*J23,2) -> 0 | L23: =PRESUPUESTOS!N23 -> 0 | N23: =ROUND(M23*L23,2) -> 0 | O23: =Q23-M23 -> 0 | P23: =ROUND(O23*L23,2) -> 0 | Q23: =PRESUPUESTOS!M23 -> 0 | R23: =ROUND(Q23*L23,2) -> 0
A24: 200 | B24: 02.01.05.01 | C24: ESCARIFICADO Y COMPACTACION CON PLANCHA COMPACTADORA e = 30 cm | D24: m2 | E24: =PRESUPUESTOS!F24 -> 4.72 | F24: =IF(Q24=0,0,((M24/Q24)*J24)) -> 0 | G24: =ROUND(E24*F24,2) -> 0 | H24: =J24-F24 -> 68.95 | I24: =ROUND(E24*H24,2) -> 325.44 | J24: =PRESUPUESTOS!E24 -> 68.95 | K24: =ROUND(E24*J24,2) -> 325.44 | L24: =PRESUPUESTOS!N24 -> 4.36 | M24: 0 | N24: =ROUND(M24*L24,2) -> 0 | O24: =Q24-M24 -> 70.33 | P24: =ROUND(O24*L24,2) -> 306.64 | Q24: =PRESUPUESTOS!M24 -> 70.33 | R24: =ROUND(Q24*L24,2) -> 306.64
A25: 200 | B25: 02.01.05.02 | C25: ESCARIFICADO Y COMPACTACION CON PLANCHA COMPACTADORA H=0.60m (02 CAPAS 30cm c/u) | D25: m2 | E25: =PRESUPUESTOS!F25 -> 7.85 | F25: =IF(Q25=0,0,((M25/Q25)*J25)) -> 5.136 | G25: =ROUND(E25*F25,2) -> 40.32 | H25: =J25-F25 -> 3.424 | I25: =ROUND(E25*H25,2) -> 26.88 | J25: =PRESUPUESTOS!E25 -> 8.56 | K25: =ROUND(E25*J25,2) -> 67.2 | L25: =PRESUPUESTOS!N25 -> 7.37 | M25: 5.238 | N25: =ROUND(M25*L25,2) -> 38.6 | O25: =Q25-M25 -> 3.492 | P25: =ROUND(O25*L25,2) -> 25.74 | Q25: =PRESUPUESTOS!M25 -> 8.73 | R25: =ROUND(Q25*L25,2) -> 64.34
A26: 200 | B26: 02.01.05.05 | C26: AFIRMADO DE 8" PARA PISOS,PATIOS Y VEREDAS,COMPACTADO. | D26: m2 | E26: =PRESUPUESTOS!F26 -> 15.19 | F26: =IF(Q26=0,0,((M26/Q26)*J26)) -> 0 | G26: =ROUND(E26*F26,2) -> 0 | H26: =J26-F26 -> 68.95 | I26: =ROUND(E26*H26,2) -> 1047.35 | J26: =PRESUPUESTOS!E26 -> 68.95 | K26: =ROUND(E26*J26,2) -> 1047.35 | L26: =PRESUPUESTOS!N26 -> 11.5 | M26: 0 | N26: =ROUND(M26*L26,2) -> 0 | O26: =Q26-M26 -> 70.33 | P26: =ROUND(O26*L26,2) -> 808.8 | Q26: =PRESUPUESTOS!M26 -> 70.33 | R26: =ROUND(Q26*L26,2) -> 808.8
A27: 200 | B27: 02.01.05.06 | C27: AFIRMADO DE 12" EN PISOS INTERIOR/EXTERIOR,COMPACTADO. | D27: m2 | E27: =PRESUPUESTOS!F27 -> 21.79 | F27: =IF(Q27=0,0,((M27/Q27)*J27)) -> 4.28 | G27: =ROUND(E27*F27,2) -> 93.26 | H27: =J27-F27 -> 4.28 | I27: =ROUND(E27*H27,2) -> 93.26 | J27: =PRESUPUESTOS!E27 -> 8.56 | K27: =ROUND(E27*J27,2) -> 186.52 | L27: =PRESUPUESTOS!N27 -> 14.5 | M27: 4.365 | N27: =ROUND(M27*L27,2) -> 63.29 | O27: =Q27-M27 -> 4.365 | P27: =ROUND(O27*L27,2) -> 63.29 | Q27: =PRESUPUESTOS!M27 -> 8.73 | R27: =ROUND(Q27*L27,2) -> 126.59
B28: 02.02 | C28: Obras de Concreto Simple | E28: =PRESUPUESTOS!F28 -> 0 | F28: =IF(Q28=0,0,((M28/Q28)*J28)) -> 0 | G28: =ROUND(E28*F28,2) -> 0 | H28: =J28-F28 -> 0 | I28: =ROUND(E28*H28,2) -> 0 | J28: =PRESUPUESTOS!E28 -> 0 | K28: =ROUND(E28*J28,2) -> 0 | L28: =PRESUPUESTOS!N28 -> 0 | N28: =ROUND(M28*L28,2) -> 0 | O28: =Q28-M28 -> 0 | P28: =ROUND(O28*L28,2) -> 0 | Q28: =PRESUPUESTOS!M28 -> 0 | R28: =ROUND(Q28*L28,2) -> 0
B29: 02.02.01 | C29: Falsos Cimientos | E29: =PRESUPUESTOS!F29 -> 0 | F29: =IF(Q29=0,0,((M29/Q29)*J29)) -> 0 | G29: =ROUND(E29*F29,2) -> 0 | H29: =J29-F29 -> 0 | I29: =ROUND(E29*H29,2) -> 0 | J29: =PRESUPUESTOS!E29 -> 0 | K29: =ROUND(E29*J29,2) -> 0 | L29: =PRESUPUESTOS!N29 -> 0 | N29: =ROUND(M29*L29,2) -> 0 | O29: =Q29-M29 -> 0 | P29: =ROUND(O29*L29,2) -> 0 | Q29: =PRESUPUESTOS!M29 -> 0 | R29: =ROUND(Q29*L29,2) -> 0
A30: 300 | B30: 02.02.01.01 | C30: SUBCIMIENTO, SUBZAPATA MEZCLA 1:12 + 30 % P.G. | D30: m3 | E30: =PRESUPUESTOS!F30 -> 173.72 | F30: =IF(Q30=0,0,((M30/Q30)*J30)) -> 97.107 | G30: =ROUND(E30*F30,2) -> 16869.43 | H30: =J30-F30 -> 226.583 | I30: =ROUND(E30*H30,2) -> 39362 | J30: =PRESUPUESTOS!E30 -> 323.69 | K30: =ROUND(E30*J30,2) -> 56231.43 | L30: =PRESUPUESTOS!N30 -> 184.1 | M30: 99.048 | N30: =ROUND(M30*L30,2) -> 18234.74 | O30: =Q30-M30 -> 231.112 | P30: =ROUND(O30*L30,2) -> 42547.72 | Q30: =PRESUPUESTOS!M30 -> 330.16 | R30: =ROUND(Q30*L30,2) -> 60782.46
B31: 02.02.02 | C31: Cimientos | E31: =PRESUPUESTOS!F31 -> 0 | F31: =IF(Q31=0,0,((M31/Q31)*J31)) -> 0 | G31: =ROUND(E31*F31,2) -> 0 | H31: =J31-F31 -> 0 | I31: =ROUND(E31*H31,2) -> 0 | J31: =PRESUPUESTOS!E31 -> 0 | K31: =ROUND(E31*J31,2) -> 0 | L31: =PRESUPUESTOS!N31 -> 0 | N31: =ROUND(M31*L31,2) -> 0 | O31: =Q31-M31 -> 0 | P31: =ROUND(O31*L31,2) -> 0 | Q31: =PRESUPUESTOS!M31 -> 0 | R31: =ROUND(Q31*L31,2) -> 0
A32: 300 | B32: 02.02.02.02 | C32: CIMIENTOS CORRIDOS 1:10 + 30 % P.G. f'c >=100Kg/cm2 | D32: m3 | E32: =PRESUPUESTOS!F32 -> 179.78 | F32: =IF(Q32=0,0,((M32/Q32)*J32)) -> 17.311 | G32: =ROUND(E32*F32,2) -> 3112.17 | H32: =J32-F32 -> 7.419 | I32: =ROUND(E32*H32,2) -> 1333.79 | J32: =PRESUPUESTOS!E32 -> 24.73 | K32: =ROUND(E32*J32,2) -> 4445.96 | L32: =PRESUPUESTOS!N32 -> 182.46 | M32: 16.968 | N32: =ROUND(M32*L32,2) -> 3095.98 | O32: =Q32-M32 -> 7.272 | P32: =ROUND(O32*L32,2) -> 1326.85 | Q32: =PRESUPUESTOS!M32 -> 24.24 | R32: =ROUND(Q32*L32,2) -> 4422.83
A33: 400 | B33: 02.02.02.03 | C33: CIMIENTO CORRIDO - ENCOFRADO Y DESENCOFRADO | D33: m2 | E33: =PRESUPUESTOS!F33 -> 46.17 | F33: =IF(Q33=0,0,((M33/Q33)*J33)) -> 13.854 | G33: =ROUND(E33*F33,2) -> 639.64 | H33: =J33-F33 -> 9.236 | I33: =ROUND(E33*H33,2) -> 426.43 | J33: =PRESUPUESTOS!E33 -> 23.09 | K33: =ROUND(E33*J33,2) -> 1066.07 | L33: =PRESUPUESTOS!N33 -> 23.83 | M33: 13.578 | N33: =ROUND(M33*L33,2) -> 323.56 | O33: =Q33-M33 -> 9.052 | P33: =ROUND(O33*L33,2) -> 215.71 | Q33: =PRESUPUESTOS!M33 -> 22.63 | R33: =ROUND(Q33*L33,2) -> 539.27
A34: 300 | B34: 02.02.02.04 | C34: CALZADURA: CONCRETO C:H 1:10 + 30 % P.G. | D34: m3 | E34: =PRESUPUESTOS!F34 -> 179.78 | F34: =IF(Q34=0,0,((M34/Q34)*J34)) -> 0 | G34: =ROUND(E34*F34,2) -> 0 | H34: =J34-F34 -> 163.82 | I34: =ROUND(E34*H34,2) -> 29451.56 | J34: =PRESUPUESTOS!E34 -> 163.82 | K34: =ROUND(E34*J34,2) -> 29451.56 | L34: =PRESUPUESTOS!N34 -> 207.85 | M34: 0 | N34: =ROUND(M34*L34,2) -> 0 | O34: =Q34-M34 -> 160.54 | P34: =ROUND(O34*L34,2) -> 33368.24 | Q34: =PRESUPUESTOS!M34 -> 160.54 | R34: =ROUND(Q34*L34,2) -> 33368.24
A35: 400 | B35: 02.02.02.05 | C35: CALZADURA: ENCOFRADO Y DESENCOFRADO | D35: m2 | E35: =PRESUPUESTOS!F35 -> 37.47 | F35: =IF(Q35=0,0,((M35/Q35)*J35)) -> 0 | G35: =ROUND(E35*F35,2) -> 0 | H35: =J35-F35 -> 327.63 | I35: =ROUND(E35*H35,2) -> 12276.3 | J35: =PRESUPUESTOS!E35 -> 327.63 | K35: =ROUND(E35*J35,2) -> 12276.3 | L35: =PRESUPUESTOS!N35 -> 26.53 | M35: 0 | N35: =ROUND(M35*L35,2) -> 0 | O35: =Q35-M35 -> 321.08 | P35: =ROUND(O35*L35,2) -> 8518.25 | Q35: =PRESUPUESTOS!M35 -> 321.08 | R35: =ROUND(Q35*L35,2) -> 8518.25
B36: 02.02.03 | C36: Sobrecimientos | E36: =PRESUPUESTOS!F36 -> 0 | F36: =IF(Q36=0,0,((M36/Q36)*J36)) -> 0 | G36: =ROUND(E36*F36,2) -> 0 | H36: =J36-F36 -> 0 | I36: =ROUND(E36*H36,2) -> 0 | J36: =PRESUPUESTOS!E36 -> 0 | K36: =ROUND(E36*J36,2) -> 0 | L36: =PRESUPUESTOS!N36 -> 0 | N36: =ROUND(M36*L36,2) -> 0 | O36: =Q36-M36 -> 0 | P36: =ROUND(O36*L36,2) -> 0 | Q36: =PRESUPUESTOS!M36 -> 0 | R36: =ROUND(Q36*L36,2) -> 0
A37: 300 | B37: 02.02.03.01 | C37: SOBRECIMIENTO, CONCRETO 1:8 + 25% P.M. f'c >=100Kg/cm2 | D37: m3 | E37: =PRESUPUESTOS!F37 -> 260.59 | F37: =IF(Q37=0,0,((M37/Q37)*J37)) -> 1.605 | G37: =ROUND(E37*F37,2) -> 418.25 | H37: =J37-F37 -> 1.605 | I37: =ROUND(E37*H37,2) -> 418.25 | J37: =PRESUPUESTOS!E37 -> 3.21 | K37: =ROUND(E37*J37,2) -> 836.49 | L37: =PRESUPUESTOS!N37 -> 201.22 | M37: 1.575 | N37: =ROUND(M37*L37,2) -> 316.92 | O37: =Q37-M37 -> 1.575 | P37: =ROUND(O37*L37,2) -> 316.92 | Q37: =PRESUPUESTOS!M37 -> 3.15 | R37: =ROUND(Q37*L37,2) -> 633.84
A38: 400 | B38: 02.02.03.02 | C38: SOBRECIMIENTO, ENCOFRADO Y DESENCOFRADO | D38: m2 | E38: =PRESUPUESTOS!F38 -> 37.7 | F38: =IF(Q38=0,0,((M38/Q38)*J38)) -> 17.58 | G38: =ROUND(E38*F38,2) -> 662.77 | H38: =J38-F38 -> 26.37 | I38: =ROUND(E38*H38,2) -> 994.15 | J38: =PRESUPUESTOS!E38 -> 43.95 | K38: =ROUND(E38*J38,2) -> 1656.92 | L38: =PRESUPUESTOS!N38 -> 24.18 | M38: 17.228 | N38: =ROUND(M38*L38,2) -> 416.57 | O38: =Q38-M38 -> 25.842 | P38: =ROUND(O38*L38,2) -> 624.86 | Q38: =PRESUPUESTOS!M38 -> 43.07 | R38: =ROUND(Q38*L38,2) -> 1041.43
B39: 02.03 | C39: Obras de Concreto Armado | E39: =PRESUPUESTOS!F39 -> 0 | F39: =IF(Q39=0,0,((M39/Q39)*J39)) -> 0 | G39: =ROUND(E39*F39,2) -> 0 | H39: =J39-F39 -> 0 | I39: =ROUND(E39*H39,2) -> 0 | J39: =PRESUPUESTOS!E39 -> 0 | K39: =ROUND(E39*J39,2) -> 0 | L39: =PRESUPUESTOS!N39 -> 0 | N39: =ROUND(M39*L39,2) -> 0 | O39: =Q39-M39 -> 0 | P39: =ROUND(O39*L39,2) -> 0 | Q39: =PRESUPUESTOS!M39 -> 0 | R39: =ROUND(Q39*L39,2) -> 0
B40: 02.03.02 | C40: Zapatas | E40: =PRESUPUESTOS!F40 -> 0 | F40: =IF(Q40=0,0,((M40/Q40)*J40)) -> 0 | G40: =ROUND(E40*F40,2) -> 0 | H40: =J40-F40 -> 0 | I40: =ROUND(E40*H40,2) -> 0 | J40: =PRESUPUESTOS!E40 -> 0 | K40: =ROUND(E40*J40,2) -> 0 | L40: =PRESUPUESTOS!N40 -> 0 | N40: =ROUND(M40*L40,2) -> 0 | O40: =Q40-M40 -> 0 | P40: =ROUND(O40*L40,2) -> 0 | Q40: =PRESUPUESTOS!M40 -> 0 | R40: =ROUND(Q40*L40,2) -> 0
A41: 300 | B41: 02.03.02.01 | C41: ZAPATAS.- CONCRETO 210 kg/cm2 | D41: m3 | E41: =PRESUPUESTOS!F41 -> 292.79 | F41: =IF(Q41=0,0,((M41/Q41)*J41)) -> 198.375 | G41: =ROUND(E41*F41,2) -> 58082.22 | H41: =J41-F41 -> 198.375 | I41: =ROUND(E41*H41,2) -> 58082.22 | J41: =PRESUPUESTOS!E41 -> 396.75 | K41: =ROUND(E41*J41,2) -> 116164.43 | L41: =PRESUPUESTOS!N41 -> 286.6 | M41: 206.31 | N41: =ROUND(M41*L41,2) -> 59128.45 | O41: =Q41-M41 -> 206.31 | P41: =ROUND(O41*L41,2) -> 59128.45 | Q41: =PRESUPUESTOS!M41 -> 412.62 | R41: =ROUND(Q41*L41,2) -> 118256.89
...

Sheet COSTO INDIRECTO
B1: COSTOS INDIRECTOS
B3: ITEM | C3: DESCRIPCION | D3: COSTO PREVISTO META | K3: PREVISTO ACTUALIZADO | N3: COSTO PREVISTO EJECUTADO
D4: UNIDAD | E4: CANTIDAD | F4: TIEMPO | G4: PARTICIPACION | H4: COSTO | I4: PARCIAL | K4: COSTO | L4: PARCIAL | N4: METRADO | O4: COSTO PREVISTO A LA FECHA | P4: COSTO PENDIENTE
C5: GASTOS GENERALES FIJOS | I5: =SUM(I6:I9) -> 3500 | L5: =SUM(L6:L9) -> 6400 | O5: =SUM(O6:O9) -> 800 | P5: =SUM(P6:P9) -> 5600
B6: 1 | C6: Pruebas y ensayos
C7: Diseño de Mezcla | D7: est | E7: 2 | H7: 750 | I7: =E7*H7 -> 1500 | L7: =+'ANALISIS COSTOS INDIRECTOS'!L7 -> 1600 | N7: 0.4 | O7: =SUM('ANALISIS COSTOS INDIRECTOS'!N7) -> 800 | P7: =L7-O7 -> 800
C8: Ensayos Varios | D8: und | E8: 2 | H8: 500 | I8: =E8*H8 -> 1000 | L8: =+'ANALISIS COSTOS INDIRECTOS'!L8 -> 2400 | N8: 0 | O8: =SUM('ANALISIS COSTOS INDIRECTOS'!N8) -> 0 | P8: =L8-O8 -> 2400
C9: Rotura de Probetas | D9: Und | E9: 2 | H9: 500 | I9: =E9*H9 -> 1000 | L9: =+'ANALISIS COSTOS INDIRECTOS'!L9 -> 2400 | N9: 0 | O9: =SUM('ANALISIS COSTOS INDIRECTOS'!N9) -> 0 | P9: =L9-O9 -> 2400
C11: GASTOS GENERALES VARIABLES | I11: =SUM(I12:I34) -> 160049.99 | L11: =SUM(L12:L34) -> 231312.21 | O11: =SUM(O12:O34) -> 70733.441 | P11: =SUM(P12:P34) -> 160578.77
B12: 1.01 | C12: Personal Profesional
C13: Residente de obra (Ing.Civil) | D13: mes | E13: 1 | F13: 5 | G13: 1 | H13: 10000 | I13: =+E13*F13*G13*H13 -> 50000 | L13: =+'ANALISIS COSTOS INDIRECTOS'!L13 -> 81000 | N13: 1 | O13: =SUM('ANALISIS COSTOS INDIRECTOS'!N13) -> 27000 | P13: =L13-O13 -> 54000
C14: Especialista de calidad(Ing.Civil) | D14: mes | E14: 1 | F14: 5 | G14: 0.5 | H14: 4500 | I14: =+E14*F14*G14*H14 -> 11250 | L14: =+'ANALISIS COSTOS INDIRECTOS'!L14 -> 25800 | N14: 1 | O14: =SUM('ANALISIS COSTOS INDIRECTOS'!N14) -> 8600 | P14: =L14-O14 -> 17200
C15: Especialista de Seguridad (Ing. De Seguridad) | D15: mes | E15: 1 | F15: 5 | G15: 1 | H15: 4000 | I15: =+E15*F15*G15*H15 -> 20000 | L15: =+'ANALISIS COSTOS INDIRECTOS'!L15 -> 25200 | N15: 1 | O15: =SUM('ANALISIS COSTOS INDIRECTOS'!N15) -> 8400 | P15: =L15-O15 -> 16800
C16: Administrador de obra | D16: mes | E16: 1 | F16: 5 | G16: 1 | H16: 3000 | I16: =+E16*F16*G16*H16 -> 15000 | L16: =+'ANALISIS COSTOS INDIRECTOS'!L16 -> 12500 | N16: 1 | O16: =SUM('ANALISIS COSTOS INDIRECTOS'!N16) -> 2500 | P16: =L16-O16 -> 10000
B17: 2.01 | C17: Personal Tecnico
C18: Maestro de Obra | D18: mes | E18: 1 | F18: 5 | G18: 1 | H18: 3500 | I18: =+E18*F18*G18*H18 -> 17500 | L18: =+'ANALISIS COSTOS INDIRECTOS'!L18 -> 21000 | N18: 1 | O18: =SUM('ANALISIS COSTOS INDIRECTOS'!N18) -> 7000 | P18: =L18-O18 -> 14000
C19: Almacenero | D19: mes | E19: 1 | F19: 5 | G19: 1 | H19: 1500 | I19: =+E19*F19*G19*H19 -> 7500 | L19: =+'ANALISIS COSTOS INDIRECTOS'!L19 -> 10800 | N19: 1 | O19: =SUM('ANALISIS COSTOS INDIRECTOS'!N19) -> 3600 | P19: =L19-O19 -> 7200
C20: Guardián | D20: mes | E20: 1 | F20: 5 | G20: 1 | H20: 1300 | I20: =+E20*F20*G20*H20 -> 6500 | L20: =+'ANALISIS COSTOS INDIRECTOS'!L20 -> 8100 | N20: 1 | O20: =SUM('ANALISIS COSTOS INDIRECTOS'!N20) -> 2700 | P20: =L20-O20 -> 5400
C21: Asistente técnico | D21: mes | E21: 1 | F21: 5 | G21: 1 | H21: 2000 | I21: =+E21*F21*G21*H21 -> 10000 | L21: =+'ANALISIS COSTOS INDIRECTOS'!L21 -> 12600 | N21: 1 | O21: =SUM('ANALISIS COSTOS INDIRECTOS'!N21) -> 4200 | P21: =L21-O21 -> 8400
B22: 3.01 | C22: Consumos, Moviliarios y Servicios Oficinas
C23: Utiles de oficina y dibujo | D23: mes | F23: 5 | H23: 100 | I23: =+F23*H23 -> 500 | L23: =+'ANALISIS COSTOS INDIRECTOS'!L23 -> 980 | N23: 1 | O23: =SUM('ANALISIS COSTOS INDIRECTOS'!N23) -> 200 | P23: =L23-O23 -> 780
C24: Cuaderno de Obra y Legalizacion | D24: vez | F24: 1 | H24: 250 | I24: =+F24*H24 -> 250 | L24: =+'ANALISIS COSTOS INDIRECTOS'!L24 -> 600 | N24: 0.2 | O24: =SUM('ANALISIS COSTOS INDIRECTOS'!N24) -> 300 | P24: =L24-O24 -> 300
C25: Insumos para impresora y fotocopiadora | D25: mes | F25: 5 | H25: 100 | I25: =+F25*H25 -> 500 | L25: =+'ANALISIS COSTOS INDIRECTOS'!L25 -> 615 | N25: 1 | O25: =SUM('ANALISIS COSTOS INDIRECTOS'!N25) -> 120 | P25: =L25-O25 -> 495
C26: Pólizas y Seguros | D26: mes | F26: 5 | H26: 500 | I26: =+F26*H26 -> 2500 | L26: =+'ANALISIS COSTOS INDIRECTOS'!L26 -> 3120 | N26: 1 | O26: =SUM('ANALISIS COSTOS INDIRECTOS'!N26) -> 600 | P26: =L26-O26 -> 2520
C27: Implementos de seguridad | D27: vez | F27: 1 | H27: 900 | I27: =+F27*H27 -> 900 | L27: =+'ANALISIS COSTOS INDIRECTOS'!L27 -> 4620 | N27: 0.2 | O27: =SUM('ANALISIS COSTOS INDIRECTOS'!N27) -> 850 | P27: =L27-O27 -> 3770
C28: Botiquín | D28: mes | F28: 5 | H28: 150 | I28: =+F28*H28 -> 750 | L28: =+'ANALISIS COSTOS INDIRECTOS'!L28 -> 560 | N28: 1 | O28: =SUM('ANALISIS COSTOS INDIRECTOS'!N28) -> 100 | P28: =L28-O28 -> 460
C29: Liquidaciòn de obra | D29: vez | F29: 1 | H29: 1000 | I29: =+F29*H29 -> 1000 | L29: =+'ANALISIS COSTOS INDIRECTOS'!L29 -> 1000 | N29: 0 | O29: =SUM('ANALISIS COSTOS INDIRECTOS'!N29) -> 0 | P29: =L29-O29 -> 1000
B30: 4.01 | C30: Gastos Financieros
C31: Carta Fianza de Adelanto Directo | F31: 5 | G31: 0.0013 | H31: 192144.9 | I31: =+F31*G31*H31 -> 1248.9419 | L31: =+'ANALISIS COSTOS INDIRECTOS'!L31 -> 2401.8113 | N31: 1 | O31: =SUM('ANALISIS COSTOS INDIRECTOS'!N31) -> 480.36226 | P31: =L31-O31 -> 1921.449
C32: Carta Fianza de Adelanto de Materiales | F32: 5 | G32: 0.0013 | H32: 384289.81 | I32: =+F32*G32*H32 -> 2497.8838 | L32: =+'ANALISIS COSTOS INDIRECTOS'!L32 -> 4803.6226 | N32: 1 | O32: =SUM('ANALISIS COSTOS INDIRECTOS'!N32) -> 960.72452 | P32: =L32-O32 -> 3842.8981
C33: Carta Fianza de Fiel cumplimiento | F33: 5 | G33: 0.0013 | H33: 96072.452 | I33: =+F33*G33*H33 -> 624.47094 | L33: =+'ANALISIS COSTOS INDIRECTOS'!L33 -> 1200.9057 | N33: 1 | O33: =SUM('ANALISIS COSTOS INDIRECTOS'!N33) -> 240.18113 | P33: =L33-O33 -> 960.72452
C34: SENCICO | F34: 5 | G34: 0.002 | H34: 1152869.4 | I34: =+F34*G34*H34 -> 11528.694 | L34: =+'ANALISIS COSTOS INDIRECTOS'!L34 -> 14410.868 | N34: 1 | O34: =SUM('ANALISIS COSTOS INDIRECTOS'!N34) -> 2882.1736 | P34: =L34-O34 -> 11528.694

Sheet ANALISIS COSTOS INDIRECTOS
B1: ANALISIS DE COSTOS INDIRECTOS
B3: ITEM | C3: DESCRIPCION | D3: COSTO PREVISTO META | K3: PREVISTO ACTUALIZADO | N3: MESES
D4: UNIDAD | E4: CANTIDAD | F4: TIEMPO | G4: PARTICIPACION | H4: COSTO | I4: PARCIAL | K4: COSTO | L4: PARCIAL | N4: MES 1 NOVIEMBRE | O4: MES 2 DICIEMBRE | P4: MES 3 ENERO | Q4: MES 4 FEBRERO | R4: MES 5 MARZO
C5: GASTOS GENERALES FIJOS | I5: =SUM(I6:I9) -> 3500 | L5: =SUM(L6:L9) -> 6400
B6: 1 | C6: Pruebas y ensayos
C7: Diseño de Mezcla | D7: est | E7: 2 | H7: 750 | I7: =E7*H7 -> 1500 | L7: =SUM(N7:R7) -> 1600 | N7: 800 | O7: 800
C8: Ensayos Varios | D8: und | E8: 2 | H8: 500 | I8: =E8*H8 -> 1000 | L8: =SUM(N8:R8) -> 2400 | O8: 600 | P8: 600 | Q8: 600 | R8: 600
C9: Rotura de Probetas | D9: Und | E9: 2 | H9: 500 | I9: =E9*H9 -> 1000 | L9: =SUM(N9:R9) -> 2400 | O9: 600 | P9: 600 | Q9: 600 | R9: 600
C11: GASTOS GENERALES VARIABLES | I11: =SUM(I12:I34) -> 160049.99 | L11: =SUM(L12:L34) -> 231312.21
B12: 1.01 | C12: Personal Profesional
C13: Residente de obra (Ing.Civil) | D13: mes | E13: 1 | F13: 5 | G13: 1 | H13: 10000 | I13: =+E13*F13*G13*H13 -> 50000 | L13: =SUM(N13:R13) -> 81000 | N13: =13500*2 -> 27000 | O13: 13500 | P13: 13500 | Q13: 13500 | R13: 13500
C14: Especialista de calidad(Ing.Civil) | D14: mes | E14: 1 | F14: 5 | G14: 0.5 | H14: 4500 | I14: =+E14*F14*G14*H14 -> 11250 | L14: =SUM(N14:R14) -> 25800 | N14: =4300*2 -> 8600 | O14: 4300 | P14: 4300 | Q14: 4300 | R14: 4300
C15: Especialista de Seguridad (Ing. De Seguridad) | D15: mes | E15: 1 | F15: 5 | G15: 1 | H15: 4000 | I15: =+E15*F15*G15*H15 -> 20000 | L15: =SUM(N15:R15) -> 25200 | N15: =4200*2 -> 8400 | O15: 4200 | P15: 4200 | Q15: 4200 | R15: 4200
C16: Administrador de obra | D16: mes | E16: 1 | F16: 5 | G16: 1 | H16: 3000 | I16: =+E16*F16*G16*H16 -> 15000 | L16: =SUM(N16:R16) -> 12500 | N16: 2500 | O16: 2500 | P16: 2500 | Q16: 2500 | R16: 2500
B17: 2.01 | C17: Personal Tecnico
C18: Maestro de Obra | D18: mes | E18: 1 | F18: 5 | G18: 1 | H18: 3500 | I18: =+E18*F18*G18*H18 -> 17500 | L18: =SUM(N18:R18) -> 21000 | N18: =3500*2 -> 7000 | O18: 3500 | P18: 3500 | Q18: 3500 | R18: 3500
C19: Almacenero | D19: mes | E19: 1 | F19: 5 | G19: 1 | H19: 1500 | I19: =+E19*F19*G19*H19 -> 7500 | L19: =SUM(N19:R19) -> 10800 | N19: =1800*2 -> 3600 | O19: 1800 | P19: 1800 | Q19: 1800 | R19: 1800
C20: Guardián | D20: mes | E20: 1 | F20: 5 | G20: 1 | H20: 1300 | I20: =+E20*F20*G20*H20 -> 6500 | L20: =SUM(N20:R20) -> 8100 | N20: =1350*2 -> 2700 | O20: 1350 | P20: 1350 | Q20: 1350 | R20: 1350
C21: Asistente técnico | D21: mes | E21: 1 | F21: 5 | G21: 1 | H21: 2000 | I21: =+E21*F21*G21*H21 -> 10000 | L21: =SUM(N21:R21) -> 12600 | N21: =2100*2 -> 4200 | O21: 2100 | P21: 2100 | Q21: 2100 | R21: 2100
B22: 3.01 | C22: Consumos, Moviliarios y Servicios Oficinas
C23: Utiles de oficina y dibujo | D23: mes | F23: 5 | H23: 100 | I23: =+F23*H23 -> 500 | L23: =SUM(N23:R23) -> 980 | N23: 200 | O23: 200 | P23: 210 | Q23: 180 | R23: 190
C24: Cuaderno de Obra y Legalizacion | D24: vez | F24: 1 | H24: 250 | I24: =+F24*H24 -> 250 | L24: =SUM(N24:R24) -> 600 | N24: 300 | P24: 300
C25: Insumos para impresora y fotocopiadora | D25: mes | F25: 5 | H25: 100 | I25: =+F25*H25 -> 500 | L25: =SUM(N25:R25) -> 615 | N25: 120 | O25: 120 | P25: 120 | Q25: 125 | R25: 130
C26: Pólizas y Seguros | D26: mes | F26: 5 | H26: 500 | I26: =+F26*H26 -> 2500 | L26: =SUM(N26:R26) -> 3120 | N26: 600 | O26: 600 | P26: 650 | Q26: 650 | R26: 620
C27: Implementos de seguridad | D27: vez | F27: 1 | H27: 900 | I27: =+F27*H27 -> 900 | L27: =SUM(N27:R27) -> 4620 | N27: 850 | O27: 920 | P27: 970 | Q27: 930 | R27: 950
C28: Botiquín | D28: mes | F28: 5 | H28: 150 | I28: =+F28*H28 -> 750 | L28: =SUM(N28:R28) -> 560 | N28: 100 | O28: 105 | P28: 120 | Q28: 125 | R28: 110
C29: Liquidaciòn de obra | D29: vez | F29: 1 | H29: 1000 | I29: =+F29*H29 -> 1000 | L29: =SUM(N29:R29) -> 1000 | R29: 1000
B30: 4.01 | C30: Gastos Financieros
C31: Carta Fianza de Adelanto Directo | F31: 5 | G31: 0.0013 | H31: 192144.9 | I31: =+F31*G31*H31 -> 1248.9419 | L31: =SUM(N31:R31) -> 2401.8113 | N31: =+H31*0.25% -> 480.36226 | O31: =+H31*0.25% -> 480.36226 | P31: =+H31*0.25% -> 480.36226 | Q31: =+H31*0.25% -> 480.36226 | R31: =+H31*0.25% -> 480.36226
C32: Carta Fianza de Adelanto de Materiales | F32: 5 | G32: 0.0013 | H32: 384289.81 | I32: =+F32*G32*H32 -> 2497.8838 | L32: =SUM(N32:R32) -> 4803.6226 | N32: =+H32*0.25% -> 960.72452 | O32: =+H32*0.25% -> 960.72452 | P32: =+H32*0.25% -> 960.72452 | Q32: =+H32*0.25% -> 960.72452 | R32: =+H32*0.25% -> 960.72452
C33: Carta Fianza de Fiel cumplimiento | F33: 5 | G33: 0.0013 | H33: 96072.452 | I33: =+F33*G33*H33 -> 624.47094 | L33: =SUM(N33:R33) -> 1200.9057 | N33: =+H33*0.25% -> 240.18113 | O33: =+H33*0.25% -> 240.18113 | P33: =+H33*0.25% -> 240.18113 | Q33: =+H33*0.25% -> 240.18113 | R33: =+H33*0.25% -> 240.18113
C34: SENCICO | F34: 5 | G34: 0.002 | H34: 1152869.4 | I34: =+F34*G34*H34 -> 11528.694 | L34: =SUM(N34:R34) -> 14410.868 | N34: =+H34*0.25% -> 2882.1736 | O34: =+H34*0.25% -> 2882.1736 | P34: =+H34*0.25% -> 2882.1736 | Q34: =+H34*0.25% -> 2882.1736 | R34: =+H34*0.25% -> 2882.1736

Sheet RESUMEN - ANALISIS
A1: RESUMEN
A3: PROYECTO: | B3: I.E. N° 1182 "EL BOSQUE" - CERCO + INGRESOS Y CASETAS
C4: ANALISIS DE PRECIOS VENTA | F4: COSTO PREVISTO
A5: CODIGO | B5: PARTIDA DE CONTROL | C5: COSTO TOTAL VENTA | D5: % | E5: COSTO EJECUTADO VENTA | F5: COSTO TOTAL META | G5: % | H5: COSTO EJECUTADO META
B6: PRESUPUESTO CONTRACTUAL
A7: 100 | B7: OBRAS PROVISIONALES | C7: =SUMIF('COSTO DIRECTO'!$A$7:$A$70,'RESUMEN - ANALISIS'!A7,'COSTO DIRECTO'!$K$7:$K$70) -> 3661.14 | D7: =E7/C7 -> 0.12499932 | E7: =SUMIF('COSTO DIRECTO'!$A$7:$A$70,'RESUMEN - ANALISIS'!A7,'COSTO DIRECTO'!$G$7:$G$70) -> 457.64 | F7: =SUMIF('COSTO DIRECTO'!$A$7:$A$70,'RESUMEN - ANALISIS'!A7,'COSTO DIRECTO'!$R$7:$R$70) -> 2506.28 | G7: =H7/F7 -> 0.12499801 | H7: =SUMIF('COSTO DIRECTO'!$A$7:$A$70,'RESUMEN - ANALISIS'!A7,'COSTO DIRECTO'!$N$7:$N$70) -> 313.28
A8: 200 | B8: MOVIMIENTO DE TIERRAS | C8: =SUMIF('COSTO DIRECTO'!$A$7:$A$70,'RESUMEN - ANALISIS'!A8,'COSTO DIRECTO'!$K$7:$K$70) -> 159518.36 | D8: =E8/C8 -> 0.13756366 | E8: =SUMIF('COSTO DIRECTO'!$A$7:$A$70,'RESUMEN - ANALISIS'!A8,'COSTO DIRECTO'!$G$7:$G$70) -> 21943.93 | F8: =SUMIF('COSTO DIRECTO'!$A$7:$A$70,'RESUMEN - ANALISIS'!A8,'COSTO DIRECTO'!$R$7:$R$70) -> 102563.43 | G8: =H8/F8 -> 0.11749802 | H8: =SUMIF('COSTO DIRECTO'!$A$7:$A$70,'RESUMEN - ANALISIS'!A8,'COSTO DIRECTO'!$N$7:$N$70) -> 12051
A9: 300 | B9: CONCRETO | C9: =SUMIF('COSTO DIRECTO'!$A$7:$A$70,'RESUMEN - ANALISIS'!A9,'COSTO DIRECTO'!$K$7:$K$70) -> 360886.42 | D9: =E9/C9 -> 0.40097366 | E9: =SUMIF('COSTO DIRECTO'!$A$7:$A$70,'RESUMEN - ANALISIS'!A9,'COSTO DIRECTO'!$G$7:$G$70) -> 144705.95 | F9: =SUMIF('COSTO DIRECTO'!$A$7:$A$70,'RESUMEN - ANALISIS'!A9,'COSTO DIRECTO'!$R$7:$R$70) -> 335452.9 | G9: =H9/F9 -> 0.39375623 | H9: =SUMIF('COSTO DIRECTO'!$A$7:$A$70,'RESUMEN - ANALISIS'!A9,'COSTO DIRECTO'!$N$7:$N$70) -> 132086.67
A10: 400 | B10: ENCOFRADO | C10: =SUMIF('COSTO DIRECTO'!$A$7:$A$70,'RESUMEN - ANALISIS'!A10,'COSTO DIRECTO'!$K$7:$K$70) -> 221395.36 | D10: =E10/C10 -> 0.28554849 | E10: =SUMIF('COSTO DIRECTO'!$A$7:$A$70,'RESUMEN - ANALISIS'!A10,'COSTO DIRECTO'!$G$7:$G$70) -> 63219.11 | F10: =SUMIF('COSTO DIRECTO'!$A$7:$A$70,'RESUMEN - ANALISIS'!A10,'COSTO DIRECTO'!$R$7:$R$70) -> 136602.51 | G10: =H10/F10 -> 0.28322979 | H10: =SUMIF('COSTO DIRECTO'!$A$7:$A$70,'RESUMEN - ANALISIS'!A10,'COSTO DIRECTO'!$N$7:$N$70) -> 38689.9
A11: 500 | B11: ACERO | C11: =SUMIF('COSTO DIRECTO'!$A$7:$A$70,'RESUMEN - ANALISIS'!A11,'COSTO DIRECTO'!$K$7:$K$70) -> 215263.24 | D11: =E11/C11 -> 0.35606753 | E11: =SUMIF('COSTO DIRECTO'!$A$7:$A$70,'RESUMEN - ANALISIS'!A11,'COSTO DIRECTO'!$G$7:$G$70) -> 76648.25 | F11: =SUMIF('COSTO DIRECTO'!$A$7:$A$70,'RESUMEN - ANALISIS'!A11,'COSTO DIRECTO'!$R$7:$R$70) -> 119385.55 | G11: =H11/F11 -> 0.54626603 | H11: =SUMIF('COSTO DIRECTO'!$A$7:$A$70,'RESUMEN - ANALISIS'!A11,'COSTO DIRECTO'!$N$7:$N$70) -> 65216.27
B12: TOTALES | C12: =SUM(C7:C11) -> 960724.52 | E12: =SUM(E7:E11) -> 306974.88 | F12: =SUM(F7:F11) -> 696510.67 | H12: =SUM(H7:H11) -> 248357.12
A15: CODIGO | B15: PARTIDA DE CONTROL | C15: COSTO TOTAL VENTA | D15: % | E15: COSTO EJECUTADO VENTA | F15: COSTO TOTAL META | G15: % | H15: COSTO EJECUTADO META
A17: 600 | B17: GASTOS GENERALES | C17: =PRESUPUESTOS!G72 -> 96072.45 | D17: =E17/C17 -> 0.31952436 | E17: =E12*0.1 -> 30697.488 | F17: ='COSTO INDIRECTO'!L5+'COSTO INDIRECTO'!L11 -> 237712.21 | G17: =H17/F17 -> 0.30092456 | H17: ='COSTO INDIRECTO'!O5+'COSTO INDIRECTO'!O11 -> 71533.441
B18: UTILIDAD | C18: =PRESUPUESTOS!G73 -> 76857.96 | D18: =E18/C18 -> 0.31952436 | E18: =E12*0.08 -> 24557.99
B20: OTROS
B21: REINTEGROS POR FORMULA POLINOMICA | C21: =C12*0.02 -> 19214.49 | D21: =E21/C21 -> 0.062452866 | E21: 1200
B23: CONTINGENCIAS
B24: CONTING. INFRAESTRUCTURAS (2%) | F24: =F12*0.02 -> 13930.213 | G24: =H24/F24 -> 0 | H24: 0
B25: CONTING. EQUIP. BIOMEDICO (2%) | F25: 0
B26: CONTING. LEVANT. OBSERVACIONES (1.5%) | F26: =F12*0.015 -> 10447.66 | G26: =H26/F26 -> 0 | H26: 0
B28: TOTALES | C28: =SUM(C16:C27) -> 192144.9 | E28: =SUM(E16:E27) -> 56455.478 | F28: =SUM(F16:F27) -> 262090.08 | H28: =SUM(H16:H27) -> 71533.441
B31: RESUMEN | C31: ACUM A JULIO 2024 | E31: META ACTUAL TOTAL | F31: META ANTERIOR | H31: DIFERENCIA
B33: TOTAL COSTO REAL | C33: =#REF!+#REF! -> #REF! | E33: =F12 -> 696510.67 | H33: =+F33-E33 -> -696510.67
B35: TOTAL COSTO VENTA | C35: =E12+E28 -> 363430.36 | E35: =C12 -> 960724.52 | H35: =+F35-E35 -> -960724.52
B37: RESULTADO OPERATIVO | C37: =C35-C33 -> #REF! | E37: =E35-E33 -> 264213.85 | F37: =F35-F33 -> 0
B38: MARGEN DE UTILIDAD | C38: =C37/C35 -> #REF! | E38: =E37/E35 -> 0.2750152 | F38: =F37/F35 -> #DIV/0!

Sheet DIFERENCIAS
C3: VENTA (S/) | E3: META TOTAL (PRESENTE MES) (S/) | I3: META TOTAL (MES ANTERIOR) (S/) | M3: META INICIAL (S/)
A4: UC | B4: DESCRIPCIÓN | C4: INGRESO PREVISTO TOTAL | E4: COSTO PREVISTO | F4: RENTABILIDAD | I4: COSTO PREVISTO | J4: RENTABILIDAD | M4: COSTO PREVISTO | N4: RENTABILIDAD | Q4: DESVIACIONES (META INICIAL TOTAL- META TOTAL)
B5: PRESUPUESTO CONTRACTUAL
A6: 100 | B6: OBRAS PROVISIONALES | C6: =+'RESUMEN - ANALISIS'!C7 -> 3661.14 | E6: =+'RESUMEN - ANALISIS'!F7 -> 2506.28 | F6: =C6-E6 -> 1154.86 | G6: =+F6/C6 -> 0.31543727 | I6: =+'RESUMEN - ANALISIS'!F7 -> 2506.28 | J6: =C6-I6 -> 1154.86 | K6: =J6/C6 -> 0.31543727 | M6: =+'RESUMEN - ANALISIS'!F7 -> 2506.28 | N6: =C6-M6 -> 1154.86 | O6: =N6/C6 -> 0.31543727 | Q6: =E6-M6 -> 0 | R6: =M6/E6 -> 1
A7: 200 | B7: MOVIMIENTO DE TIERRAS | C7: =+'RESUMEN - ANALISIS'!C8 -> 159518.36 | E7: =+'RESUMEN - ANALISIS'!F8 -> 102563.43 | F7: =C7-E7 -> 56954.93 | G7: =+F7/C7 -> 0.3570431 | I7: =+'RESUMEN - ANALISIS'!F8 -> 102563.43 | J7: =C7-I7 -> 56954.93 | K7: =J7/C7 -> 0.3570431 | M7: =+'RESUMEN - ANALISIS'!F8 -> 102563.43 | N7: =C7-M7 -> 56954.93 | O7: =N7/C7 -> 0.3570431 | Q7: =E7-M7 -> 0 | R7: =M7/E7 -> 1
A8: 300 | B8: CONCRETO | C8: =+'RESUMEN - ANALISIS'!C9 -> 360886.42 | E8: =+'RESUMEN - ANALISIS'!F9 -> 335452.9 | F8: =C8-E8 -> 25433.52 | G8: =+F8/C8 -> 0.070475137 | I8: =+'RESUMEN - ANALISIS'!F9 -> 335452.9 | J8: =C8-I8 -> 25433.52 | K8: =J8/C8 -> 0.070475137 | M8: =+'RESUMEN - ANALISIS'!F9 -> 335452.9 | N8: =C8-M8 -> 25433.52 | O8: =N8/C8 -> 0.070475137 | Q8: =E8-M8 -> 0 | R8: =M8/E8 -> 1
A9: 400 | B9: ENCOFRADO | C9: =+'RESUMEN - ANALISIS'!C10 -> 221395.36 | E9: =+'RESUMEN - ANALISIS'!F10 -> 136602.51 | F9: =C9-E9 -> 84792.85 | G9: =+F9/C9 -> 0.3829929 | I9: =+'RESUMEN - ANALISIS'!F10 -> 136602.51 | J9: =C9-I9 -> 84792.85 | K9: =J9/C9 -> 0.3829929 | M9: =+'RESUMEN - ANALISIS'!F10 -> 136602.51 | N9: =C9-M9 -> 84792.85 | O9: =N9/C9 -> 0.3829929 | Q9: =E9-M9 -> 0 | R9: =M9/E9 -> 1
A10: 500 | B10: ACERO | C10: =+'RESUMEN - ANALISIS'!C11 -> 215263.24 | E10: =+'RESUMEN - ANALISIS'!F11 -> 119385.55 | F10: =C10-E10 -> 95877.69 | G10: =+F10/C10 -> 0.44539741 | I10: =+'RESUMEN - ANALISIS'!F11 -> 119385.55 | J10: =C10-I10 -> 95877.69 | K10: =J10/C10 -> 0.44539741 | M10: =+'RESUMEN - ANALISIS'!F11 -> 119385.55 | N10: =C10-M10 -> 95877.69 | O10: =N10/C10 -> 0.44539741 | Q10: =E10-M10 -> 0 | R10: =M10/E10 -> 1
A11: 600 | B11: GASTOS GENERALES | C11: =+'RESUMEN - ANALISIS'!C17 -> 96072.45 | E11: =+'RESUMEN - ANALISIS'!F17 -> 237712.21 | F11: =C11-E11 -> -141639.76 | G11: =+F11/C11 -> -1.4743015 | I11: =+'RESUMEN - ANALISIS'!F17 -> 237712.21 | J11: =C11-I11 -> -141639.76 | K11: =J11/C11 -> -1.4743015 | M11: =+'RESUMEN - ANALISIS'!F17 -> 237712.21 | N11: =C11-M11 -> -141639.76 | O11: =N11/C11 -> -1.4743015 | Q11: =E11-M11 -> 0 | R11: =M11/E11 -> 1
A12: TOTALES VENTA Y COSTE DIRECTO | C12: =SUM(C5:C11) -> 1056797 | E12: =SUM(E5:E11) -> 934222.88 | F12: =C12-E12 -> 122574.09 | G12: =F12/C12 -> 0.11598642 | I12: =SUM(I5:I11) -> 934222.88 | J12: =C12-I12 -> 122574.09 | K12: =J12/C12 -> 0.11598642 | M12: =SUM(M5:M11) -> 934222.88 | N12: =C12-M12 -> 122574.09 | O12: =N12/C12 -> 0.11598642 | Q12: =SUM(Q5:Q11) -> 0 | R12: =E12/M12 -> 1

Sheet COSTOS INCURRIDOS
J2: NOVIEMBRE | L2: DICIEMBRE | N2: ENERO | P2: FEBRERO | R2: MARZO
A3: ITEM | B3: DESCRIPCION | C3: PROVEEDOR | D3: UNIDAD | E3: CANTIDAD | F3: P.U. | G3: SUBTOTAL | H3: PARTIDA DE CONTROL | I3: TIPO DE COSTO | J3: METRADO UTILIZADO | K3: SUB TOTAL | L3: METRADO UTILIZADO | M3: SUB TOTAL | N3: METRADO UTILIZADO | O3: SUB TOTAL | P3: METRADO UTILIZADO | Q3: SUB TOTAL | R3: METRADO UTILIZADO | S3: SUB TOTAL
B4: ORDENES DE COMPRA
A5: OC001 | B5: ALAMBRE NEGRO RECOCIDO N° 8 | D5: kg | E5: 530 | F5: 2.9 | G5: =+E5*F5 -> 1537 | H5: 400 | I5: MATERIALES | J5: 212 | K5: =+J5*F5 -> 614.8 | L5: 132.5 | M5: =+L5*F5 -> 384.25 | N5: 106 | O5: =+N5*F5 -> 307.4 | P5: 79.5 | Q5: =+P5*F5 -> 230.55 | S5: =+R5*F5 -> 0
A6: OC001 | B6: CLAVOS PARA MADERA CON CABEZA DE 4" | D6: kg | E6: 550 | F6: 3.06 | G6: =+E6*F6 -> 1683 | H6: 400 | I6: MATERIALES | J6: 220 | K6: =+J6*F6 -> 673.2 | L6: 137.5 | M6: =+L6*F6 -> 420.75 | N6: 110 | O6: =+N6*F6 -> 336.6 | P6: 82.5 | Q6: =+P6*F6 -> 252.45
A7: OC001 | B7: CLAVOS PARA MADERA CON CABEZA DE 3" | D7: kg | E7: 15 | F7: 3.06 | G7: =+E7*F7 -> 45.9 | H7: 400 | I7: MATERIALES | J7: 6 | K7: =+J7*F7 -> 18.36 | L7: 3.75 | M7: =+L7*F7 -> 11.475 | N7: 1.5 | O7: =+N7*F7 -> 4.59 | P7: 3.75 | Q7: =+P7*F7 -> 11.475
A8: OC001 | B8: ALAMBRE NEGRO N° 16 | D8: kg | E8: 880 | F8: 2.9 | G8: =+E8*F8 -> 2552 | H8: 500 | I8: MATERIALES | L8: 237.6 | M8: =+L8*F8 -> 689.04 | N8: 484 | O8: =+N8*F8 -> 1403.6 | P8: 158.4 | Q8: =+P8*F8 -> 459.36
A9: OC001 | B9: ALAMBRE NEGRO RECOCIDO N° 16 | D9: kg | E9: 900 | F9: 2.9 | G9: =+E9*F9 -> 2610 | H9: 500 | I9: MATERIALES | L9: 243 | M9: =+L9*F9 -> 704.7 | N9: 495 | O9: =+N9*F9 -> 1435.5 | P9: 162 | Q9: =+P9*F9 -> 469.8
A10: OC002 | B10: TRIPLAY FENOLICO | D10: p2 | E10: 2000 | F10: 4.5 | G10: =+E10*F10 -> 9000 | H10: 400 | I10: MATERIALES | J10: 500 | K10: =+J10*F10 -> 2250 | L10: 600 | M10: =+L10*F10 -> 2700 | N10: 400 | O10: =+N10*F10 -> 1800 | P10: 500 | Q10: =+P10*F10 -> 2250
A11: OC003 | B11: PIEDRA GRANDE DE 8" | D11: m3 | E11: 170.7807 | F11: 54 | G11: =+E11*F11 -> 9222.1578 | H11: 300 | I11: MATERIALES | J11: 170.7807 | K11: =+J11*F11 -> 9222.1578
A12: OC004 | B12: ACERO CORRUGADO fy = 4200 kg/cm2 GRADO 60 | D12: kg | E12: 37571.338 | F12: 2.35 | G12: =+E12*F12 -> 88292.644 | H12: 500 | I12: MATERIALES | L12: 10100 | M12: =+L12*F12 -> 23735 | N12: 20660 | O12: =+N12*F12 -> 48551 | P12: 6811.34 | Q12: =+P12*F12 -> 16006.649
A13: OC005 | B13: LADRILLO PARA TECHO 8H DE 15X30X30 cm | D13: und | E13: 220.542 | F13: 11.23 | G13: =+E13*F13 -> 2476.6867 | H13: 300 | I13: MATERIALES | N13: 88 | O13: =+N13*F13 -> 988.24 | P13: 132.54 | Q13: =+P13*F13 -> 1488.4242
A14: OC006 | B14: SC CONCRETO PREMEZCLADO F'C=100 KG/CM2 | D14: m3 | E14: 399.10255 | F14: 180 | G14: =+E14*F14 -> 71838.459 | H14: 300 | I14: MATERIALES | J14: 399.10255 | K14: =+J14*F14 -> 71838.459
A15: OC006 | B15: SC CONCRETO PREMEZCLADO F'C=210 KG/CM2 | D15: m3 | E15: 557.3187 | F15: 200 | G15: =+E15*F15 -> 111463.74 | H15: 300 | I15: MATERIALES | N15: 250 | O15: =+N15*F15 -> 50000 | P15: 200 | Q15: =+P15*F15 -> 40000 | R15: 107.32 | S15: =+R15*F15 -> 21464
A16: OC006 | B16: SC CONCRETO PREMEZCLADO F'C=210 KG/CM2 H67 CON ADITIVO INPERMEBILIZANTE | D16: m3 | E16: 269.187 | F16: 230 | G16: =+E16*F16 -> 61913.01 | H16: 300 | I16: MATERIALES | N16: 156 | O16: =+N16*F16 -> 35880 | P16: 113.19 | Q16: =+P16*F16 -> 26033.7
A17: OC006 | B17: SC CONCRETO PREMEZCLADO F'C=175 KG/CM2 | D17: kg | E17: 2.512 | F17: 190 | G17: =+E17*F17 -> 477.28 | H17: 300 | I17: MATERIALES | L17: 0.9 | M17: =+L17*F17 -> 171 | N17: 1.0048 | O17: =+N17*F17 -> 190.912 | P17: 0.61 | Q17: =+P17*F17 -> 115.9
B18: ORDENES DE SERVICIO
A19: OS001 | B19: NIVEL TOPOGRAFICO | D19: hm | E19: 26.38188 | F19: 8.1 | G19: =+E19*F19 -> 213.69323 | H19: 100 | I19: EQUIPOS | J19: 15 | K19: =+J19*F19 -> 121.5 | L19: 9 | M19: =+L19*F19 -> 72.9 | N19: 2.38 | O19: =+N19*F19 -> 19.278
A20: OS001 | B20: ESTACION TOTAL | D20: hm | E20: 26.38188 | F20: 14 | G20: =+E20*F20 -> 369.34632 | H20: 100 | I20: EQUIPOS | J20: 8.4 | K20: =+J20*F20 -> 117.6 | L20: 7.3 | M20: =+L20*F20 -> 102.2 | N20: 5 | O20: =+N20*F20 -> 70 | P20: 5.68 | Q20: =+P20*F20 -> 79.52
A21: OS002 | B21: PLANCHA COMPACTADORA VIBRT. 4,0 HP | D21: hm | E21: 6.187654 | F21: 26.11 | G21: =+E21*F21 -> 161.55965 | H21: 200 | I21: EQUIPOS | N21: 3 | O21: =+N21*F21 -> 78.33 | P21: 2 | Q21: =+P21*F21 -> 52.22 | R21: 1.19 | S21: =+R21*F21 -> 31.0709
A22: OS002 | B22: VIBRADOR A GASOLINA | D22: hm | E22: 505.08573 | F22: 5.9 | G22: =+E22*F22 -> 2980.0058 | H22: 300 | I22: EQUIPOS | N22: 313 | O22: =+N22*F22 -> 1846.7 | P22: 177 | Q22: =+P22*F22 -> 1044.3 | R22: 15.09 | S22: =+R22*F22 -> 89.031
A23: OS002 | B23: BOMBAS | D23: m3 | E23: 389.1285 | F23: 30 | G23: =+E23*F23 -> 11673.855 | H23: 300 | I23: EQUIPOS | N23: 235 | O23: =+N23*F23 -> 7050 | P23: 137 | Q23: =+P23*F23 -> 4110 | R23: 17.13 | S23: =+R23*F23 -> 513.9
A24: OS003 | B24: SC MANO DE OBRA ACERO CORRUGADO | D24: kg | E24: 35113.4 | F24: 0.74 | G24: =+E24*F24 -> 25983.916 | H24: 500 | I24: SUBCONTRATO
A25: OS004 | B25: SC AFIRMADO COMPACTADO 8" | D25: m2 | E25: 70.33 | F25: 13 | G25: =+E25*F25 -> 914.29 | H25: 200 | I25: SUBCONTRATO
A26: OS004 | B26: SC AFIRMADO COMPACTADO 12" | D26: m2 | E26: 8.73 | F26: 15 | G26: =+E26*F26 -> 130.95 | H26: 200 | I26: SUBCONTRATO
A27: OS004 | B27: SC EXCAVACION DE ZANJAS Y ZAPATAS Rt> 2KG/CM2 H=1.5m | D27: m3 | E27: 39.81 | F27: 19 | G27: =+E27*F27 -> 756.39 | H27: 200 | I27: SUBCONTRATO
A28: OS004 | B28: SC EXCAVACION DE ZANJAS Y ZAPATAS Rt> 2KG/CM2 H=2.00m | D28: m3 | E28: 1876.4 | F28: 21.1 | G28: =+E28*F28 -> 39592.04 | H28: 200 | I28: SUBCONTRATO
A29: OS004 | B29: SC RELLENO COMPACTADO CON EQUIPO | D29: m3 | E29: 1138.01 | F29: 15 | G29: =+E29*F29 -> 17070.15 | H29: 200 | I29: SUBCONTRATO
A30: OS004 | B30: SC ELIMINACION DE MATERIAL EXCEDENTE CON VOLQUETES | D30: m3 | E30: 1173.963 | F30: 17.4 | G30: =+E30*F30 -> 20426.956 | H30: 200 | I30: SUBCONTRATO
A31: OS005 | B31: SC ALQUILER DE ENCOFRADO COLUMNAS | D31: m2 | E31: 551.646 | F31: 19.04 | G31: =+E31*F31 -> 10503.34 | H31: 400 | I31: SERVICIOS | N31: 195 | O31: =+N31*F31 -> 3712.8 | P31: 356.65 | Q31: =+P31*F31 -> 6790.616
A32: OS005 | B32: SC ALQUILER DE ENCOFRADO VIGAS | D32: m2 | E32: 444.904 | F32: 26.78 | G32: =+E32*F32 -> 11914.529 | H32: 400 | I32: SERVICIOS | N32: 145 | O32: =+N32*F32 -> 3883.1 | P32: 299.9 | Q32: =+P32*F32 -> 8031.322
A33: OS005 | B33: SC ALQUILER DE ENCOFRADO LOSAS MACIZAS | D33: m2 | E33: 6.67 | F33: 11.23 | G33: =+E33*F33 -> 74.9041 | H33: 400 | I33: SERVICIOS | N33: 2 | O33: =+N33*F33 -> 22.46 | P33: 4.67 | Q33: =+P33*F33 -> 52.4441
A34: OS005 | B34: SC ALQUILER DE ENCOFRADO LOSAS ALIGERADAS | D34: m2 | E34: 11.064669 | F34: 11.23 | G34: =+E34*F34 -> 124.25623 | H34: 400 | I34: SERVICIOS | N34: 3 | O34: =+N34*F34 -> 33.69 | P34: 8.06 | Q34: =+P34*F34 -> 90.5138

Sheet STAFF
A2: MONTO DE PLANILLAS DE EMPLEADOS
A4: MES | B4: MONTO
A5: JULIO | B5: =32500*2 -> 65000
A6: AGOSTO | B6: 29800
A7: SEPTIEMBRE | B7: 31200
A8: OCTUBRE | B8: 33000
A9: NOVIEMBRE | B9: 25460
A10: TOTAL | B10: =SUM(B5:B9) -> 184460

Sheet OBREROS
B2: REGISTRO DE RECURSOS SEMANAL (EN HORAS HOMBRE)
B4: =+[1]Procesos!A4 -> CR: | C4: =[2]Caratula!C6 -> 001
B5: =+[1]Procesos!A5 -> PROYECTO: | C5: =[2]Caratula!C7 -> I.E. N° 1182 "EL BOSQUE" - CERCO + INGRESOS Y CASETAS
B6: =+[1]Procesos!A6 -> CORTE: | C6: =[2]Caratula!C8 -> 45504
E7: Previsto | I7: Previsto
B8: CÓDIGO | C8: DESCRIPCIÓN | D8: UND | E8: ORIG | F8: REV. 1 | G8: REV. 2 | H8: REV. 3 | I8: REV. 4 | J8: PREV | K8: N° DE SEMANA / FECHA DE CORTE | AE8: ACUM
K9: =[2]Semanas!B8 -> 1 | L9: =[2]Semanas!C8 -> 2 | M9: =[2]Semanas!D8 -> 3 | N9: =[2]Semanas!E8 -> 4 | O9: =[2]Semanas!F8 -> 5 | P9: =[2]Semanas!G8 -> 6 | Q9: =[2]Semanas!H8 -> 7 | R9: =[2]Semanas!I8 -> 8 | ... AD9: =[2]Semanas!U8 -> 20
K10: =[2]Semanas!B9 -> 45481 | L10: =[2]Semanas!C9 -> 45488 | M10: =[2]Semanas!D9 -> 45495 | N10: =[2]Semanas!E9 -> 45502 | O10: =[2]Semanas!F9 -> 45509 | P10: =[2]Semanas!G9 -> 45516 | Q10: =[2]Semanas!H9 -> 45523 | R10: =[2]Semanas!I9 -> 45530 | ... AD10: =[2]Semanas!U9 -> 45614
A11: =+A10+1 -> 1 | B11: 100 | C11: =+VLOOKUP(B11,[2]Procesos!A12:$C$40,2,0) -> OBRAS PROVISIONALES | D11: =[2]Procesos!$B$7 -> HH | E11: 100.63 | J11: =SUMIF($E$7:$J$7,"Previsto",E11:I11) -> 100.63 | K11: 12.8 | L11: 14.2 | M11: 10.2 | N11: 11.2 | O11: 11.4 | P11: 11.35 | Q11: 9.5 | R11: 11.5 | S11: 4.5 | T11: 4.2 | U11: 3 | V11: 2.8 | W11: 4.2 | X11: 4.5 | Y11: 4.5 | Z11: 4.3 | AA11: 0 | AB11: 0 | AC11: 0 | AD11: 0 | AE11: =SUM(K11:AD11) -> 124.15 | AG11: 17
A12: =+A11+1 -> 2 | B12: 200 | C12: =+VLOOKUP(B12,[2]Procesos!A13:$C$40,2,0) -> MOVIMIENTO DE TIERRAS | D12: =[2]Procesos!$B$7 -> HH | E12: 3931.7 | J12: =SUMIF($E$7:$J$7,"Previsto",E12:I12) -> 3931.7 | K12: 385 | L12: 375 | M12: 390 | N12: 400 | O12: 385 | P12: 405 | Q12: 380 | R12: 395 | S12: 180 | T12: 182 | U12: 185 | V12: 190 | W12: 4.5 | X12: 5 | Y12: 4.25 | Z12: 4.3 | AA12: 3.5 | AB12: 3.8 | AC12: 3.5 | AD12: 3 | AE12: =SUM(K12:AD12) -> 3883.85
A13: =+A12+1 -> 3 | B13: 300 | C13: =+VLOOKUP(B13,[2]Procesos!A14:$C$40,2,0) -> CONCRETO | D13: =[2]Procesos!$B$7 -> HH | E13: 2487.06 | J13: =SUMIF($E$7:$J$7,"Previsto",E13:I13) -> 2487.06 | K13: 0 | L13: 0 | M13: 0 | N13: 0 | O13: 190 | P13: 195 | Q13: 165 | R13: 174 | S13: 260 | T13: 280 | U13: 290 | V13: 285 | W13: 140 | X13: 146 | Y13: 150 | Z13: 155 | AA13: 20 | AB13: 22 | AC13: 24 | AD13: 21 | AE13: =SUM(K13:AD13) -> 2517
A14: =+A13+1 -> 4 | B14: 400 | C14: =+VLOOKUP(B14,[2]Procesos!A15:$C$40,2,0) -> ENCOFRADO | D14: =[2]Procesos!$B$7 -> HH | E14: 5370.78 | J14: =SUMIF($E$7:$J$7,"Previsto",E14:I14) -> 5370.78 | K14: 0 | L14: 0 | M14: 0 | N14: 0 | O14: 490 | P14: 465 | Q14: 460 | R14: 480 | S14: 365 | T14: 390 | U14: 375 | V14: 382 | W14: 500 | X14: 505 | Y14: 495 | Z14: 498 | AA14: 0 | AB14: 0 | AC14: 0 | AD14: 0 | AE14: =SUM(K14:AD14) -> 5405
A15: =+A14+1 -> 5 | B15: 500 | C15: =+VLOOKUP(B15,[2]Procesos!A16:$C$40,2,0) -> ACERO | D15: =[2]Procesos!$B$7 -> HH | E15: 39327.01 | J15: =SUMIF($E$7:$J$7,"Previsto",E15:I15) -> 39327.01 | K15: 0 | L15: 0 | M15: 0 | N15: 0 | O15: 4100 | P15: 4150 | Q15: 4050 | R15: 4060 | S15: 4600 | T15: 4800 | U15: 4820 | V15: 4500 | W15: 1290 | X15: 1260 | Y15: 1280 | Z15: 1240 | AA15: 0 | AB15: 0 | AC15: 0 | AD15: 0 | AE15: =SUM(K15:AD15) -> 40150
C19: TOTALES | E19: =+SUM(E11:E15) -> 51217.18 | F19: =SUM(F11:F18) -> 0 | G19: =SUM(G11:G18) -> 0 | H19: =SUM(H11:H18) -> 0 | I19: =SUM(I11:I18) -> 0 | J19: =+SUM(J11:J15) -> 51217.18 | K19: =SUM(K11:K18) -> 397.8 | L19: =SUM(L11:L18) -> 389.2 | M19: =SUM(M11:M18) -> 400.2 | N19: =SUM(N11:N18) -> 411.2 | O19: =SUM(O11:O18) -> 5176.4 | P19: =SUM(P11:P18) -> 5226.35 | Q19: =SUM(Q11:Q18) -> 5064.5 | R19: =SUM(R11:R18) -> 5120.5 | ... AE19: =SUM(AE11:AE18) -> 52080
B25: REGISTRO DE RECURSOS SEMANAL (EN COSTO)
E28: Previsto | I28: Previsto
B29: CÓDIGO | C29: DESCRIPCIÓN | D29: UND | E29: ORIG | F29: REV. 1 | G29: REV. 2 | H29: REV. 3 | I29: REV. 4 | J29: PREV | K29: N° DE SEMANA / FECHA DE CORTE | AE29: ACUM
K30: 1 | L30: 2 | M30: 3 | N30: 4 | O30: 5 | P30: 6 | Q30: 7 | R30: 8 | S30: 9 | T30: 10 | U30: 11 | V30: 12 | W30: 13 | X30: 14 | Y30: 15 | Z30: 16 | AA30: 17 | AB30: 18 | AC30: 19 | AD30: 20
K31: 45481 | L31: 45488 | M31: 45495 | N31: 45502 | O31: 45509 | P31: 45516 | Q31: 45523 | R31: 45530 | S31: 45537 | T31: 45544 | U31: 45551 | V31: 45558 | W31: 45565 | X31: 45572 | Y31: 45579 | Z31: 45586 | AA31: 45593 | AB31: 45600 | AC31: 45607 | AD31: 45614
A32: =+A31+1 -> 1 | B32: 100 | C32: OBRAS PROVISIONALES | D32: S/ | E32: 1710.71 | J32: 1710.71 | K32: 217.6 | L32: 241.4 | M32: 173.4 | N32: 190.4 | O32: 193.8 | P32: 192.95 | Q32: 161.5 | R32: 195.5 | S32: 76.5 | T32: 71.4 | U32: 51 | V32: 47.6 | W32: 71.4 | X32: 76.5 | Y32: 76.5 | Z32: 73.1 | AA32: 0 | AB32: 0 | AC32: 0 | AD32: 0 | AE32: =SUM(K32:AD32) -> 2110.55
A33: =+A32+1 -> 2 | B33: 200 | C33: MOVIMIENTO DE TIERRAS | D33: S/ | E33: 66838.9 | J33: 66838.9 | K33: 6545 | L33: 6375 | M33: 6630 | N33: 6800 | O33: 6545 | P33: 6885 | Q33: 6460 | R33: 6715 | S33: 3060 | T33: 3094 | U33: 3145 | V33: 3230 | W33: 76.5 | X33: 85 | Y33: 72.25 | Z33: 73.1 | AA33: 59.5 | AB33: 64.6 | AC33: 59.5 | AD33: 51 | AE33: =SUM(K33:AD33) -> 66025.45
A34: =+A33+1 -> 3 | B34: 300 | C34: CONCRETO | D34: S/ | E34: 42280.02 | J34: 42280.02 | K34: 0 | L34: 0 | M34: 0 | N34: 0 | O34: 3230 | P34: 3315 | Q34: 2805 | R34: 2958 | S34: 4420 | T34: 4760 | U34: 4930 | V34: 4845 | W34: 2380 | X34: 2482 | Y34: 2550 | Z34: 2635 | AA34: 340 | AB34: 374 | AC34: 408 | AD34: 357 | AE34: =SUM(K34:AD34) -> 42789
A35: =+A34+1 -> 4 | B35: 400 | C35: ENCOFRADO | D35: S/ | E35: 91303.26 | J35: 91303.26 | K35: 0 | L35: 0 | M35: 0 | N35: 0 | O35: 8330 | P35: 7905 | Q35: 7820 | R35: 8160 | S35: 6205 | T35: 6630 | U35: 6375 | V35: 6494 | W35: 8500 | X35: 8585 | Y35: 8415 | Z35: 8466 | AA35: 0 | AB35: 0 | AC35: 0 | AD35: 0 | AE35: =SUM(K35:AD35) -> 91885
A36: =+A35+1 -> 5 | B36: 500 | C36: ACERO | D36: S/ | E36: 668559.17 | J36: 668559.17 | K36: 0 | L36: 0 | M36: 0 | N36: 0 | O36: 69700 | P36: 70550 | Q36: 68850 | R36: 69020 | S36: 78200 | T36: 81600 | U36: 81940 | V36: 76500 | W36: 21930 | X36: 21420 | Y36: 21760 | Z36: 21080 | AA36: 0 | AB36: 0 | AC36: 0 | AD36: 0 | AE36: =SUM(K36:AD36) -> 682550
C40: TOTALES | E40: =+SUM(E32:E36) -> 870692.06 | F40: =SUM(F32:F39) -> 0 | G40: =SUM(G32:G39) -> 0 | H40: =SUM(H32:H39) -> 0 | I40: =SUM(I32:I39) -> 0 | J40: =+SUM(J32:J36) -> 870692.06 | K40: =SUM(K32:K39) -> 6762.6 | L40: =SUM(L32:L39) -> 6616.4 | M40: =SUM(M32:M39) -> 6803.4 | N40: =SUM(N32:N39) -> 6990.4 | O40: =SUM(O32:O39) -> 87998.8 | P40: =SUM(P32:P39) -> 88847.95 | Q40: =SUM(Q32:Q39) -> 86096.5 | R40: =SUM(R32:R39) -> 87048.5 | ... AE40: =SUM(AE32:AE39) -> 885360
N45: 822.8 | O45: 743.75 | P45: 246.5 | Q45: 297.5 | R45: 0
N46: 26350 | O46: 26605 | P46: 12529 | Q46: 306.85 | R46: 234.6
N47: 0 | O47: 12308 | P47: 18955 | Q47: 10047 | R47: 1479
