Workbook

Sheet 1Planilla
A1: ANEXO I
A2: ESTRUCTURACION LABORAL Y PLANILLA PERSONAL
A3: 1.1: DESCRIPCION SERVICIO Y TURNOS LABORALES
A4: SERVICIO : | B4: ALQUILER DE MAQUINARIA PESADA
A5: CONTRATANTE: | B5: COMPAÑÍA MINERA ANTAMINA
A6: TURNOS LABORALES: | B6: 10 DIAS DE TRABAJO POR 10 DIAS DE DESCANSO
A7: OPERACIÓN MINA : | B7: 20 HRS LABORALES NETAS DIARIAS OPERADORES MINA
A8: ADMINISTRACION MINA | B8: 12 HORAS LABORALES DIARIAS OPERACIÓN MINA
A9: CONDICION : | B9: MAQUINARIAS OPERATIVAS Y CON OPERADOR
A10: TOTAL DE MAQUINARIAS: | B10: =+'2Maq'!B8 -> 10
A11: ADMINISTRACION HUARAZ | B11: 06 días a la semana
A13: 1.2: DESCRIPCION DEL PERSONAL LABORAL ACTIVIDAD Y PLANILLA DE SALARIO
B14: HABER ACTUAL | D14: Derechos Laborales | F14: TOTAL | G14: OBSERVACION
A15: Actividad del Personal | B15: Haber mes | C15: Total Percibido | D15: Haber mes | E15: Sub total | F15: PLANILLA
A16: ADMINISTRACION HUARAZ | B16: PERCIBIDO | C16: =+C17+C23 -> 0 | D16: DESCONTADO | E16: =SUM(E17:E27) -> 0 | G16: =+C16+E16 -> 0 | H16: SUB TOTAL
A17: 1º DIRECTIVOS | C17: =SUM(B18:B22) -> 0 | E17: =SUM(D18:D22) -> 0 | G17: =SUM(F18:F21) -> 0
A18: Directivo 1º (Tiempo Parcial) | B18: =+M18 -> 0 | D18: =+N18 -> 0 | F18: =+B18+D18 -> 0 | G18: A considerar
A19: Directivo 2º (Tiempo Parcial) | B19: =+M19 -> 0 | D19: =+N19 -> 0 | F19: =+B19+D19 -> 0 | G19: A considerar
A20: Directivo 3º (Tiempo Parcial) | B20: =+M20 -> 0 | D20: =+N20 -> 0 | F20: =+B20+D20 -> 0 | G20: A considerar
A21: Directivo 4º (Tiempo Parcial) | B21: =+M21 -> 0 | D21: =+N21 -> 0 | F21: =+B21+D21 -> 0 | G21: A considerar haber y funciones
A22: Directivo 5º (Tiempo Parcial) | B22: =+M22 -> 0 | D22: =+N22 -> 0 | F22: =+B22+D22 -> 0 | G22: A considerar haber y funciones
A23: 2º Administrativo Huaraz | C23: =SUM(B24:B27) -> 0 | E23: =SUM(D24:D27) -> 0 | G23: =SUM(F24:F27) -> 0
A24: Abogado (Tiempo Parcial) | B24: =+M24 -> 0 | D24: =+N24 -> 0 | F24: =+B24+D24 -> 0 | G24: A considerar
A25: Contador (Tiempo parcial) | B25: =+M25 -> 0 | D25: =+N25 -> 0 | F25: =+B25+D25 -> 0 | G25: A considerar
A26: Asistente Contable (Tpo completo | B26: =+M26 -> 0 | D26: =+N26 -> 0 | F26: =+B26+D26 -> 0 | G26: Considerar nueva curricula
A27: Secretaria (Tiempo completo) | B27: =+M27 -> 0 | D27: =+N27 -> 0 | F27: =+B27+D27 -> 0 | G27: Considerar nueva curricula
A28: OPERACIÓN MINA | C28: =+C29+C42+C53 -> 0 | E28: =+E29+E42+E53 -> 0 | G28: =+C28+E28 -> 0 | H28: SUB TOTAL
A29: 3º Administrativo MINA | C29: =SUM(B30:B41) -> 0 | E29: =SUM(D30:D41) -> 0 | G29: =+C29+E29 -> 0 | H29: SUB TOTAL
A30: Administrador 1º Rotación | B30: =+M30 -> 0 | D30: =+B30*'6SueAct'!$C$7 -> 0 | F30: =+B30+D30 -> 0 | G30: Considerar nueva curricula
A31: Administrador 2º Rotación | B31: =+M31 -> 0 | D31: =+B31*'6SueAct'!$C$7 -> 0 | F31: =+B31+D31 -> 0 | G31: Considerar nueva curricula
A32: Almacen 1º Rotación | B32: =+M32 -> 0 | D32: =+B32*'6SueAct'!$C$7 -> 0 | F32: =+B32+D32 -> 0 | G32: Considerar nueva curricula
A33: Almacen 2º Rotación | B33: =+M33 -> 0 | D33: =+B33*'6SueAct'!$C$7 -> 0 | F33: =+B33+D33 -> 0 | G33: Considerar nueva curricula
A34: Supervisor 1º Turno 1º Rotación | B34: =+M34 -> 0 | D34: =+B34*'6SueAct'!$C$7 -> 0 | F34: =+B34+D34 -> 0 | G34: A considerar
A35: Supervisor 2º Turno 1º Rotación | B35: =+M35 -> 0 | D35: =+B35*'6SueAct'!$C$7 -> 0 | F35: =+B35+D35 -> 0 | G35: A considerar
A36: Supervisor 1º Turno 2º Rotación | B36: =+M36 -> 0 | D36: =+B36*'6SueAct'!$C$7 -> 0 | F36: =+B36+D36 -> 0 | G36: A considerar
A37: Supervisor 2º Turno 2º Rotación | B37: =+M37 -> 0 | D37: =+B37*'6SueAct'!$C$7 -> 0 | F37: =+B37+D37 -> 0 | G37: A considerar
A38: Seguridad Jefatura 1º Rotación | B38: =+M38 -> 0 | D38: =+B38*'6SueAct'!$C$7 -> 0 | F38: =+B38+D38 -> 0 | G38: Considerar nueva curricula
A39: Seguridad Supervisor 2º Rotación | B39: =+M39 -> 0 | D39: =+B39*'6SueAct'!$C$7 -> 0 | F39: =+B39+D39 -> 0 | G39: Considerar nueva curricula
A40: Gerente Operacion 1º Rotación | B40: =+M40 -> 0 | D40: =+B40*'6SueAct'!$C$7 -> 0 | F40: =+B40+D40 -> 0 | G40: Implementar y considerar curricula
B41: =+M41 -> 0 | D41: =+B41*'6SueAct'!$C$7 -> 0 | F41: =+B41+D41 -> 0 | G41: Implementar y considerar curricula
...

Sheet 2Maq
A1: ANEXO II
A2: ESTRUCTURACION PERSONAL vs MAQUINARIA
A3: 1.1: DESCRICCION DEL SERVICIO
A4: SERVICIO : | B4: ACARREO DE MATERIALES EN OPERACIONES Y CARRETERA
A5: TURNOS LABORALES: | B5: 10 DIAS DE TRABAJO POR 10 DIAS DE DESCANSO
A6: HORAS CONTATADA DIA : | B6: 20 HORAS MAQUINAS DIARIAS
A7: CONDICION : | B7: MAQUINAS OPERATIVAS Y CON OPERADOR - MAQUINARIA SECA
A8: TOTAL MAQUINARIA: | B8: =SUM(B13:B14) -> 10
A9: TOTAL Hora/Maquina Mes: | B9: =B8*'6SueAct'!F7 -> 5000
A10: 1.2: DESCRICCION LABORAL
C11: PERSONAL POR | E11: TOTAL | G11: OBSERVACION
A12: Actividad del Personal | B12: Maquinaria | C12: TURNO 1 | D12: TURNO 2 | E12: PERSONAL
A13: Conductores Volquetes | B13: 7 | C13: =B13*2 -> 14 | D13: =B13*2 -> 14 | E13: =SUM(C13:D13) -> 28 | G13: De acuerdo contrato
A14: Operador - Excavadora | B14: 3 | C14: =B14*2 -> 6 | D14: =B14*2 -> 6 | E14: =SUM(C14:D14) -> 12 | G14: De acuerdo contrato
A15: Supervisor de campo | C15: =+'1Planilla'!J34+'1Planilla'!J36 -> 0 | D15: =+'1Planilla'!J35+'1Planilla'!J37 -> 0 | E15: =SUM(C15:D15) -> 0 | G15: Capacitar y Evaluar
A16: Supervisor de Seguridad | C16: 1 | D16: 1 | E16: =SUM(C16:D16) -> 2 | G16: Necesario
A17: Administrador | C17: 1 | D17: 1 | E17: =SUM(C17:D17) -> 2 | G17: =+$G$15 -> Capacitar y Evaluar
A18: Técnico Mecánico | C18: 1 | D18: 1 | E18: =SUM(C18:D18) -> 2 | G18: =+$G$15 -> Capacitar y Evaluar
A19: Técnico Electricista | C19: 0 | D19: 0 | E19: =SUM(C19:D19) -> 0 | G19: Capacitar y Evaluar
A20: Apoyo Mecánico | C20: 1 | D20: 1 | E20: =SUM(C20:D20) -> 2 | G20: =+$G$15 -> Capacitar y Evaluar
A21: Soldadores | C21: 1 | D21: 1 | E21: =SUM(C21:D21) -> 2 | G21: =+$G$15 -> Capacitar y Evaluar
A22: Almacenero | C22: 1 | D22: 1 | E22: =SUM(C22:D22) -> 2 | G22: =+$G$15 -> Capacitar y Evaluar
A23: Llantero | C23: 1 | D23: 1 | E23: =SUM(C23:D23) -> 2 | G23: =+$G$15 -> Capacitar y Evaluar
A24: GERENTE OPERACIONES | C24: 0 | D24: 0 | E24: =SUM(C24:D24) -> 0 | G24: IMPLEMENTAR
A25: JEFE DE OPERACIONES | C25: 0 | D25: 0 | E25: =SUM(C25:D25) -> 0 | G25: IMPLEMENTAR
A26: SUB TOTAL PERSONAL POR TURNO | C26: =SUM(C13:C25) -> 27 | D26: =SUM(D13:D25) -> 27 | E26: =SUM(E13:F25) -> 54
A28: 1.3: DESCRICCION DE MAQUINARIAS Y CARACTERISTICAS
A29: TIPO DE MAQUINARIA | B29: Modelo | C29: Placa | D29: Año de Fabricaci | E29: HP | F29: Horómetro | G29: Fecha de Lectura | H29: Capaciad (m³) | I29: Condicion
A31: 1.- Volquete 6X4 R | B31: FM 440 | C31: WGM 857 | D31: 2008 | E31: 440 | F31: 7054.4 | G31: 40298 | H31: 15 | I31: Operativo | J31: 1
A32: 2.- Volquete 6X4 R | B32: FM 440 | C32: WGM 858 | D32: 2008 | E32: 440 | F32: 7230.26 | G32: 40293 | H32: =+H31 -> 15 | I32: Operativo | J32: 0
A33: 3.- Volquete 6X4 R | B33: FM 440 | C33: WGM 859 | D33: 2008 | E33: 440 | F33: 7441 | G33: 40294 | H33: =+H31 -> 15 | I33: Operativo | J33: 1
A34: 4.- Volquete 6X4 R | B34: FM 420 | C34: XO6044 | D34: 2003 | E34: 420 | F34: 25590.6 | G34: 40295 | H34: =+H31 -> 15 | I34: Operativo | J34: 1
A35: 5.- Volquete 6X4 R | B35: NL 12 | C35: XO4065 | D35: 2000 | E35: 400 | F35: 30538 | G35: 40231 | H35: =+H31 -> 15 | I35: Inoperativo | J35: 1
A36: 6.- Volquete 6X4 R | B36: NL 12 | C36: XO4066 | D36: 2000 | E36: 400 | F36: 33,982.40 | G36: 40303 | H36: =+H31 -> 15 | I36: Operativo | J36: 1
A37: 7.- Volquete 6X4 R | B37: NL 12 | C37: XO5085 | D37: 2001 | E37: 400 | F37: 28749.7 | G37: 40297 | H37: =+H31 -> 15 | I37: Inoperativo | J37: 1
A38: 8.- Volquete 6X4 R | B38: NL 12 | C38: XO5387 | D38: 2001 | E38: 400 | F38: 28112.9 | G38: 40300 | H38: =+H31 -> 15 | I38: Inoperativo | J38: 1
A39: 9.- Excavadora sobre oruga | B39: BL | C39: CAT | D39: 2002 | E39: 260 | F39: 25590.6 | G39: 40301 | H39: 2,10 m³ | I39: Inoperativo | J39: 0
A40: 10.- Excavadora sobre oruga | B40: DL | C40: CAT | D40: 2007 | E40: 268 | F40: 10252.4 | G40: 40299 | H40: 2,10 m³ | I40: Inoperativo | J40: 1
A41: 11.- Excavadora sobre oruga | B41: EC360BL | C41: VOLVO | D41: 2008 | E41: 250 | F41: 7862.5 | G41: 40295 | H41: 1,96 m³ | I41: Operativo | J41: 1
A42: 12.- Excavadora sobre oruga | B42: PC300LC8 | C42: KOMATSU | D42: 2009 | E42: 246 | F42: 1625 | G42: 40302 | H42: 2,54 m³ | I42: Operativo | J42: 1
...

Sheet 3insumo
B1: ANEXO III
A2: DESCRIPCION DE PARTES, INSUMOS, CANTIDADES Y COSTOS
A3: PARA EL MANTENIMIENTO PREVENTIVO PROGRAMADO
A4: EXCAVADORA KOMATSU PC300 LC-8
A6: FaCo 1 Gl = | C6: 3.785 | D6: litros | E6: I.G.V. = | F6: 1 | G6: T.C. 1 US = | H6: 2.94
A8: ITEM | B8: DESCRIPCION | C8: COD. | D8: CANT | E8: Und. | F8: Costo Unitario | G8: Costo Total S/. | H8: Costo Total $
B9: LUBRICANTES Y RETEN
A10: 1 | B10: Valvoline Premiun Blue 15W40 | C10: P15400500 | D10: 1 | E10: gal | F10: =O7/D10 -> 0 | G10: =D10*F10 -> 0 | H10: =+G10/H6 -> 0
A11: =A10+1 -> 2 | B11: Valvoline Transmission TO-4 30 | C11: TO4300500 | D11: 1 | E11: gal | F11: =O8/D11 -> 0 | G11: =D11*F11 -> 0 | H11: =+G11/H6 -> 0
A12: =A11+1 -> 3 | B12: Valvoline Transmission TO-4 10W | C12: TO4100500 | D12: 1 | E12: gal | F12: =O9/D12 -> 0 | G12: =D12*F12 -> 0 | H12: =+G12/H6 -> 0
B13: GRASA
A14: =+A12+1 -> 4 | B14: Boquillas de engrase, círculo de giro y piñon de giro | C14: VV612 | D14: 1 | E14: Kg | G14: =F16*D14 -> 0 | H14: =G14/H6 -> 0
F16: =O11 -> 0
B18: FILTROS
A19: =A14+1 -> 5 | B19: Filtro de aire primario | C19: 6001856110 | D19: 1 | E19: unid | F19: =O16/D19 -> 0 | G19: =D19*F19 -> 0 | H19: =G19/H6 -> 0
A20: =+A19+1 -> 6 | B20: Filtro de aire secundario | C20: 6001856120 | D20: 1 | E20: unid | F20: =O17/D20 -> 0 | G20: =D20*F20 -> 0 | H20: =G20/H6 -> 0
A21: =+A20+1 -> 7 | B21: Filtro de aceite del motor | C21: 6742014540 | D21: 1 | E21: unid | F21: =O18/D21 -> 0 | G21: =D21*F21 -> 0 | H21: =G21/H6 -> 0
A22: =+A21+1 -> 8 | B22: Filtro de combustible primario | C22: 6003193610 | D22: 1 | E22: unid | F22: =O19/D22 -> 0 | G22: =D22*F22 -> 0 | H22: =G22/H6 -> 0
A23: =+A22+1 -> 9 | B23: Filtro de combustible secundario | C23: 6754796140 | D23: 1 | E23: unid | F23: =O20/D23 -> 0 | G23: =D23*F23 -> 0 | H23: =G23/H6 -> 0
A24: =+A23+1 -> 10 | B24: Filtro aire acondicionado recircu. | C24: 2089797620 | D24: 1 | E24: unid | F24: =O21/D24 -> 0 | G24: =D24*F24 -> 0 | H24: =G24/H6 -> 0
A25: =+A24+1 -> 11 | B25: Filtro aire acondicionado limpio | C25: 17M9113530 | D25: 1 | E25: unid | F25: =O22/D25 -> 0 | G25: =D25*F25 -> 0 | H25: =G25/H6 -> 0
B26: FILTROS HIDRAULICOS
A27: =+A25+1 -> 12 | B27: Filtro Hidráulico | C27: 2076071182 | D27: 1 | E27: unid | F27: =O24 -> 0 | G27: =D27*F27 -> 0 | H27: =G27/H6 -> 0
A28: =+A27+1 -> 13 | B28: Cartucho | C28: 6004111191 | D28: 1 | E28: unid | F28: =O25 -> 0 | G28: =D28*F28 -> 0 | H28: =G28/H6 -> 0
A29: =+A28+1 -> 14 | B29: Respiradero adicional Hidráulico | C29: 2076051310 | D29: 1 | E29: unid | F29: =O26 -> 0 | G29: =D29*F29 -> 0 | H29: =G29/H6 -> 0
A30: =+A29+1 -> 15 | B30: Respiradero Hidráulico | C30: 20Y6021470 | D30: 1 | E30: unid | F30: =O27 -> 0 | G30: =D30*F30 -> 0 | H30: =G30/H6 -> 0
B31: ELEMENTOS DE DESGASTE
A32: =+A30+1 -> 16 | B32: Puntas roquera (Hensley) | C32: HLK30RP2 | D32: 1 | E32: unid | F32: =+O29 -> 0 | G32: =+F32*D32 -> 0 | H32: =G32/$H$6 -> 0
A33: =+A32+1 -> 17 | B33: Lock (pasador de uñas) | C33: HLKP30C | D33: 1 | E33: unid | F33: =+O30 -> 0 | G33: =+F33*D33 -> 0 | H33: =G33/$H$6 -> 0
A34: =+A33+1 -> 18 | B34: Cuchilla Lateral (Hensley) | C34: HLSCB330SO | D34: 1 | E34: unid | F34: =+O31 -> 0 | G34: =+F34*D34 -> 0 | H34: =G34/$H$6 -> 0
A35: =+A34+1 -> 19 | B35: Tuerca | C35: 25531R1 | D35: 1 | E35: unid | F35: =+O32 -> 0 | G35: =+F35*D35 -> 0 | H35: =G35/$H$6 -> 0
A36: =+A35+1 -> 20 | B36: Perno de cuchilla | C36: 209011690 | D36: 1 | E36: unid | F36: =+O33 -> 0 | G36: =+F36*D36 -> 0 | H36: =G36/$H$6 -> 0
A37: =+A36+1 -> 21 | B37: Kit de 30 pernos y tuercas | C37: 2073205061 | D37: 1 | E37: unid | F37: =+O34 -> 0 | G37: =+F37*D37 -> 0 | H37: =G37/$H$6 -> 0
A38: =+A37+1 -> 22 | B38: Tuerca | C38: 25531R1 | D38: 1 | E38: unid | F38: =+O35 -> 0 | G38: =+F38*D38 -> 0 | H38: =G38/$H$6 -> 0
A39: =+A38+1 -> 23 | B39: Zapata 700 mm Triple | C39: 2073261310 | D39: 1 | E39: unid | F39: =+O36 -> 0 | G39: =+F39*D39 -> 0 | H39: =G39/$H$6 -> 0
B40: OTROS
A41: =+A39+1 -> 24 | B41: Correa de la tranmision | D41: 1 | E41: unid | F41: =O38 -> 0 | G41: =F41*D41 -> 0 | H41: =G41/H6 -> 0
A42: =+A41+1 -> 25 | B42: Refrigerante | C42: 1400164H1 | D42: 1 | E42: gal | F42: =O39 -> 0 | G42: =D42*F42 -> 0 | H42: =G42/H6 -> 0
A43: =+A42+1 -> 26 | B43: Bateria 15 placas- 24V | D43: 1 | E43: unid | F43: =O40 -> 0 | G43: =D43*F43 -> 0 | H43: =G43/H6 -> 0
B44: MUESTRAS DE ACEITES
...

Sheet 4Trans
A1: ANEXO IV
A2: CALCULO DE COSTO POR TRANSPORTE DE PARA PARTES, INSUMOS POR PESO
A3: =+'[1]3insumo'!A3:H3 -> PARA EL MANTENIMIENTO PREVENTIVO PROGRAMADO
A4: EXCAVADORA KOMAT'SU PC300LC-8
A6: Nº | B6: DESCRIPCIÓN | C6: Unidad | D6: Cant | E6: Ciclo Meses | F6: pesos (kg)
A7: 1 | B7: Aceite Motor | C7: 55 gln | D7: 1 | E7: 2 | F7: 208
A8: 2 | B8: Aceite de Mando de rotación de Giro | C8: 5 gln | D8: 1 | E8: 2 | F8: 18.91
A9: 3 | B9: Aceite Transmision caja mandos finales | C9: 5 gln | D9: 3 | E9: 2 | F9: 53.73
A10: 4 | B10: Aceite Sistema Hidraúlico | C10: 55 gln | D10: 1 | E10: 4 | F10: 226.9
A11: 5 | B11: Grasa varillaje de pluma y brazo | C11: 54 kg | D11: 1 | E11: 2 | F11: 54
A12: 6 | B12: Grasa varillaje cucharon
A13: 7 | B13: Grasa acoplador ràpido
A14: 8 | B14: Grasa cojinete de rotaciòn
A15: 9 | B15: Grasa engranaje de rotaciòn
A16: 10 | B16: Filtro Aire (P) | C16: und. | D16: 2 | E16: 2 | F16: 1.5
A17: 11 | B17: Filtro Aire (S) | C17: und. | D17: 2 | E17: 2 | F17: 2.5
A18: 12 | B18: Filtro Aceite de motor | C18: und. | D18: 4 | E18: 2 | F18: 1
A19: 13 | B19: Filtro Combustible (P) | C19: und. | D19: 4 | E19: 2 | F19: 1.5
A20: 14 | B20: Filtro Combustible (S) | C20: und. | D20: 2 | E20: 2 | F20: 1.5
A21: 15 | B21: Filtro Hidráulico Piloto | C21: und. | D21: 2 | E21: 2 | F21: 2
A22: 16 | B22: Filtro Hidráulico de Retorno | C22: und. | D22: 2 | E22: 2 | F22: 2
A23: 17 | B23: Filtro Racor | C23: und. | D23: 2 | E23: 2 | F23: 0.5
A24: 18 | B24: Filtro Elemento Tanque | C24: und. | D24: 4 | E24: 2 | F24: 1.5
A25: 19 | B25: Refrigerante | C25: 5 gln | D25: 1 | E25: 2 | F25: 18
A26: 20 | B26: Correa de trasmisión | C26: und. | D26: 1 | E26: 5 | F26: 1
A27: 21 | B27: Baterias | C27: und. | D27: 2 | E27: 5 | F27: 50
... A32: 26 | B32: PERNOS Y TERCAS | C32: und. | D32: 16 | E32: 7 | F32: 115.2
D33: Peso Total | F33: =SUM(F7:F32) -> 4961.74
A35: Transportes Pedesa - Traslado Lima @ Mina
A36: Nº | B36: Descripcion | C36: horometro | D36: Peso (kg) | F36: Costo
A37: 1 | B37: Insumos: filtros, aceites | C37: 1200 | D37: 328.64 | F37: =D37*A45 -> 0
A38: 2 | B38: Insumos: aceites, filtros, grasa | C38: 2400 | D38: 606.54 | F38: =D38*A45 -> 0
A39: 3 | B39: Insumos: carrileria, materiales de desgaste | C39: 4200 | D39: 4317.2 | F39: =D39*A45 -> 0
E40: Sub Total | F40: =SUM(F37:F39) -> 0
A41: Transporte Pereda: (Transporte carga) | E41: Factor | F41: 5,9Tn/9000hr | L41: 1.19
A42: 4,000 kg = S/.2,800 (sin I.G.V.) | E42: S/ x hora | F42: =(9000/F49)*A45 -> 0
A43: 4,000 kg = S/.3,320
A44: 0,001 kg = S/.0,833 | C44: horometro | D44: mes | E44: pack | F44: Peso Transp.
A45: =+I40 -> 0 | C45: 6000 | D45: 2 | E45: 1 | F45: =+D37 -> 328.64
C46: 7200 | D46: 4 | E46: 2 | F46: =+D38 -> 606.54
...

Sheet 5 EPP
A1: ANEXO V
A3: EQUIPOS DE PROTECCION PARA TODO EL PERSONAL EN MINA
A5: MAQ | B5: RENDIMIENTO Hora /Semestral | C5: Horas/Año | D5: Mes/año | E5: Horas/Mes | F5: Días/Mes | G5: Horas/Día | H5: Operadores | I5: Administra.
A6: =+'2Maq'!B8 -> 10 | B6: =C6/2 -> 2500 | C6: =F6*G6*D6 -> 5000 | D6: =+'6SueAct'!E7 -> 10 | E6: =F6*G6 -> 500 | F6: =+'6SueAct'!G7 -> 25 | G6: 20 | H6: =+'1Planilla'!K54+'1Planilla'!K61 -> 0 | I6: =+'1Planilla'!K30+'1Planilla'!K43 -> 0
A8: Item | B8: DESCRIPCION | C8: Concepto | D8: Cantidad | E8: Und. | F8: Rend.Prome | G8: Consumo | H8: Precio Unitario | I8: COSTO REAL
F9: hr - maquina | G9: por hora
A10: 5.1 | B10: EQUIPOS DE PROTECCION PERSONAL ADMINISTRACION | F10: SUB TOTAL S/. /hora | I10: =SUM(I11:I21)/'2Maq'!B8 -> 0.0016
B11: Casco | C11: Seguridad | D11: =+$I$6 -> 0 | E11: und | F11: =$B$6 -> 2500 | G11: =D11/F11 -> 0 | H11: 33.61 | I11: =G11*H11 -> 0
B12: Zapatos | D12: =+$I$6 -> 0 | E12: und | F12: =$B$6 -> 2500 | G12: =D12/F12 -> 0 | H12: 79.83 | I12: =G12*H12 -> 0
B13: Lentes Oscuros | D13: =+$I$6 -> 0 | E13: und | F13: =$B$6 -> 2500 | G13: =D13/F13 -> 0 | H13: 12.61 | I13: =G13*H13 -> 0
B14: Lentes Transparentes | D14: =+$I$6 -> 0 | E14: und | F14: =$B$6 -> 2500 | G14: =D14/F14 -> 0 | H14: 12.61 | I14: =G14*H14 -> 0
B15: Guantes de Cuero | D15: =+$I$6 -> 0 | E15: und | F15: =$B$6 -> 2500 | G15: =D15/F15 -> 0 | H15: 9.66 | I15: =G15*H15 -> 0
B16: Guantes de Operador | D16: 0 | E16: und | F16: =$B$6 -> 2500 | G16: =D16/F16 -> 0 | H16: 9.66 | I16: =G16*H16 -> 0
B17: Implementos para botiquin de equipos | D17: 1 | E17: und | F17: =$B$6 -> 2500 | G17: =D17/F17 -> 0.0004 | H17: 40 | I17: =G17*H17 -> 0.016
B18: Chalecos tela importada dril | D18: =+$I$6 -> 0 | E18: und | F18: =$B$6 -> 2500 | G18: =D18/F18 -> 0 | H18: 25.21 | I18: =G18*H18 -> 0
B19: Overol impermeable termico | D19: =SUM('1Planilla'!J34:J37) -> 0 | E19: und | F19: =$B$6 -> 2500 | G19: =D19/F19 -> 0 | H19: 117.65 | I19: =G19*H19 -> 0
B20: Overol de tela con cinta reflectivo | D20: =+$I$6 -> 0 | E20: und | F20: =$B$6 -> 2500 | G20: =D20/F20 -> 0 | H20: 46.22 | I20: =G20*H20 -> 0
B21: Tapa oido | D21: =+$I$6 -> 0 | E21: und | F21: 500 | G21: =D21/F21 -> 0 | H21: 3 | I21: =G21*H21 -> 0
A22: 5.2 | B22: EQUIPOS DE PROTECCION PERSONAL OPERACIÓN | F22: SUB TOTAL S/. /hora | I22: =SUM(I23:I42)/'2Maq'!B8 -> 0.0199744
B23: Casco | C23: Seguridad | D23: =+$H$6 -> 0 | E23: und | F23: =$B$6 -> 2500 | G23: =D23/F23 -> 0 | H23: 33.61 | I23: =G23*H23 -> 0
B24: Zapatos | D24: =+D23 -> 0 | E24: und | F24: =$B$6 -> 2500 | G24: =D24/F24 -> 0 | H24: 79.83 | I24: =G24*H24 -> 0
B25: Lentes Oscuros | D25: =+D23 -> 0 | E25: und | F25: =$B$6 -> 2500 | G25: =D25/F25 -> 0 | H25: 12.61 | I25: =G25*H25 -> 0
B26: Lentes Transparentes | D26: =+D23 -> 0 | E26: und | F26: =$B$6 -> 2500 | G26: =D26/F26 -> 0 | H26: 12.61 | I26: =G26*H26 -> 0
B27: Guantes de Cuero | D27: =+D23 -> 0 | E27: und | F27: =$B$6 -> 2500 | G27: =D27/F27 -> 0 | H27: 9.66 | I27: =G27*H27 -> 0
B28: Implementos para botiquin de equipos | D28: 2 | E28: und | F28: =$B$6 -> 2500 | G28: =D28/F28 -> 0.0008 | H28: 40 | I28: =G28*H28 -> 0.032
B29: Chalecos tela importada dril | D29: =+D23 -> 0 | E29: und | F29: =$B$6 -> 2500 | G29: =D29/F29 -> 0 | H29: 25.21 | I29: =G29*H29 -> 0
B30: Overol impermeable termico | D30: =+D24 -> 0 | E30: und | F30: =$B$6 -> 2500 | G30: =D30/F30 -> 0 | H30: 117.65 | I30: =G30*H30 -> 0
B31: Overol de tela con cinta reflectivo | D31: =+D23 -> 0 | E31: und | F31: =$B$6 -> 2500 | G31: =D31/F31 -> 0 | H31: 46.22 | I31: =G31*H31 -> 0
B32: Tapa oido | D32: =+D23 -> 0 | E32: und | F32: =$B$6 -> 2500 | G32: =D32/F32 -> 0 | H32: 3 | I32: =G32*H32 -> 0
B33: Mascarilla | D33: =+D23 -> 0 | E33: und | F33: =$B$6 -> 2500 | G33: =D33/F33 -> 0 | H33: 3 | I33: =G33*H33 -> 0
B34: Pantalon de cuero | D34: 1 | E34: und | F34: =$B$6 -> 2500 | G34: =D34/F34 -> 0.0004 | H34: 66.39 | I34: =G34*H34 -> 0.026556
B35: Casaca de cuero | D35: 1 | E35: und | F35: =$B$6 -> 2500 | G35: =D35/F35 -> 0.0004 | H35: 71.43 | I35: =G35*H35 -> 0.028572
B36: Escarpin de cuero | D36: 1 | E36: und | F36: =$B$6 -> 2500 | G36: =D36/F36 -> 0.0004 | H36: 15 | I36: =G36*H36 -> 0.006
B37: Mandil soldadura | D37: 1 | E37: und | F37: =$B$6 -> 2500 | G37: =D37/F37 -> 0.0004 | H37: 25.21 | I37: =G37*H37 -> 0.010084
B38: Capuchon para soldar | D38: 1 | E38: und | F38: =$B$6 -> 2500 | G38: =D38/F38 -> 0.0004 | H38: 21.85 | I38: =G38*H38 -> 0.00874
B39: Careta para esmerilar | D39: 1 | E39: und | F39: =$B$6 -> 2500 | G39: =D39/F39 -> 0.0004 | H39: 35 | I39: =G39*H39 -> 0.014
B40: Careta de soldador | D40: 2 | E40: und | F40: =$B$6 -> 2500 | G40: =D40/F40 -> 0.0008 | H40: 50 | I40: =G40*H40 -> 0.04
B41: Mascarilla para soldador | D41: 2 | E41: und | F41: =$B$6 -> 2500 | G41: =D41/F41 -> 0.0008 | H41: 23.75 | I41: =G41*H41 -> 0.019
B42: Guantes de cuero para soldar | D42: 2 | E42: und | F42: =$B$6 -> 2500 | G42: =D42/F42 -> 0.0008 | H42: 18.49 | I42: =G42*H42 -> 0.014792
A43: NOTA: Para determinar el costo horario de los equipos de protección personal se considera un rendimiento
...

Sheet 6SueAct
A1: ANEXO VI
A2: ESTRUCTURA DE HONORARIOS ACTUAL DEL PERSONAL - MES
A4: COSTOS ADMINISTRATIVOS Y DE PERSONAL HORA / MAQUINA
C6: % Pago Admi | D6: Horas/Año | E6: Mes / año | F6: Horas /Mes | G6: Días/Mes | H6: Horas/Día | I6: T.C. US$
B7: Derechos y obligaciones laborales % = | C7: 0.485 | D7: =G7*H7*E7 -> 5000 | E7: 10 | F7: =G7*H7 -> 500 | G7: 25 | H7: 20 | I7: ='3insumo'!H6 -> 2.94
A9: Item | B9: DESCRIPCION | C9: Concepto | D9: Personal | F9: hr-maq. Mes Total | G9: Factor Personal÷hr maq. mes | H9: Costo Unitario | I9: Costo Real
A10: 4.1 | B10: PERSONAL ADMINISTRATIVO Y TALLER | I10: =SUM(I11:I38) -> 4.318434
B11: Personal Administrativo Huaraz (3) | C11: Administración | D11: 3 | E11: jornal | F11: =$F$7*'2Maq'!$B$8 -> 5000 | G11: =(D11/F11) -> 0.0006 | H11: =SUM('1Planilla'!B25:B27) -> 0 | I11: =G11*H11 -> 0
B12: Derechos obligaciones Labo administrador Hz | E12: D-OLA | H12: =H11*$C$7 -> 0 | I12: =G11*H12 -> 0
B13: Personal Directivos (3) | C13: Dirección | D13: 3 | E13: Honorario | G13: =(D13/F11) -> 0.0006 | H13: =SUM('1Planilla'!B18:B20) -> 0 | I13: =G13*H13 -> 0
B14: Derechos obligaciones Directivos | E14: D-OLA | H14: 0 | I14: =G13*H14 -> 0
B15: Personal Asesor Legal (1) | C15: Legal | D15: 1 | E15: Honorario | G15: =D15/F11 -> 0.0002 | H15: =+'1Planilla'!B24 -> 0 | I15: =G15*H15 -> 0
B16: Derechos obligaciones Laborales Asesor Legal | H16: =H15*$C$7 -> 0 | I16: =G15*H16 -> 0
B17: Personal Administrativo Mina (2) | C17: Administración | D17: 2 | E17: jornal | F17: =$F$7*'2Maq'!$B$8 -> 5000 | G17: =(D17/F17) -> 0.0004 | H17: =SUM('1Planilla'!B30:B31) -> 0 | I17: =G17*H17 -> 0
B18: Derechos obligaciones laborales administrador | E18: D-OLA | H18: =H17*C7 -> 0 | I18: =G17*H18 -> 0
B19: Personal de Seguridad (2) | D19: 2 | E19: jornal | G19: =(D19/F17) -> 0.0004 | H19: =SUM('1Planilla'!B38:B39) -> 0 | I19: =G19*H19 -> 0
B20: Derechos y obligaciones laborales P.Seguri | E20: D-OLPS | H20: =H19*C7 -> 0 | I20: =G19*H20 -> 0
B21: Personal de Mantenimiento Mecanicos Eléctric (2) | C21: Operación | D21: 2 | E21: jornal | F21: =$F$7*'2Maq'!$B$8 -> 5000 | G21: =(D21/F21) -> 0.0004 | H21: =SUM('1Planilla'!B43:B44) -> 0 | I21: =G21*H21 -> 0
B22: Derechos y obligaciones laborales P.Mante | E22: D-OLPM | H22: =H21*C7 -> 0 | I22: =G21*H22 -> 0
B23: Personal de Apoyo Mantenimiento (2) | C23: Operación | D23: 2 | E23: jornal | F23: =$F$7*'2Maq'!$B$8 -> 5000 | G23: =(D23/F23) -> 0.0004 | H23: =SUM('1Planilla'!B47:B48) -> 0 | I23: =G23*H23 -> 0
B24: Derechos y obligaciones laborales PAMant Mec | E24: D-OLPa | H24: =H23*C7 -> 0 | I24: =G23*H24 -> 0
B25: Personal Eléctricos (2) | C25: Operación | D25: 0 | E25: jornal | F25: =$F$7*'2Maq'!$B$8 -> 5000 | G25: =(D25/F25) -> 0 | H25: =SUM('1Planilla'!B45:B46) -> 0 | I25: =G25*H25 -> 0
B26: Derechos y obligaciones laborales P. Elec | E26: D-OLPM | H26: =H25*C7 -> 0 | I26: =G25*H26 -> 0
B27: Personal Soldador (2) | C27: Operación | D27: 2 | E27: jornal | F27: =$F$7*'2Maq'!$B$8 -> 5000 | G27: =(D27/F27) -> 0.0004 | H27: =SUM('1Planilla'!B49:B50) -> 0 | I27: =G27*H27 -> 0
B28: Derechos y obligaciones laborales P.Soldadr | E28: D-OLPS | H28: =H27*C7 -> 0 | I28: =G27*H28 -> 0
B29: Personal Almacenero (2) | C29: Operación | D29: 2 | E29: jornal | F29: =$F$7*'2Maq'!$B$8 -> 5000 | G29: =(D29/F29) -> 0.0004 | H29: =SUM('1Planilla'!B32:B33) -> 0 | I29: =G29*H29 -> 0
B30: Derechos y obligaciones laborales P.Almace | E30: D-OLPA | H30: =H29*C7 -> 0 | I30: =G29*H30 -> 0
B31: Personal Llantero (2) | C31: Operación | D31: 2 | E31: jornal | F31: =$F$7*'2Maq'!$B$8 -> 5000 | G31: =(D31/F31) -> 0.0004 | H31: =SUM('1Planilla'!B51:B52) -> 0 | I31: =G31*H31 -> 0
B32: Derechos y obligaciones laborales Llantero | E32: D-OLPA | H32: =H31*C7 -> 0 | I32: =G31*H32 -> 0
B33: Personal Supervisor (4) | C33: Operación | D33: 4 | E33: jornal | F33: =$F$7*'2Maq'!$B$8 -> 5000 | G33: =(D33/F33) -> 0.0008 | H33: =SUM('1Planilla'!B34:B37) -> 0 | I33: =G33*H33 -> 0
B34: Derechos y obligaciones laborales P.Super | E34: D-OLPS | H34: =H33*C7 -> 0 | I34: =G33*H34 -> 0
B35: Atencion medica Yanacancha | C35: Operación | D35: =SUM(D17:D34)/2 -> 9 | E35: ATM | F35: =$F$7*'2Maq'!$B$8 -> 5000 | G35: =(D35/F35) -> 0.0018 | H35: =N35*D35 -> 657.72 | I35: =G35*H35 -> 1.183896 | K35: Atención Medica Yanacan | N35: 73.08
B36: Alimentación, Hospedaje, Lavandería | E36: AHLav | H36: =N36*D35 -> 301.41 | I36: =G35*H36 -> 0.542538 | K36: Alimentación, Hospedaje, Lavandería | N36: 33.49
B37: Pasaporte medico | C37: Operación | D37: =SUM(D17:D34) -> 18 | E37: PSME | F37: =$D$7*'2Maq'!$B$8 -> 50000 | G37: =(D37/F37) -> 0.00036 | H37: =N37*D37 -> 3600 | I37: =G37*H37 -> 1.296 | K37: Pasaporte y EPS | N37: 200
B38: EPS | E38: EPS | H38: =N37*D37 -> 3600 | I38: =G37*H38 -> 1.296
A39: 4.2 | B39: PERSONAL OPERATIVO | C39: SUB TOTAL S/. / hora | I39: =SUM(I40:I47) -> 2.18256
B40: Personal Operador Excavadora | C40: Operación | D40: 4 | E40: jornal | F40: =$F$7 -> 500 | G40: =D40/F40 -> 0.008 | H40: ='1Planilla'!B61 -> 0 | I40: =H40*G40 -> 0 | K40: Son el total de haberes a fin de cumplir las 500 hrs mes
B41: Derechos y obligaciones laborales operador | E41: D-OLOx | H41: =H40*C7 -> 0 | I41: =H41*G40 -> 0
B42: Atención Médica en Yanacancha - dias | D42: 2 | E42: ATM/dias | G42: =D42/F40 -> 0.004 | H42: =N35*D42 -> 146.16 | I42: =H42*G42 -> 0.58464 | K42: Al mes solo se considera dos personas día
B43: Alimentación, Hospedaje, Lavandería - dias | E43: AHLav | H43: =N36*D42 -> 66.98 | I43: =H43*G42 -> 0.26792
...

Sheet 7chrFM
B1: ESTRUCTURA ACTUAL DE COSTO HORARIO MAQUINARIA PESADA | L1: Item | M1: DESCRIPCION | N1: Nº Referencia | O1: Tipo ó Producto | P1: Cant. | Q1: Und. | R1: Rendimiento Promedio hora-maquina | S1: CONSUMO POR HORA | T1: PRECIO UNIT S/. | U1: COSTO REAL Soles/hora
A2: EXCAVADORA KOMATSU PC300-LC8 | L2: 3 | M2: COSTO DE POSESION | S2: SUB TOTAL S/. | U2: =SUM(U3:U12) -> 48.251807
A3: COSTO DE OPERACIÓN HORARIA: MAQUINA SECA EN SOLES (S/.) ( hr - Maq.) | L3: 3.01 | M3: Interes del Capital Invertido Excavadora | Q3: ( Cae ) x i / 200 Nae | U3: =('7,1Grafico'!G20*'7,1Grafico'!G22)/(200*'7,1Grafico'!G24) -> 0.0852845
L4: =+L3+0.01 -> 3.02 | M4: Depreciación Horaria Excavadora | Q4: ( Cae x Kre ) / Nv e | U4: ='7,1Grafico'!G20*'7,1Grafico'!G21/'7,1Grafico'!G23 -> 45.485067
B5: Horas Trabajadas efectivas por dia | C5: 12 | D5: Hrs / Año | E5: Mes/año | F5: Horas/Mes | G5: Días / Mes | H5: T.C. US$ | I5: Hr WM /Día | J5: Hr no WM/día | L5: =+L4+0.01 -> 3.03 | M5: Depreciación Horaria Camioneta | Q5: ( Cac x Kvr ) / Nv c | U5: =(('7,1Grafico'!G25*'7,1Grafico'!G21)/'7,1Grafico'!G26)/'2Maq'!B8 -> 0.45733333
B6: Total de Maquinarias consideradas | C6: =+'2Maq'!B8 -> 10 | D6: =I6*G6*E6 -> 5000 | E6: 10 | F6: =G6*I6 -> 500 | G6: 25 | H6: 2.94 | I6: 20 | J6: =20-I6 -> 0 | L6: =+L5+0.01 -> 3.04 | M6: Interes del Capital Invertido Camioneta | Q6: ( Cac ) x i / 200 Na c | U6: =+'[1]7chrFM'!$U$6 -> 0.00065621448 | W6: I = IMA x %i / Nº de horas anuales
A7: Item | B7: DESCRIPCION | C7: Nº Referencia | D7: Tipo ó Producto | E7: Cant. | F7: Und. | G7: Rendimiento promedio hora-maquina | H7: CONSUMO POR HORA | I7: PRECIO UNIT S/. | J7: COSTO REAL Soles/hora | L7: =+L6+0.01 -> 3.05 | M7: Poliza de seguro del excavadora | P7: 1 | Q7: POSV | R7: =($I$6+$J$6)*$G$6*$E$6 -> 5000 | S7: =P7/R7 -> 0.0002 | T7: 3822 | U7: =S7*T7 -> 0.7644
A8: 1 | B8: COSTO DE OPERACIÓN HORARIA | H8: TOTAL S/. | J8: =SUM(J9,J11,J36,J42,J53,J56,J63,J75,J78,J80,J47) -> 25.593098 | L8: =+L7+0.01 -> 3.06 | M8: Soat | O8: SOAT | P8: 1 | Q8: SOAT | R8: =+C6*D6 -> 50000 | S8: =P8/R8 -> 2e-05 | T8: 800 | U8: =S8*T8 -> 0.016
A9: 1.1 | B9: COMBUSTIBLE | H9: SUB TOTAL S/. | J9: =+J10 -> 0 | L9: =+L8+0.01 -> 3.07 | M9: Certificación de la excavadora | O9: Excavadora | P9: 1 | Q9: certificado | R9: =+G76 -> 5000 | S9: =P9/R9 -> 0.0002 | T9: =1800*H6 -> 5292 | U9: =S9*T9 -> 1.0584
B10: Consumo = 0.0325 x Gal / H x BHP | D10: DIESEL B2 | E10: 4.5 | F10: gal. | H10: =E10 -> 4.5 | I10: ='3insumo'!F50 -> 0 | J10: =H10*I10 -> 0 | L10: =+L9+0.01 -> 3.08 | M10: Depreciación Horaria Equipo de Taller | Q10: ( Ca ta x Kvr ) / Nv t | T10: 51622.49 | U10: =(('7,1Grafico'!G28*'7,1Grafico'!G21)/'7,1Grafico'!G29)/'2Maq'!B8 -> 0.13866667
A11: 1.2 | B11: LUBRICANTES Y FILTROS | H11: SUB TOTAL S/. | J11: =SUM(J12:J35) -> 0 | L11: =+L10+0.01 -> 3.09 | M11: Cetificación de equipos de Taller | P11: 1 | R11: =+C6*D6 -> 50000 | S11: =P11/R11 -> 2e-05 | T11: 12000 | U11: =S11*T11 -> 0.24
B12: ACEITE DE MOTOR | C12: ='3insumo'!C10 -> P15400500 | D12: EO15W40DH | E12: 9.25 | F12: gal. | G12: 250 | H12: =E12/G12 -> 0.037 | I12: ='3insumo'!G10 -> 0 | J12: =H12*I12 -> 0 | L12: =+L11+0.01 -> 3.1 | M12: Cartificación de la camioneta | P12: 1 | R12: =+C6*D6 -> 50000 | S12: =P12/R12 -> 2e-05 | T12: 300 | U12: =S12*T12 -> 0.006
B13: ACEITE CAJA DE MAQUINA DE GIRO | C13: ='3insumo'!C11 -> TO4300500 | D13: TO30 | E13: 4.36 | F13: gal. | G13: 1000 | H13: =E13/G13 -> 0.00436 | I13: ='3insumo'!G11 -> 0 | J13: =H13*I13 -> 0 | N13: SUB - TOTAL COSTO HORARIO (S/. / HORA ) = 1 + 3 | T13: S/. | U13: =U2+J8 -> 73.844905
B14: ACEITE TRAS CAJA DE MANDOS FINALES | C14: ='3insumo'!C11 -> TO4300500 | D14: TO30 | E14: 4.76 | F14: gal. | G14: 2000 | H14: =E14/G14 -> 0.00238 | I14: ='3insumo'!G11 -> 0 | J14: =H14*I14 -> 0 | L14: 4 | M14: COSTOS ADMINISTRATIVOS- TALLER MINA | S14: SUB TOTAL S/. | U14: =+(U15+U47+U68) -> 4.8103398
B15: ACEITE TRA CAJA DEL AMORTIGUADOR | C15: ='3insumo'!C11 -> TO4300500 | D15: TO30 | E15: 0.34 | F15: gal. | G15: 2000 | H15: =E15/G15 -> 0.00017 | I15: ='3insumo'!G11 -> 0 | J15: =H15*I15 -> 0 | L15: 4.1 | M15: PERSONAL ADMINISTRATIVO Y TALLER | U15: =SUM(U16:U46) -> 4.318434
B16: ACEITE SISTEMA HIDRAULICO | C16: ='3insumo'!C12 -> TO4100500 | D16: TO10 | E16: 49.67 | F16: gal. | G16: 5000 | H16: =E16/G16 -> 0.009934 | I16: ='3insumo'!F12 -> 0 | J16: =H16*I16 -> 0 | M16: Personal Administrativo Huaraz (3) | O16: Administración | P16: 3 | Q16: jornal | R16: =+$F$6*$C$6 -> 5000 | S16: =($P$16/$R$16) -> 0.0006 | T16: ='6SueAct'!H11 -> 0 | U16: =S16*T16 -> 0 | V16: Personal Administrativo Hz | Y16: =SUM(U16:U21) -> 0
B17: GRASA VARILLAJE DE PLUMA Y BRAZO | C17: 39W610 | D17: Pto.Engrase | E17: 1 | F17: kg. | G17: 100 | H17: =(E17/G17)+(E18/G18)+(E19/G19)+(E20/G20)+(E21/G21) -> 0.038 | I17: ='3insumo'!F16 -> 0 | J17: =H17*I17 -> 0 | M17: Derechos y obligaciones L. administativo Hz | Q17: D-OLA | T17: ='6SueAct'!H12 -> 0 | U17: =S16*T17 -> 0
B18: GRASA VARILLAJE CUCHARON | C18: 39W610 | D18: Pto.Engrase | E18: 1 | F18: kg. | G18: 100 | M18: Personal Directivos (3) (No esta considerado) | O18: Administración | P18: 0 | Q18: honorario | R18: =+$F$6*$C$6 -> 5000 | S18: =($P$18/$R$18) -> 0 | T18: =+'6SueAct'!H13 -> 0 | U18: =S18*T18 -> 0
B19: GRASA ACOPLAMIENTO RAPIDO | C19: 39W610 | D19: Pto.Engrase | E19: 1 | F19: kg. | G19: 100 | M19: Derechos obligaciones Directivos | Q19: D-OLD | T19: =+'6SueAct'!H14 -> 0 | U19: =S18*T19 -> 0
B20: GRASA COJINETE DE ROTACION | C20: SMOLY0400 | D20: Pto.Engrase | E20: 1 | F20: kg. | G20: 250 | M20: Personal Asesor Legal (1) (No esta considerado) | O20: Administración | P20: 0 | Q20: honorario | R20: =+$F$6*$C$6 -> 5000 | S20: =(P20/R20) -> 0 | T20: =+'6SueAct'!H15 -> 0 | U20: =S20*T20 -> 0
B21: GRASA ENGRANAJE DE ROTACION | C21: SMOLY0400 | D21: Pto.Engrase | E21: 1 | F21: kg. | G21: 250 | M21: Derechos obligaciones Laborales Asesor Legal | Q21: D-OLL | T21: =+'6SueAct'!H16 -> 0 | U21: =S20*T21 -> 0
B22: FILTRO DE AIRE (P) | C22: ='3insumo'!C19 -> 6001856110 | D22: KOMATSU | E22: 1 | F22: und. | G22: 500 | H22: =E22/G22 -> 0.002 | I22: ='3insumo'!G19 -> 0 | J22: =H22*I22 -> 0 | M22: Personal Administrativo Mina (2) | O22: Administración | P22: 2 | Q22: jornal | R22: =+$F$6*$C$6 -> 5000 | S22: =(P22/R22) -> 0.0004 | T22: ='6SueAct'!H17 -> 0 | U22: =S22*T22 -> 0 | V22: Personal Administrativo Mina | Y22: =SUM(U22:U25)+SUM(U40:U41) -> 0
B23: FILTRO DE AIRE (S) | C23: ='3insumo'!C20 -> 6001856120 | D23: =+D22 -> KOMATSU | E23: 1 | F23: und. | G23: 500 | H23: =E23/G23 -> 0.002 | I23: ='3insumo'!F20 -> 0 | J23: =H23*I23 -> 0 | M23: Derechos y obligaciones labor. administ. Mina | Q23: D-OLA | T23: ='6SueAct'!H18 -> 0 | U23: =S22*T23 -> 0
B24: FILTRO DE ACEITE DE MOTOR | C24: ='3insumo'!C21 -> 6742014540 | D24: =+D22 -> KOMATSU | E24: 1 | F24: und. | G24: 250 | H24: =E24/G24 -> 0.004 | I24: ='3insumo'!F21 -> 0 | J24: =H24*I24 -> 0 | M24: Personal de Seguridad (2) | O24: Administración | P24: 2 | Q24: jornal | R24: =+$F$6*$C$6 -> 5000 | S24: =(P24/R24) -> 0.0004 | T24: ='6SueAct'!H19 -> 0 | U24: =S24*T24 -> 0
B25: PRE FILTRO DE COMBUSTIBLE (P) | C25: ='3insumo'!C22 -> 6003193610 | D25: =+D22 -> KOMATSU | E25: 1 | F25: und. | G25: 250 | H25: =E25/G25 -> 0.004 | I25: ='3insumo'!F22 -> 0 | J25: =H25*I25 -> 0 | M25: Derechos y obligaciones labora. P.Seguridad | Q25: D-OLPS | T25: ='6SueAct'!H20 -> 0 | U25: =S24*T25 -> 0
B26: FILTRO DE COMBUSTIBLE (S) | C26: ='3insumo'!C23 -> 6754796140 | D26: =+D22 -> KOMATSU | E26: 1 | F26: und. | G26: 250 | H26: =E26/G26 -> 0.004 | I26: ='3insumo'!F23 -> 0 | J26: =H26*I26 -> 0 | M26: Personal de Mantenimiento (mecanicos) (2) | O26: Taller | P26: 2 | Q26: jornal | R26: =+$F$6*$C$6 -> 5000 | S26: =(P26/R26) -> 0.0004 | T26: ='6SueAct'!H21 -> 0 | U26: =S26*T26 -> 0 | V26: Personal Taller Mina | Y26: =SUM(U26:U41) -> 0
B27: FILTRO HIDRAULICO | C27: ='3insumo'!C27 -> 2076071182 | D27: =+D23 -> KOMATSU | E27: 1 | F27: und. | G27: 1000 | H27: =E27/G27 -> 0.001 | I27: ='3insumo'!F27 -> 0 | J27: =H27*I27 -> 0 | M27: Derechos y obligaciones labora. P.Mantenim. | Q27: D-OLPMM | T27: ='6SueAct'!H22 -> 0 | U27: =S26*T27 -> 0
B28: CARTUCHO o INHIBIDOR DE CORROSION | C28: ='3insumo'!C28 -> 6004111191 | D28: =+D22 -> KOMATSU | E28: 1 | F28: und. | G28: 1000 | H28: =E28/G28 -> 0.001 | I28: ='3insumo'!F28 -> 0 | J28: =H28*I28 -> 0 | M28: Personal de Apoyo Mantenimiento (2) | O28: Taller | P28: 2 | Q28: jornal | R28: =+$F$6*$C$6 -> 5000 | S28: =(P28/R28) -> 0.0004 | T28: ='6SueAct'!H23 -> 0 | U28: =S28*T28 -> 0
B29: FILTRO DE AIRE ACONDICIONADO RECIRCUL | C29: ='3insumo'!C24 -> 2089797620 | D29: =+D23 -> KOMATSU | E29: 1 | F29: und. | G29: =+D6 -> 5000 | H29: =E29/G29 -> 0.0002 | I29: ='3insumo'!F24 -> 0 | J29: =H29*I29 -> 0 | M29: Derechos y obligaciones labora. P.A.Manteni. | Q29: D-OLPa | T29: ='6SueAct'!H24 -> 0 | U29: =S28*T29 -> 0
B30: FILTRO DE AIRE ACONDICIONADO LIMPIO | C30: ='3insumo'!C25 -> 17M9113530 | D30: =+D24 -> KOMATSU | E30: 1 | F30: und. | G30: =G29 -> 5000 | H30: =E30/G30 -> 0.0002 | I30: ='3insumo'!F25 -> 0 | J30: =H30*I30 -> 0 | M30: Personal Mantenimiento Eléctrico (2) | O30: Taller | P30: 0 | Q30: jornal | R30: =+$F$6*$C$6 -> 5000 | S30: =(P30/R30) -> 0 | T30: =+'6SueAct'!H25 -> 0 | U30: =S30*T30 -> 0
B31: RESPIRADERO TANQUE HIDRAULICO | C31: ='3insumo'!C30 -> 20Y6021470 | D31: =+D22 -> KOMATSU | E31: 1 | F31: und. | G31: 500 | H31: =E31/G31 -> 0.002 | I31: ='3insumo'!F30 -> 0 | J31: =H31*I31 -> 0 | M31: Derechos y obligA. labora. P. Mantenimiento Eléctric | Q31: D-OLME | T31: ='6SueAct'!H26 -> 0 | U31: =S30*T31 -> 0
B32: RESPIRADERO ADICIONAL TANQUE HIDRAU | C32: ='3insumo'!C29 -> 2076051310 | D32: =+D22 -> KOMATSU | E32: 1 | F32: und. | G32: 500 | H32: =E32/G32 -> 0.002 | I32: ='3insumo'!F29 -> 0 | J32: =H32*I32 -> 0 | M32: Personal Soldador (2) | O32: Taller | P32: 2 | Q32: jornal | R32: =+$F$6*$C$6 -> 5000 | S32: =(P32/R32) -> 0.0004 | T32: ='6SueAct'!H27 -> 0 | U32: =S32*T32 -> 0
B33: REFRIGERANTE | C33: ='3insumo'!C42 -> 1400164H1 | D33: =+D22 -> KOMATSU | E33: 8.45 | F33: gal. | G33: 4000 | H33: =E33/G33 -> 0.0021125 | I33: ='3insumo'!F42 -> 0 | J33: =H33*I33 -> 0
B34: CORREA DE TRANSMISION | C34: =+'[2]AII insu'!C38 -> 0 | E34: 1 | F34: und. | G34: 6000 | H34: =E34/G34 -> 0.00016666667 | I34: ='3insumo'!F41 -> 0 | J34: =H34*I34 -> 0 | M34: Derechos y obligaciones laborales P.Soldador | T34: ='6SueAct'!H28 -> 0 | U34: =S32*T34 -> 0
B35: BATERIA DE 15 PLACAS 24 VOLTIOS | C35: 0 | E35: 2 | F35: und. | G35: 6000 | H35: =E35/G35 -> 0.00033333333 | I35: ='3insumo'!F43 -> 0 | J35: =H35*I35 -> 0 | Q35: D-OLS
A36: 1.3 | B36: ANALISIS DE ACEITE | H36: SUB TOTAL S/. | J36: =SUM(J37:J41) -> 0 | M36: Personal Almacen (2) | O36: Taller | P36: 2 | Q36: jornal | R36: =+$F$6*$C$6 -> 5000 | S36: =(P36/R36) -> 0.0004 | T36: ='6SueAct'!H29 -> 0 | U36: =S36*T36 -> 0
B37: DEL MOTOR | E37: 14 | F37: Muestras | G37: 2000 | H37: =E37/G37 -> 0.007 | I37: ='3insumo'!F45 -> 0 | J37: =I37*H37 -> 0 | M37: Derechos y obligaciones laborales P.Almacen | Q37: D-OLPA | T37: ='6SueAct'!H30 -> 0 | U37: =S36*T37 -> 0
B38: HIDRAULICO | E38: 3 | F38: Muestras | G38: 2000 | H38: =E38/G38 -> 0.0015 | I38: ='3insumo'!F46 -> 0 | J38: =I38*H38 -> 0 | M38: Personal Llantero (2) | O38: Taller | P38: 2 | Q38: jornal | R38: =+$F$6*$C$6 -> 5000 | S38: =(P38/R38) -> 0.0004 | T38: ='6SueAct'!H31 -> 0 | U38: =S38*T38 -> 0
B39: DE ROTACION | E39: 3 | F39: Muestras | G39: 2000 | H39: =E39/G39 -> 0.0015 | I39: ='3insumo'!F47 -> 0 | J39: =I39*H39 -> 0 | M39: Derechos y obligaciones laborales P.Llantero | Q39: D-OLPA | T39: ='6SueAct'!H32 -> 0 | U39: =S38*T39 -> 0
B40: MANDOS FINALES | E40: 4 | F40: Muestras | G40: 2000 | H40: =E40/G40 -> 0.002 | I40: ='3insumo'!F48 -> 0 | J40: =I40*H40 -> 0 | M40: Personal Supervisor (4) | O40: Supervision | P40: 4 | Q40: jornal | R40: =+$F$6*$C$6 -> 5000 | S40: =(P40/R40) -> 0.0008 | T40: ='6SueAct'!H33 -> 0 | U40: =S40*T40 -> 0
...

Sheet 7,1Grafico
A1: ESTADISTICA COSTO HORARIO VIGENTE
A2: EXCAVADORA KOMATSU PC300-LC8
A4: Descripción | C4: % | D4: S/.
A5: COSTO DE OPERACIÓN HORARIA | C5: =D5/$D$10 -> 0.29513218 | D5: ='7chrFM'!U73 -> 25.593098
A6: COSTO DE POSESION HORARIA | C6: =D6/$D$10 -> 0.55642585 | D6: ='7chrFM'!U74 -> 48.251807
A7: PERSONAL ADMINISTRATIVO Y TALLER MINA HORARIA | C7: =D7/$D$10 -> 0.055471444 | D7: ='7chrFM'!U75 -> 4.8103398
A8: COSTO ADMINISTRATIVO 5% DE COSTOS 1 + 2 + 3 + 4 | C8: =D8/$D$10 -> 0.045351474 | D8: ='7chrFM'!U76 -> 3.9327622
A9: UTILIDAD | C9: 0.05 | D9: =SUM(D5:D8)*C9 -> 4.1294004
A10: TOTAL FACTURADO SIN EL IGV | D10: =SUM(D5:D9) -> 86.717407
M11: =155.09-33.53 -> 121.56
M12: =M11*0.05 -> 6.078
M13: =SUM(M11:M12) -> 127.638
M14: =+M13*1.05 -> 134.0199
B18: DATOS UTILIZADOS
B19: RUBRO | C19: SIMBOLO | E19: RANGO | G19: VALOR UTILIZADO
B20: Costo Actual de Maquinaria | C20: Ca (volquete) | G20: =+O28 -> 852845 | N20: =(G20*G22)/(200*G24) -> 0.0852845
B21: Coeficiente de Valor residual | C21: Kvr | E21: 0.80 - 0.90 | G21: 0.8
B22: Interes horario de inversión de capital inv. | C22: i ( % ) | E22: 04 - 10 | G22: 0.1 | M22: 0.1
B23: Vida útil Excavadora (hr) | C23: Nv (excavadora) | E23: 8,000 - 16,000 | G23: 15000 | K23: 3 | L23: 1 | M23: =SUM(K23:L23) -> 4
B24: Uso anual (hr) | C24: Na (excavadora) | E24: 5,200 - 7,000 | G24: =+'7chrFM'!D6 -> 5000
B25: Costo Actual Camioneta | C25: Cac (4X4 2D) | G25: 102900
B26: Vida útil Camioneta (hr) | C26: Nvc (camioneta) | E26: 15,000 - 20,000 | G26: 18000 | N26: T:C: Mina | O26: 2.94
B27: Uso anual (hr) camioneta | C27: Nac (camioneta) | E27: 1,500 - 4,000 | G27: 4000 | N27: T:C: compra | O27: 2.891
B28: Equipo de Taller | C28: Ca (taller) | G28: 52000 | L28: 295000 | M28: 1 | N28: =L28*M28 -> 295000 | O28: =N28*O27 -> 852845
B29: Vida Util (hr) taller | C29: Nv (taller) | E29: 15,000- 30,600 | G29: 30000 | L29: 295000 | M29: 1.19 | N29: =L29*M29 -> 351050 | O29: =N29*O27 -> 1014885.6
L30: 295000 | M30: 1.19 | N30: =L30*M30 -> 351050 | O30: =N30*O26 -> 1032087
B31: (N+1) x V x i x N = 3+1 x 1'032,087.00 x 10% x 3 | C31: 4 x 309626,1 | E31: 4 x 309626,1 | G31: =M23*C35/E32 -> 170569
B32: 2N 2 * 3 | C32: =2*K23 -> 6 | E32: =+C32 -> 6 | I32: =G31/G33 -> 11.371267
A33: I = | B33: Ve hrs 15,000 | C33: =+G23 -> 15000 | E33: =+C33 -> 15000 | G33: =+E33 -> 15000
C35: =G20*M22*K23 -> 255853.5
D38: =1032085*0.1*3*4/6/15000 -> 13.761133

Sheet Costo Horario NL12
A1: ESTRUCTURA DE COSTO HORARIO MAQUINARIA PESADA
A2: CAMION VOLQUETE MARCA VOLVO MODELOS: FM12-440
A3: COSTO DE OPERACIÓN HORARIA MAQUINA SECA DEL VOLQUETE EN SOLES (S/.) ( hr - Maq.)
A4: DESCRIPCION | E4: PRODUCTO | F4: RENDIMIENTO PROMEDIO | G4: CONSUMO | H4: PRECIO | I4: COSTO REAL
G5: POR HORA | H5: UNIT S/. | I5: Soles / Hora
A6: 1 | B6: COSTO DE OPERACIÓN HORARIA | I6: =SUM(I7,I9,I30,I36,I41,I44,I51,I64) -> 48.918347
A7: 1.1 | B7: COMBUSTIBLE | G7: SUB TOTAL S/. | I7: =SUM(I8) -> 0
B8: Consumo = 0.0325 x Gal / H x BHP | E8: DIESEL 2 | F8: 4,5 gal. x hr-maq. | G8: 4.5 | H8: 0 | I8: =G8*H8 -> 0
A9: 1.2 | B9: LUBRICANTES Y FILTROS | G9: SUB TOTAL S/. | I9: =SUM(I10:I29) -> 5.8867643
B10: ACEITE MOTOR | D10: 85102465 | E10: VDS-3 15W40 | F10: 10 gal. x 600 hr.-maq. | G10: =10/500 -> 0.02 | H10: 43.51 | I10: =G10*H10 -> 0.8702
B11: FILTRO DE ACEITE | D11: 478736 | E11: Volvo | F11: 2 und. x 600 hr.-maq. | G11: =2/500 -> 0.004 | H11: 39.45 | I11: =G11*H11 -> 0.1578
B12: FILTRO DE COMBUSTIBLE | D12: 20972293 | E12: Volvo | F12: 2 und. x 600 hr.-maq. | G12: =1/500 -> 0.002 | H12: 30 | I12: =G12*H12 -> 0.06
B13: FILTRO SEPARADOR DE AGUA | D13: 20879812 | E13: Volvo | F13: 1 und. x 600 hr.-maq. | G13: =1/500 -> 0.002 | H13: 112.35 | I13: =G13*H13 -> 0.2247
B14: FILTRO DE AIRE PRIMARIO | D14: 8149064 | E14: Volvo | F14: 1 und. x 600 hr.-maq. | G14: =1/500 -> 0.002 | H14: 365.3 | I14: =G14*H14 -> 0.7306
B15: FILTRO DE AIRE SECUNDARIO | E15: Volvo | F15: 1 und x 1800 hr.-maq. | G15: 0.00055555556 | H15: 224.5 | I15: =H15*G15 -> 0.12472222
B16: ACEITE DE CAJA DE C AMBIOS | D16: 1161280 | E16: SAE 80W/90 | F16: 4 gal. x 1800 hr.-maq. | G16: =4/2000 -> 0.002 | H16: 32.77 | I16: =G16*H16 -> 0.06554
B17: ACEITE CORONA Y CUBOS REDUCTORES | D17: 1161279 | E17: API GL5 SAE 85W140 | F17: 10 gal. x 1800 hr.-maq. | G17: =10/2000 -> 0.005 | H17: 32.77 | I17: =G17*H17 -> 0.16385
B18: FILTRO DE DIRECCION HIDRAULICA | D18: 20580233 | E18: Volvo | F18: 1 und. x 600 hr.-maq. | G18: =1/500 -> 0.002 | H18: 22.17 | I18: =G18*H18 -> 0.04434
B19: ACEITE DE DIRECCION HIDRAULICA | D19: 1161997 | E19: ATF Dexron II | F19: 2gal. x 1800 hr.-maq. | G19: =2/2000 -> 0.001 | H19: 60 | I19: =G19*H19 -> 0.06
B20: FILTRO DEL SISTEMA HIDRAULICO | F20: 1 und. x 600 hr.-maq. | G20: =1/500 -> 0.002 | H20: 86.28 | I20: =G20*H20 -> 0.17256
B21: FILTRO SECADOR DE AIRE | D21: 20972915 | E21: Volvo | F21: 1 und x 600 hr.-maq. | G21: =1/500 -> 0.002 | H21: 138.66 | I21: =G21*H21 -> 0.27732
B22: LIQUIDO DE EMBRAGUE | D22: 85112077 | E22: DOT 4 | F22: 1 x 1800 hr.-maq. | G22: =1/2000 -> 0.0005 | H22: 66.62 | I22: =G22*H22 -> 0.03331
B23: ACEITE HIDRAULICO DE LEVANTE DE TOLVA | E23: SAE 30 | F23: 14 gal. x 1800 hr.-maq | G23: =14/2000 -> 0.007 | H23: 32.77 | I23: =G23*H23 -> 0.22939
B24: COMPRESOR DE AIRE | D24: 20701801 | E24: Volvo | F24: 1 kit x 1800 hr.-maq | G24: =1/2000 -> 0.0005 | H24: 2610 | I24: =G24*H24 -> 1.305
B25: GRASA PARA LUBRICACION DE CHASIS/ ARBOL DE TRANSMISION | D25: 1161962 | E25: EP NLGI Nº 2 | F25: 20 kg. x 500 hr.-maq. | G25: =20/500 -> 0.04 | H25: 23.78 | I25: =G25*H25 -> 0.9512
B26: CORREA DE POLEA Y VENTILADOR | D26: 20712530 | E26: Volvo | F26: 1 und. x 2000 hr.-maq | G26: =1/2000 -> 0.0005 | H26: 148.2642 | I26: =G26*H26 -> 0.0741321
B27: LIQUIDO REFRIGERANTE | D27: 1089240 | E27: Volvo Coolant Verde | F27: 11 gal. x 2000 hr.-maq | G27: =11/2000 -> 0.0055 | H27: 62.2 | I27: =G27*H27 -> 0.3421
A30: 1.3 | B30: ANALISIS DE ACEITE | G30: SUB TOTAL S/. | I30: =SUM(I31:I35) -> 0.42336
B31: ANALISIS DE ACEITE DE MOTOR | F31: 4 muestra x 2000 hr.-maq | G31: =4/2000 -> 0.002 | H31: =35.28*2 -> 70.56 | I31: =H31*G31 -> 0.14112
B32: ANALISIS DE ACEITE DE CAJA DE CAMBIOS | F32: 2 muestra x 2000 hr.-maq | G32: =2/2000 -> 0.001 | H32: =35.28*2 -> 70.56 | I32: =H32*G32 -> 0.07056
B33: ANALISIS DE ACEITE CORONA | F33: 2 muestra x 2000 hr.-maq | G33: =2/2000 -> 0.001 | H33: =35.28*2 -> 70.56 | I33: =H33*G33 -> 0.07056
B34: ANALISIS DE REFRIGERANTE | F34: 4 muestra x 2000 hr.-maq | G34: =4/2000 -> 0.002 | H34: =35.28*2 -> 70.56 | I34: =H34*G34 -> 0.14112
A36: 1.4 | B36: NEUMATICO | G36: SUB TOTAL S/. | I36: =SUM(I37:I40) -> 13.811467
B37: Neumático 12.00 x R20 Goodyear 9377 OTR | F37: 08 und. x 1,800 hr.-maq. | G37: =8/1800 -> 0.0044444444 | H37: 2446.08 | I37: =G37*H37 -> 10.871467
B38: Neumático 12.00 x R20 Rack | F38: 02 und. x 1,800 hr.-maq. | G38: =2/1800 -> 0.0011111111 | H38: 1808.1 | I38: =G38*H38 -> 2.009
B39: Camaras Goodyear 12.00 x R20 | F39: 10 und. x 1,800 hr.-maq. | G39: =10/1800 -> 0.0055555556 | H39: 114.66 | I39: =G39*H39 -> 0.637
B40: Protectores Goodyear 12.00 x R | F40: 10 und. x 1,800 hr.-maq. | G40: =10/1800 -> 0.0055555556 | H40: 52.92 | I40: =G40*H40 -> 0.294
A41: 1.5 | B41: RESERVA PARA REPARACIONES | G41: SUB TOTAL S/. | I41: =SUM(I42:I43) -> 5
B42: Repuestos (*) | F42: 1 kit. x 15000 hr.-maq. | G42: =1/15000 -> 6.6666667e-05 | H42: 60000 | I42: =G42*H42 -> 4
B43: Mano de Obra | F43: 25% repuestos | I43: =I42*0.25 -> 1
...

Sheet Propuesto Costo Horario
