Workbook

Sheet Espectro Diseño
B2: ZUCS | C2: =(C5*C6*C7*C11)/C12 -> 0.13089005
B3: R
B5: Z4 | C5: 0.45
B6: Uc | C6: 1
B7: C | C7: =2.5*(C9/C8) -> 1.5706806
B8: T (hn/CT) | C8: =38.2/60 -> 0.63666667
B9: Tp | C9: 0.4
B10: TL | C10: 2.5
B11: S1 | C11: 1
B12: R | C12: =C13*C14*C15 -> 5.4
B13: Ro | C13: 6
B14: Ia | C14: 0.9
B15: Ip | C15: 1
B17: k | C17: =0.75+(0.5*C8) -> 1.0683333

Sheet CARGAS
B2: DEAD | C2: Peso Propio de los Elementos Estructurales
B4: CM | C4: Peso Acabados + Peso ladrillo Techo + Peso muros albañilería + Tanque Elevado
C6: Peso Acabados | E6: 100 | F6: kg/m2
C7: Peso Ladrillo de Techo | E7: =F16 -> 90 | F7: kg/m2
E8: Vc=0.05+0.25H
E9: Vc=0.05+0.25(0.15)
E10: Vc | F10: =0.05+0.25*(0.15) -> 0.0875 | G10: m3/m2
E12: Peso Esp. Concreto | G12: 2400 | H12: kg/m3
E14: Wc | F14: =G12*F10 -> 210 | G14: kg/m2
E15: Wladrillo = Wlosa-Wc
E16: Wladrillo | F16: =300-F14 -> 90 | G16: kg/m2
C18: Peso Muros sobre Área | E18: 250 | F18: kg/m2
C20: Peso Muros sobre Viga | E20: e | F20: 0.15 | G20: m
E21: h | F21: 1.2 | G21: m
E22: Peso Esp. | F22: 1350 | G22: kg/m3
E23: Wmuro | F23: =F22*F21*F20 -> 243 | G23: kg/m
C25: Tanque Losa Ascensor (1) | E25: Vol | F25: 2.5 | G25: m3
E26: Peso Esp. H2O | F26: 1000 | G26: kg/m3
E27: Wtanque | F27: =F26*F25 -> 2500 | G27: kg
E28: Área | F28: 4 | G28: m2
E29: Wtanque/m2 | F29: =F27/F28 -> 625 | G29: kg/m2
C31: Tanque Losa Central (4) | E31: Vol | F31: =2.5*4 -> 10 | G31: m3
E32: Peso Esp. H2O | F32: 1000 | G32: kg/m3
E33: Wtanque | F33: =F32*F31 -> 10000 | G33: kg
E34: Área | F34: 17.5 | G34: m2
E35: Wtanque/m2 | F35: =F33/F34 -> 571.42857 | G35: kg/m2
B37: LIVE | C37: Carga Viva de Entrepiso
C38: Sótano | D38: Garaje | E38: 250 | F38: kg/m2
C39: Semisótano | D39: Garaje | E39: 250 | F39: kg/m2
D40: Escalera | E40: 250 | F40: kg/m2
C41: 1°-2°nivel | D41: Restaurante | E41: 400 | F41: kg/m2
D42: Escalera | E42: 500 | F42: kg/m2
C43: 3°-10°nivel | D43: Departamentos | E43: 200 | F43: kg/m2
D44: Escalera | E44: 200 | F44: kg/m2
B46: LIVE UP | C46: Carga Viva de Techo
D47: Azotea | E47: 100 | F47: kg/m2

Sheet COMBINACIONES
B1: COMBINACIÓN N°01: 1.4CM+1.7CV
B3: COMB1 | C3: 1.4 | D3: DEAD | E3: 1.4 | F3: CM | G3: 1.7 | H3: LIVE | I3: 1.7 | J3: LIVE UP
B4: COMB2 | C4: 1.4 | D4: DEAD | E4: 1.4 | F4: CM | G4: 1.7 | H4: LIVE 1 | I4: 1.7 | J4: LIVE UP
B5: COMB3 | C5: 1.4 | D5: DEAD | E5: 1.4 | F5: CM | G5: 1.7 | H5: LIVE 2 | I5: 1.7 | J5: LIVE UP
B7: COMBINACIÓN N°02: 1.25CM+1.25CV+-CS
B9: COMB4 | C9: 1.25 | D9: DEAD | E9: 1.25 | F9: CM | G9: 1.25 | H9: LIVE | I9: 1.25 | J9: LIVE UP | K9: 1 | L9: SxD
B10: COMB5 | C10: 1.25 | D10: DEAD | E10: 1.25 | F10: CM | G10: 1.25 | H10: LIVE | I10: 1.25 | J10: LIVE UP | K10: -1 | L10: SxD
B11: COMB6 | C11: 1.25 | D11: DEAD | E11: 1.25 | F11: CM | G11: 1.25 | H11: LIVE | I11: 1.25 | J11: LIVE UP | K11: 1 | L11: SyD
B12: COMB7 | C12: 1.25 | D12: DEAD | E12: 1.25 | F12: CM | G12: 1.25 | H12: LIVE | I12: 1.25 | J12: LIVE UP | K12: -1 | L12: SyD
B13: COMB8 | C13: 1.25 | D13: DEAD | E13: 1.25 | F13: CM | G13: 1.25 | H13: LIVE 1 | I13: 1.25 | J13: LIVE UP | K13: 1 | L13: SxD
B14: COMB9 | C14: 1.25 | D14: DEAD | E14: 1.25 | F14: CM | G14: 1.25 | H14: LIVE 1 | I14: 1.25 | J14: LIVE UP | K14: -1 | L14: SxD
B15: COMB10 | C15: 1.25 | D15: DEAD | E15: 1.25 | F15: CM | G15: 1.25 | H15: LIVE 1 | I15: 1.25 | J15: LIVE UP | K15: 1 | L15: SyD
B16: COMB11 | C16: 1.25 | D16: DEAD | E16: 1.25 | F16: CM | G16: 1.25 | H16: LIVE 1 | I16: 1.25 | J16: LIVE UP | K16: -1 | L16: SyD
B17: COMB12 | C17: 1.25 | D17: DEAD | E17: 1.25 | F17: CM | G17: 1.25 | H17: LIVE 2 | I17: 1.25 | J17: LIVE UP | K17: 1 | L17: SxD
B18: COMB13 | C18: 1.25 | D18: DEAD | E18: 1.25 | F18: CM | G18: 1.25 | H18: LIVE 2 | I18: 1.25 | J18: LIVE UP | K18: -1 | L18: SxD
B19: COMB14 | C19: 1.25 | D19: DEAD | E19: 1.25 | F19: CM | G19: 1.25 | H19: LIVE 2 | I19: 1.25 | J19: LIVE UP | K19: 1 | L19: SyD
B20: COMB15 | C20: 1.25 | D20: DEAD | E20: 1.25 | F20: CM | G20: 1.25 | H20: LIVE 2 | I20: 1.25 | J20: LIVE UP | K20: -1 | L20: SyD
B22: COMBINACIÓN N°03: 0.90CM+-CS
B24: COMB16 | C24: 0.9 | D24: DEAD | E24: 0.9 | F24: CM | G24: 1 | H24: SxD
B25: COMB17 | C25: 0.9 | D25: DEAD | E25: 0.9 | F25: CM | G25: -1 | H25: SxD
B26: COMB18 | C26: 0.9 | D26: DEAD | E26: 0.9 | F26: CM | G26: 1 | H26: SyD
B27: COMB19 | C27: 0.9 | D27: DEAD | E27: 0.9 | F27: CM | G27: -1 | H27: SyD
B29: COMBINACIÓN N°04: ENVOLVENTE
B31: COMB20 | C31: COMB1 + COMB2 + … + COMB19

Sheet PESO
B2: PISO 1 - 2 | C2: =I21+I23+0.25*I25 -> 850.99903 | D2: Ton
B4: DEAD | C4: COLUNAS | D4: 58 | E4: 3 | F4: 0.4 | G4: 0.5 | H4: 2.4028 | I4: =D4*E4*F4*G4*H4 -> 83.61744 | J4: Ton
C5: VIGAS | D5: 2 | E5: =3.5*3 -> 10.5 | F5: 0.25 | G5: 0.4 | H5: 2.4028 | I5: =D5*E5*F5*G5*H5 -> 5.04588 | J5: Ton
D6: 4 | E6: =3.5*3+5 -> 15.5 | F6: 0.25 | G6: 0.4 | H6: 2.4028 | I6: =D6*E6*F6*G6*H6 -> 14.89736 | J6: Ton
D7: 4 | E7: =3.5*3+5*2 -> 20.5 | F7: 0.25 | G7: 0.4 | H7: 2.4028 | I7: =D7*E7*F7*G7*H7 -> 19.70296 | J7: Ton
D8: 2 | E8: =4*5+2*4 -> 28 | F8: 0.25 | G8: 0.4 | H8: 2.4028 | I8: =D8*E8*F8*G8*H8 -> 13.45568 | J8: Ton
D9: 2 | E9: =41-4 -> 37 | F9: 0.25 | G9: 0.4 | H9: 2.4028 | I9: =D9*E9*F9*G9*H9 -> 17.78072 | J9: Ton
D10: 2 | E10: 41 | F10: 0.25 | G10: 0.4 | H10: 2.4028 | I10: =D10*E10*F10*G10*H10 -> 19.70296 | J10: Ton
C11: MUROS | D11: 6 | E11: 5 | F11: 0.25 | G11: 3 | H11: 2.4028 | I11: =D11*E11*F11*G11*H11 -> 54.063 | J11: Ton
D12: 2 | E12: 4 | F12: 0.25 | G12: 3 | H12: 2.4028 | I12: =D12*E12*F12*G12*H12 -> 14.4168 | J12: Ton
D13: 4 | E13: 6 | F13: 0.25 | G13: 3 | H13: 2.4028 | I13: =D13*E13*F13*G13*H13 -> 43.2504 | J13: Ton
C14: ESCALERA | D14: 3 | E14: 3.3541 | F14: 0.15 | G14: 1 | H14: 2.4028 | I14: =D14*E14*F14*G14*H14 -> 3.6266542 | J14: Ton
D15: 2 | E15: 2.25 | F15: 0.15 | G15: 1 | H15: 2.4028 | I15: =D15*E15*F15*G15*H15 -> 1.62189 | J15: Ton
C16: LOSA 5cm | D16: 1 | E16: =(41*20.5)-(80+(3.5*5*4)+(1.5*5*2)) -> 675.5 | F16: 0.05 | G16: 1 | H16: 2.4028 | I16: =D16*E16*F16*G16*H16 -> 81.15457 | J16: Ton
C17: VIGUETAS | D17: 132 | E17: 5 | F17: 0.1 | G17: 0.15 | H17: 2.4028 | I17: =D17*E17*F17*G17*H17 -> 23.78772 | J17: Ton
D18: 264 | E18: 3.5 | F18: 0.1 | G18: 0.15 | H18: 2.4028 | I18: =D18*E18*F18*G18*H18 -> 33.302808 | J18: Ton
D19: 144 | E19: 4 | F19: 0.1 | G19: 0.15 | H19: 2.4028 | I19: =D19*E19*F19*G19*H19 -> 20.760192 | J19: Ton
D20: 200 | E20: 5 | F20: 0.1 | G20: 0.15 | H20: 2.4028 | I20: =D20*E20*F20*G20*H20 -> 36.042 | J20: Ton
I21: =SUM(I4:I20) -> 486.22903 | J21: Ton
B23: CM | C23: LOSA | D23: 1 | E23: =E16 -> 675.5 | F23: 1 | G23: 1 | H23: =0.1+0.09+0.25 -> 0.44 | I23: =D23*E23*F23*G23*H23 -> 297.22 | J23: Ton
B25: LIVE | C25: LOSA | D25: 1 | E25: =E16 -> 675.5 | F25: 1 | G25: 1 | H25: 0.4 | I25: =D25*E25*F25*G25*H25 -> 270.2 | J25: Ton
B28: PISO 3 - 6 | C28: =I47+I49+0.25*I51 -> 817.22403 | D28: Ton
B30: DEAD | C30: COLUNAS | D30: 58 | E30: 3 | F30: 0.4 | G30: 0.5 | H30: 2.4028 | I30: =D30*E30*F30*G30*H30 -> 83.61744 | J30: Ton
C31: VIGAS | D31: 2 | E31: =3.5*3 -> 10.5 | F31: 0.25 | G31: 0.4 | H31: 2.4028 | I31: =D31*E31*F31*G31*H31 -> 5.04588 | J31: Ton
D32: 4 | E32: =3.5*3+5 -> 15.5 | F32: 0.25 | G32: 0.4 | H32: 2.4028 | I32: =D32*E32*F32*G32*H32 -> 14.89736 | J32: Ton
D33: 4 | E33: =3.5*3+5*2 -> 20.5 | F33: 0.25 | G33: 0.4 | H33: 2.4028 | I33: =D33*E33*F33*G33*H33 -> 19.70296 | J33: Ton
D34: 2 | E34: =4*5+2*4 -> 28 | F34: 0.25 | G34: 0.4 | H34: 2.4028 | I34: =D34*E34*F34*G34*H34 -> 13.45568 | J34: Ton
D35: 2 | E35: =41-4 -> 37 | F35: 0.25 | G35: 0.4 | H35: 2.4028 | I35: =D35*E35*F35*G35*H35 -> 17.78072 | J35: Ton
D36: 2 | E36: 41 | F36: 0.25 | G36: 0.4 | H36: 2.4028 | I36: =D36*E36*F36*G36*H36 -> 19.70296 | J36: Ton
C37: MUROS | D37: 6 | E37: 5 | F37: 0.25 | G37: 3 | H37: 2.4028 | I37: =D37*E37*F37*G37*H37 -> 54.063 | J37: Ton
D38: 2 | E38: 4 | F38: 0.25 | G38: 3 | H38: 2.4028 | I38: =D38*E38*F38*G38*H38 -> 14.4168 | J38: Ton
D39: 4 | E39: 6 | F39: 0.25 | G39: 3 | H39: 2.4028 | I39: =D39*E39*F39*G39*H39 -> 43.2504 | J39: Ton
C40: ESCALERA | D40: 3 | E40: 3.3541 | F40: 0.15 | G40: 1 | H40: 2.4028 | I40: =D40*E40*F40*G40*H40 -> 3.6266542 | J40: Ton
D41: 2 | E41: 2.25 | F41: 0.15 | G41: 1 | H41: 2.4028 | I41: =D41*E41*F41*G41*H41 -> 1.62189 | J41: Ton
C42: LOSA 5cm | D42: 1 | E42: =(41*20.5)-(80+(3.5*5*4)+(1.5*5*2)) -> 675.5 | F42: 0.05 | G42: 1 | H42: 2.4028 | I42: =D42*E42*F42*G42*H42 -> 81.15457 | J42: Ton
C43: VIGUETAS | D43: 132 | E43: 5 | F43: 0.1 | G43: 0.15 | H43: 2.4028 | I43: =D43*E43*F43*G43*H43 -> 23.78772 | J43: Ton
D44: 264 | E44: 3.5 | F44: 0.1 | G44: 0.15 | H44: 2.4028 | I44: =D44*E44*F44*G44*H44 -> 33.302808 | J44: Ton
D45: 144 | E45: 4 | F45: 0.1 | G45: 0.15 | H45: 2.4028 | I45: =D45*E45*F45*G45*H45 -> 20.760192 | J45: Ton
D46: 200 | E46: 5 | F46: 0.1 | G46: 0.15 | H46: 2.4028 | I46: =D46*E46*F46*G46*H46 -> 36.042 | J46: Ton
I47: =SUM(I30:I46) -> 486.22903 | J47: Ton
...

Sheet VERIFICACIONES
A2: 1 | B2: VERIFICACIÓN POR PARTICIPACIÓN MODAL
B8: TABLE: Modal Load Participation Ratios
B9: OutputCase | C9: ItemType | D9: Item | E9: Static | F9: Dynamic
B10: Text | C10: Text | D10: Text | E10: Percent | F10: Percent
B11: MODAL | C11: Acceleration | D11: UX | E11: 100 | F11: 98.208 | G11: =IF(F11>90,"OK","ERROR") -> OK
B12: MODAL | C12: Acceleration | D12: UY | E12: 100 | F12: 97.4525 | G12: =IF(F12>90,"OK","ERROR") -> OK
B13: MODAL | C13: Acceleration | D13: UZ | E13: 0 | F13: 0
A16: 2 | B16: VERIFICACIÓN DE DESPLAZAMIENTOS LATERALES
B35: DIRECCIÓN X
B37: EJES | C37: N° PISO | D37: DESP. ABS. | E37: Δi | F37: hei | G37: DISTORSIÓN
B38: EJE A Y EJE 1 | C38: PISO 6 | D38: 9.972119 | E38: =D38-D39 -> 1.96879 | F38: 300 | G38: =E38/F38 -> 0.0065626333 | H38: =IF(G38<0.007,"OK","ERROR") -> OK
C39: PISO 5 | D39: 8.003329 | E39: =D39-D40 -> 1.946674 | F39: 300 | G39: =E39/F39 -> 0.0064889133 | H39: =IF(G39<0.007,"OK","ERROR") -> OK
C40: PISO 4 | D40: 6.056655 | E40: =D40-D41 -> 1.867993 | F40: 300 | G40: =E40/F40 -> 0.0062266433 | H40: =IF(G40<0.007,"OK","ERROR") -> OK
C41: PISO 3 | D41: 4.188662 | E41: =D41-D42 -> 1.707759 | F41: 300 | G41: =E41/F41 -> 0.00569253 | H41: =IF(G41<0.007,"OK","ERROR") -> OK
C42: PISO 2 | D42: 2.480903 | E42: =D42-D43 -> 1.429107 | F42: 300 | G42: =E42/F42 -> 0.00476369 | H42: =IF(G42<0.007,"OK","ERROR") -> OK
C43: PISO 1 | D43: 1.051796 | E43: =D43-D44 -> 0.958583 | F43: 300 | G43: =E43/F43 -> 0.0031952767 | H43: =IF(G43<0.007,"OK","ERROR") -> OK
C44: SEMISÓTANO | D44: 0.093213 | E44: =D44-D45 -> 0.093213 | F44: 280 | G44: =E44/F44 -> 0.00033290357 | H44: =IF(G44<0.007,"OK","ERROR") -> OK
C45: SÓTANO | D45: 0 | E45: =D45-D46 -> 0 | F45: 280 | G45: =E45/F45 -> 0 | H45: =IF(G45<0.007,"OK","ERROR") -> OK
C46: BASE | D46: 0
B47: EJE A Y EJE 3 | C47: PISO 10 | D47: 16.478506 | E47: =D47-D48 -> 1.766289 | F47: 300 | G47: =E47/F47 -> 0.00588763 | H47: =IF(G47<0.007,"OK","ERROR") -> OK
C48: PISO 9 | D48: 14.712217 | E48: =D48-D49 -> 1.812626 | F48: 300 | G48: =E48/F48 -> 0.0060420867 | H48: =IF(G48<0.007,"OK","ERROR") -> OK
C49: PISO 8 | D49: 12.899591 | E49: =D49-D50 -> 1.846858 | F49: 300 | G49: =E49/F49 -> 0.0061561933 | H49: =IF(G49<0.007,"OK","ERROR") -> OK
C50: PISO 7 | D50: 11.052733 | E50: =D50-D51 -> 1.855454 | F50: 300 | G50: =E50/F50 -> 0.0061848467 | H50: =IF(G50<0.007,"OK","ERROR") -> OK
C51: PISO 6 | D51: 9.197279 | E51: =D51-D52 -> 1.821895 | F51: 300 | G51: =E51/F51 -> 0.0060729833 | H51: =IF(G51<0.007,"OK","ERROR") -> OK
C52: PISO 5 | D52: 7.375384 | E52: =D52-D53 -> 1.798122 | F52: 300 | G52: =E52/F52 -> 0.00599374 | H52: =IF(G52<0.007,"OK","ERROR") -> OK
C53: PISO 4 | D53: 5.577262 | E53: =D53-D54 -> 1.722415 | F53: 300 | G53: =E53/F53 -> 0.0057413833 | H53: =IF(G53<0.007,"OK","ERROR") -> OK
C54: PISO 3 | D54: 3.854847 | E54: =D54-D55 -> 1.571917 | F54: 300 | G54: =E54/F54 -> 0.0052397233 | H54: =IF(G54<0.007,"OK","ERROR") -> OK
C55: PISO 2 | D55: 2.28293 | E55: =D55-D56 -> 1.313002 | F55: 300 | G55: =E55/F55 -> 0.0043766733 | H55: =IF(G55<0.007,"OK","ERROR") -> OK
C56: PISO 1 | D56: 0.969928 | E56: =D56-D57 -> 0.87936 | F56: 300 | G56: =E56/F56 -> 0.0029312 | H56: =IF(G56<0.007,"OK","ERROR") -> OK
C57: SEMISÓTANO | D57: 0.090568 | E57: =D57-D58 -> 0.090568 | F57: 280 | G57: =E57/F57 -> 0.00032345714 | H57: =IF(G57<0.007,"OK","ERROR") -> OK
C58: SÓTANO | D58: 0 | E58: =D58-D59 -> 0 | F58: 280 | G58: =E58/F58 -> 0 | H58: =IF(G58<0.007,"OK","ERROR") -> OK
C59: BASE | D59: 0
B60: EJE A Y EJE 8 | C60: PISO 10 | D60: 16.505414 | E60: =D60-D61 -> 1.773582 | F60: 300 | G60: =E60/F60 -> 0.00591194 | H60: =IF(G60<0.007,"OK","ERROR") -> OK
C61: PISO 9 | D61: 14.731832 | E61: =D61-D62 -> 1.819025 | F61: 300 | G61: =E61/F61 -> 0.0060634167 | H61: =IF(G61<0.007,"OK","ERROR") -> OK
C62: PISO 8 | D62: 12.912807 | E62: =D62-D63 -> 1.852222 | F62: 300 | G62: =E62/F62 -> 0.0061740733 | H62: =IF(G62<0.007,"OK","ERROR") -> OK
C63: PISO 7 | D63: 11.060585 | E63: =D63-D64 -> 1.859748 | F63: 300 | G63: =E63/F63 -> 0.00619916 | H63: =IF(G63<0.007,"OK","ERROR") -> OK
C64: PISO 6 | D64: 9.200837 | E64: =D64-D65 -> 1.82496 | F64: 300 | G64: =E64/F64 -> 0.0060832 | H64: =IF(G64<0.007,"OK","ERROR") -> OK
C65: PISO 5 | D65: 7.375877 | E65: =D65-D66 -> 1.800276 | F65: 300 | G65: =E65/F65 -> 0.00600092 | H65: =IF(G65<0.007,"OK","ERROR") -> OK
C66: PISO 4 | D66: 5.575601 | E66: =D66-D67 -> 1.723529 | F66: 300 | G66: =E66/F66 -> 0.0057450967 | H66: =IF(G66<0.007,"OK","ERROR") -> OK
C67: PISO 3 | D67: 3.852072 | E67: =D67-D68 -> 1.571982 | F67: 300 | G67: =E67/F67 -> 0.00523994 | H67: =IF(G67<0.007,"OK","ERROR") -> OK
...

Sheet VIGAS
B2: DISEÑO DE VIGAS POR FLEXIÓN
B4: VIGA EJE 10 ENTRE E-F QUINTO PISO
B6: Mu | C6: 7.67 | D6: Ton-m
B7: f'c | C7: 210 | D7: kg/cm2
B8: fy | C8: 4200 | D8: kg/cm2 | F8: N° | G8: ÁREA | H8: Ø
B9: h | C9: 40 | D9: cm | F9: 3 (3/8") | G9: 0.71 | H9: 0.95
B10: b | C10: 25 | D10: cm | F10: 4 (1/2") | G10: 1.29 | H10: 1.27
B11: r | C11: 4 | D11: cm | F11: 5 (5/8") | G11: 1.98 | H11: 1.59
B12: d | C12: =C9-C11-H9-(H11/2) -> 34.255 | D12: cm | F12: 6 (3/4") | G12: 2.85 | H12: 1.91
B13: Ø | C13: 0.9 | F13: 8 (1") | G13: 5.07 | H13: 2.54
B14: a | C14: =C12/5 -> 6.851 | D14: cm
B15: As | C15: =(C6*10^5)/(C13*C8*(C12-(C14/2))) -> 6.5816848 | D15: cm2 | E15: =(C6*10^5)/(C13*C8*(C12-(C16/2))) -> 6.512349 | F15: =(C6*10^5)/(C13*C8*(C12-(E16/2))) -> 6.5055363 | G15: =(C6*10^5)/(C13*C8*(C12-(F16/2))) -> 6.5048677 | H15: cm2 | I15: 2Ø5/8"+2Ø1/2" | J15: Separación de Barras
B16: a | C16: =(C15*C8)/(0.85*C7*C10) -> 6.1945269 | D16: cm | E16: =(E15*C8)/(0.85*C7*C10) -> 6.1292696 | F16: =(F15*C8)/(0.85*C7*C10) -> 6.1228577 | G16: =(F15*C8)/(0.85*C7*C10) -> 6.1228577 | I16: =2*G11+2*G10 -> 6.54 | J16: =(C10-2*C11-2*H9-2*H11-2*H10)/3 -> 3.1266667 | K16: cm
J17: =IF(J16>2.54,"OK","ERROR") -> OK
B18: pmin | C18: =0.7*SQRT(C7)/C8 -> 0.0024152295 | E18: As,min | F18: =C18*C10*C12 -> 2.0683421 | G18: cm2 | H18: 2Ø5/8" | L18: Eje E | M18: 2Ø5/8" | N18: 2Ø1/2" | S18: Eje F
B19: pmáx | C19: 0.0163 | E19: As,máx | F19: =C19*C10*C12 -> 13.958912 | G19: cm2 | T19: Ldg
M20: 1.50m | R20: 1.50m
B21: As | C21: =2*G11 -> 3.96 | D21: cm2 | E21: 2Ø5/8"
B22: d | C22: =C9-C11-H9-(H11/2) -> 34.255
B23: Mu | C23: =(C21*C13*C8*(C22-(G16/2)))/(10^5) -> 4.6693033 | D23: Ton-m
L27: 1.50m | R27: 1.50m
B29: DISEÑO DE LONGITUD DE BASTONES POR FLEXIÓN (CAPÍTULO 12)
B31: X | C31: =4.6-3.86 -> 0.74 | D31: m | J31: X | K31: =4.6-4.4 -> 0.2 | L31: m
B32: d | C32: =(C9-C11-H9-(H10/2))/100 -> 0.34415 | D32: m | J32: d | K32: =(C9-C11-H9-(H10/2))/100 -> 0.34415 | L32: m
B33: 12db | C33: =12*H10/100 -> 0.1524 | D33: m | J33: 12db | K33: =12*H10/100 -> 0.1524 | L33: m
B34: Lb | C34: =C31+MAX(C32:C33) -> 1.08415 | D34: m | J34: Lb | K34: =K31+MAX(K32:K33)*2 -> 0.8883 | L34: m
B36: RECOMENDACIÓN | D36: Lb | E36: =4.4/3 -> 1.4666667 | F36: m | J36: RECOMENDACIÓN | L36: Lb | M36: =4.4/3 -> 1.4666667 | N36: m
B38: X | C38: =0.66-0.2 -> 0.46 | D38: m
B39: d | C39: =(C9-C11-H9-(H10/2))/100 -> 0.34415 | D39: m
B40: 12db | C40: =12*H10/100 -> 0.1524 | D40: m
B41: Lb | C41: =C38+MAX(C39:C40) -> 0.80415 | D41: m
B44: LONGITUD DE DESARROLLO SIN GANCHO | G44: LONGITUD DE DESARROLLO CON GANCHO
B46: Ld | C46: =((C8/10*1.3*1*1)/(2.6*SQRT(C7/10)))*H11/100 -> 0.72862954 | D46: m | G46: Ldg | H46: =((0.24*1*1*C8/10)/SQRT(C7/10))*H11/100 -> 0.34974218 | I46: m
G49: LONGITUD DEL GANCHO
G51: Lg | H51: =12*H11/100 -> 0.1908 | I51: m
B69: DISEÑO DE VIGAS POR CORTANTE
B71: VIGA EJE 14 ENTRE A-D SEGUNDO NIVEL
B73: Vu | C73: 4.31 | D73: Ton
B74: Ø | C74: 0.85
B75: Vc | C75: =(0.53*SQRT(C7)*C10*C12)/1000 -> 6.577328 | D75: Ton
...

Sheet COLUMNAS
B2: DISEÑO DE COLUMNAS POR FLEXOCOMPRESIÓN | K2: N° | L2: ÁREA | M2: Ø
K3: 3 (3/8") | L3: 0.71 | M3: 0.95
B4: REFUERZO LONGITUDINAL | K4: 4 (1/2") | L4: 1.29 | M4: 1.27
K5: 5 (5/8") | L5: 1.98 | M5: 1.59
B6: COLUMNA ENTRE EJE 9 Y E | K6: 6 (3/4") | L6: 2.85 | M6: 1.91
K7: 8 (1") | L7: 5.07 | M7: 2.54
B11: pmin | C11: 0.01 | E11: As, min | F11: =C14*C11 -> 20 | G11: cm2 | H11: 12Ø5/8" | I11: =12*L5 -> 23.76 | J11: cm2
B12: pmáx | C12: 0.06 | E12: As,máx | F12: =C14*C12 -> 120 | G12: cm2
B14: Acol | C14: =40*50 -> 2000 | D14: cm2
Q17: PRIMER PISO | T17: SEGUNDO PISO | W17: TERCER PISO
B18: DIAGRAMA DE ITERACIONES | Q18: P | R18: M2 | S18: M3 | T18: P | U18: M2 | V18: M3 | W18: P | X18: M2 | Y18: M3
Q19: kg | R19: kg-cm | S19: kg-cm | T19: tonf | U19: tonf-m | V19: tonf-m | W19: tonf | X19: tonf-m | Y19: tonf-m
B20: Curve #1 0 deg | Q20: -168459.55 | R20: -68084.25 | S20: 158034.85 | T20: -136576.26 | U20: -43085.11 | V20: 187856.67 | W20: -104852.25 | X20: -65340.84 | Y20: 230338.87
B21: Point | C21: P kg | D21: M2 kg-cm | E21: M3 kg-cm | F21: P kg | G21: M3 kg-cm | H21: M3 NEG kg-cm | Q21: -167450.39 | R21: -16872.68 | S21: -8766.28 | T21: -135567.09 | U21: -983.73 | V21: -11630.68 | W21: -103843.09 | X21: -2936.53 | Y21: -8022.58
B22: 1 | C22: -362813 | D22: 0 | E22: 0 | F22: =C22*0.7 -> -253969.1 | G22: 0 | H22: =-G22 -> 0 | Q22: -166441.23 | R22: 34338.89 | S22: -175567.4 | T22: -134557.93 | U22: 41117.65 | V22: -211118.04 | W22: -102833.92 | X22: 59467.77 | Y22: -246384.02
B23: 2 | C23: -362813 | D23: 0 | E23: 1124187 | F23: =C23*0.7 -> -253969.1 | G23: =E23*0.7 -> 786930.9 | H23: =-G23 -> -786930.9 | Q23: -143441.87 | R23: -57971.08 | S23: 138333.5 | T23: -116922.35 | U23: -34343.94 | V23: 162229.12 | W23: -90494.67 | X23: -56298.89 | Y23: 200273.38
B24: 3 | C24: -332155 | D24: 0 | E24: 1725979 | F24: =C24*0.7 -> -232508.5 | G24: =E24*0.7 -> 1208185.3 | H24: =-G24 -> -1208185.3 | Q24: -142432.71 | R24: -15716.71 | S24: -7115.97 | T24: -115913.19 | U24: -522.78 | V24: -10524.57 | W24: -89485.5 | X24: -2397.82 | Y24: -7300.07
B25: 4 | C25: -279893 | D25: 0 | E25: 2202292 | F25: =C25*0.7 -> -195925.1 | G25: =E25*0.7 -> 1541604.4 | H25: =-G25 -> -1541604.4 | Q25: -141423.55 | R25: 26537.66 | S25: -152565.45 | T25: -114904.03 | U25: 33298.38 | V25: -183278.25 | W25: -88476.34 | X25: 51503.24 | Y25: -214873.53
B26: 5 | C26: -223345 | D26: 0 | E26: 2546997 | F26: =C26*0.7 -> -156341.5 | G26: =E26*0.7 -> 1782897.9 | H26: =-G26 -> -1782897.9 | Q26: -149804.82 | R26: -54801.71 | S26: 142687.99 | T26: -123465.88 | U26: -26572.05 | V26: 168172.4 | W26: -97283.2 | X26: -45612.68 | Y26: 208479.84
B27: 6 | C27: -157285 | D27: 0 | E27: 2805333 | F27: =C27*0.7 -> -110099.5 | G27: =E27*0.7 -> 1963733.1 | H27: =-G27 -> -1963733.1 | Q27: -148795.66 | R27: -16273.28 | S27: -7260.25 | T27: -122456.72 | U27: -909.68 | V27: -10781.14 | W27: -96274.04 | X27: -2971.15 | Y27: -7543.24
B28: 7 | C28: -114701 | D28: 0 | E28: 2694246 | F28: =C28*0.7 -> -80290.7 | G28: =E28*0.7 -> 1885972.2 | H28: =-G28 -> -1885972.2 | Q28: -147786.49 | R28: 22255.15 | S28: -157208.5 | T28: -121447.55 | U28: 24752.7 | V28: -189734.69 | W28: -95264.87 | X28: 39670.37 | Y28: -223566.33
B29: 8 | C29: -67243 | D29: 0 | E29: 2376608 | F29: =C29*0.7 -> -47070.1 | G29: =E29*0.7 -> 1663625.6 | H29: =-G29 -> -1663625.6 | Q29: -134192.82 | R29: 525076.28 | S29: 529870.51 | T29: -108549.12 | U29: 635342.82 | V29: 575564.33 | W29: -83444.67 | X29: 713747.66 | Y29: 679410.83
B30: 9 | C30: -14136 | D30: 0 | E30: 1818661 | F30: =C30*0.7 -> -9895.2 | G30: =E30*0.7 -> 1273062.7 | H30: =-G30 -> -1273062.7 | Q30: -133291.78 | R30: 89192.22 | S30: 82245.71 | T30: -107648.08 | U30: 52285.52 | V30: 34541.95 | W30: -82543.64 | X30: 36282.64 | Y30: 26743.55
B31: 10 | C31: 45166 | D31: 0 | E31: 937403 | F31: =C31*0.7 -> 31616.2 | G31: =E31*0.7 -> 656182.1 | H31: =-G31 -> -656182.1 | Q31: -132390.75 | R31: 403459.49 | S31: 66544.1 | T31: -106747.04 | U31: 602903.48 | V31: 149442.01 | W31: -81642.6 | X31: 752168.38 | Y31: 211103.35
B32: 11 | C32: 100800 | D32: 0 | E32: 0 | F32: =C32*0.7 -> 70560 | G32: 0 | H32: =-G32 -> 0 | Q32: -153265.08 | R32: -639265.98 | S32: -259042.95 | T32: -125426.61 | U32: -704236.55 | V32: -255138.51 | W32: -97315.37 | X32: -821200.31 | Y32: -285551.6
Q33: -152364.04 | R33: -118773.66 | S33: -96820.84 | T33: -124525.57 | U33: -53877.56 | V33: -54633.55 | W33: -96414.33 | X33: -41373.34 | Y33: -40614.97
Q34: -151463 | R34: -348432.66 | S34: -366521.92 | T34: -123624.53 | U34: -537193.83 | V34: -510051.01 | W34: -95513.29 | X34: -654897.12 | Y34: -632705.41
B35: Curve #7 90 deg | Q35: -134192.82 | R35: 525076.28 | S35: 529870.51 | T35: -108549.12 | U35: 635342.82 | V35: 575564.33 | W35: -83444.67 | X35: 713747.66 | Y35: 679410.83
B36: Point | C36: P kg | D36: M2 kg-cm | E36: M3 kg-cm | F36: P kg | G36: M2 kg-cm | H36: M2 NEG kg-cm | Q36: -133291.78 | R36: 89192.22 | S36: 82245.71 | T36: -107648.08 | U36: 52285.52 | V36: 34541.95 | W36: -82543.64 | X36: 36282.64 | Y36: 26743.55
B37: 1 | C37: -362813 | D37: 0 | E37: 0 | F37: =C37*0.7 -> -253969.1 | G37: =D37*0.7 -> 0 | H37: =-G37 -> 0 | Q37: -132390.75 | R37: 403459.49 | S37: 66544.1 | T37: -106747.04 | U37: 602903.48 | V37: 149442.01 | W37: -81642.6 | X37: 752168.38 | Y37: 211103.35
B38: 2 | C38: -362813 | D38: 1416882 | E38: 0 | F38: =C38*0.7 -> -253969.1 | G38: =D38*0.7 -> 991817.4 | H38: =-G38 -> -991817.4 | Q38: -153265.08 | R38: -639265.98 | S38: -259042.95 | T38: -125426.61 | U38: -704236.55 | V38: -255138.51 | W38: -97315.37 | X38: -821200.31 | Y38: -285551.6
B39: 3 | C39: -333091 | D39: 2195826 | E39: 0 | F39: =C39*0.7 -> -233163.7 | G39: =D39*0.7 -> 1537078.2 | H39: =-G39 -> -1537078.2 | Q39: -152364.04 | R39: -118773.66 | S39: -96820.84 | T39: -124525.57 | U39: -53877.56 | V39: -54633.55 | W39: -96414.33 | X39: -41373.34 | Y39: -40614.97
B40: 4 | C40: -281996 | D40: 2802034 | E40: 0 | F40: =C40*0.7 -> -197397.2 | G40: =D40*0.7 -> 1961423.8 | H40: =-G40 -> -1961423.8 | Q40: -151463 | R40: -348432.66 | S40: -366521.92 | T40: -123624.53 | U40: -537193.83 | V40: -510051.01 | W40: -95513.29 | X40: -654897.12 | Y40: -632705.41
B41: 5 | C41: -226920 | D41: 3254093 | E41: 0 | F41: =C41*0.7 -> -158844 | G41: =D41*0.7 -> 2277865.1 | H41: =-G41 -> -2277865.1 | Q41: -136466.85 | R41: 343320.35 | S41: 696374.43 | T41: -110481.29 | U41: 427186.42 | V41: 753013.18 | W41: -84943.06 | X41: 476268.01 | Y41: 887743.62
B42: 6 | C42: -163044 | D42: 3607371 | E42: 0 | F42: =C42*0.7 -> -114130.8 | G42: =D42*0.7 -> 2525159.7 | H42: =-G42 -> -2525159.7 | Q42: -135565.81 | R42: 56950.36 | S42: 120299.96 | T42: -109580.25 | U42: 36004.75 | V42: 54386.67 | W42: -84042.02 | X42: 24450.43 | Y42: 42404.55
B43: 7 | C43: -119892 | D43: 3484399 | E43: 0 | F43: =C43*0.7 -> -83924.4 | G43: =D43*0.7 -> 2439079.3 | H43: =-G43 -> -2439079.3 | Q43: -134664.77 | R43: 285799.19 | S43: 157476.32 | T43: -108679.21 | U43: 425329.54 | V43: 288990.94 | W43: -83140.98 | X43: 533946.1 | Y43: 391559.82
B44: 8 | C44: -75502 | D44: 3175649 | E44: 0 | F44: =C44*0.7 -> -52851.4 | G44: =D44*0.7 -> 2222954.3 | H44: =-G44 -> -2222954.3 | Q44: -150991.05 | R44: -457510.06 | S44: -425546.88 | T44: -123494.44 | U44: -496080.14 | V44: -432587.37 | W44: -95816.99 | X44: -583720.66 | Y44: -493884.39
B45: 9 | C45: -22407 | D45: 2496288 | E45: 0 | F45: =C45*0.7 -> -15684.9 | G45: =D45*0.7 -> 1747401.6 | H45: =-G45 -> -1747401.6 | Q45: -150090.01 | R45: -86531.8 | S45: -134875.09 | T45: -122593.4 | U45: -37596.79 | V45: -74478.26 | W45: -94915.95 | X45: -29541.12 | Y45: -56275.96
B46: 10 | C46: 31303 | D46: 1479903 | E46: 0 | F46: =C46*0.7 -> 21912.1 | G46: =D46*0.7 -> 1035932.1 | H46: =-G46 -> -1035932.1 | Q46: -149188.98 | R46: -230772.36 | S46: -457454.13 | T46: -121692.36 | U46: -359619.89 | V46: -649599.94 | W46: -94014.91 | X46: -436674.84 | Y46: -813161.88
B47: 11 | C47: 100800 | D47: 0 | E47: 0 | F47: =C47*0.7 -> 70560 | G47: =D47*0.7 -> 0 | H47: =-G47 -> 0 | Q47: -136466.85 | R47: 343320.35 | S47: 696374.43 | T47: -110481.29 | U47: 427186.42 | V47: 753013.18 | W47: -84943.06 | X47: 476268.01 | Y47: 887743.62
...

Sheet DI COLUMNA
C2: Curve 1 | D2: 0 degrees | F2: Curve 2 | G2: 15 degrees | I2: Curve 3 | J2: 30 degrees | L2: Curve 4 | M2: 45 degrees | O2: Curve 5 | P2: 60 degrees | R2: Curve 6 | S2: 75 degrees | U2: Curve 7 | V2: 90 degrees | X2: Curve 8 | Y2: 105 degrees | AA2: Curve 9 | AB2: 120 degrees | AD2: Curve 10 | AE2: 135 degrees | AG2: Curve 11 | AH2: 150 degrees | AJ2: Curve 12 | AK2: 165 degrees | AM2: Curve 13 | AN2: 180 degrees | AP2: Curve 14 | AQ2: 195 degrees | AS2: Curve 15 | AT2: 210 degrees | AV2: Curve 16 | AW2: 225 degrees | AY2: Curve 17 | AZ2: 240 degrees | BB2: Curve 18 | BC2: 255 degrees | BE2: Curve 19 | BF2: 270 degrees | BH2: Curve 20 | BI2: 285 degrees | BK2: Curve 21 | BL2: 300 degrees | BN2: Curve 22 | BO2: 315 degrees | BQ2: Curve 23 | BR2: 330 degrees | BT2: Curve 24 | BU2: 345 degrees
B4: 1 | C4: -362813 | D4: 0 | E4: 0 | F4: -362813 | G4: 0 | H4: 0 | I4: -362813 | J4: 0 | K4: 0 | L4: -362813 | M4: 0 | N4: 0 | O4: -362813 | P4: 0 | Q4: 0 | R4: -362813 | S4: 0 | T4: 0 | U4: -362813 | V4: 0 | W4: 0 | X4: -362813 | Y4: 0 | Z4: 0 | AA4: -362813 | AB4: 0 | AC4: 0 | AD4: -362813 | AE4: 0 | AF4: 0 | AG4: -362813 | AH4: 0 | AI4: 0 | AJ4: -362813 | AK4: 0 | AL4: 0 | AM4: -362813 | AN4: 0 | AO4: 0 | AP4: -362813 | AQ4: 0 | AR4: 0 | AS4: -362813 | AT4: 0 | AU4: 0 | AV4: -362813 | AW4: 0 | AX4: 0 | AY4: -362813 | AZ4: 0 | BA4: 0 | BB4: -362813 | BC4: 0 | BD4: 0 | BE4: -362813 | BF4: 0 | BG4: 0 | BH4: -362813 | BI4: 0 | BJ4: 0 | BK4: -362813 | BL4: 0 | BM4: 0 | BN4: -362813 | BO4: 0 | BP4: 0 | BQ4: -362813 | BR4: 0 | BS4: 0 | BT4: -362813 | BU4: 0 | BV4: 0
B5: 2 | C5: -362813 | D5: 0 | E5: 1124187 | F5: -362813 | G5: 347978 | H5: 551376 | I5: -362813 | J5: 443082 | K5: 421358 | L5: -362813 | M5: 542749 | N5: 332830 | O5: -362813 | P5: 655310 | Q5: 274163 | R5: -362813 | S5: 832927 | T5: 239355 | U5: -362813 | V5: 1416882 | W5: 0 | X5: -362813 | Y5: 832927 | Z5: -239355 | AA5: -362813 | AB5: 655310 | AC5: -274163 | AD5: -362813 | AE5: 542749 | AF5: -332830 | AG5: -362813 | AH5: 443082 | AI5: -421358 | AJ5: -362813 | AK5: 347978 | AL5: -551376 | AM5: -362813 | AN5: 0 | AO5: -1124187 | AP5: -362813 | AQ5: -347978 | AR5: -551376 | AS5: -362813 | AT5: -443082 | AU5: -421358 | AV5: -362813 | AW5: -542749 | AX5: -332830 | AY5: -362813 | AZ5: -655310 | BA5: -274163 | BB5: -362813 | BC5: -832927 | BD5: -239355 | BE5: -362813 | BF5: -1416882 | BG5: 0 | BH5: -362813 | BI5: -832927 | BJ5: 239355 | BK5: -362813 | BL5: -655310 | BM5: 274163 | BN5: -362813 | BO5: -542749 | BP5: 332830 | BQ5: -362813 | BR5: -443082 | BS5: 421358 | BT5: -362813 | BU5: -347978 | BV5: 551376
B6: 3 | C6: -332155 | D6: 0 | E6: 1725979 | F6: -362813 | G6: 646800 | H6: 1158095 | I6: -362813 | J6: 894916 | K6: 851740 | L6: -362813 | M6: 1074982 | N6: 703020 | O6: -362813 | P6: 1308037 | Q6: 580826 | R6: -357585 | S6: 1756644 | T6: 332443 | U6: -333091 | V6: 2195826 | W6: 0 | X6: -357585 | Y6: 1756644 | Z6: -332443 | AA6: -362813 | AB6: 1308037 | AC6: -580826 | AD6: -362813 | AE6: 1074982 | AF6: -703020 | AG6: -362813 | AH6: 894916 | AI6: -851740 | AJ6: -362813 | AK6: 646800 | AL6: -1158095 | AM6: -332155 | AN6: 0 | AO6: -1725979 | AP6: -362813 | AQ6: -646800 | AR6: -1158095 | AS6: -362813 | AT6: -894916 | AU6: -851740 | AV6: -362813 | AW6: -1074982 | AX6: -703020 | AY6: -362813 | AZ6: -1308037 | BA6: -580826 | BB6: -357585 | BC6: -1756644 | BD6: -332443 | BE6: -333091 | BF6: -2195826 | BG6: 0 | BH6: -357585 | BI6: -1756644 | BJ6: 332443 | BK6: -362813 | BL6: -1308037 | BM6: 580826 | BN6: -362813 | BO6: -1074982 | BP6: 703020 | BQ6: -362813 | BR6: -894916 | BS6: 851740 | BT6: -362813 | BU6: -646800 | BV6: 1158095
B7: 4 | C7: -279893 | D7: 0 | E7: 2202292 | F7: -305755 | G7: 710089 | H7: 1854674 | I7: -324004 | J7: 1335795 | K7: 1383554 | L7: -325643 | M7: 1712048 | N7: 1080963 | O7: -314936 | P7: 2155068 | Q7: 735650 | R7: -299185 | S7: 2550249 | T7: 345959 | U7: -281996 | V7: 2802034 | W7: 0 | X7: -299185 | Y7: 2550249 | Z7: -345959 | AA7: -314936 | AB7: 2155068 | AC7: -735650 | AD7: -325643 | AE7: 1712048 | AF7: -1080963 | AG7: -324004 | AH7: 1335795 | AI7: -1383554 | AJ7: -305755 | AK7: 710089 | AL7: -1854674 | AM7: -279893 | AN7: 0 | AO7: -2202292 | AP7: -305755 | AQ7: -710089 | AR7: -1854674 | AS7: -324004 | AT7: -1335795 | AU7: -1383554 | AV7: -325643 | AW7: -1712048 | AX7: -1080963 | AY7: -314936 | AZ7: -2155068 | BA7: -735650 | BB7: -299185 | BC7: -2550249 | BD7: -345959 | BE7: -281996 | BF7: -2802034 | BG7: 0 | BH7: -299185 | BI7: -2550249 | BJ7: 345959 | BK7: -314936 | BL7: -2155068 | BM7: 735650 | BN7: -325643 | BO7: -1712048 | BP7: 1080963 | BQ7: -324004 | BR7: -1335795 | BS7: 1383554 | BT7: -305755 | BU7: -710089 | BV7: 1854674
B8: 5 | C8: -223345 | D8: 0 | E8: 2546997 | F8: -235055 | G8: 774347 | H8: 2294765 | I8: -244406 | J8: 1548103 | K8: 1881019 | L8: -247084 | M8: 2299786 | N8: 1303921 | O8: -240490 | P8: 2789847 | Q8: 794764 | R8: -235004 | S8: 3085081 | T8: 372936 | U8: -226920 | V8: 3254093 | W8: 0 | X8: -235004 | Y8: 3085081 | Z8: -372936 | AA8: -240490 | AB8: 2789847 | AC8: -794764 | AD8: -247084 | AE8: 2299786 | AF8: -1303921 | AG8: -244406 | AH8: 1548103 | AI8: -1881019 | AJ8: -235055 | AK8: 774347 | AL8: -2294765 | AM8: -223345 | AN8: 0 | AO8: -2546997 | AP8: -235055 | AQ8: -774347 | AR8: -2294765 | AS8: -244406 | AT8: -1548103 | AU8: -1881019 | AV8: -247084 | AW8: -2299786 | AX8: -1303921 | AY8: -240490 | AZ8: -2789847 | BA8: -794764 | BB8: -235004 | BC8: -3085081 | BD8: -372936 | BE8: -226920 | BF8: -3254093 | BG8: 0 | BH8: -235004 | BI8: -3085081 | BJ8: 372936 | BK8: -240490 | BL8: -2789847 | BM8: 794764 | BN8: -247084 | BO8: -2299786 | BP8: 1303921 | BQ8: -244406 | BR8: -1548103 | BS8: 1881019 | BT8: -235055 | BU8: -774347 | BV8: 2294765
B9: 6 | C9: -157285 | D9: 0 | E9: 2805333 | F9: -155705 | G9: 867445 | H9: 2476312 | I9: -149899 | J9: 1690018 | K9: 2026615 | L9: -149590 | M9: 2497840 | N9: 1414198 | O9: -157427 | P9: 3038700 | Q9: 872426 | R9: -162615 | S9: 3383333 | T9: 419783 | U9: -163044 | V9: 3607371 | W9: 0 | X9: -162615 | Y9: 3383333 | Z9: -419783 | AA9: -157427 | AB9: 3038700 | AC9: -872426 | AD9: -149590 | AE9: 2497840 | AF9: -1414198 | AG9: -149899 | AH9: 1690018 | AI9: -2026615 | AJ9: -155705 | AK9: 867445 | AL9: -2476312 | AM9: -157285 | AN9: 0 | AO9: -2805333 | AP9: -155705 | AQ9: -867445 | AR9: -2476312 | AS9: -149899 | AT9: -1690018 | AU9: -2026615 | AV9: -149590 | AW9: -2497840 | AX9: -1414198 | AY9: -157427 | AZ9: -3038700 | BA9: -872426 | BB9: -162615 | BC9: -3383333 | BD9: -419783 | BE9: -163044 | BF9: -3607371 | BG9: 0 | BH9: -162615 | BI9: -3383333 | BJ9: 419783 | BK9: -157427 | BL9: -3038700 | BM9: 872426 | BN9: -149590 | BO9: -2497840 | BP9: 1414198 | BQ9: -149899 | BR9: -1690018 | BS9: 2026615 | BT9: -155705 | BU9: -867445 | BV9: 2476312
B10: 7 | C10: -114701 | D10: 0 | E10: 2694246 | F10: -88530 | G10: 864282 | H10: 2325545 | I10: -71869 | J10: 1678187 | K10: 1774923 | L10: -71784 | M10: 2232406 | N10: 1354152 | O10: -85026 | P10: 2820377 | Q10: 879832 | R10: -102940 | S10: 3242704 | T10: 415590 | U10: -119892 | V10: 3484399 | W10: 0 | X10: -102940 | Y10: 3242704 | Z10: -415590 | AA10: -85026 | AB10: 2820377 | AC10: -879832 | AD10: -71784 | AE10: 2232406 | AF10: -1354152 | AG10: -71869 | AH10: 1678187 | AI10: -1774923 | AJ10: -88530 | AK10: 864282 | AL10: -2325545 | AM10: -114701 | AN10: 0 | AO10: -2694246 | AP10: -88530 | AQ10: -864282 | AR10: -2325545 | AS10: -71869 | AT10: -1678187 | AU10: -1774923 | AV10: -71784 | AW10: -2232406 | AX10: -1354152 | AY10: -85026 | AZ10: -2820377 | BA10: -879832 | BB10: -102940 | BC10: -3242704 | BD10: -415590 | BE10: -119892 | BF10: -3484399 | BG10: 0 | BH10: -102940 | BI10: -3242704 | BJ10: 415590 | BK10: -85026 | BL10: -2820377 | BM10: 879832 | BN10: -71784 | BO10: -2232406 | BP10: 1354152 | BQ10: -71869 | BR10: -1678187 | BS10: 1774923 | BT10: -88530 | BU10: -864282 | BV10: 2325545
B11: 8 | C11: -67243 | D11: 0 | E11: 2376608 | F11: -24971 | G11: 850849 | H11: 1780315 | I11: -5132 | J11: 1339709 | K11: 1329073 | L11: -5650 | M11: 1702210 | N11: 1061169 | O11: -18313 | P11: 2093670 | Q11: 839886 | R11: -44816 | S11: 2685666 | T11: 416768 | U11: -75502 | V11: 3175649 | W11: 0 | X11: -44816 | Y11: 2685666 | Z11: -416768 | AA11: -18313 | AB11: 2093670 | AC11: -839886 | AD11: -5650 | AE11: 1702210 | AF11: -1061169 | AG11: -5132 | AH11: 1339709 | AI11: -1329073 | AJ11: -24971 | AK11: 850849 | AL11: -1780315 | AM11: -67243 | AN11: 0 | AO11: -2376608 | AP11: -24971 | AQ11: -850849 | AR11: -1780315 | AS11: -5132 | AT11: -1339709 | AU11: -1329073 | AV11: -5650 | AW11: -1702210 | AX11: -1061169 | AY11: -18313 | AZ11: -2093670 | BA11: -839886 | BB11: -44816 | BC11: -2685666 | BD11: -416768 | BE11: -75502 | BF11: -3175649 | BG11: 0 | BH11: -44816 | BI11: -2685666 | BJ11: 416768 | BK11: -18313 | BL11: -2093670 | BM11: 839886 | BN11: -5650 | BO11: -1702210 | BP11: 1061169 | BQ11: -5132 | BR11: -1339709 | BS11: 1329073 | BT11: -24971 | BU11: -850849 | BV11: 1780315
B12: 9 | C12: -14136 | D12: 0 | E12: 1818661 | F12: 36887 | G12: 706222 | H12: 987396 | I12: 49690 | J12: 847457 | K12: 733138 | L12: 48910 | M12: 954764 | N12: 665992 | O12: 40155 | P12: 1178684 | Q12: 614437 | R12: 16013 | S12: 1724365 | T12: 405818 | U12: -22407 | V12: 2496288 | W12: 0 | X12: 16013 | Y12: 1724365 | Z12: -405818 | AA12: 40155 | AB12: 1178684 | AC12: -614437 | AD12: 48910 | AE12: 954764 | AF12: -665992 | AG12: 49690 | AH12: 847457 | AI12: -733138 | AJ12: 36887 | AK12: 706222 | AL12: -987396 | AM12: -14136 | AN12: 0 | AO12: -1818661 | AP12: 36887 | AQ12: -706222 | AR12: -987396 | AS12: 49690 | AT12: -847457 | AU12: -733138 | AV12: 48910 | AW12: -954764 | AX12: -665992 | AY12: 40155 | AZ12: -1178684 | BA12: -614437 | BB12: 16013 | BC12: -1724365 | BD12: -405818 | BE12: -22407 | BF12: -2496288 | BG12: 0 | BH12: 16013 | BI12: -1724365 | BJ12: 405818 | BK12: 40155 | BL12: -1178684 | BM12: 614437 | BN12: 48910 | BO12: -954764 | BP12: 665992 | BQ12: 49690 | BR12: -847457 | BS12: 733138 | BT12: 36887 | BU12: -706222 | BV12: 987396
B13: 10 | C13: 45166 | D13: 0 | E13: 937403 | F13: 86432 | G13: 280828 | H13: 241457 | I13: 87538 | J13: 273996 | K13: 216474 | L13: 87134 | M13: 287069 | N13: 218736 | O13: 85844 | P13: 318232 | Q13: 232711 | R13: 78445 | S13: 479389 | T13: 281240 | U13: 31303 | V13: 1479903 | W13: 0 | X13: 78445 | Y13: 479389 | Z13: -281240 | AA13: 85844 | AB13: 318232 | AC13: -232711 | AD13: 87134 | AE13: 287069 | AF13: -218736 | AG13: 87538 | AH13: 273996 | AI13: -216474 | AJ13: 86432 | AK13: 280828 | AL13: -241457 | AM13: 45166 | AN13: 0 | AO13: -937403 | AP13: 86432 | AQ13: -280828 | AR13: -241457 | AS13: 87538 | AT13: -273996 | AU13: -216474 | AV13: 87134 | AW13: -287069 | AX13: -218736 | AY13: 85844 | AZ13: -318232 | BA13: -232711 | BB13: 78445 | BC13: -479389 | BD13: -281240 | BE13: 31303 | BF13: -1479903 | BG13: 0 | BH13: 78445 | BI13: -479389 | BJ13: 281240 | BK13: 85844 | BL13: -318232 | BM13: 232711 | BN13: 87134 | BO13: -287069 | BP13: 218736 | BQ13: 87538 | BR13: -273996 | BS13: 216474 | BT13: 86432 | BU13: -280828 | BV13: 241457
B14: 11 | C14: 100800 | D14: 0 | E14: 0 | F14: 100800 | G14: 0 | H14: 0 | I14: 100800 | J14: 0 | K14: 0 | L14: 100800 | M14: 0 | N14: 0 | O14: 100800 | P14: 0 | Q14: 0 | R14: 100800 | S14: 0 | T14: 0 | U14: 100800 | V14: 0 | W14: 0 | X14: 100800 | Y14: 0 | Z14: 0 | AA14: 100800 | AB14: 0 | AC14: 0 | AD14: 100800 | AE14: 0 | AF14: 0 | AG14: 100800 | AH14: 0 | AI14: 0 | AJ14: 100800 | AK14: 0 | AL14: 0 | AM14: 100800 | AN14: 0 | AO14: 0 | AP14: 100800 | AQ14: 0 | AR14: 0 | AS14: 100800 | AT14: 0 | AU14: 0 | AV14: 100800 | AW14: 0 | AX14: 0 | AY14: 100800 | AZ14: 0 | BA14: 0 | BB14: 100800 | BC14: 0 | BD14: 0 | BE14: 100800 | BF14: 0 | BG14: 0 | BH14: 100800 | BI14: 0 | BJ14: 0 | BK14: 100800 | BL14: 0 | BM14: 0 | BN14: 100800 | BO14: 0 | BP14: 0 | BQ14: 100800 | BR14: 0 | BS14: 0 | BT14: 100800 | BU14: 0 | BV14: 0

Sheet MUROS DE CORTE
B2: DISEÑO DE MUROS DE CORTE | G2: N° | H2: ÁREA | I2: Ø
G3: 3 (3/8") | H3: 0.71 | I3: 0.95
B4: Lm | C4: 5 | D4: m | G4: 4 (1/2") | H4: 1.29 | I4: 1.27
B5: tm | C5: 0.25 | D5: m | G5: 5 (5/8") | H5: 1.98 | I5: 1.59
G6: 6 (3/4") | H6: 2.85 | I6: 1.91
G7: 8 (1") | H7: 5.07 | I7: 2.54
B8: CON ELEMENTOS DE BORDE
B10: *ALMA DEL MURO
B12: REFUERZO HORIZONTAL
B14: pmin | C14: 0.0025
B15: b | C15: 100 | D15: cm
B16: As,min | C16: =C14*C15*C5*100 -> 6.25 | D16: cm2/m
B17: Ø 3/8" | C17: =H3 -> 0.71
B18: S | C18: =(C17*2*C15)/C16 -> 22.72 | D18: cm | E18: USAR Ø 3/8"@0.20m
B20: REFUERZO VERTICAL
B22: pmin | C22: 0.0025
B23: b | C23: 100 | D23: cm
B24: As,min | C24: =C22*C23*C5*100 -> 6.25 | D24: cm2/m
B25: Ø 3/8" | C25: =H3 -> 0.71
B26: S | C26: =(C25*2*C23)/C24 -> 22.72 | D26: cm | E26: USAR Ø 3/8"@0.20m
B28: *ELEMENTOS DE CONFINAMIENTO
B30: pmin | C30: 0.01 | E30: As, min | F30: =C33*C30 -> 20 | G30: cm2 | H30: 12Ø5/8" | I30: =12*L24 -> 0 | J30: cm2
B31: pmáx | C31: 0.06 | E31: As,máx | F31: =C33*C31 -> 120 | G31: cm2
B33: Acol | C33: =40*50 -> 2000 | D33: cm2
Q35: PRIMER PISO
B36: DIAGRAMA DE ITERACIONES | Q36: ALMA DEL MURO | S36: ELEMENTOS DE BORDE
Q37: P | R37: M2 | S37: P | T37: M2
B38: Curve #7 90 deg | Q38: tonf | R38: tonf-m | S38: tonf | T38: tonf-m
B39: Point | C39: P tonf | D39: M2 tonf-m | E39: M3 tonf-m | F39: P tonf | G39: M2 tonf-m | H39: M2 NEG tonf-m | Q39: -69.574 | R39: -0.20302 | S39: -59.8155 | T39: 0.59655
B40: 1 | C40: -2474 | D40: -0.0198 | E40: -5.2802 | F40: =C40*0.7 -> -1731.8 | G40: =D40*0.7 -> -0.01386 | H40: =-G40 -> 0.01386 | Q40: -66.055 | R40: -0.06919 | S40: -59.1427 | T40: -0.45485
B41: 2 | C41: -2474 | D41: 1213.1528 | E41: 29.1863 | F41: =C41*0.7 -> -1731.8 | G41: =D41*0.7 -> 849.20696 | H41: =-G41 -> -849.20696 | Q41: -63.752 | R41: 0.02412 | S41: -53.904 | T41: -0.24764
B42: 3 | C42: -2255 | D42: 1659.6205 | E42: 22.1008 | F42: =C42*0.7 -> -1578.5 | G42: =D42*0.7 -> 1161.7343 | H42: =-G42 -> -1161.7343 | Q42: -67.271 | R42: -0.1072 | S42: -53.5676 | T42: -0.30434
B43: 4 | C43: -1982 | D43: 2013.6261 | E43: 15.1403 | F43: =C43*0.7 -> -1387.4 | G43: =D43*0.7 -> 1409.5383 | H43: =-G43 -> -1409.5383 | Q43: -61.127 | R43: -0.19581 | S43: -53.2312 | T43: -0.36105
B44: 5 | C44: -1690 | D44: 2282.3285 | E44: 8.368 | F44: =C44*0.7 -> -1183 | G44: =D44*0.7 -> 1597.63 | H44: =-G44 -> -1597.63 | Q44: -59.345 | R44: -0.0669 | S44: -53.7696 | T44: -0.32401
B45: 6 | C45: -1368 | D45: 2480.3504 | E45: 1.852 | F45: =C45*0.7 -> -957.6 | G45: =D45*0.7 -> 1736.2453 | H45: =-G45 -> -1736.2453 | Q45: -57.274 | R45: 0.02088 | S45: -53.0968 | T45: 0.41011
B46: 7 | C46: -1050 | D46: 2497.0789 | E46: -7.9657 | F46: =C46*0.7 -> -735 | G46: =D46*0.7 -> 1747.9552 | H46: =-G46 -> -1747.9552 | Q46: -59.056 | R46: -0.10541 | S46: -53.3465 | T46: 0.55873
B47: 8 | C47: -739.7417 | D47: 2324.3699 | E47: -18.6414 | F47: =C47*0.7 -> -517.81919 | G47: =D47*0.7 -> 1627.0589 | H47: =-G47 -> -1627.0589 | Q47: -66.498 | R47: -0.1926 | S47: -52.6737 | T47: -0.41095
B48: 9 | C48: -429.6805 | D48: 1979.367 | E48: -29.3279 | F48: =C48*0.7 -> -300.77635 | G48: =D48*0.7 -> 1385.5569 | H48: =-G48 -> -1385.5569 | Q48: -62.451 | R48: -0.0661 | S48: -47.7965 | T48: -0.21982
B49: 10 | C49: -106.4185 | D49: 1433.4846 | E49: -38.5289 | F49: =C49*0.7 -> -74.49295 | G49: =D49*0.7 -> 1003.4392 | H49: =-G49 -> -1003.4392 | Q49: -60.255 | R49: 0.01947 | S49: -47.4601 | T49: -0.27693
B50: 11 | C50: 526.7556 | D50: 0.0207 | E50: 5.5146 | F50: =C50*0.7 -> 368.72892 | G50: =D50*0.7 -> 0.01449 | H50: =-G50 -> -0.01449 | Q50: -64.303 | R50: -0.10466 | S50: -47.1237 | T50: -0.33403
...

Sheet DI MURO CORTE
C2: Curve 1 | D2: 0 degrees | F2: Curve 2 | G2: 15 degrees | I2: Curve 3 | J2: 30 degrees | L2: Curve 4 | M2: 45 degrees | O2: Curve 5 | P2: 60 degrees | R2: Curve 6 | S2: 75 degrees | U2: Curve 7 | V2: 90 degrees | X2: Curve 8 | Y2: 105 degrees | AA2: Curve 9 | AB2: 120 degrees | AD2: Curve 10 | AE2: 135 degrees | AG2: Curve 11 | AH2: 150 degrees | AJ2: Curve 12 | AK2: 165 degrees | AM2: Curve 13 | AN2: 180 degrees | AP2: Curve 14 | AQ2: 195 degrees | AS2: Curve 15 | AT2: 210 degrees | AV2: Curve 16 | AW2: 225 degrees | AY2: Curve 17 | AZ2: 240 degrees | BB2: Curve 18 | BC2: 255 degrees | BE2: Curve 19 | BF2: 270 degrees | BH2: Curve 20 | BI2: 285 degrees | BK2: Curve 21 | BL2: 300 degrees | BN2: Curve 22 | BO2: 315 degrees | BQ2: Curve 23 | BR2: 330 degrees | BT2: Curve 24 | BU2: 345 degrees
B4: 1 | C4: -2328 | D4: -0.0198 | E4: -12.5119 | F4: -2328 | G4: -0.0198 | H4: -12.5119 | I4: -2328 | J4: -0.0198 | K4: -12.5119 | L4: -2328 | M4: -0.0198 | N4: -12.5119 | O4: -2328 | P4: -0.0198 | Q4: -12.5119 | R4: -2328 | S4: -0.0198 | T4: -12.5119 | U4: -2328 | V4: -0.0198 | W4: -12.5119 | X4: -2328 | Y4: -0.0198 | Z4: -12.5119 | AA4: -2328 | AB4: -0.0198 | AC4: -12.5119 | AD4: -2328 | AE4: -0.0198 | AF4: -12.5119 | AG4: -2328 | AH4: -0.0198 | AI4: -12.5119 | AJ4: -2328 | AK4: -0.0198 | AL4: -12.5119 | AM4: -2328 | AN4: -0.0198 | AO4: -12.5119 | AP4: -2328 | AQ4: -0.0198 | AR4: -12.5119 | AS4: -2328 | AT4: -0.0198 | AU4: -12.5119 | AV4: -2328 | AW4: -0.0198 | AX4: -12.5119 | AY4: -2328 | AZ4: -0.0198 | BA4: -12.5119 | BB4: -2328 | BC4: -0.0198 | BD4: -12.5119 | BE4: -2328 | BF4: -0.0198 | BG4: -12.5119 | BH4: -2328 | BI4: -0.0198 | BJ4: -12.5119 | BK4: -2328 | BL4: -0.0198 | BM4: -12.5119 | BN4: -2328 | BO4: -0.0198 | BP4: -12.5119 | BQ4: -2328 | BR4: -0.0198 | BS4: -12.5119 | BT4: -2328 | BU4: -0.0198 | BV4: -12.5119
B5: 2 | C5: -2328 | D5: -0.0198 | E5: 27.814 | F5: -2328 | G5: 402.8632 | H5: 19.9736 | I5: -2328 | J5: 580.6917 | K5: 28.8141 | L5: -2328 | M5: 794.6003 | N5: 30.7419 | O5: -2328 | P5: 958.2772 | Q5: 28.6712 | R5: -2328 | S5: 1061.0697 | T5: 26.3396 | U5: -2328 | V5: 1145.8599 | W5: 24.2375 | X5: -2328 | Y5: 1119.2882 | Z5: 22.8856 | AA5: -2328 | AB5: 1010.7955 | AC5: 12.6867 | AD5: -2328 | AE5: 837.833 | AF5: -2.3768 | AG5: -2328 | AH5: 621.4789 | AI5: -16.7194 | AJ5: -2328 | AK5: 450.9253 | AL5: -21.4671 | AM5: -2326 | AN5: 0.2173 | AO5: -82.4244 | AP5: -2328 | AQ5: -450.8808 | AR5: -21.4351 | AS5: -2328 | AT5: -621.4604 | AU5: -16.6885 | AV5: -2328 | AW5: -837.8264 | AX5: -2.3465 | AY5: -2328 | AZ5: -1011 | BA5: 12.7167 | BB5: -2328 | BC5: -1119 | BD5: 22.9154 | BE5: -2328 | BF5: -1146 | BG5: 24.267 | BH5: -2328 | BI5: -1061 | BJ5: 26.3677 | BK5: -2328 | BL5: -958.3031 | BM5: 28.6983 | BN5: -2328 | BO5: -794.6353 | BP5: 30.768 | BQ5: -2328 | BR5: -580.7413 | BS5: 28.8371 | BT5: -2328 | BU5: -402.9446 | BV5: 19.9899
B6: 3 | C6: -2328 | D6: -0.0198 | E6: 49.6841 | F6: -2328 | G6: 740.8832 | H6: 36.8802 | I6: -2328 | J6: 1172.2178 | K6: 30.0337 | L6: -2276 | M6: 1356.5663 | N6: 24.8725 | O6: -2219 | P6: 1455.3661 | Q6: 21.8536 | R6: -2177 | S6: 1523.6081 | T6: 19.6397 | U6: -2141 | V6: 1580.581 | W6: 17.7054 | X6: -2146 | Y6: 1571.1727 | Z6: 16.7191 | AA6: -2150 | AB6: 1560.5064 | AC6: 15.609 | AD6: -2157 | AE6: 1545.4844 | AF6: 14.1415 | AG6: -2173 | AH6: 1508.021 | AI6: 9.9496 | AJ6: -2328 | AK6: 1142.5154 | AL6: -26.9196 | AM6: -1850 | AN6: 0.248 | AO6: -121.7233 | AP6: -2328 | AQ6: -1142 | AR6: -26.8824 | AS6: -2173 | AT6: -1508 | AU6: 9.9865 | AV6: -2157 | AW6: -1545 | AX6: 14.1778 | AY6: -2150 | AZ6: -1561 | BA6: 15.645 | BB6: -2146 | BC6: -1571 | BD6: 16.7547 | BE6: -2141 | BF6: -1581 | BG6: 17.7408 | BH6: -2177 | BI6: -1524 | BJ6: 19.6735 | BK6: -2219 | BL6: -1455 | BM6: 21.8857 | BN6: -2276 | BO6: -1357 | BP6: 24.9023 | BQ6: -2328 | BR6: -1172 | BS6: 30.0601 | BT6: -2328 | BU6: -740.9686 | BV6: 36.9005
B7: 4 | C7: -2328 | D7: -0.0198 | E7: 69.9593 | F7: -2300 | G7: 1291.6401 | H7: 35.4255 | I7: -2082 | J7: 1666.3955 | K7: 22.6517 | L7: -2000 | M7: 1780.7338 | N7: 17.9716 | O7: -1952 | P7: 1841.5602 | Q7: 15.2501 | R7: -1917 | S7: 1883.8501 | T7: 13.2325 | U7: -1886 | V7: 1918.7619 | W7: 11.4885 | X7: -1884 | Y7: 1916.0887 | Z7: 10.2246 | AA7: -1883 | AB7: 1913.0154 | AC7: 8.7905 | AD7: -1880 | AE7: 1908.8808 | AF7: 6.8799 | AG7: -1875 | AH7: 1901.384 | AI7: 3.6975 | AJ7: -1868 | AK7: 1850.5126 | AL7: -8.3818 | AM7: -1365 | AN7: 0.2872 | AO7: -139.6238 | AP7: -1868 | AQ7: -1850 | AR7: -8.3407 | AS7: -1875 | AT7: -1901 | AU7: 3.7421 | AV7: -1880 | AW7: -1909 | AX7: 6.9238 | AY7: -1883 | AZ7: -1913 | BA7: 8.834 | BB7: -1884 | BC7: -1916 | BD7: 10.2678 | BE7: -1886 | BF7: -1919 | BG7: 11.5314 | BH7: -1917 | BI7: -1884 | BJ7: 13.2736 | BK7: -1952 | BL7: -1842 | BM7: 15.2892 | BN7: -2000 | BO7: -1781 | BP7: 18.0082 | BQ7: -2082 | BR7: -1666 | BS7: 22.6843 | BT7: -2300 | BU7: -1292 | BV7: 35.45
B8: 5 | C8: -2328 | D8: -0.0198 | E8: 88.1147 | F8: -1955 | G8: 1811.6634 | H8: 28.0093 | I8: -1780 | J8: 2027.5262 | K8: 15.7616 | L8: -1713 | M8: 2090.5863 | N8: 11.5629 | O8: -1674 | P8: 2124.0173 | Q8: 9.1063 | R8: -1644 | S8: 2147.3435 | T8: 7.2841 | U8: -1619 | V8: 2166.7197 | W8: 5.6929 | X8: -1612 | Y8: 2164.4517 | Z8: 4.1412 | AA8: -1603 | AB8: 2161.7347 | AC8: 2.361 | AD8: -1591 | AE8: 2157.8209 | AF8: -0.0138 | AG8: -1569 | AH8: 2149.9565 | AI8: -3.9818 | AJ8: -1504 | AK8: 2112.5311 | AL8: -14.594 | AM8: -866.0675 | AN8: 0.3394 | AO8: -136.3032 | AP8: -1504 | AQ8: -2112 | AR8: -14.5459 | AS8: -1569 | AT8: -2150 | AU8: -3.927 | AV8: -1591 | AW8: -2158 | AX8: 0.0403 | AY8: -1603 | AZ8: -2162 | BA8: 2.4146 | BB8: -1612 | BC8: -2164 | BD8: 4.1945 | BE8: -1619 | BF8: -2167 | BG8: 5.7458 | BH8: -1644 | BI8: -2147 | BJ8: 7.3349 | BK8: -1674 | BL8: -2124 | BM8: 9.1548 | BN8: -1713 | BO8: -2091 | BP8: 11.6084 | BQ8: -1780 | BR8: -2028 | BS8: 15.8025 | BT8: -1955 | BU8: -1812 | BV8: 28.0401
B9: 6 | C9: -2328 | D9: -0.0198 | E9: 105.5714 | F9: -1591 | G9: 2147.5909 | H9: 21.8379 | I9: -1461 | J9: 2265.5604 | K9: 9.6936 | L9: -1408 | M9: 2296.811 | N9: 5.8997 | O9: -1377 | P9: 2313.6699 | Q9: 3.6852 | R9: -1354 | S9: 2325.6105 | T9: 2.0571 | U9: -1333 | V9: 2335.7439 | W9: 0.6189 | X9: -1320 | Y9: 2327.5512 | Z9: -1.2881 | AA9: -1305 | AB9: 2317.5411 | AC9: -3.464 | AD9: -1283 | AE9: 2303.0984 | AF9: -6.3451 | AG9: -1245 | AH9: 2274.9525 | AI9: -11.2097 | AJ9: -1132 | AK9: 2164.1119 | AL9: -24.3915 | AM9: -347.6007 | AN9: 0.4122 | AO9: -112.3006 | AP9: -1132 | AQ9: -2164 | AR9: -24.3336 | AS9: -1245 | AT9: -2275 | AU9: -11.1411 | AV9: -1283 | AW9: -2303 | AX9: -6.2769 | AY9: -1305 | AZ9: -2318 | BA9: -3.3963 | BB9: -1320 | BC9: -2328 | BD9: -1.2209 | BE9: -1333 | BF9: -2336 | BG9: 0.6857 | BH9: -1354 | BI9: -2326 | BJ9: 2.1214 | BK9: -1377 | BL9: -2314 | BM9: 3.7467 | BN9: -1408 | BO9: -2297 | BP9: 5.9577 | BQ9: -1461 | BR9: -2266 | BS9: 9.7461 | BT9: -1591 | BU9: -2148 | BV9: 21.8783
B10: 7 | C10: -1868 | D10: -0.0198 | E10: 142.2203 | F10: -1208 | G10: 2270.828 | H10: 12.8992 | I10: -1132 | J10: 2330.6762 | K10: 0.286 | L10: -1105 | M10: 2333.5439 | N10: -3.3519 | O10: -1087 | P10: 2330.623 | Q10: -5.0883 | R10: -1075 | S10: 2327.8094 | T10: -6.3592 | U10: -1064 | V10: 2324.8432 | W10: -7.4658 | X10: -1041 | Y10: 2312.5391 | Z10: -8.9616 | AA10: -1014 | AB10: 2296.5892 | AC10: -10.7163 | AD10: -978.1433 | AE10: 2272.142 | AF10: -13.0926 | AG10: -913.559 | AH10: 2217.7242 | AI10: -17.4639 | AJ10: -740.5028 | AK10: 1991.3164 | AL10: -32.0358 | AM10: -186.6027 | AN10: 0.0207 | AO10: -103.7344 | AP10: -740.4524 | AQ10: -1991 | AR10: -31.9865 | AS10: -913.5375 | AT10: -2218 | AU10: -17.3994 | AV10: -978.1433 | AW10: -2272 | AX10: -13.0227 | AY10: -1014 | AZ10: -2297 | BA10: -10.6463 | BB10: -1041 | BC10: -2313 | BD10: -8.8916 | BE10: -1064 | BF10: -2325 | BG10: -7.3958 | BH10: -1075 | BI10: -2328 | BJ10: -6.2893 | BK10: -1087 | BL10: -2331 | BM10: -5.0183 | BN10: -1105 | BO10: -2334 | BP10: -3.282 | BQ10: -1132 | BR10: -2331 | BS10: 0.3559 | BT10: -1208 | BU10: -2271 | BV10: 12.9541
B11: 8 | C11: -1364 | D11: -0.0198 | E11: 153.9845 | F11: -820.8033 | G11: 2086.6386 | H11: 5.8785 | I11: -819.7907 | J11: 2148.7433 | K11: -8.3965 | L11: -816.1814 | M11: 2160.7216 | N11: -12.6511 | O11: -811.8566 | P11: 2161.5918 | Q11: -14.5375 | R11: -807.4437 | S11: 2159.0118 | T11: -15.5713 | U11: -803.4296 | V11: 2156.2838 | W11: -16.4386 | X11: -773.485 | Y11: 2125.7321 | Z11: -18.1863 | AA11: -738.8102 | AB11: 2087.6359 | AC11: -20.2209 | AD11: -689.9926 | AE11: 2028.3059 | AF11: -23.1474 | AG11: -602.1424 | AH11: 1906.0756 | AI11: -28.5501 | AJ11: -365.4001 | AK11: 1506.0207 | AL11: -42.5262 | AM11: -46.8843 | AN11: 0.0207 | AO11: -87.8675 | AP11: -365.3329 | AQ11: -1506 | AR11: -42.4892 | AS11: -602.1136 | AT11: -1906 | AU11: -28.4929 | AV11: -690.016 | AW11: -2028 | AX11: -23.0772 | AY11: -738.8175 | AZ11: -2088 | BA11: -20.1503 | BB11: -773.485 | BC11: -2126 | BD11: -18.1163 | BE11: -803.4296 | BF11: -2156 | BG11: -16.3687 | BH11: -807.4437 | BI11: -2159 | BJ11: -15.5013 | BK11: -811.8566 | BL11: -2162 | BM11: -14.4676 | BN11: -816.1814 | BO11: -2161 | BP11: -12.5812 | BQ11: -819.7907 | BR11: -2149 | BS11: -8.3266 | BT11: -820.8033 | BU11: -2087 | BV11: 5.9484
B12: 9 | C12: -823.944 | D12: -1.008 | E12: 140.2679 | F12: -315.3104 | G12: 1337.0461 | H12: 29.1208 | I12: -494.0333 | J12: 1747.552 | K12: -13.7046 | L12: -519.4353 | M12: 1802.6656 | N12: -20.0178 | O12: -531.1669 | P12: 1827.1263 | Q12: -22.824 | R12: -538.4611 | S12: 1841.45 | T12: -24.4208 | U12: -543.0429 | V12: 1849.8331 | W12: -25.4052 | X12: -504.7576 | Y12: 1790.689 | Z12: -27.4541 | AA12: -458.9116 | AB12: 1715.1645 | AC12: -29.9445 | AD12: -394.1929 | AE12: 1600.8739 | AF12: -33.6027 | AG12: -282.5499 | AH12: 1386.5458 | AI12: -39.8312 | AJ12: -46.1441 | AK12: 874.1389 | AL12: -48.8966 | AM12: 61.8264 | AN12: 0.0207 | AO12: -65.3839 | AP12: -46.0433 | AQ12: -873.8769 | AR12: -48.8826 | AS12: -282.5067 | AT12: -1386 | AU12: -39.7886 | AV12: -394.1761 | AW12: -1601 | AX12: -33.5463 | AY12: -458.9117 | AZ12: -1715 | BA12: -29.8793 | BB12: -504.7736 | BC12: -1791 | BD12: -27.3836 | BE12: -543.0429 | BF12: -1850 | BG12: -25.3353 | BH12: -538.4611 | BI12: -1841 | BJ12: -24.3509 | BK12: -531.1669 | BL12: -1827 | BM12: -22.7541 | BN12: -519.4353 | BO12: -1803 | BP12: -19.9478 | BQ12: -494.0333 | BR12: -1748 | BS12: -13.6346 | BT12: -315.3437 | BU12: -1337 | BV12: 29.1945
B13: 10 | C13: -292.4538 | D13: -1.9867 | E13: 93.7385 | F13: 131.3957 | G13: 464.0237 | H13: 31.8471 | I13: 28.5922 | J13: 705.8541 | K13: 22.6638 | L13: -94.3007 | M13: 991.5338 | N13: 1.4435 | O13: -188.8361 | P13: 1203.9319 | Q13: -17.602 | R13: -248.7646 | S13: 1333.3463 | T13: -30.1608 | U13: -268.0272 | V13: 1373.8535 | W13: -32.8659 | X13: -216.507 | Y13: 1267.7043 | Z13: -35.5604 | AA13: -154.6142 | AB13: 1134.1632 | AC13: -38.8982 | AD13: -62.8934 | AE13: 927.9028 | AF13: -42.2454 | AG13: 61.3377 | AH13: 639.3944 | AI13: -41.9301 | AJ13: 166.632 | AK13: 393.1392 | AL13: -31.6998 | AM13: 183.4369 | AN13: 0.0207 | AO13: -32.9941 | AP13: 166.632 | AQ13: -393.0978 | AR13: -31.6998 | AS13: 61.4239 | AT13: -639.1454 | AU13: -41.9297 | AV13: -62.8598 | AW13: -927.7838 | AX13: -42.2174 | AY13: -154.6144 | AZ13: -1134 | BA13: -38.8535 | BB13: -216.5336 | BC13: -1268 | BD13: -35.5024 | BE13: -268.1635 | BF13: -1374 | BG13: -32.7865 | BH13: -248.9127 | BI13: -1334 | BJ13: -30.0802 | BK13: -188.9973 | BL13: -1204 | BM13: -17.5202 | BN13: -94.4784 | BO13: -991.9158 | BP13: 1.5269 | BQ13: 28.4193 | BR13: -706.2198 | BS13: 22.7461 | BT13: 131.1201 | BU13: -464.6224 | BV13: 31.9391
B14: 11 | C14: 335.7333 | D14: 0.0207 | E14: 13.0673 | F14: 335.7333 | G14: 0.0207 | H14: 13.0673 | I14: 335.7333 | J14: 0.0207 | K14: 13.0673 | L14: 335.7333 | M14: 0.0207 | N14: 13.0673 | O14: 335.7333 | P14: 0.0207 | Q14: 13.0673 | R14: 335.7333 | S14: 0.0207 | T14: 13.0673 | U14: 335.7333 | V14: 0.0207 | W14: 13.0673 | X14: 335.7333 | Y14: 0.0207 | Z14: 13.0673 | AA14: 335.7333 | AB14: 0.0207 | AC14: 13.0673 | AD14: 335.7333 | AE14: 0.0207 | AF14: 13.0673 | AG14: 335.7333 | AH14: 0.0207 | AI14: 13.0673 | AJ14: 335.7333 | AK14: 0.0207 | AL14: 13.0673 | AM14: 335.7333 | AN14: 0.0207 | AO14: 13.0673 | AP14: 335.7333 | AQ14: 0.0207 | AR14: 13.0673 | AS14: 335.7333 | AT14: 0.0207 | AU14: 13.0673 | AV14: 335.7333 | AW14: 0.0207 | AX14: 13.0673 | AY14: 335.7333 | AZ14: 0.0207 | BA14: 13.0673 | BB14: 335.7333 | BC14: 0.0207 | BD14: 13.0673 | BE14: 335.7333 | BF14: 0.0207 | BG14: 13.0673 | BH14: 335.7333 | BI14: 0.0207 | BJ14: 13.0673 | BK14: 335.7333 | BL14: 0.0207 | BM14: 13.0673 | BN14: 335.7333 | BO14: 0.0207 | BP14: 13.0673 | BQ14: 335.7333 | BR14: 0.0207 | BS14: 13.0673 | BT14: 335.7333 | BU14: 0.0207 | BV14: 13.0673
L17: Curve 1 | M17: 0 degrees | O17: Curve 2 | P17: 15 degrees | R17: Curve 3 | S17: 30 degrees | U17: Curve 4 | V17: 45 degrees | X17: Curve 5 | Y17: 60 degrees | AA17: Curve 6 | AB17: 75 degrees | AD17: Curve 7 | AE17: 90 degrees | AG17: Curve 8 | AH17: 105 degrees | AJ17: Curve 9 | AK17: 120 degrees | AM17: Curve 10 | AN17: 135 degrees | AP17: Curve 11 | AQ17: 150 degrees | AS17: Curve 12 | AT17: 165 degrees | AV17: Curve 13 | AW17: 180 degrees | AY17: Curve 14 | AZ17: 195 degrees | BB17: Curve 15 | BC17: 210 degrees | BE17: Curve 16 | BF17: 225 degrees | BH17: Curve 17 | BI17: 240 degrees | BK17: Curve 18 | BL17: 255 degrees | BN17: Curve 19 | BO17: 270 degrees | BQ17: Curve 20 | BR17: 285 degrees | BT17: Curve 21 | BU17: 300 degrees | BW17: Curve 22 | BX17: 315 degrees | BZ17: Curve 23 | CA17: 330 degrees | CC17: Curve 24 | CD17: 345 degrees
K19: 1 | L19: -2346 | M19: -0.0198 | N19: -9.9314 | O19: -2346 | P19: -0.0198 | Q19: -9.9314 | R19: -2346 | S19: -0.0198 | T19: -9.9314 | U19: -2346 | V19: -0.0198 | W19: -9.9314 | X19: -2346 | Y19: -0.0198 | Z19: -9.9314 | AA19: -2346 | AB19: -0.0198 | AC19: -9.9314 | AD19: -2346 | AE19: -0.0198 | AF19: -9.9314 | AG19: -2346 | AH19: -0.0198 | AI19: -9.9314 | AJ19: -2346 | AK19: -0.0198 | AL19: -9.9314 | AM19: -2346 | AN19: -0.0198 | AO19: -9.9314 | AP19: -2346 | AQ19: -0.0198 | AR19: -9.9314 | AS19: -2346 | AT19: -0.0198 | AU19: -9.9314 | AV19: -2346 | AW19: -0.0198 | AX19: -9.9314 | AY19: -2346 | AZ19: -0.0198 | BA19: -9.9314 | BB19: -2346 | BC19: -0.0198 | BD19: -9.9314 | BE19: -2346 | BF19: -0.0198 | BG19: -9.9314 | BH19: -2346 | BI19: -0.0198 | BJ19: -9.9314 | BK19: -2346 | BL19: -0.0198 | BM19: -9.9314 | BN19: -2346 | BO19: -0.0198 | BP19: -9.9314 | BQ19: -2346 | BR19: -0.0198 | BS19: -9.9314 | BT19: -2346 | BU19: -0.0198 | BV19: -9.9314 | BW19: -2346 | BX19: -0.0198 | BY19: -9.9314 | BZ19: -2346 | CA19: -0.0198 | CB19: -9.9314 | CC19: -2346 | CD19: -0.0198 | CE19: -9.9314
K20: 2 | L20: -2346 | M20: -0.0198 | N20: 30.3945 | O20: -2346 | P20: 408.7694 | Q20: 22.1101 | R20: -2346 | S20: 588.3839 | T20: 30.7829 | U20: -2346 | V20: 803.0952 | W20: 32.6316 | X20: -2346 | Y20: 967.2858 | Z20: 30.5112 | AA20: -2346 | AB20: 1070.2131 | AC20: 28.1549 | AD20: -2346 | AE20: 1155.3683 | AF20: 26.015 | AG20: -2346 | AH20: 1128.7985 | AI20: 24.6459 | AJ20: -2346 | AK20: 1020.3114 | AL20: 14.4289 | AM20: -2346 | AN20: 847.3365 | AO20: -0.6602 | AP20: -2346 | AQ20: 630.9021 | AR20: -15.0486 | AS20: -2346 | AT20: 459.8668 | AU20: -19.9197 | AV20: -2331 | AW20: 0.2173 | AX20: -81.8589 | AY20: -2346 | AZ20: -459.8223 | BA20: -19.8878 | BB20: -2346 | BC20: -630.8836 | BD20: -15.0177 | BE20: -2346 | BF20: -847.33 | BG20: -0.6299 | BH20: -2346 | BI20: -1020 | BJ20: 14.4589 | BK20: -2346 | BL20: -1129 | BM20: 24.6757 | BN20: -2346 | BO20: -1155 | BP20: 26.0445 | BQ20: -2346 | BR20: -1070 | BS20: 28.183 | BT20: -2346 | BU20: -967.3117 | BV20: 30.5383 | BW20: -2346 | BX20: -803.1302 | BY20: 32.6577 | BZ20: -2346 | CA20: -588.4334 | CB20: 30.8059 | CC20: -2346 | CD20: -408.8508 | CE20: 22.1264
K21: 3 | L21: -2346 | M21: -0.0198 | N21: 52.2646 | O21: -2346 | P21: 748.3053 | Q21: 38.8689 | R21: -2346 | S21: 1181.3293 | T21: 31.8417 | U21: -2291 | V21: 1366.8095 | W21: 26.5754 | X21: -2234 | Y21: 1465.9589 | Z21: 23.5147 | AA21: -2192 | AB21: 1534.6283 | AC21: 21.2538 | AD21: -2155 | AE21: 1591.799 | AF21: 19.2905 | AG21: -2159 | AH21: 1582.3832 | AI21: 18.2838 | AJ21: -2164 | AK21: 1571.6865 | AL21: 17.1494 | AM21: -2170 | AN21: 1556.7881 | AO21: 15.6341 | AP21: -2186 | AQ21: 1519.1864 | AR21: 11.3866 | AS21: -2339 | AT21: 1152.6812 | AU21: -25.6256 | AV21: -1852 | AW21: 0.248 | AX21: -121.5736 | AY21: -2339 | AZ21: -1153 | BA21: -25.5884 | BB21: -2186 | BC21: -1519 | BD21: 11.4235 | BE21: -2170 | BF21: -1557 | BG21: 15.6704 | BH21: -2164 | BI21: -1572 | BJ21: 17.1853 | BK21: -2159 | BL21: -1582 | BM21: 18.3194 | BN21: -2155 | BO21: -1592 | BP21: 19.3259 | BQ21: -2192 | BR21: -1535 | BS21: 21.2876 | BT21: -2234 | BU21: -1466 | BV21: 23.5468 | BW21: -2291 | BX21: -1367 | BY21: 26.6052 | BZ21: -2346 | CA21: -1181 | CB21: 31.8681 | CC21: -2346 | CD21: -748.3906 | CE21: 38.8892
K22: 4 | L22: -2346 | M22: -0.0198 | N22: 72.5398 | O22: -2316 | P22: 1300.6669 | Q22: 37.2291 | R22: -2096 | S22: 1677.4247 | T22: 24.241 | U22: -2013 | V22: 1792.7877 | W22: 19.4575 | X22: -1965 | Y22: 1854.2438 | Z22: 16.6675 | AA22: -1929 | AB22: 1896.8853 | AC22: 14.6105 | AD22: -1898 | AE22: 1932.3849 | AF22: 12.803 | AG22: -1896 | AH22: 1929.6551 | AI22: 11.5112 | AJ22: -1894 | AK22: 1926.4157 | AL22: 10.0625 | AM22: -1891 | AN22: 1922.1487 | AO22: 8.1087 | AP22: -1885 | AQ22: 1914.4642 | AR22: 4.8382 | AS22: -1876 | AT22: 1862.1525 | AU22: -7.4289 | AV22: -1361 | AW22: 0.2872 | AX22: -140.0073 | AY22: -1876 | AZ22: -1862 | BA22: -7.3878 | BB22: -1885 | BC22: -1914 | BD22: 4.8828 | BE22: -1891 | BF22: -1922 | BG22: 8.1527 | BH22: -1894 | BI22: -1926 | BJ22: 10.1061 | BK22: -1896 | BL22: -1930 | BM22: 11.5544 | BN22: -1898 | BO22: -1932 | BP22: 12.8459 | BQ22: -1929 | BR22: -1897 | BS22: 14.6516 | BT22: -1965 | BU22: -1854 | BV22: 16.7066 | BW22: -2013 | BX22: -1793 | BY22: 19.4941 | BZ22: -2096 | CA22: -1677 | CB22: 24.2736 | CC22: -2316 | CD22: -1301 | CE22: 37.2536
K23: 5 | L23: -2346 | M23: -0.0198 | N23: 90.6952 | O23: -1968 | P23: 1823.1343 | Q23: 29.5416 | R23: -1791 | S23: 2041.1776 | T23: 17.0485 | U23: -1723 | V23: 2105.3878 | W23: 12.7251 | X23: -1683 | Y23: 2139.5523 | Z23: 10.1887 | AA23: -1653 | AB23: 2163.452 | AC23: 8.3039 | AD23: -1627 | AE23: 2183.2878 | AF23: 6.6697 | AG23: -1620 | AH23: 2180.936 | AI23: 5.0649 | AJ23: -1611 | AK23: 2178.1304 | AL23: 3.2478 | AM23: -1598 | AN23: 2173.9445 | AO23: 0.8319 | AP23: -1576 | AQ23: 2165.6208 | AR23: -3.246 | AS23: -1508 | AT23: 2126.1423 | AU23: -14.1038 | AV23: -856.4035 | AW23: 0.3394 | AX23: -137.3954 | AY23: -1508 | AZ23: -2126 | BA23: -14.0557 | BB23: -1576 | BC23: -2166 | BD23: -3.1912 | BE23: -1598 | BF23: -2174 | BG23: 0.886 | BH23: -1611 | BI23: -2178 | BJ23: 3.3014 | BK23: -1620 | BL23: -2181 | BM23: 5.1182 | BN23: -1627 | BO23: -2183 | BP23: 6.7226 | BQ23: -1653 | BR23: -2163 | BS23: 8.3547 | BT23: -1683 | BU23: -2140 | BV23: 10.2372 | BW23: -1723 | BX23: -2105 | BY23: 12.7707 | BZ23: -1791 | CA23: -2041 | CB23: 17.0894 | CC23: -1968 | CD23: -1823 | CE23: 29.5724
