Workbook
Name N19ai19: MO!$O$21

Sheet ANALISIS RIESGOS
A1: MATRIZ DE RIESGOS Y OPORTUNIDADES
A3: Ítem | B3: Identificación | C3: ESPECIALIDAD | D3: Análisis | E3: Rubro | F3: Gravedad | G3: Monto S/. | H3: Amenazas | I3: Oportunidad | J3: Observaciones | K3: ESTATUS RO | L3: Responsable | M3: Soluciones
A4: 01 | B4: Debido a la modalidad del contrato (suma alzada): se tenga que ejecutar mayores prestaciones adicionales sin que necesariamente sean reconocidos por la Entidad. Mov. De Tierras | C4: MOV. DE TIERRAS | D4: Gestionar ante la Entidad adicionales y deductivos vinculantes, no obstante sean rechazados se deberá dejar antecedes para un posterior reconocimiento mediante la via que corresponda. | E4: METRADO | F4: MUY BAJA | G4: 15000 | H4: =+IF(G4>0,G4,0) -> 15000 | J4: Costo total que se podria presentar en cualquier momento | K4: No Considerado en RO | L4: Obra | M4: Elaboración del presupuesto compromiso con metrados reales lo que permitirá determinar la brecha entre lo considerado en el Expediente Técnico y lo realmente a ejecutar. | AE4: ALTA
A5: =+A4+1 -> 2 | B5: Debido a la modalidad del contrato (suma alzada): se tenga que ejecutar mayores prestaciones adicionales sin que necesariamente sean reconocidos por la Entidad. Estructuras | C5: ESTRUCTURAS | D5: Gestionar ante la Entidad adicionales y deductivos vinculantes, no obstante sean rechazados se deberá dejar antecedes para un posterior reconocimiento mediante la via que corresponda. | E5: METRADO | F5: MUY BAJA | G5: 25000 | H5: =+IF(G5>0,G5,0) -> 25000 | J5: Costo total que se podria presentar en cualquier momento | K5: No Considerado en RO | L5: Obra | M5: Elaboración del presupuesto compromiso con metrados reales lo que permitirá determinar la brecha entre lo considerado en el Expediente Técnico y lo realmente a ejecutar. | AE5: ALTA
A6: =+A5+1 -> 3 | B6: Adecuaciones | C6: GG | D6: Adecuaciones de instalaciones de obra. | E6: EXTERNO | F6: ALTA | G6: 5000 | H6: =+IF(G6>0,G6,0) -> 5000 | J6: Costo mensual que se podria considerar en el mes de octubre y noviembre | K6: Costo Considerado en RO | L6: Área legal | M6: Se solicita apoyo al área legal
A7: =+A6+1 -> 4 | B7: Paralizaciones varias,: gremios sindicales, paro de transportistas, etc. | C7: GG | D7: Costos Stand by asociados a paralizaciones | E7: EXTERNO | F7: MUY BAJA | G7: 5000 | H7: =+IF(G7>0,G7,0) -> 5000 | J7: Costo mensual que se podria presentar en cada mes de la obra | K7: No Considerado en RO | L7: Externo | M7: Se realizará una contingencia ante estos eventos días antes. Envío de comunicación ante la entidad comunicando evento.
A8: =+A7+1 -> 5 | B8: Alquiler de GE para suministro de energía de obra | C8: ELÉCTRICAS | D8: Se puede dar si se corta la Energia Eléctrica | E8: EXTERNO | F8: ALTA | G8: 3000 | H8: =+IF(G8>0,G8,0) -> 3000 | J8: Costo mensual de combustible y alquiler de GE por si se corta la energia electrica | K8: No Considerado en RO | L8: Area Legal | M8: Enviar costo de adicional a Entidad. Revisar contingencia de órganos de control de contratos, de revisar GE defintivos de acuerdo a rpta de entidad.
A9: =+A8+1 -> 6 | B9: Sobre costo de Agregados (Estructuras) | C9: ESTRUCTURAS | D9: Podria darse debido a la inaccesibilidad de la cantera actual por lluvias | E9: EXTERNO | F9: MUY BAJA | H9: =+IF(G9>0,G9,0) -> 0 | J9: Suministro de agregados en el mes de septiembre, podría ser un 20% al estimado inciialmente debido a la lejanía de las canteras | K9: No Considerado en RO | L9: Obra | M9: Encontrar proveedores con lleguen al costo considerando viaje puesto en obra.
A10: =+A9+1 -> 7 | F10: MUY BAJA | H10: =+IF(G10>0,G10,0) -> 0
A11: =+A10+1 -> 8 | F11: MUY BAJA | H11: =+IF(G11>0,G11,0) -> 0
G12: =SUM(G4:G11) -> 53000 | H12: =SUM(H4:H11) -> 53000 | I12: =SUM(I4:I11) -> 0
B19: Etiquetas de fila | C19: Suma de Amenazas | D19: Suma de Oportunidad
B20: METRADO | C20: 0
B21: PANDEMIA | C21: 0 | D21: 1958414.8
B22: PLAZO | D22: 3779808.1
B23: ALCANCE | C23: -7095143.5 | D23: 681215.99
B24: EXTERNO | C24: -210000
B25: SUPERVISION | C25: -1514650 | D25: 20586
B26: CONTRATO | C26: 0
B27: ENTIDAD | C27: -1087010.2
B28: INGENIERIA | C28: -3582801.2 | D28: 0
B29: Total general | C29: -13489605 | D29: 6440024.9

Sheet RG
B1: =CONCATENATE(B3," - ",B4," - ",B5," - ",B6) -> I.E.N 1182 - - EL BOSQUE - CERCO + INGRESOS Y CASETAS -
N2: =+YEAR(N5) -> 2024 | O2: =+YEAR(O5) -> 2024 | P2: =+YEAR(P5) -> 2025 | Q2: =+YEAR(Q5) -> 2025 | R2: =+YEAR(R5) -> 2025 | S2: =S5 -> 2025
B3: I.E.N 1182 | E3: ACUMULADO | G3: MES ENERO DEL 2025 | J3: ACUMULADO DEL 2024 | K3: ACUMULADO DE OBRA | L3: SALDO DE OBRA | N3: PROYECCIÓN | U3: AÑOS SIGUIENTES | Y3: TOTAL DE OBRA | AH3: Acum. del Ej. | AN3: TOTAL | AO3: MES DEL INFORME | AP3: ANTERIORES | AQ3: 45597 | AR3: 45627 | AS3: 45658 | AT3: 45689 | AU3: 45717
N4: 1 | O4: =+N4+1 -> 2 | P4: =+O4+1 -> 3 | Q4: =+P4+1 -> 4 | R4: =+Q4+1 -> 5 | S4: Saldo del Ejercicio
B5: EL BOSQUE - CERCO + INGRESOS Y CASETAS | E5: Años Anteriores | G5: Previsto | H5: Real | N5: 45597 | O5: =+N5+31 -> 45628 | P5: =+O5+31 -> 45659 | Q5: =+P5+31 -> 45690 | R5: =+Q5+31 -> 45721 | S5: 2025 | U5: =+S5+1 -> 2026 | V5: =+U5+1 -> 2027 | W5: =+V5+1 -> 2028 | Y5: RO con Venta Mejor Escenario | Z5: RO con Venta Aprobada a la Fecha | AA5: RO Sin Adicional Contractual aprobado + 20% ahorro en SC Instalaciones (IISS/IEE) | AB5: RO ABRIL Sin Adicional contractual aprobado | AC5: Anterior | AD5: Meta | AE5: Presupuesto Interno | AF5: Presupuesto | AH5: Anterior
B7: Venta Total Producida | E7: =+E9 -> #REF! | G7: =+G9 -> 0 | H7: =+H9 -> 0 | J7: =+J9 -> 0 | K7: =+K9 -> 0 | L7: =+L9 -> 0 | N7: =+N9 -> 0 | O7: =+O9 -> 0 | P7: =+P9 -> 0 | Q7: =+Q9 -> 0 | R7: =+R9 -> 0 | S7: =+S9 -> 0 | U7: =+U9 -> 0 | V7: =+V9 -> 0 | W7: =+W9 -> 0 | Y7: =+Y9 -> 1511228 | Z7: =+Z9 -> 0 | AA7: =+AA9 -> 0 | AB7: =+AB9 -> 0 | AC7: =+AC9 -> 0 | AD7: =+AD9 -> 0 | AE7: =+AE9 -> 0 | AF7: =+AF9 -> 0 | AH7: =+AH9 -> 0 | AJ7: =+AF7-Z7 -> 0 | AN7: =+AN9 -> 0 | AO7: =+AO9 -> 0 | AQ7: =+AQ9 -> 0 | AR7: =+AR9 -> 0 | AS7: =+AS9 -> 0 | AT7: =+AT9 -> 0 | AU7: =+AU9 -> 0
B9: Venta | E9: =+SUM(E11:E13) -> #REF! | G9: =+SUM(G11:G13) -> 0 | H9: =+SUM(H11:H13) -> 0 | J9: =+SUM(J11:J13) -> 0 | K9: =+SUM(K11:K13) -> 0 | L9: =+SUM(L11:L13) -> 0 | N9: =+SUM(N11:N13) -> 0 | O9: =+SUM(O11:O13) -> 0 | P9: =+SUM(P11:P13) -> 0 | Q9: =+SUM(Q11:Q13) -> 0 | R9: =+SUM(R11:R13) -> 0 | S9: =+SUM(S11:S13) -> 0 | U9: =+SUM(U11:U13) -> 0 | V9: =+SUM(V11:V13) -> 0 | W9: =+SUM(W11:W13) -> 0 | Y9: =+SUM(Y11:Y13) -> 1511228 | Z9: =+SUM(Z11:Z13) -> 0 | AA9: =+SUM(AA11:AA13) -> 0 | AB9: =+SUM(AB11:AB13) -> 0 | AC9: =+SUM(AC11:AC13) -> 0 | AD9: =+SUM(AD11:AD13) -> 0 | AE9: =+SUM(AE11:AE13) -> 0 | AF9: =+SUM(AF11:AF13) -> 0 | AH9: =+SUM(AH11:AH13) -> 0 | AJ9: =+AF9-Z9 -> 0 | AK9: =+Z9-AC9 -> 0 | AN9: =+SUM(AN11:AN13) -> 0 | AO9: =+SUM(AO11:AO13) -> 0 | AQ9: =+SUM(AQ11:AQ13) -> 0 | AR9: =+SUM(AR11:AR13) -> 0 | AS9: =+SUM(AS11:AS13) -> 0 | AT9: =+SUM(AT11:AT13) -> 0 | AU9: =+SUM(AU11:AU13) -> 0
B11: Valorización: Venta Directa - Contrato Principal | E11: =+'DIRECTO '!E11+#REF! -> #REF! | L11: =+SUM(N11:R11) -> 0 | S11: =+SUMIFS(N11:R11,N$2:R$2,$S$5) -> 0 | U11: =+SUMIFS(N11:S11,N$2:S$2,$U$5) -> 0 | V11: =+SUMIFS(N11:S11,N$2:S$2,$V$5) -> 0 | W11: =+SUMIFS(N11:S11,N$2:S$2,$W$5) -> 0 | Y11: =+Z11 -> 0 | Z11: =+K11+L11 -> 0 | AJ11: =+AF11-Z11 -> 0 | AK11: =+Z11-AC11 -> 0
B12: Valorización: Venta Indirecta - Contrato Principal | E12: =+'DIRECTO '!E12+#REF! -> #REF! | L12: =+SUM(N12:R12) -> 0 | S12: =+SUMIFS(N12:R12,N$2:R$2,$S$5) -> 0 | U12: =+SUMIFS(N12:S12,N$2:S$2,$U$5) -> 0 | V12: =+SUMIFS(N12:S12,N$2:S$2,$V$5) -> 0 | W12: =+SUMIFS(N12:S12,N$2:S$2,$W$5) -> 0 | Y12: =+Z12 -> 0 | Z12: =+K12+L12 -> 0 | AJ12: =+AF12-Z12 -> 0 | AK12: =+Z12-AC12 -> 0
B13: Otros | Y13: =1783249.01/1.18 -> 1511228
B15: Costo Total | E15: =+SUM(E17:E26)+E29 -> #REF! | G15: =+SUM(G17:G26,G29) -> #REF! | H15: =SUM(H17:H26,H29) -> #REF! | J15: =+SUM(J17:J26,J29) -> #REF! | K15: =+SUM(K17:K26,K29) -> #REF! | L15: =+SUM(L17:L26,L29) -> 0 | N15: =+SUM(N17:N26,N29) -> 0 | O15: =+SUM(O17:O26,O29) -> 0 | P15: =+SUM(P17:P26,P29) -> 0 | Q15: =+SUM(Q17:Q26,Q29) -> 0 | R15: =+SUM(R17:R26,R29) -> 0 | S15: =+SUM(S17:S26,S29) -> 0 | U15: =+SUM(U17:U26,U29) -> 0 | V15: =+SUM(V17:V26,V29) -> 0 | W15: =+SUM(W17:W26,W29) -> 0 | Y15: =+SUM(Y17:Y26,Y29) -> 0 | Z15: =+SUM(Z17:Z26,Z29) -> #REF! | AA15: =+SUM(AA17:AA26)-(#REF!+#REF!)+AA29+AA28 -> #REF! | AB15: =+SUM(AB17:AB26,AB29) -> 0 | AC15: =+SUM(AC17:AC26,AC29) -> #REF! | AD15: =+SUM(AD17:AD26,AD29) -> #REF! | AE15: =+SUM(AE17:AE26,AE29) -> #REF! | AF15: =+SUM(AF17:AF26,AF29) -> #REF! | AH15: =+SUM(AH17:AH26,AH29) -> #REF! | AJ15: =+AF15-Z15 -> #REF! | AN15: =+SUM(AN17:AN26,AN29) -> #REF! | AO15: =+SUM(AO17:AO26,AO29) -> #REF! | AQ15: =+SUM(AQ17:AQ26,AQ29) -> 0 | AR15: =+SUM(AR17:AR26,AR29) -> 0 | AS15: =+SUM(AS17:AS26,AS29) -> 0 | AT15: =+SUM(AT17:AT26,AT29) -> 0 | AU15: =+SUM(AU17:AU26,AU29) -> 0
B17: Materiales | E17: =+'DIRECTO '!E17+#REF! -> #REF! | L17: =+SUM(N17:R17) -> 0 | S17: =+SUMIFS(N17:R17,N$2:R$2,$S$5) -> 0 | U17: =+SUMIFS(N17:S17,N$2:S$2,$U$5) -> 0 | V17: =+SUMIFS(N17:S17,N$2:S$2,$V$5) -> 0 | W17: =+SUMIFS(N17:S17,N$2:S$2,$W$5) -> 0 | Y17: =+Z17 -> 0 | Z17: =+K17+L17 -> 0 | AJ17: =+AF17-Z17 -> 0 | AK17: =Mat!Y26 -> 0 | AL17: =IF(ABS(Z17-AK17)>1,"Revisar Rubros","OK") -> OK
B18: Mano de Obra | E18: =+'DIRECTO '!E18+#REF! -> #REF! | L18: =+SUM(N18:R18) -> 0 | S18: =+SUMIFS(N18:R18,N$2:R$2,$S$5) -> 0 | U18: =+SUMIFS(N18:S18,N$2:S$2,$U$5) -> 0 | V18: =+SUMIFS(N18:S18,N$2:S$2,$V$5) -> 0 | W18: =+SUMIFS(N18:S18,N$2:S$2,$W$5) -> 0 | Y18: =+Z18 -> 0 | Z18: =+K18+L18 -> 0 | AJ18: =+AF18-Z18 -> 0 | AK18: =+MO!Y75 -> 0 | AL18: =IF(ABS(Z18-AK18)>1,"Revisar Rubros","OK") -> OK
B19: Subcontratos de obra | E19: =+'DIRECTO '!E19+#REF! -> #REF! | L19: =+SUM(N19:R19) -> 0 | S19: =+SUMIFS(N19:R19,N$2:R$2,$S$5) -> 0 | U19: =+SUMIFS(N19:S19,N$2:S$2,$U$5) -> 0 | V19: =+SUMIFS(N19:S19,N$2:S$2,$V$5) -> 0 | W19: =+SUMIFS(N19:S19,N$2:S$2,$W$5) -> 0 | Y19: =+Z19 -> 0 | Z19: =+K19+L19 -> 0 | AJ19: =+AF19-Z19 -> 0 | AK19: =+SC!#REF! -> #REF! | AL19: =IF(ABS(Z19-AK19)>1,"Revisar Rubros","OK") -> #REF!
B20: Servicios Contratados | E20: =+'DIRECTO '!E20+#REF! -> #REF! | L20: =+SUM(N20:R20) -> 0 | S20: =+SUMIFS(N20:R20,N$2:R$2,$S$5) -> 0 | U20: =+SUMIFS(N20:S20,N$2:S$2,$U$5) -> 0 | V20: =+SUMIFS(N20:S20,N$2:S$2,$V$5) -> 0 | W20: =+SUMIFS(N20:S20,N$2:S$2,$W$5) -> 0 | Y20: =+Z20 -> 0 | Z20: =+K20+L20 -> 0 | AJ20: =+AF20-Z20 -> 0 | AK20: =+SER!Y44 -> 22778.589 | AL20: =IF(ABS(Z20-AK20)>1,"Revisar Rubros","OK") -> Revisar Rubros
B21: Equipos y Vehículos | E21: =+'DIRECTO '!E21+#REF! -> #REF! | L21: =+SUM(N21:R21) -> 0 | S21: =+SUMIFS(N21:R21,N$2:R$2,$S$5) -> 0 | U21: =+SUMIFS(N21:S21,N$2:S$2,$U$5) -> 0 | V21: =+SUMIFS(N21:S21,N$2:S$2,$V$5) -> 0 | W21: =+SUMIFS(N21:S21,N$2:S$2,$W$5) -> 0 | Y21: =+Z21 -> 0 | Z21: =+K21+L21 -> 0 | AJ21: =+AF21-Z21 -> 0 | AL21: =IF(ABS(Z21-AK21)>1,"Revisar Rubros","OK") -> OK
C22: Propios | E22: =+'DIRECTO '!E22+#REF! -> #REF! | L22: =+SUM(N22:R22) -> 0 | S22: =+SUMIFS(N22:R22,N$2:R$2,$S$5) -> 0 | U22: =+SUMIFS(N22:S22,N$2:S$2,$U$5) -> 0 | V22: =+SUMIFS(N22:S22,N$2:S$2,$V$5) -> 0 | W22: =+SUMIFS(N22:S22,N$2:S$2,$W$5) -> 0 | Y22: =+Z22 -> 0 | Z22: =+K22+L22 -> 0 | AJ22: =+AF22-Z22 -> 0 | AK22: =+Eq!Y56 -> 0 | AL22: =IF(ABS(Z22-AK22)>1,"Revisar Rubros","OK") -> OK
C23: Terceros | E23: =+'DIRECTO '!E23+#REF! -> #REF! | L23: =+SUM(N23:R23) -> 0 | S23: =+SUMIFS(N23:R23,N$2:R$2,$S$5) -> 0 | U23: =+SUMIFS(N23:S23,N$2:S$2,$U$5) -> 0 | V23: =+SUMIFS(N23:S23,N$2:S$2,$V$5) -> 0 | W23: =+SUMIFS(N23:S23,N$2:S$2,$W$5) -> 0 | Y23: =+Z23 -> 0 | Z23: =+K23+L23 -> 0 | AJ23: =+AF23-Z23 -> 0 | AK23: =+Eq!Y57 -> 0 | AL23: =IF(ABS(Z23-AK23)>1,"Revisar Rubros","OK") -> OK
B24: Fletes | E24: =+'DIRECTO '!E24+#REF! -> #REF! | L24: =+SUM(N24:R24) -> 0 | S24: =+SUMIFS(N24:R24,N$2:R$2,$S$5) -> 0 | U24: =+SUMIFS(N24:S24,N$2:S$2,$U$5) -> 0 | V24: =+SUMIFS(N24:S24,N$2:S$2,$V$5) -> 0 | W24: =+SUMIFS(N24:S24,N$2:S$2,$W$5) -> 0 | Y24: =+Z24 -> 0 | Z24: =+K24+L24 -> 0 | AJ24: =+AF24-Z24 -> 0 | AK24: =+Fletes!Y39 -> 0 | AL24: =IF(ABS(Z24-AK24)>1,"Revisar Rubros","OK") -> OK
B25: Staff (Sueldos) | E25: =+'DIRECTO '!E25+#REF! -> #REF! | L25: =+SUM(N25:R25) -> 0 | S25: =+SUMIFS(N25:R25,N$2:R$2,$S$5) -> 0 | U25: =+SUMIFS(N25:S25,N$2:S$2,$U$5) -> 0 | V25: =+SUMIFS(N25:S25,N$2:S$2,$V$5) -> 0 | W25: =+SUMIFS(N25:S25,N$2:S$2,$W$5) -> 0 | Y25: =+Z25 -> 0 | Z25: =+K25+L25 -> 0 | AJ25: =+AF25-Z25 -> 0 | AK25: =+Staff!BK27 -> 0 | AL25: =IF(ABS(Z25-AK25)>1,"Revisar Rubros","OK") -> OK
B26: Gastos Generales | E26: =+'DIRECTO '!E26+#REF! -> #REF! | L26: =+SUM(N26:R26) -> 0 | S26: =+SUMIFS(N26:R26,N$2:R$2,$S$5) -> 0 | U26: =+SUMIFS(N26:S26,N$2:S$2,$U$5) -> 0 | V26: =+SUMIFS(N26:S26,N$2:S$2,$V$5) -> 0 | W26: =+SUMIFS(N26:S26,N$2:S$2,$W$5) -> 0 | Y26: =+Z26 -> 0 | Z26: =+K26+L26 -> 0 | AJ26: =+AF26-Z26 -> 0 | AK26: =+GG!Y35 -> 24799.991 | AL26: =IF(ABS(Z26-AK26)>1,"Revisar Rubros","OK") -> Revisar Rubros
B28: COSTOS SC CON AHORRO DEL 20%(VENTA) | E28: =+'DIRECTO '!E25+#REF! -> #REF! | S28: =+SUMIFS(N28:R28,N$2:R$2,$S$5) -> 0 | U28: =+SUMIFS(N28:S28,N$2:S$2,$U$5) -> 0 | V28: =+SUMIFS(N28:S28,N$2:S$2,$V$5) -> 0 | W28: =+SUMIFS(N28:S28,N$2:S$2,$W$5) -> 0 | AA28: =(+#REF!+#REF!)*0.8 -> #REF! | AN28: =SUM(AO28:AU28) -> #REF! | AO28: =+'DIRECTO '!AK25+#REF! -> #REF!
B29: COSTO A LA FECHA + PROYECCION A ABRIL ( IISS/IIEE) | E29: =+'DIRECTO '!E28+#REF! -> #REF! | G29: =+'DIRECTO '!G28+#REF! -> #REF! | H29: =+'DIRECTO '!H28+#REF! -> #REF! | J29: =+'DIRECTO '!J28+#REF! -> #REF! | K29: =+'DIRECTO '!K28+#REF! -> #REF! | L29: =+SUM(N29:R29) -> 0 | S29: =+SUMIFS(N29:R29,N$2:R$2,$S$5) -> 0 | U29: =+SUMIFS(N29:S29,N$2:S$2,$U$5) -> 0 | V29: =+SUMIFS(N29:S29,N$2:S$2,$V$5) -> 0 | W29: =+SUMIFS(N29:S29,N$2:S$2,$W$5) -> 0 | Z29: =+K29+L29 -> #REF! | AA29: =+AS37+AS38 -> #REF! | AC29: =+'DIRECTO '!Z28+#REF! -> #REF! | AD29: =+'DIRECTO '!AA28+#REF! -> #REF! | AE29: =+'DIRECTO '!AB28+#REF! -> #REF! | AF29: =+'DIRECTO '!AC28+#REF! -> #REF! | AH29: =+'DIRECTO '!AE28+#REF! -> #REF! | AN29: =SUM(AO29:AU29) -> #REF! | AO29: =+'DIRECTO '!AK28+#REF! -> #REF!
B31: Margen Ponderado S/. | C31: S/. | E31: =+E7*E32 -> #REF! | G31: =+G7*G32 -> 0 | H31: =+H7*H32 -> 0 | J31: =+J7*J32 -> 0 | K31: =+K7*K32 -> 0 | L31: =+L7*L32 -> 0 | N31: =+N7*N32 -> 0 | O31: =+O7*O32 -> 0 | P31: =+P7*P32 -> 0 | Q31: =+Q7*Q32 -> 0 | R31: =+R7*R32 -> 0 | S31: =+S7*S32 -> 0 | U31: =+U7*U32 -> 0 | V31: =+V7*V32 -> 0 | W31: =+W7*W32 -> 0 | Y31: =+Y7-Y15 -> 1511228 | Z31: =+Z7-Z15 -> #REF! | AA31: =+AA7-AA15 -> #REF! | AB31: =+AB7-AB15 -> 0 | AC31: =+AC7-AC15 -> #REF! | AD31: =+AD7-AD15 -> #REF! | AE31: =+AE7-AE15 -> #REF! | AF31: =+AF7-AF15 -> #REF! | AH31: 0 | AJ31: =+Z31-AC31 -> #REF! | AL31: =+Z31 -> #REF!
C32: % | E32: =+$Z$32 -> 0 | G32: =+$Z$32 -> 0 | H32: =+$Z$32 -> 0 | J32: =+$Z$32 -> 0 | K32: =+$Z$32 -> 0 | L32: =+$Z$32 -> 0 | N32: =+$Z$32 -> 0 | O32: =+$Z$32 -> 0 | P32: =+$Z$32 -> 0 | Q32: =+$Z$32 -> 0 | R32: =+$Z$32 -> 0 | S32: =+$Z$32 -> 0 | U32: =+$Z$32 -> 0 | V32: =+$Z$32 -> 0 | W32: =+$Z$32 -> 0 | Y32: =+IF(Y7=0,0,Y31/Y7) -> 1 | Z32: =+IF(Z7=0,0,Z31/Z7) -> 0 | AA32: =+IF(AA7=0,0,AA31/AA7) -> 0 | AB32: =+IF(AB7=0,0,AB31/AB7) -> 0 | AC32: =+IF(AC7=0,0,AC31/AC7) -> 0 | AD32: =+IF(AD7=0,0,AD31/AD7) -> 0 | AE32: =+IF(AE7=0,0,AE31/AE7) -> 0 | AF32: =+IF(AF7=0,0,AF31/AF7) -> 0 | AH32: 0
B34: Margen Absoluto | C34: S/. | E34: =+E7-E15+E29 -> #REF! | G34: =+G7-G15+G29 -> #REF! | H34: =+H7-H15+H29 -> #REF! | J34: =+J7-J15+J29 -> #REF! | K34: =+K7-K15 -> #REF! | L34: =+L7-L15 -> 0 | N34: =+N7-N15+N29 -> 0 | O34: =+O7-O15+O29 -> 0 | P34: =+P7-P15+P29 -> 0 | Q34: =+Q7-Q15+Q29 -> 0 | R34: =+R7-R15+R29 -> 0 | S34: =+S7-S15+S29 -> 0 | U34: =+U7-U15+U29 -> 0 | V34: =+V7-V15+V29 -> 0 | W34: =+W7-W15+W29 -> 0 | Y34: =+Y7-Y15+Y29 -> 1511228 | Z34: =+Z7-Z15+Z29 -> #REF! | AB34: =+AB7-AB15+AB29 -> 0 | AC34: =+AC7-AC15+AC29 -> #REF! | AD34: =+AD7-AD15+AD29 -> #REF! | AE34: =+AE7-AE15+AE29 -> #REF! | AF34: =+AF7-AF15+AF29 -> #REF! | AH34: 0
C35: % | E35: =+IF(E9=0,0,E34/E9) -> #REF! | G35: =+IF(G9=0,0,G34/G9) -> 0 | H35: =+IF(H9=0,0,H34/H9) -> 0 | J35: =+IF(J7=0,0,J34/J7) -> 0 | K35: =+IF(K7=0,0,K34/K7) -> 0 | L35: =+IF(L7=0,0,L34/L7) -> 0 | N35: =+IF(N7=0,0,N34/N7) -> 0 | O35: =+IF(O7=0,0,O34/O7) -> 0 | P35: =+IF(P7=0,0,P34/P7) -> 0 | Q35: =+IF(Q7=0,0,Q34/Q7) -> 0 | R35: =+IF(R7=0,0,R34/R7) -> 0 | S35: =+IF(S7=0,0,S34/S7) -> 0 | U35: =+IF(U7=0,0,U34/U7) -> 0 | V35: =+IF(V7=0,0,V34/V7) -> 0 | W35: =+IF(W7=0,0,W34/W7) -> 0 | Y35: =+IF(Y7=0,0,Y34/Y7) -> 1 | Z35: =+IF(Z7=0,0,Z34/Z7) -> 0 | AB35: =+IF(AB7=0,0,AB34/AB7) -> 0 | AC35: =+IF(AC7=0,0,AC34/AC7) -> 0 | AD35: =+IF(AD7=0,0,AD34/AD7) -> 0 | AE35: =+IF(AE7=0,0,AE34/AE7) -> 0 | AF35: =+IF(AF7=0,0,AF34/AF7) -> 0 | AH35: 0
AO36: AC A FEBRERO | AQ36: MARZO | AR36: ABRIL | AS36: TOTAL
C37: =+#REF!*1.18 -> #REF! | Y37: =+Y35-CONSOLIDADO!W34 -> #REF! | Z37: =+Z35-CONSOLIDADO!W34 -> #REF! | AN37: AHORRO EN IIEE | AO37: =+#REF! -> #REF! | AQ37: =+#REF! -> #REF! | AR37: =+#REF! -> #REF! | AS37: =+AO37+AQ37+AR37 -> #REF!
AN38: AHORRO EN IISS | AO38: =+#REF! -> #REF! | AQ38: =+#REF! -> #REF! | AR38: =+#REF! -> #REF! | AS38: =+AO38+AQ38+AR38 -> #REF!
B39: COSTO APLICADO | K39: =+K7-K31 -> 0 | R39: =R7*(1-R32) -> 0 | Y39: =+Y31-CONSOLIDADO!W33 -> #REF! | Z39: =+Z31-CONSOLIDADO!W33 -> #REF!
B41: RESULTADO PENDIENTE | K41: =K15-K39 -> #REF! | R41: =+R15-R39+K41 -> #REF!
B43: ACTIVOS | K43: ='ER Pendiente'!H40+'ER Pendiente'!H15 -> #REF!
B45: PROVISIONES | K45: =+'ER Pendiente'!I40+'ER Pendiente'!I22 -> 0
B47: DIFERENCIA DE MARGENES | K47: =+'DIRECTO '!K46+#REF! -> #REF!
B49: CONTINGENCIA | K49: =+K41-K43+K45 -> #REF!
C51: Mayor Margen +
C53: Menor Margen -
B56: MARGEN CONSORCIO (PONDERADO) | Z56: 11555 | AF56: 16571
B57: MARGEN GARANTIZADO | Z57: 10554 | AF57: 10554
...

Sheet Riesgos y Oport.
A1: MATRIZ DE RIESGOS Y OPORTUNIDADES
A3: Ítem | B3: Identificación | C3: ESPECIALIDAD | D3: Análisis | E3: Rubro | F3: Gravedad | G3: Monto S/. | H3: Amenazas | I3: Oportunidad | J3: Observaciones | K3: ESTATUS RO | L3: Responsable | M3: Soluciones
A4: 01 | B4: Debido a la modalidad del contrato (suma alzada): se tenga que ejecutar mayores prestaciones adicionales sin que necesariamente sean reconocidos por la Entidad. Mov. De Tierras | C4: MOV. DE TIERRAS | D4: Gestionar ante la Entidad adicionales y deductivos vinculantes, no obstante sean rechazados se deberá dejar antecedes para un posterior reconocimiento mediante la via que corresponda. | E4: METRADO | F4: MUY BAJA | H4: =+IF(G4>0,G4,0) -> 0 | J4: Costo por definir por especialista | K4: No Considerado en RO | L4: Obra | M4: Elaboración del presupuesto compromiso con metrados reales lo que permitirá determinar la brecha entre lo considerado en el Expediente Técnico y lo realmente a ejecutar. | AE4: ALTA
A5: 02 | B5: Debido a la modalidad del contrato (suma alzada): se tenga que ejecutar mayores prestaciones adicionales sin que necesariamente sean reconocidos por la Entidad. Estructuras | C5: ESTRUCTURAS | D5: Gestionar ante la Entidad adicionales y deductivos vinculantes, no obstante sean rechazados se deberá dejar antecedes para un posterior reconocimiento mediante la via que corresponda. | E5: METRADO | F5: MUY BAJA | H5: =+IF(G5>0,G5,0) -> 0 | J5: Costo por definir por especialista | K5: No Considerado en RO | L5: Obra | M5: Elaboración del presupuesto compromiso con metrados reales lo que permitirá determinar la brecha entre lo considerado en el Expediente Técnico y lo realmente a ejecutar. | AE5: ALTA
A6: 03 | B6: Costos incurridos durante el EEN y Mayores Gastos Generales de las Ampliaciones de Plazo 1 y 2, no sean reconocidos en su totalidad por la Entidad. | C6: GG | D6: Pasos a seguir ante la Entidad: Comunicación, Conciliación, y finalmente Arbitrar.. Entidad ha aprobado un monto de S/.63'268.96 | E6: PLAZO | F6: ALTA | K6: Costo Considerado en RO | L6: Área legal | M6: Se solicita apoyo al área legal | AE6: MUY BAJA
A7: 04 | B7: Costos incurridos durante el EEN y Mayores Gastos Generales de las Ampliaciones de Plazo 3 Parte I | C7: GG | D7: Entidad ha aprobado 10 días. Sin embargo son 23 días . De estos no se está reconociendo ningun costo asociado. Costo ya incurrido. | E7: PLAZO | F7: MODERADA | G7: =21000*10 -> 210000 | I7: =+IF(G7>0,G7,0) -> 210000 | K7: Costo Considerado en RO | L7: Área legal | M7: Se debe aplicar la ley de contrataciones del estado.
A8: 05 | B8: Costos incurridos durante el EEN y Mayores Gastos Generales de las Ampliaciones de Plazo 3 Parte II | C8: GG | D8: Costo y plazo de 13 días aun no aprobados pero si incurridos en costo. | E8: PLAZO | F8: ALTA | G8: =21000*13 -> 273000 | I8: =+IF(G8>0,G8,0) -> 273000 | K8: Costo Considerado en RO | L8: Área legal | M8: Se debe verificar si es posible una AP N°04 y una vez reconocido dicho plazo, se debe aplicar la ley de contrataciones del Estado.
A9: 06 | B9: Costos incurrido en el periodo de Estado de Emergencia. Se ha Presentado un monto de reconocimiento a la entidad de: 1'783'448.06 Inc. IGV | C9: GG | D9: Entidad sólo ha reconocido S/. 40'675.76k. | E9: PLAZO | F9: ALTA | K9: Costo Considerado en RO | L9: Área legal | M9: Se solicita apoyo al área legal
A10: 07 | B10: Adecuaciones | C10: GG | D10: Adecuaciones de instalaciones de obra para reinicio de obra. | E10: PANDEMIA | F10: ALTA | G10: =+RG!Y13 -> 1511228 | I10: =+G10 -> 1511228 | K10: Costo Considerado en RO | L10: Área legal | M10: Se solicita apoyo al área legal
A11: 08 | B11: Removilización | C11: GG | D11: Entidad sólo ha reconocido S/. 18'967.36 | E11: PANDEMIA | F11: ALTA | G11: =212950.08/1.18 -> 180466.17 | I11: =+G11 -> 180466.17 | K11: Costo Considerado en RO | L11: Área legal | M11: Se solicita apoyo al área legal
A12: 09 | B12: Costos de reconocimiento de Plan Sanitario Covid | C12: GG | D12: Se presentan todos los costos asociados a gastos como alojamiento, alimentación, exámenes médicos, pruebas, Costo SB de Mano de Obra. | E12: PANDEMIA | F12: ALTA | K12: Costo Considerado en RO | L12: Área legal | M12: Coordinar un costo reembolsable con la entidad (Tiempo y Material ) Presentar a tiempo los costos asociados al Plan Sanitario Mensualmente.
A13: 10 | B13: Costos de baja de rendimiento, debido a afectación de personal (MO directa) Covid. | C13: OBRA | D13: Bajas de personal fortuitos que disminuyen rendimientos de manera fortuita. | E13: PANDEMIA | F13: MODERADA | H13: =+IF(G13>0,G13,0) -> 0 | J13: Costo por definir | K13: No Considerado en RO | L13: Obra | M13: Implementación de medidas consignadas en el marco legal dado por el Gobierno Central ( 005). Obra planifica tener una cartera de personal listo para ingreso.
A14: 11 | B14: Rellenos: Cambio de especificación de material | C14: MOV. DE TIERRAS | D14: Las canteras que se dieron como punto de extracción en proceso de licitación no tienen el material adecuado. Por lo que se debió traer el material desde otros destinos | E14: ALCANCE | F14: MODERADA | G14: 4453323.8 | H14: =-IF(G14>0,G14,0) -> -4453323.8 | I14: =-H14*0.1 -> 445332.38 | J14: Costo de SC si CSZ asume costo de trabajos. Monto de oportunidad por utilidad de adjudicación | K14: No Considerado en RO | L14: Area Legal | M14: Apoyo en la insisitencia de la aprobación del adicional
A15: 12 | B15: Paralizaciones varias,: gremios sindicales, paro de transportistas, etc. | C15: GG | D15: Costos Stand by asociados a paralizaciones ( provisiona 10 días ) | E15: EXTERNO | F15: MUY BAJA | G15: =-21000*10 -> -210000 | H15: =-21000*10 -> -210000 | K15: No Considerado en RO | L15: Externo | M15: Se realizará una contingencia ante estos eventos días antes. Envío de comunicación ante la entidad comunicando evento.
A16: 13 | B16: Rotación de Encofrados. | C16: ESTRUCTURAS | D16: Oposición de la Supervisión al desencofrado de losas a los 7 días luego de haber alcanzado la resistencia indicada(70%) El criterio de supervisión es desencofrar a mayor tiempo. Por lo que se requeriría mayor equipamiento. Generandose una desviación a lo inicialmente planificado. | E16: SUPERVISION | F16: MODERADA | G16: 1000000 | H16: =-IF(G16>0,G16,0) -> -1000000 | J16: Se está considerando el precio de metrado de encofrado.de acuerdo al cálculo de AC y JZ | K16: No Considerado en RO | L16: Obra | M16: Envio de Informe a la entidad, considerando las consideraciones técnicas y la muestraa de prueba empírica in situ que demuestran al factibilidad de este procedimiento.
A17: 14 | B17: Muros de Contención, Sardineles, Refuerzo en Pavimento Rígido incluye el relleno con Material de Préstamo | C17: ESTRUCTURAS | D17: De no tener respuesta, el CSZ deberá asumir el costo de este trabajo para no impactar en el cronograma. | E17: ALCANCE | F17: ALTA | G17: 2358836.1 | H17: =-IF(G17>0,G17,0) -> -2358836.1 | I17: =-H17*0.1 -> 235883.61 | J17: Considerar que la incidencia de GG en obra es 300k mensuales | K17: No Considerado en RO | L17: Area Legal | M17: Insistencia a nivel de alta dirección para lograr la aprobación.
A18: 15 | B18: Mejoramiento de Suelo en la Proyección de la Cimentación de los Muros de Contención Plataformas 3 y 4 ( Micropilotes) | C18: ESTRUCTURAS | D18: La supervision brindo una opinión favorable para el mejoramiento co micropilotes, en la cimentación de la PT03. Quedando pendiente la rpta de la Entidad. La denegación de este adicional implicará la imposibilidad de ejecutar el edificio (J, I1, I2 ) de la PT03 | E18: SUPERVISION | F18: MODERADA | G18: =141000*3.65 -> 514650 | H18: =-IF(G18>0,G18,0) -> -514650 | I18: =-H18*0.04 -> 20586 | J18: Costo de SC si CSZ asume costo de trabajos. Monto de oportunidad por utilidad de adjudicación | K18: No Considerado en RO | L18: Obra
A19: 16 | B19: Sobre costo de Agregados ( Arquitectura) | C19: ESTRUCTURAS | D19: El expediente técnico consideró como cantera de agregados, a una que se encontraba dentro de la ciudad de Huancavelica. (terreno donde se ubica una chancadora ) cuya producción co cubre la demanda requerida por la obra. Como consecuencia de ellos, se requiere el suministro de material de zonas fuera del área de influencia. | E19: ALCANCE | F19: MUY BAJA | G19: =914918*0.2 -> 182983.6 | H19: =-IF(G19>0,G19,0) -> -182983.6 | J19: Suministro de agregados en acabados húmedos, podría ser un 20% al estimado inciialmente debido a la lejanía de las canteras | K19: No Considerado en RO | L19: Obra | M19: Encontrar proveedores con lleguen al costo considerando viaje puesto en obra.
A20: 17 | B20: Conflicto de zonificación entre Casa de Fuerza Vs. Resonancia Magnetica | C20: GG | D20: De acuerdo a los especialistas de CSZ, la casa de Fuerza debe reubicarse. Ya que esta no se podría reubicar al costado del cuarto de Resonancia Magnética. Este hecho podría ser observado por el usuario final. | E20: ENTIDAD | F20: MUY BAJA | G20: 0 | H20: =+IF(G20>0,G20,0) -> 0 | J20: De ratificarse la entidad en continuar con la ubicación.. CSZ procederá con lo contractual. | K20: No Considerado en RO | L20: Área legal | M20: Envio de cartas, de advertencias y desvinculación de responsabilidad. Y Reportes en cuaderno de Obra
G21: =SUM(G4:G20) -> 10474488 | H21: =SUM(H4:H20) -> -8719793.5 | I21: =SUM(I4:I20) -> 2876496.1
B28: Etiquetas de fila | C28: Suma de Amenazas | D28: Suma de Oportunidad
B29: METRADO | C29: 0
B30: PANDEMIA | C30: 0 | D30: 1958414.8
B31: PLAZO | D31: 3779808.1
B32: ALCANCE | C32: -5633302.8 | D32: 535031.92
B33: EXTERNO | C33: -210000
B34: SUPERVISION | C34: -1514650 | D34: 20586
B35: CONTRATO | C35: 0
B36: ENTIDAD | C36: -1087010.2
B37: INGENIERIA | C37: -3582801.2 | D37: 0
B38: Total general | C38: -12027764 | D38: 6293840.8

Sheet C+AD
B1: =CONCATENATE(B3," - ",B4," - ",B5," - ",B6) -> I.E.N 1182 - - EL BOSQUE - CERCO + INGRESOS Y CASETAS - CONSOLIDADO
N2: =+YEAR(N5) -> 2019 | O2: =+YEAR(O5) -> 2019 | P2: =+YEAR(P5) -> 2019 | Q2: =+YEAR(Q5) -> 2019 | R2: =+YEAR(R5) -> 2019 | S2: =S5 -> 2024
B3: I.E.N 1182 | E3: ACUMULADO | G3: =+RG!G3 -> MES ENERO DEL 2025 | J3: ACUMULADO DEL 2024 | K3: ACUMULADO DE OBRA | L3: SALDO DE OBRA | N3: PROYECCIÓN | U3: AÑOS SIGUIENTES | X3: TOTAL DE OBRA | AD3: Acum. del Ej. | AJ3: TOTAL | AK3: MES DEL INFORME | AL3: 43647 | AM3: 43678 | AN3: 43709 | AO3: 43739 | AP3: 43770 | AQ3: 43800 | AR3: 43831 | AS3: 43862 | AT3: 43891 | AU3: 43922 | AV3: 43952 | AW3: 43983 | AX3: 44013 | AY3: 44044 | AZ3: 44075 | BA3: 44105 | BB3: 44136 | BC3: 44166 | BD3: =BC3+31 -> 44197 | BE3: =BD3+31 -> 44228 | BF3: =BE3+31 -> 44259 | BG3: =BF3+31 -> 44290 | BH3: =BG3+31 -> 44321 | BI3: =BH3+31 -> 44352 | BJ3: =BI3+31 -> 44383 | BK3: =BJ3+31 -> 44414 | ... CA3: =BZ3+31 -> 44910
N4: 1 | O4: =+N4+1 -> 2 | P4: =+O4+1 -> 3 | Q4: =+P4+1 -> 4 | R4: =+Q4+1 -> 5 | S4: Saldo del Ejercicio
B5: EL BOSQUE - CERCO + INGRESOS Y CASETAS | E5: Años Anteriores | G5: Previsto | H5: Real | N5: 43648 | O5: =+N5+31 -> 43679 | P5: =+O5+31 -> 43710 | Q5: =+P5+31 -> 43741 | R5: =+Q5+31 -> 43772 | S5: 2024 | U5: 2024 | W5: MEJOR ESCENARIO | X5: Actual | Y5: Anterior | Z5: Meta | AA5: Presupuesto Interno | AB5: Presupuesto | AD5: Anterior
B6: CONSOLIDADO
B7: Venta Total Producida | E7: =+E9 -> #REF! | G7: =+G9 -> #REF! | H7: =+H9 -> #REF! | J7: =+J9 -> #REF! | K7: =+K9 -> #REF! | L7: =+L9 -> #REF! | N7: =+N9 -> #REF! | O7: =+O9 -> #REF! | P7: =+P9 -> #REF! | Q7: =+Q9 -> #REF! | R7: =+R9 -> #REF! | S7: =+S9 -> 0 | U7: =+U9 -> 0 | W7: =+W9 -> #REF! | X7: =+X9 -> #REF! | Y7: =+Y9 -> #REF! | Z7: =+Z9 -> #REF! | AA7: =+AA9 -> #REF! | AB7: =+AB9 -> #REF! | AD7: =+AD9 -> #REF! | AF7: =+AB7-X7 -> #REF! | AJ7: =+AJ9 -> #REF! | AK7: =+AK9 -> #REF! | AL7: =+AL9 -> #REF! | AM7: =+AM9 -> #REF! | AN7: =+AN9 -> #REF! | AO7: =+AO9 -> #REF! | AP7: =+AP9 -> #REF! | AQ7: =+AQ9 -> #REF! | ... CA7: =+CA9 -> #REF!
B9: Venta | E9: =+SUM(E11:E14) -> #REF! | G9: =+SUM(G11:G14) -> #REF! | H9: =+SUM(H11:H14) -> #REF! | J9: =+SUM(J11:J14) -> #REF! | K9: =+SUM(K11:K14) -> #REF! | L9: =+SUM(L11:L14) -> #REF! | N9: =+SUM(N11:N14) -> #REF! | O9: =+SUM(O11:O14) -> #REF! | P9: =+SUM(P11:P14) -> #REF! | Q9: =+SUM(Q11:Q14) -> #REF! | R9: =+SUM(R11:R14) -> #REF! | S9: =+SUM(S11:S14) -> 0 | U9: =+SUM(U11:U14) -> 0 | W9: =+SUM(W11:W14) -> #REF! | X9: =+SUM(X11:X14) -> #REF! | Y9: =+SUM(Y11:Y14) -> #REF! | Z9: =+SUM(Z11:Z14) -> #REF! | AA9: =+SUM(AA11:AA14) -> #REF! | AB9: =+SUM(AB11:AB14) -> #REF! | AD9: =+SUM(AD11:AD14) -> #REF! | AF9: =+AB9-X9 -> #REF! | AG9: =+X9-Y9 -> #REF! | AJ9: =+SUM(AJ11:AJ14) -> #REF! | AK9: =+SUM(AK11:AK14) -> #REF! | AL9: =+SUM(AL11:AL14) -> #REF! | AM9: =+SUM(AM11:AM14) -> #REF! | AN9: =+SUM(AN11:AN14) -> #REF! | AO9: =+SUM(AO11:AO14) -> #REF! | AP9: =+SUM(AP11:AP14) -> #REF! | AQ9: =+SUM(AQ11:AQ14) -> #REF! | ... CA9: =+SUM(CA11:CA14) -> #REF!
B11: Valorización: Venta Directa - Contrato Principal | E11: =+'DIRECTO '!E11+#REF! -> #REF! | G11: =+'DIRECTO '!G11+#REF! -> #REF! | H11: =+'DIRECTO '!H11+#REF! -> #REF! | J11: =+'DIRECTO '!J11+#REF! -> #REF! | K11: =+'DIRECTO '!K11+#REF! -> #REF! | L11: =+SUM(N11:R11) -> #REF! | N11: =+'DIRECTO '!N11+#REF! -> #REF! | O11: =+'DIRECTO '!O11+#REF! -> #REF! | P11: =+'DIRECTO '!P11+#REF! -> #REF! | Q11: =+'DIRECTO '!Q11+#REF! -> #REF! | R11: =+'DIRECTO '!R11+#REF! -> #REF! | S11: =+SUMIFS(N11:R11,N$2:R$2,$S$5) -> 0 | U11: =+SUMIFS(N11:S11,N$2:S$2,$U$5) -> 0 | W11: =+X11 -> #REF! | X11: =+K11+L11 -> #REF! | Y11: =+'DIRECTO '!Z11+#REF! -> #REF! | Z11: =+'DIRECTO '!AA11+#REF! -> #REF! | AA11: =+'DIRECTO '!AB11+#REF! -> #REF! | AB11: =+'DIRECTO '!AC11+#REF! -> #REF! | AD11: =+'DIRECTO '!AE11+#REF! -> #REF! | AF11: =+AB11-X11 -> #REF! | AG11: =+X11-Y11 -> #REF! | AJ11: =SUM(AK11:CA11) -> #REF! | AK11: =+'DIRECTO '!AK11+#REF! -> #REF! | AL11: =+'DIRECTO '!AM11+#REF! -> #REF! | AM11: =+'DIRECTO '!AN11+#REF! -> #REF! | AN11: =+'DIRECTO '!AO11+#REF! -> #REF! | AO11: =+'DIRECTO '!AP11+#REF! -> #REF! | AP11: =+'DIRECTO '!AQ11+#REF! -> #REF! | AQ11: =+'DIRECTO '!#REF!+#REF! -> #REF! | AR11: =+'DIRECTO '!#REF!+#REF! -> #REF! | AS11: =+'DIRECTO '!#REF!+#REF! -> #REF! | AT11: =+'DIRECTO '!#REF!+#REF! -> #REF! | AU11: =+'DIRECTO '!#REF!+#REF! -> #REF! | AV11: =+'DIRECTO '!#REF!+#REF! -> #REF! | AW11: =+'DIRECTO '!#REF!+#REF! -> #REF! | AX11: =+'DIRECTO '!#REF!+#REF! -> #REF! | ... CA11: =+'DIRECTO '!#REF!+#REF! -> #REF!
B12: Valorización: Venta Indirecta - Contrato Principal | E12: =+'DIRECTO '!E12+#REF! -> #REF! | G12: =+'DIRECTO '!G12+#REF! -> #REF! | H12: =+'DIRECTO '!H12+#REF! -> #REF! | J12: =+'DIRECTO '!J12+#REF! -> #REF! | K12: =+'DIRECTO '!K12+#REF! -> #REF! | L12: =+SUM(N12:R12) -> #REF! | N12: =+'DIRECTO '!N12+#REF! -> #REF! | O12: =+'DIRECTO '!O12+#REF! -> #REF! | P12: =+'DIRECTO '!P12+#REF! -> #REF! | Q12: =+'DIRECTO '!Q12+#REF! -> #REF! | R12: =+'DIRECTO '!R12+#REF! -> #REF! | S12: =+SUMIFS(N12:R12,N$2:R$2,$S$5) -> 0 | U12: =+SUMIFS(N12:S12,N$2:S$2,$U$5) -> 0 | W12: =+X12 -> #REF! | X12: =+K12+L12 -> #REF! | Y12: =+'DIRECTO '!Z12+#REF! -> #REF! | Z12: =+'DIRECTO '!AA12+#REF! -> #REF! | AA12: =+'DIRECTO '!AB12+#REF! -> #REF! | AB12: =+'DIRECTO '!AC12+#REF! -> #REF! | AD12: =+'DIRECTO '!AE12+#REF! -> #REF! | AF12: =+AB12-X12 -> #REF! | AG12: =+X12-Y12 -> #REF! | AJ12: =SUM(AK12:CA12) -> #REF! | AK12: =+'DIRECTO '!AK12+#REF! -> #REF! | AL12: =+'DIRECTO '!AM12+#REF! -> #REF! | AM12: =+'DIRECTO '!AN12+#REF! -> #REF! | AN12: =+'DIRECTO '!AO12+#REF! -> #REF! | AO12: =+'DIRECTO '!AP12+#REF! -> #REF! | AP12: =+'DIRECTO '!AQ12+#REF! -> #REF! | AQ12: =+'DIRECTO '!#REF!+#REF! -> #REF! | AR12: =+'DIRECTO '!#REF!+#REF! -> #REF! | AS12: =+'DIRECTO '!#REF!+#REF! -> #REF! | AT12: =+'DIRECTO '!#REF!+#REF! -> #REF! | AU12: =+'DIRECTO '!#REF!+#REF! -> #REF! | AV12: =+'DIRECTO '!#REF!+#REF! -> #REF! | AW12: =+'DIRECTO '!#REF!+#REF! -> #REF! | AX12: =+'DIRECTO '!#REF!+#REF! -> #REF! | ... CA12: =+'DIRECTO '!#REF!+#REF! -> #REF!
B13: Otros: | E13: =+'DIRECTO '!#REF!+#REF! -> #REF! | G13: =+'DIRECTO '!#REF!+#REF! -> #REF! | H13: =+'DIRECTO '!#REF!+#REF! -> #REF! | J13: =+'DIRECTO '!#REF!+#REF! -> #REF! | K13: =+'DIRECTO '!#REF!+#REF! -> #REF! | L13: =+SUM(N13:R13) -> #REF! | N13: =+'DIRECTO '!#REF!+#REF! -> #REF! | O13: =+'DIRECTO '!#REF!+#REF! -> #REF! | P13: =+'DIRECTO '!#REF!+#REF! -> #REF! | Q13: =+'DIRECTO '!#REF!+#REF! -> #REF! | R13: =+'DIRECTO '!#REF!+#REF! -> #REF! | S13: =+SUMIFS(N13:R13,N$2:R$2,$S$5) -> 0 | U13: =+SUMIFS(N13:S13,N$2:S$2,$U$5) -> 0 | W13: =+X13 -> 0 | X13: 0 | Y13: =+'DIRECTO '!#REF!+#REF! -> #REF! | Z13: =+'DIRECTO '!#REF!+#REF! -> #REF! | AA13: =+'DIRECTO '!#REF!+#REF! -> #REF! | AB13: =+'DIRECTO '!#REF!+#REF! -> #REF! | AD13: =+'DIRECTO '!#REF!+#REF! -> #REF! | AF13: =+AB13-X13 -> #REF! | AG13: =+X13-Y13 -> #REF! | AJ13: =SUM(AK13:CA13) -> #REF! | AK13: =+'DIRECTO '!#REF!+#REF! -> #REF! | AL13: =+'DIRECTO '!#REF!+#REF! -> #REF! | AM13: =+'DIRECTO '!#REF!+#REF! -> #REF! | AN13: =+'DIRECTO '!#REF!+#REF! -> #REF! | AO13: =+'DIRECTO '!#REF!+#REF! -> #REF! | AP13: =+'DIRECTO '!#REF!+#REF! -> #REF! | AQ13: =+'DIRECTO '!#REF!+#REF! -> #REF! | AR13: =+'DIRECTO '!#REF!+#REF! -> #REF! | ... CA13: =+'DIRECTO '!#REF!+#REF! -> #REF!
B14: Ventas de Activos al final de obra(camioneta + minicargador +eq. Electronicos+eq. topografico) | E14: =+'DIRECTO '!E13+#REF! -> #REF! | G14: =+'DIRECTO '!G13+#REF! -> #REF! | H14: =+'DIRECTO '!H13+#REF! -> #REF! | J14: =+'DIRECTO '!J13+#REF! -> #REF! | K14: =+'DIRECTO '!K13+#REF! -> #REF! | L14: =+SUM(N14:R14) -> #REF! | N14: =+'DIRECTO '!N13+#REF! -> #REF! | O14: =+'DIRECTO '!O13+#REF! -> #REF! | P14: =+'DIRECTO '!P13+#REF! -> #REF! | Q14: =+'DIRECTO '!Q13+#REF! -> #REF! | R14: =+'DIRECTO '!R13+#REF! -> #REF! | S14: =+SUMIFS(N14:R14,N$2:R$2,$S$5) -> 0 | U14: =+SUMIFS(N14:S14,N$2:S$2,$U$5) -> 0 | W14: =+X14 -> #REF! | X14: =+CONSOLIDADO!#REF! -> #REF! | Y14: =+'DIRECTO '!Z13+#REF! -> #REF! | Z14: =+'DIRECTO '!AA13+#REF! -> #REF! | AA14: =+'DIRECTO '!AB13+#REF! -> #REF! | AB14: =+'DIRECTO '!AC13+#REF! -> #REF! | AD14: =+'DIRECTO '!AE13+#REF! -> #REF! | AF14: =+AB14-X14 -> #REF! | AG14: =+X14-Y14 -> #REF! | AJ14: =SUM(AK14:CA14) -> #REF! | AK14: =+'DIRECTO '!AK13+#REF! -> #REF! | AL14: =+'DIRECTO '!AM13+#REF! -> #REF! | AM14: =+'DIRECTO '!AN13+#REF! -> #REF! | AN14: =+'DIRECTO '!AO13+#REF! -> #REF! | AO14: =+'DIRECTO '!AP13+#REF! -> #REF! | AP14: =+'DIRECTO '!AQ13+#REF! -> #REF! | AQ14: =+'DIRECTO '!#REF!+#REF! -> #REF! | AR14: =+'DIRECTO '!#REF!+#REF! -> #REF! | AS14: =+'DIRECTO '!#REF!+#REF! -> #REF! | AT14: =+'DIRECTO '!#REF!+#REF! -> #REF! | AU14: =+'DIRECTO '!#REF!+#REF! -> #REF! | AV14: =+'DIRECTO '!#REF!+#REF! -> #REF! | AW14: =+'DIRECTO '!#REF!+#REF! -> #REF! | AX14: =+'DIRECTO '!#REF!+#REF! -> #REF! | ... CA14: =+'DIRECTO '!#REF!+#REF! -> #REF!
B16: Costo Total | E16: =+SUM(E18:E27)+E29 -> #REF! | G16: =+SUM(G18:G27,G29) -> #REF! | H16: =SUM(H18:H27,H29) -> #REF! | J16: =+SUM(J18:J27,J29) -> #REF! | K16: =+SUM(K18:K27,K29) -> #REF! | L16: =+SUM(L18:L27,L29) -> #REF! | N16: =+SUM(N18:N27,N29) -> #REF! | O16: =+SUM(O18:O27,O29) -> #REF! | P16: =+SUM(P18:P27,P29) -> #REF! | Q16: =+SUM(Q18:Q27,Q29) -> #REF! | R16: =+SUM(R18:R27,R29) -> #REF! | S16: =+SUM(S18:S27,S29) -> 0 | U16: =+SUM(U18:U27,U29) -> 0 | W16: =+SUM(W18:W27,W29) -> #REF! | X16: =+SUM(X18:X27,X29) -> #REF! | Y16: =+SUM(Y18:Y27,Y29) -> #REF! | Z16: =+SUM(Z18:Z27,Z29) -> #REF! | AA16: =+SUM(AA18:AA27,AA29) -> #REF! | AB16: =+SUM(AB18:AB27,AB29) -> #REF! | AD16: =+SUM(AD18:AD27,AD29) -> #REF! | AF16: =+AB16-X16 -> #REF! | AJ16: =+SUM(AJ18:AJ27,AJ29) -> #REF! | AK16: =+SUM(AK18:AK27,AK29) -> #REF! | AL16: =+SUM(AL18:AL27,AL29) -> #REF! | AM16: =+SUM(AM18:AM27,AM29) -> #REF! | AN16: =+SUM(AN18:AN27,AN29) -> #REF! | AO16: =+SUM(AO18:AO27,AO29) -> #REF! | AP16: =+SUM(AP18:AP27,AP29) -> #REF! | AQ16: =+SUM(AQ18:AQ27,AQ29) -> #REF! | ... CA16: =+SUM(CA18:CA27,CA29) -> #REF! | CD16: 525387.51
B18: Materiales | E18: =+'DIRECTO '!E17+#REF! -> #REF! | G18: =+'DIRECTO '!G17+#REF! -> #REF! | H18: =+'DIRECTO '!H17+#REF! -> #REF! | J18: =+'DIRECTO '!J17+#REF! -> #REF! | K18: =+'DIRECTO '!K17+#REF! -> #REF! | L18: =+SUM(N18:R18) -> #REF! | N18: =+'DIRECTO '!N17+#REF! -> #REF! | O18: =+'DIRECTO '!O17+#REF! -> #REF! | P18: =+'DIRECTO '!P17+#REF! -> #REF! | Q18: =+'DIRECTO '!Q17+#REF! -> #REF! | R18: =+'DIRECTO '!R17+#REF! -> #REF! | S18: =+SUMIFS(N18:R18,N$2:R$2,$S$5) -> 0 | U18: =+SUMIFS(N18:S18,N$2:S$2,$U$5) -> 0 | W18: =+X18 -> #REF! | X18: =+K18+L18 -> #REF! | Y18: =+'DIRECTO '!Z17+#REF! -> #REF! | Z18: =+'DIRECTO '!AA17+#REF! -> #REF! | AA18: =+'DIRECTO '!AB17+#REF! -> #REF! | AB18: =+'DIRECTO '!AC17+#REF! -> #REF! | AD18: =+'DIRECTO '!AE17+#REF! -> #REF! | AF18: =+AB18-X18 -> #REF! | AG18: =Mat!Y26 -> 0 | AH18: =IF(ABS(X18-AG18)>1,"Revisar Rubros","OK") -> #REF! | AJ18: =SUM(AK18:CA18) -> #REF! | AK18: =+'DIRECTO '!AK17+#REF! -> #REF! | AL18: =+'DIRECTO '!AM17+#REF! -> #REF! | AM18: =+'DIRECTO '!AN17+#REF! -> #REF! | AN18: =+'DIRECTO '!AO17+#REF! -> #REF! | AO18: =+'DIRECTO '!AP17+#REF! -> #REF! | AP18: =+'DIRECTO '!AQ17+#REF! -> #REF! | AQ18: =+'DIRECTO '!#REF!+#REF! -> #REF! | AR18: =+'DIRECTO '!#REF!+#REF! -> #REF! | AS18: =+'DIRECTO '!#REF!+#REF! -> #REF! | AT18: =+'DIRECTO '!#REF!+#REF! -> #REF! | AU18: =+'DIRECTO '!#REF!+#REF! -> #REF! | AV18: =+'DIRECTO '!#REF!+#REF! -> #REF! | AW18: =+'DIRECTO '!#REF!+#REF! -> #REF! | AX18: =+'DIRECTO '!#REF!+#REF! -> #REF! | ... CA18: =+'DIRECTO '!#REF!+#REF! -> #REF!
B19: Mano de Obra | E19: =+'DIRECTO '!E18+#REF! -> #REF! | G19: =+'DIRECTO '!G18+#REF! -> #REF! | H19: =+'DIRECTO '!H18+#REF! -> #REF! | J19: =+'DIRECTO '!J18+#REF! -> #REF! | K19: =+'DIRECTO '!K18+#REF! -> #REF! | L19: =+SUM(N19:R19) -> #REF! | N19: =+'DIRECTO '!N18+#REF! -> #REF! | O19: =+'DIRECTO '!O18+#REF! -> #REF! | P19: =+'DIRECTO '!P18+#REF! -> #REF! | Q19: =+'DIRECTO '!Q18+#REF! -> #REF! | R19: =+'DIRECTO '!R18+#REF! -> #REF! | S19: =+SUMIFS(N19:R19,N$2:R$2,$S$5) -> 0 | U19: =+SUMIFS(N19:S19,N$2:S$2,$U$5) -> 0 | W19: =+X19 -> #REF! | X19: =+K19+L19 -> #REF! | Y19: =+'DIRECTO '!Z18+#REF! -> #REF! | Z19: =+'DIRECTO '!AA18+#REF! -> #REF! | AA19: =+'DIRECTO '!AB18+#REF! -> #REF! | AB19: =+'DIRECTO '!AC18+#REF! -> #REF! | AD19: =+'DIRECTO '!AE18+#REF! -> #REF! | AF19: =+AB19-X19 -> #REF! | AG19: =+MO!Y75 -> 0 | AH19: =IF(ABS(X19-AG19)>1,"Revisar Rubros","OK") -> #REF! | AJ19: =SUM(AK19:CA19) -> #REF! | AK19: =+'DIRECTO '!AK18+#REF! -> #REF! | AL19: =+'DIRECTO '!AM18+#REF! -> #REF! | AM19: =+'DIRECTO '!AN18+#REF! -> #REF! | AN19: =+'DIRECTO '!AO18+#REF! -> #REF! | AO19: =+'DIRECTO '!AP18+#REF! -> #REF! | AP19: =+'DIRECTO '!AQ18+#REF! -> #REF! | AQ19: =+'DIRECTO '!#REF!+#REF! -> #REF! | AR19: =+'DIRECTO '!#REF!+#REF! -> #REF! | AS19: =+'DIRECTO '!#REF!+#REF! -> #REF! | AT19: =+'DIRECTO '!#REF!+#REF! -> #REF! | AU19: =+'DIRECTO '!#REF!+#REF! -> #REF! | AV19: =+'DIRECTO '!#REF!+#REF! -> #REF! | AW19: =+'DIRECTO '!#REF!+#REF! -> #REF! | AX19: =+'DIRECTO '!#REF!+#REF! -> #REF! | ... CA19: =+'DIRECTO '!#REF!+#REF! -> #REF!
B20: Subcontratos de obra | E20: =+'DIRECTO '!E19+#REF! -> #REF! | G20: =+'DIRECTO '!G19+#REF! -> #REF! | H20: =+'DIRECTO '!H19+#REF! -> #REF! | J20: =+'DIRECTO '!J19+#REF! -> #REF! | K20: =+'DIRECTO '!K19+#REF! -> #REF! | L20: =+SUM(N20:R20) -> #REF! | N20: =+'DIRECTO '!N19+#REF! -> #REF! | O20: =+'DIRECTO '!O19+#REF! -> #REF! | P20: =+'DIRECTO '!P19+#REF! -> #REF! | Q20: =+'DIRECTO '!Q19+#REF! -> #REF! | R20: =+'DIRECTO '!R19+#REF! -> #REF! | S20: =+SUMIFS(N20:R20,N$2:R$2,$S$5) -> 0 | U20: =+SUMIFS(N20:S20,N$2:S$2,$U$5) -> 0 | W20: =+X20 -> #REF! | X20: =+K20+L20 -> #REF! | Y20: =+'DIRECTO '!Z19+#REF! -> #REF! | Z20: =+'DIRECTO '!AA19+#REF! -> #REF! | AA20: =+'DIRECTO '!AB19+#REF! -> #REF! | AB20: =+'DIRECTO '!AC19+#REF! -> #REF! | AD20: =+'DIRECTO '!AE19+#REF! -> #REF! | AF20: =+AB20-X20 -> #REF! | AG20: =+SC!#REF! -> #REF! | AH20: =IF(ABS(X20-AG20)>1,"Revisar Rubros","OK") -> #REF! | AJ20: =SUM(AK20:CA20) -> #REF! | AK20: =+'DIRECTO '!AK19+#REF! -> #REF! | AL20: =+'DIRECTO '!AM19+#REF! -> #REF! | AM20: =+'DIRECTO '!AN19+#REF! -> #REF! | AN20: =+'DIRECTO '!AO19+#REF! -> #REF! | AO20: =+'DIRECTO '!AP19+#REF! -> #REF! | AP20: =+'DIRECTO '!AQ19+#REF! -> #REF! | AQ20: =+'DIRECTO '!#REF!+#REF! -> #REF! | AR20: =+'DIRECTO '!#REF!+#REF! -> #REF! | AS20: =+'DIRECTO '!#REF!+#REF! -> #REF! | AT20: =+'DIRECTO '!#REF!+#REF! -> #REF! | AU20: =+'DIRECTO '!#REF!+#REF! -> #REF! | AV20: =+'DIRECTO '!#REF!+#REF! -> #REF! | AW20: =+'DIRECTO '!#REF!+#REF! -> #REF! | AX20: =+'DIRECTO '!#REF!+#REF! -> #REF! | ... CA20: =+'DIRECTO '!#REF!+#REF! -> #REF!
B21: Servicios Contratados | E21: =+'DIRECTO '!E20+#REF! -> #REF! | G21: =+'DIRECTO '!G20+#REF! -> #REF! | H21: =+'DIRECTO '!H20+#REF! -> #REF! | J21: =+'DIRECTO '!J20+#REF! -> #REF! | K21: =+'DIRECTO '!K20+#REF! -> #REF! | L21: =+SUM(N21:R21) -> #REF! | N21: =+'DIRECTO '!N20+#REF! -> #REF! | O21: =+'DIRECTO '!O20+#REF! -> #REF! | P21: =+'DIRECTO '!P20+#REF! -> #REF! | Q21: =+'DIRECTO '!Q20+#REF! -> #REF! | R21: =+'DIRECTO '!R20+#REF! -> #REF! | S21: =+SUMIFS(N21:R21,N$2:R$2,$S$5) -> 0 | U21: =+SUMIFS(N21:S21,N$2:S$2,$U$5) -> 0 | W21: =+X21 -> #REF! | X21: =+K21+L21 -> #REF! | Y21: =+'DIRECTO '!Z20+#REF! -> #REF! | Z21: =+'DIRECTO '!AA20+#REF! -> #REF! | AA21: =+'DIRECTO '!AB20+#REF! -> #REF! | AB21: =+'DIRECTO '!AC20+#REF! -> #REF! | AD21: =+'DIRECTO '!AE20+#REF! -> #REF! | AF21: =+AB21-X21 -> #REF! | AG21: =+SER!Y44 -> 22778.589 | AH21: =IF(ABS(X21-AG21)>1,"Revisar Rubros","OK") -> #REF! | AJ21: =SUM(AK21:CA21) -> #REF! | AK21: =+'DIRECTO '!AK20+#REF! -> #REF! | AL21: =+'DIRECTO '!AM20+#REF! -> #REF! | AM21: =+'DIRECTO '!AN20+#REF! -> #REF! | AN21: =+'DIRECTO '!AO20+#REF! -> #REF! | AO21: =+'DIRECTO '!AP20+#REF! -> #REF! | AP21: =+'DIRECTO '!AQ20+#REF! -> #REF! | AQ21: =+'DIRECTO '!#REF!+#REF! -> #REF! | AR21: =+'DIRECTO '!#REF!+#REF! -> #REF! | AS21: =+'DIRECTO '!#REF!+#REF! -> #REF! | AT21: =+'DIRECTO '!#REF!+#REF! -> #REF! | AU21: =+'DIRECTO '!#REF!+#REF! -> #REF! | AV21: =+'DIRECTO '!#REF!+#REF! -> #REF! | AW21: =+'DIRECTO '!#REF!+#REF! -> #REF! | AX21: =+'DIRECTO '!#REF!+#REF! -> #REF! | ... CA21: =+'DIRECTO '!#REF!+#REF! -> #REF! | CD21: =+X16-X26-X27 -> #REF!
B22: Equipos y Vehículos | E22: =+'DIRECTO '!E21+#REF! -> #REF! | G22: =+'DIRECTO '!G21+#REF! -> #REF! | H22: =+'DIRECTO '!H21+#REF! -> #REF! | J22: =+'DIRECTO '!J21+#REF! -> #REF! | K22: =+'DIRECTO '!K21+#REF! -> #REF! | L22: =+SUM(N22:R22) -> #REF! | N22: =+'DIRECTO '!N21+#REF! -> #REF! | O22: =+'DIRECTO '!O21+#REF! -> #REF! | P22: =+'DIRECTO '!P21+#REF! -> #REF! | Q22: =+'DIRECTO '!Q21+#REF! -> #REF! | R22: =+'DIRECTO '!R21+#REF! -> #REF! | S22: =+SUMIFS(N22:R22,N$2:R$2,$S$5) -> 0 | U22: =+SUMIFS(N22:S22,N$2:S$2,$U$5) -> 0 | W22: =+X22 -> #REF! | X22: =+K22+L22 -> #REF! | Y22: =+'DIRECTO '!Z21+#REF! -> #REF! | Z22: =+'DIRECTO '!AA21+#REF! -> #REF! | AA22: =+'DIRECTO '!AB21+#REF! -> #REF! | AB22: =+'DIRECTO '!AC21+#REF! -> #REF! | AD22: =+'DIRECTO '!AE21+#REF! -> #REF! | AF22: =+AB22-X22 -> #REF! | AH22: =IF(ABS(X22-AG22)>1,"Revisar Rubros","OK") -> #REF! | AJ22: =SUM(AK22:CA22) -> #REF! | AK22: =+'DIRECTO '!AK21+#REF! -> #REF! | AL22: =+'DIRECTO '!AM21+#REF! -> #REF! | AM22: =+'DIRECTO '!AN21+#REF! -> #REF! | AN22: =+'DIRECTO '!AO21+#REF! -> #REF! | AO22: =+'DIRECTO '!AP21+#REF! -> #REF! | AP22: =+'DIRECTO '!AQ21+#REF! -> #REF! | AQ22: =+'DIRECTO '!#REF!+#REF! -> #REF! | AR22: =+'DIRECTO '!#REF!+#REF! -> #REF! | AS22: =+'DIRECTO '!#REF!+#REF! -> #REF! | AT22: =+'DIRECTO '!#REF!+#REF! -> #REF! | AU22: =+'DIRECTO '!#REF!+#REF! -> #REF! | AV22: =+'DIRECTO '!#REF!+#REF! -> #REF! | AW22: =+'DIRECTO '!#REF!+#REF! -> #REF! | AX22: =+'DIRECTO '!#REF!+#REF! -> #REF! | ... CA22: =+'DIRECTO '!#REF!+#REF! -> #REF! | CD22: 20864058
C23: Propios | E23: =+'DIRECTO '!E22+#REF! -> #REF! | G23: =+'DIRECTO '!G22+#REF! -> #REF! | H23: =+'DIRECTO '!H22+#REF! -> #REF! | J23: =+'DIRECTO '!J22+#REF! -> #REF! | K23: =+'DIRECTO '!K22+#REF! -> #REF! | L23: =+SUM(N23:R23) -> #REF! | N23: =+'DIRECTO '!N22+#REF! -> #REF! | O23: =+'DIRECTO '!O22+#REF! -> #REF! | P23: =+'DIRECTO '!P22+#REF! -> #REF! | Q23: =+'DIRECTO '!Q22+#REF! -> #REF! | R23: =+'DIRECTO '!R22+#REF! -> #REF! | S23: =+SUMIFS(N23:R23,N$2:R$2,$S$5) -> 0 | U23: =+SUMIFS(N23:S23,N$2:S$2,$U$5) -> 0 | W23: =+X23 -> #REF! | X23: =+K23+L23 -> #REF! | Y23: =+'DIRECTO '!Z22+#REF! -> #REF! | Z23: =+'DIRECTO '!AA22+#REF! -> #REF! | AA23: =+'DIRECTO '!AB22+#REF! -> #REF! | AB23: =+'DIRECTO '!AC22+#REF! -> #REF! | AD23: =+'DIRECTO '!AE22+#REF! -> #REF! | AF23: =+AB23-X23 -> #REF! | AG23: =+Eq!Y56 -> 0 | AH23: =IF(ABS(X23-AG23)>1,"Revisar Rubros","OK") -> #REF! | AJ23: =SUM(AK23:CA23) -> #REF! | AK23: =+'DIRECTO '!AK22+#REF! -> #REF! | AL23: =+'DIRECTO '!AM22+#REF! -> #REF! | AM23: =+'DIRECTO '!AN22+#REF! -> #REF! | AN23: =+'DIRECTO '!AO22+#REF! -> #REF! | AO23: =+'DIRECTO '!AP22+#REF! -> #REF! | AP23: =+'DIRECTO '!AQ22+#REF! -> #REF! | AQ23: =+'DIRECTO '!#REF!+#REF! -> #REF! | AR23: =+'DIRECTO '!#REF!+#REF! -> #REF! | AS23: =+'DIRECTO '!#REF!+#REF! -> #REF! | AT23: =+'DIRECTO '!#REF!+#REF! -> #REF! | AU23: =+'DIRECTO '!#REF!+#REF! -> #REF! | AV23: =+'DIRECTO '!#REF!+#REF! -> #REF! | AW23: =+'DIRECTO '!#REF!+#REF! -> #REF! | AX23: =+'DIRECTO '!#REF!+#REF! -> #REF! | ... CA23: =+'DIRECTO '!#REF!+#REF! -> #REF!
C24: Terceros | E24: =+'DIRECTO '!E23+#REF! -> #REF! | G24: =+'DIRECTO '!G23+#REF! -> #REF! | H24: =+'DIRECTO '!H23+#REF! -> #REF! | J24: =+'DIRECTO '!J23+#REF! -> #REF! | K24: =+'DIRECTO '!K23+#REF! -> #REF! | L24: =+SUM(N24:R24) -> #REF! | N24: =+'DIRECTO '!N23+#REF! -> #REF! | O24: =+'DIRECTO '!O23+#REF! -> #REF! | P24: =+'DIRECTO '!P23+#REF! -> #REF! | Q24: =+'DIRECTO '!Q23+#REF! -> #REF! | R24: =+'DIRECTO '!R23+#REF! -> #REF! | S24: =+SUMIFS(N24:R24,N$2:R$2,$S$5) -> 0 | U24: =+SUMIFS(N24:S24,N$2:S$2,$U$5) -> 0 | W24: =+X24 -> #REF! | X24: =+K24+L24 -> #REF! | Y24: =+'DIRECTO '!Z23+#REF! -> #REF! | Z24: =+'DIRECTO '!AA23+#REF! -> #REF! | AA24: =+'DIRECTO '!AB23+#REF! -> #REF! | AB24: =+'DIRECTO '!AC23+#REF! -> #REF! | AD24: =+'DIRECTO '!AE23+#REF! -> #REF! | AF24: =+AB24-X24 -> #REF! | AG24: =+Eq!Y57 -> 0 | AH24: =IF(ABS(X24-AG24)>1,"Revisar Rubros","OK") -> #REF! | AJ24: =SUM(AK24:CA24) -> #REF! | AK24: =+'DIRECTO '!AK23+#REF! -> #REF! | AL24: =+'DIRECTO '!AM23+#REF! -> #REF! | AM24: =+'DIRECTO '!AN23+#REF! -> #REF! | AN24: =+'DIRECTO '!AO23+#REF! -> #REF! | AO24: =+'DIRECTO '!AP23+#REF! -> #REF! | AP24: =+'DIRECTO '!AQ23+#REF! -> #REF! | AQ24: =+'DIRECTO '!#REF!+#REF! -> #REF! | AR24: =+'DIRECTO '!#REF!+#REF! -> #REF! | AS24: =+'DIRECTO '!#REF!+#REF! -> #REF! | AT24: =+'DIRECTO '!#REF!+#REF! -> #REF! | AU24: =+'DIRECTO '!#REF!+#REF! -> #REF! | AV24: =+'DIRECTO '!#REF!+#REF! -> #REF! | AW24: =+'DIRECTO '!#REF!+#REF! -> #REF! | AX24: =+'DIRECTO '!#REF!+#REF! -> #REF! | ... CA24: =+'DIRECTO '!#REF!+#REF! -> #REF!
B25: Fletes | E25: =+'DIRECTO '!E24+#REF! -> #REF! | G25: =+'DIRECTO '!G24+#REF! -> #REF! | H25: =+'DIRECTO '!H24+#REF! -> #REF! | J25: =+'DIRECTO '!J24+#REF! -> #REF! | K25: =+'DIRECTO '!K24+#REF! -> #REF! | L25: =+SUM(N25:R25) -> #REF! | N25: =+'DIRECTO '!N24+#REF! -> #REF! | O25: =+'DIRECTO '!O24+#REF! -> #REF! | P25: =+'DIRECTO '!P24+#REF! -> #REF! | Q25: =+'DIRECTO '!Q24+#REF! -> #REF! | R25: =+'DIRECTO '!R24+#REF! -> #REF! | S25: =+SUMIFS(N25:R25,N$2:R$2,$S$5) -> 0 | U25: =+SUMIFS(N25:S25,N$2:S$2,$U$5) -> 0 | W25: =+X25 -> #REF! | X25: =+K25+L25 -> #REF! | Y25: =+'DIRECTO '!Z24+#REF! -> #REF! | Z25: =+'DIRECTO '!AA24+#REF! -> #REF! | AA25: =+'DIRECTO '!AB24+#REF! -> #REF! | AB25: =+'DIRECTO '!AC24+#REF! -> #REF! | AD25: =+'DIRECTO '!AE24+#REF! -> #REF! | AF25: =+AB25-X25 -> #REF! | AG25: =+Fletes!Y39 -> 0 | AH25: =IF(ABS(X25-AG25)>1,"Revisar Rubros","OK") -> #REF! | AJ25: =SUM(AK25:CA25) -> #REF! | AK25: =+'DIRECTO '!AK24+#REF! -> #REF! | AL25: =+'DIRECTO '!AM24+#REF! -> #REF! | AM25: =+'DIRECTO '!AN24+#REF! -> #REF! | AN25: =+'DIRECTO '!AO24+#REF! -> #REF! | AO25: =+'DIRECTO '!AP24+#REF! -> #REF! | AP25: =+'DIRECTO '!AQ24+#REF! -> #REF! | AQ25: =+'DIRECTO '!#REF!+#REF! -> #REF! | AR25: =+'DIRECTO '!#REF!+#REF! -> #REF! | AS25: =+'DIRECTO '!#REF!+#REF! -> #REF! | AT25: =+'DIRECTO '!#REF!+#REF! -> #REF! | AU25: =+'DIRECTO '!#REF!+#REF! -> #REF! | AV25: =+'DIRECTO '!#REF!+#REF! -> #REF! | AW25: =+'DIRECTO '!#REF!+#REF! -> #REF! | AX25: =+'DIRECTO '!#REF!+#REF! -> #REF! | ... CA25: =+'DIRECTO '!#REF!+#REF! -> #REF!
B26: Staff (Sueldos) | E26: =+'DIRECTO '!E25+#REF! -> #REF! | G26: =+'DIRECTO '!G25+#REF! -> #REF! | H26: =+'DIRECTO '!H25+#REF! -> #REF! | J26: =+'DIRECTO '!J25+#REF! -> #REF! | K26: =+'DIRECTO '!K25+#REF! -> #REF! | L26: =+SUM(N26:R26) -> #REF! | N26: =+'DIRECTO '!N25+#REF! -> #REF! | O26: =+'DIRECTO '!O25+#REF! -> #REF! | P26: =+'DIRECTO '!P25+#REF! -> #REF! | Q26: =+'DIRECTO '!Q25+#REF! -> #REF! | R26: =+'DIRECTO '!R25+#REF! -> #REF! | S26: =+SUMIFS(N26:R26,N$2:R$2,$S$5) -> 0 | U26: =+SUMIFS(N26:S26,N$2:S$2,$U$5) -> 0 | W26: =+X26 -> #REF! | X26: =+K26+L26 -> #REF! | Y26: =+'DIRECTO '!Z25+#REF! -> #REF! | Z26: =+'DIRECTO '!AA25+#REF! -> #REF! | AA26: =+'DIRECTO '!AB25+#REF! -> #REF! | AB26: =+'DIRECTO '!AC25+#REF! -> #REF! | AD26: =+'DIRECTO '!AE25+#REF! -> #REF! | AF26: =+AB26-X26 -> #REF! | AG26: =+Staff!BK27 -> 0 | AH26: =IF(ABS(X26-AG26)>1,"Revisar Rubros","OK") -> #REF! | AJ26: =SUM(AK26:CA26) -> #REF! | AK26: =+'DIRECTO '!AK25+#REF! -> #REF! | AL26: =+'DIRECTO '!AM25+#REF! -> #REF! | AM26: =+'DIRECTO '!AN25+#REF! -> #REF! | AN26: =+'DIRECTO '!AO25+#REF! -> #REF! | AO26: =+'DIRECTO '!AP25+#REF! -> #REF! | AP26: =+'DIRECTO '!AQ25+#REF! -> #REF! | AQ26: =+'DIRECTO '!#REF!+#REF! -> #REF! | AR26: =+'DIRECTO '!#REF!+#REF! -> #REF! | AS26: =+'DIRECTO '!#REF!+#REF! -> #REF! | AT26: =+'DIRECTO '!#REF!+#REF! -> #REF! | AU26: =+'DIRECTO '!#REF!+#REF! -> #REF! | AV26: =+'DIRECTO '!#REF!+#REF! -> #REF! | AW26: =+'DIRECTO '!#REF!+#REF! -> #REF! | AX26: =+'DIRECTO '!#REF!+#REF! -> #REF! | ... CA26: =+'DIRECTO '!#REF!+#REF! -> #REF! | CD26: 21280334 | CE26: =+CD26-X26 -> #REF! | CG26: =+CG27/X16 -> #REF!
B27: Gastos Generales | E27: =+'DIRECTO '!E26+#REF! -> #REF! | G27: =+'DIRECTO '!G26+#REF! -> #REF! | H27: =+'DIRECTO '!H26+#REF! -> #REF! | J27: =+'DIRECTO '!J26+#REF! -> #REF! | K27: =+'DIRECTO '!K26+#REF! -> #REF! | L27: =+SUM(N27:R27) -> #REF! | N27: =+'DIRECTO '!N26+#REF! -> #REF! | O27: =+'DIRECTO '!O26+#REF! -> #REF! | P27: =+'DIRECTO '!P26+#REF! -> #REF! | Q27: =+'DIRECTO '!Q26+#REF! -> #REF! | R27: =+'DIRECTO '!R26+#REF! -> #REF! | S27: =+SUMIFS(N27:R27,N$2:R$2,$S$5) -> 0 | U27: =+SUMIFS(N27:S27,N$2:S$2,$U$5) -> 0 | W27: =+X27 -> #REF! | X27: =+K27+L27 -> #REF! | Y27: =+'DIRECTO '!Z26+#REF! -> #REF! | Z27: =+'DIRECTO '!AA26+#REF! -> #REF! | AA27: =+'DIRECTO '!AB26+#REF! -> #REF! | AB27: =+'DIRECTO '!AC26+#REF! -> #REF! | AD27: =+'DIRECTO '!AE26+#REF! -> #REF! | AF27: =+AB27-X27 -> #REF! | AG27: =+GG!Y35 -> 24799.991 | AH27: =IF(ABS(X27-AG27)>1,"Revisar Rubros","OK") -> #REF! | AJ27: =SUM(AK27:CA27) -> #REF! | AK27: =+'DIRECTO '!AK26+#REF! -> #REF! | AL27: =+'DIRECTO '!AM26+#REF! -> #REF! | AM27: =+'DIRECTO '!AN26+#REF! -> #REF! | AN27: =+'DIRECTO '!AO26+#REF! -> #REF! | AO27: =+'DIRECTO '!AP26+#REF! -> #REF! | AP27: =+'DIRECTO '!AQ26+#REF! -> #REF! | AQ27: =+'DIRECTO '!#REF!+#REF! -> #REF! | AR27: =+'DIRECTO '!#REF!+#REF! -> #REF! | AS27: =+'DIRECTO '!#REF!+#REF! -> #REF! | AT27: =+'DIRECTO '!#REF!+#REF! -> #REF! | AU27: =+'DIRECTO '!#REF!+#REF! -> #REF! | AV27: =+'DIRECTO '!#REF!+#REF! -> #REF! | AW27: =+'DIRECTO '!#REF!+#REF! -> #REF! | AX27: =+'DIRECTO '!#REF!+#REF! -> #REF! | ... CA27: =+'DIRECTO '!#REF!+#REF! -> #REF! | CD27: 12574362 | CG27: =+X27+X26 -> #REF!
B29: Stock de Materiales | E29: =+'DIRECTO '!E28+#REF! -> #REF! | G29: =+'DIRECTO '!G28+#REF! -> #REF! | H29: =+'DIRECTO '!H28+#REF! -> #REF! | J29: =+'DIRECTO '!J28+#REF! -> #REF! | K29: =+'DIRECTO '!K28+#REF! -> #REF! | L29: =+SUM(N29:R29) -> #REF! | N29: =+'DIRECTO '!N28+#REF! -> #REF! | O29: =+'DIRECTO '!O28+#REF! -> #REF! | P29: =+'DIRECTO '!P28+#REF! -> #REF! | Q29: =+'DIRECTO '!Q28+#REF! -> #REF! | R29: =+'DIRECTO '!R28+#REF! -> #REF! | S29: =+SUMIFS(N29:R29,N$2:R$2,$S$5) -> 0 | U29: =+SUMIFS(N29:S29,N$2:S$2,$U$5) -> 0 | X29: =+K29+L29 -> #REF! | Y29: =+'DIRECTO '!Z28+#REF! -> #REF! | Z29: =+'DIRECTO '!AA28+#REF! -> #REF! | AA29: =+'DIRECTO '!AB28+#REF! -> #REF! | AB29: =+'DIRECTO '!AC28+#REF! -> #REF! | AD29: =+'DIRECTO '!AE28+#REF! -> #REF! | AJ29: =SUM(AK29:CA29) -> #REF! | AK29: =+'DIRECTO '!AK28+#REF! -> #REF! | AL29: =+'DIRECTO '!AM28+#REF! -> #REF! | AM29: =+'DIRECTO '!AN28+#REF! -> #REF! | AN29: =+'DIRECTO '!AO28+#REF! -> #REF! | AO29: =+'DIRECTO '!AP28+#REF! -> #REF! | AP29: =+'DIRECTO '!AQ28+#REF! -> #REF! | AQ29: =+'DIRECTO '!#REF!+#REF! -> #REF! | AR29: =+'DIRECTO '!#REF!+#REF! -> #REF! | AS29: =+'DIRECTO '!#REF!+#REF! -> #REF! | AT29: =+'DIRECTO '!#REF!+#REF! -> #REF! | AU29: =+'DIRECTO '!#REF!+#REF! -> #REF! | AV29: =+'DIRECTO '!#REF!+#REF! -> #REF! | AW29: =+'DIRECTO '!#REF!+#REF! -> #REF! | AX29: =+'DIRECTO '!#REF!+#REF! -> #REF! | ... CA29: =+'DIRECTO '!#REF!+#REF! -> #REF! | CD29: 5329828.3
B31: Margen Ponderado S/. | C31: S/. | E31: =+E7*E32 -> #REF! | G31: =+G7*G32 -> #REF! | H31: =+H7*H32 -> #REF! | J31: =+J7*J32 -> #REF! | K31: =+K7*K32 -> #REF! | L31: =+L7*L32 -> #REF! | N31: =+N7*N32 -> #REF! | O31: =+O7*O32 -> #REF! | P31: =+P7*P32 -> #REF! | Q31: =+Q7*Q32 -> #REF! | R31: =+R7*R32 -> #REF! | S31: =+S7*S32 -> #REF! | U31: =+U7*U32 -> #REF! | W31: =+W7-W16 -> #REF! | X31: =+X7-X16 -> #REF! | Y31: =+Y7-Y16 -> #REF! | Z31: =+Z7-Z16 -> #REF! | AA31: =+AA7-AA16 -> #REF! | AB31: =+AB7-AB16 -> #REF! | AD31: 0 | AF31: =+X31-Y31 -> #REF! | AH31: =+X31 -> #REF! | CD31: =+X31-Y31 -> #REF!
C32: % | E32: =+$X$32 -> #REF! | G32: =+$X$32 -> #REF! | H32: =+$X$32 -> #REF! | J32: =+$X$32 -> #REF! | K32: =+$X$32 -> #REF! | L32: =+$X$32 -> #REF! | N32: =+$X$32 -> #REF! | O32: =+$X$32 -> #REF! | P32: =+$X$32 -> #REF! | Q32: =+$X$32 -> #REF! | R32: =+$X$32 -> #REF! | S32: =+$X$32 -> #REF! | U32: =+$X$32 -> #REF! | W32: =+IF(W7=0,0,W31/W7) -> #REF! | X32: =+IF(X7=0,0,X31/X7) -> #REF! | Y32: =+IF(Y7=0,0,Y31/Y7) -> #REF! | Z32: =+IF(Z7=0,0,Z31/Z7) -> #REF! | AA32: =+IF(AA7=0,0,AA31/AA7) -> #REF! | AB32: =+IF(AB7=0,0,AB31/AB7) -> #REF! | AD32: 0 | CD32: =+X32-Y32 -> #REF!
B34: Margen Absoluto | C34: S/. | E34: =+E7-E16+E29 -> #REF! | G34: =+G7-G16+G29 -> #REF! | H34: =+H7-H16+H29 -> #REF! | J34: =+J7-J16+J29 -> #REF! | K34: =+K7-K16 -> #REF! | L34: =+L7-L16 -> #REF! | N34: =+N7-N16+N29 -> #REF! | O34: =+O7-O16+O29 -> #REF! | P34: =+P7-P16+P29 -> #REF! | Q34: =+Q7-Q16+Q29 -> #REF! | R34: =+R7-R16+R29 -> #REF! | S34: =+S7-S16+S29 -> 0 | U34: =+U7-U16+U29 -> 0 | W34: =+W7-W16+W29 -> #REF! | X34: =+X7-X16+X29 -> #REF! | Y34: =+Y7-Y16+Y29 -> #REF! | Z34: =+Z7-Z16+Z29 -> #REF! | AA34: =+AA7-AA16+AA29 -> #REF! | AB34: =+AB7-AB16+AB29 -> #REF! | AD34: 0
C35: % | E35: =+IF(E9=0,0,E34/E9) -> #REF! | G35: =+IF(G9=0,0,G34/G9) -> #REF! | H35: =+IF(H9=0,0,H34/H9) -> #REF! | J35: =+IF(J7=0,0,J34/J7) -> #REF! | K35: =+IF(K7=0,0,K34/K7) -> #REF! | L35: =+IF(L7=0,0,L34/L7) -> #REF! | N35: =+IF(N7=0,0,N34/N7) -> #REF! | O35: =+IF(O7=0,0,O34/O7) -> #REF! | P35: =+IF(P7=0,0,P34/P7) -> #REF! | Q35: =+IF(Q7=0,0,Q34/Q7) -> #REF! | R35: =+IF(R7=0,0,R34/R7) -> #REF! | S35: =+IF(S7=0,0,S34/S7) -> 0 | U35: =+IF(U7=0,0,U34/U7) -> 0 | W35: =+IF(W7=0,0,W34/W7) -> #REF! | X35: =+IF(X7=0,0,X34/X7) -> #REF! | Y35: =+IF(Y7=0,0,Y34/Y7) -> #REF! | Z35: =+IF(Z7=0,0,Z34/Z7) -> #REF! | AA35: =+IF(AA7=0,0,AA34/AA7) -> #REF! | AB35: =+IF(AB7=0,0,AB34/AB7) -> #REF! | AD35: 0
W37: =+W35-CONSOLIDADO!W34 -> #REF! | X37: =+X35-CONSOLIDADO!W34 -> #REF!
B39: COSTO APLICADO | K39: =+K7-K31 -> #REF! | W39: =+W31-CONSOLIDADO!W33 -> #REF! | X39: =+X31-CONSOLIDADO!W33 -> #REF! | CD39: =Y31 -> #REF! | CE39: =+X32-Y32 -> #REF!
B41: RESULTADO PENDIENTE | K41: =K16-K39 -> #REF! | CD41: =X31 -> #REF! | CE41: =+CD41-CD39 -> #REF!
B43: ACTIVOS | K43: ='ER Pendiente'!H40+'ER Pendiente'!H15 -> #REF!
B45: PROVISIONES | K45: =+'ER Pendiente'!I40+'ER Pendiente'!I22 -> 0
B47: DIFERENCIA DE MARGENES | K47: =+'DIRECTO '!K46+#REF! -> #REF!
B49: CONTINGENCIA | K49: =+K41-K43+K45 -> #REF!
C51: Mayor Margen +
C53: Menor Margen -
B56: MARGEN CONSORCIO (PONDERADO) | X56: 11555 | AB56: 16571
B57: MARGEN GARANTIZADO | X57: 10554 | AB57: 10554
B58: MARGEN POR PRODUCTIVIDAD | X58: 10.01 | AB58: 59.97
...

Sheet CONSOLIDADO
B1: =CONCATENATE(B3," - ",B4," - ",B5," - ",B6) -> I.E.N 1182 - MES DE JULIO 2024 - EL BOSQUE - CERCO + INGRESOS Y CASETAS - CONSOLIDADO - JULIO 2024
N2: =+YEAR(N5) -> 2024 | O2: =+YEAR(O5) -> 2024 | P2: =+YEAR(P5) -> 2024 | Q2: =+YEAR(Q5) -> 2024 | R2: =+YEAR(R5) -> 2024 | S2: =S5 -> 2024
B3: I.E.N 1182 | E3: ACUMULADO | G3: MES DE JULIO 2024 | J3: ACUMULADO DEL 2024 | K3: ACUMULADO DE OBRA | L3: SALDO DE OBRA | N3: PROYECCIÓN | U3: AÑOS SIGUIENTES | W3: TOTAL DE OBRA | AC3: Acum. del Ej. | AE3: TOTAL | AF3: MES DEL INFORME | AG3: ANTERIORES | AH3: 45474 | AI3: 45505 | AJ3: 45536 | AK3: 45566 | AL3: 45597
B4: MES DE JULIO 2024 | N4: 1 | O4: =+N4+1 -> 2 | P4: =+O4+1 -> 3 | Q4: =+P4+1 -> 4 | R4: =+Q4+1 -> 5 | S4: Saldo del Ejercicio
B5: EL BOSQUE - CERCO + INGRESOS Y CASETAS | E5: Años Anteriores | G5: Previsto | H5: Real | N5: 45475 | O5: =+N5+31 -> 45506 | P5: =+O5+31 -> 45537 | Q5: =+P5+31 -> 45568 | R5: =+Q5+31 -> 45599 | S5: 2024 | U5: =+S5+1 -> 2025 | W5: Actual | X5: Anterior | Y5: Meta | Z5: Presupuesto Interno | AA5: Presupuesto | AC5: Anterior
B6: CONSOLIDADO - JULIO 2024
B7: Venta Total Producida | E7: =+E9 -> #REF! | G7: =+G9 -> #REF! | H7: =+H9 -> #REF! | J7: =+J9 -> #REF! | K7: =+K9 -> #REF! | L7: =+L9 -> #REF! | N7: =+N9 -> #REF! | O7: =+O9 -> #REF! | P7: =+P9 -> #REF! | Q7: =+Q9 -> #REF! | R7: =+R9 -> #REF! | S7: =+S9 -> #REF! | U7: =+U9 -> 0 | W7: =+W9 -> #REF! | X7: =+X9 -> #REF! | Y7: =+Y9 -> #REF! | Z7: =+Z9 -> #REF! | AA7: =+AA9 -> #REF! | AC7: =+AC9 -> #REF!
