Workbook

Sheet Espectro Diseño
B2: ZUCS | C2: =(C5*C6*C7*C11)/C12 -> 0.13089005
B3: R
B5: Z4 | C5: 0.45
B6: Uc | C6: 1
B7: C | C7: =2.5*(C9/C8) -> 1.5706806
B8: T (hn/CT) | C8: =38.2/60 -> 0.63666667
B9: Tp | C9: 0.4
B10: TL | C10: 2.5
B11: S1 | C11: 1
B12: R | C12: =C13*C14*C15 -> 5.4
B13: Ro | C13: 6
B14: Ia | C14: 0.9
B15: Ip | C15: 1
B17: k | C17: =0.75+(0.5*C8) -> 1.0683333

Sheet CARGAS
B2: DEAD | C2: Peso Propio de los Elementos Estructurales
B4: CM | C4: Peso Acabados + Peso ladrillo Techo + Peso muros albañilería + Tanque Elevado
C6: Peso Acabados | E6: 100 | F6: kg/m2
C7: Peso Ladrillo de Techo | E7: =F16 -> 90 | F7: kg/m2
E8: Vc=0.05+0.25H
E9: Vc=0.05+0.25(0.15)
E10: Vc | F10: =0.05+0.25*(0.15) -> 0.0875 | G10: m3/m2
E12: Peso Esp. Concreto | G12: 2400 | H12: kg/m3
E14: Wc | F14: =G12*F10 -> 210 | G14: kg/m2
E15: Wladrillo = Wlosa-Wc
E16: Wladrillo | F16: =300-F14 -> 90 | G16: kg/m2
C18: Peso Muros sobre Área | E18: 250 | F18: kg/m2
C20: Peso Muros sobre Viga | E20: e | F20: 0.15 | G20: m
E21: h | F21: 1.2 | G21: m
E22: Peso Esp. | F22: 1350 | G22: kg/m3
E23: Wmuro | F23: =F22*F21*F20 -> 243 | G23: kg/m
C25: Tanque Losa Ascensor (1) | E25: Vol | F25: 2.5 | G25: m3
E26: Peso Esp. H2O | F26: 1000 | G26: kg/m3
E27: Wtanque | F27: =F26*F25 -> 2500 | G27: kg
E28: Área | F28: 4 | G28: m2
E29: Wtanque/m2 | F29: =F27/F28 -> 625 | G29: kg/m2
C31: Tanque Losa Central (4) | E31: Vol | F31: =2.5*4 -> 10 | G31: m3
E32: Peso Esp. H2O | F32: 1000 | G32: kg/m3
E33: Wtanque | F33: =F32*F31 -> 10000 | G33: kg
E34: Área | F34: 17.5 | G34: m2
E35: Wtanque/m2 | F35: =F33/F34 -> 571.42857 | G35: kg/m2
B37: LIVE | C37: Carga Viva de Entrepiso
C38: Sótano | D38: Garaje | E38: 250 | F38: kg/m2
C39: Semisótano | D39: Garaje | E39: 250 | F39: kg/m2
D40: Escalera | E40: 250 | F40: kg/m2
C41: 1°-2°nivel | D41: Restaurante | E41: 400 | F41: kg/m2
D42: Escalera | E42: 500 | F42: kg/m2
C43: 3°-10°nivel | D43: Departamentos | E43: 200 | F43: kg/m2
D44: Escalera | E44: 200 | F44: kg/m2
B46: LIVE UP | C46: Carga Viva de Techo
D47: Azotea | E47: 100 | F47: kg/m2

Sheet COMBINACIONES
B1: COMBINACIÓN N°01: 1.4CM+1.7CV
B3: COMB1 | C3: 1.4 | D3: DEAD | E3: 1.4 | F3: CM | G3: 1.7 | H3: LIVE | I3: 1.7 | J3: LIVE UP
B4: COMB2 | C4: 1.4 | D4: DEAD | E4: 1.4 | F4: CM | G4: 1.7 | H4: LIVE 1 | I4: 1.7 | J4: LIVE UP
B5: COMB3 | C5: 1.4 | D5: DEAD | E5: 1.4 | F5: CM | G5: 1.7 | H5: LIVE 2 | I5: 1.7 | J5: LIVE UP
B7: COMBINACIÓN N°02: 1.25CM+1.25CV+-CS
B9: COMB4 | C9: 1.25 | D9: DEAD | E9: 1.25 | F9: CM | G9: 1.25 | H9: LIVE | I9: 1.25 | J9: LIVE UP | K9: 1 | L9: SxD
B10: COMB5 | C10: 1.25 | D10: DEAD | E10: 1.25 | F10: CM | G10: 1.25 | H10: LIVE | I10: 1.25 | J10: LIVE UP | K10: -1 | L10: SxD
B11: COMB6 | C11: 1.25 | D11: DEAD | E11: 1.25 | F11: CM | G11: 1.25 | H11: LIVE | I11: 1.25 | J11: LIVE UP | K11: 1 | L11: SyD
B12: COMB7 | C12: 1.25 | D12: DEAD | E12: 1.25 | F12: CM | G12: 1.25 | H12: LIVE | I12: 1.25 | J12: LIVE UP | K12: -1 | L12: SyD
B13: COMB8 | C13: 1.25 | D13: DEAD | E13: 1.25 | F13: CM | G13: 1.25 | H13: LIVE 1 | I13: 1.25 | J13: LIVE UP | K13: 1 | L13: SxD
B14: COMB9 | C14: 1.25 | D14: DEAD | E14: 1.25 | F14: CM | G14: 1.25 | H14: LIVE 1 | I14: 1.25 | J14: LIVE UP | K14: -1 | L14: SxD
B15: COMB10 | C15: 1.25 | D15: DEAD | E15: 1.25 | F15: CM | G15: 1.25 | H15: LIVE 1 | I15: 1.25 | J15: LIVE UP | K15: 1 | L15: SyD
B16: COMB11 | C16: 1.25 | D16: DEAD | E16: 1.25 | F16: CM | G16: 1.25 | H16: LIVE 1 | I16: 1.25 | J16: LIVE UP | K16: -1 | L16: SyD
B17: COMB12 | C17: 1.25 | D17: DEAD | E17: 1.25 | F17: CM | G17: 1.25 | H17: LIVE 2 | I17: 1.25 | J17: LIVE UP | K17: 1 | L17: SxD
B18: COMB13 | C18: 1.25 | D18: DEAD | E18: 1.25 | F18: CM | G18: 1.25 | H18: LIVE 2 | I18: 1.25 | J18: LIVE UP | K18: -1 | L18: SxD
B19: COMB14 | C19: 1.25 | D19: DEAD | E19: 1.25 | F19: CM | G19: 1.25 | H19: LIVE 2 | I19: 1.25 | J19: LIVE UP | K19: 1 | L19: SyD
B20: COMB15 | C20: 1.25 | D20: DEAD | E20: 1.25 | F20: CM | G20: 1.25 | H20: LIVE 2 | I20: 1.25 | J20: LIVE UP | K20: -1 | L20: SyD
B22: COMBINACIÓN N°03: 0.90CM+-CS
B24: COMB16 | C24: 0.9 | D24: DEAD | E24: 0.9 | F24: CM | G24: 1 | H24: SxD
B25: COMB17 | C25: 0.9 | D25: DEAD | E25: 0.9 | F25: CM | G25: -1 | H25: SxD
B26: COMB18 | C26: 0.9 | D26: DEAD | E26: 0.9 | F26: CM | G26: 1 | H26: SyD
B27: COMB19 | C27: 0.9 | D27: DEAD | E27: 0.9 | F27: CM | G27: -1 | H27: SyD
B29: COMBINACIÓN N°04: ENVOLVENTE
B31: COMB20 | C31: COMB1 + COMB2 + … + COMB19

Sheet VERIFICACIONES
A2: 1 | B2: VERIFICACIÓN POR PARTICIPACIÓN MODAL
B8: TABLE: Modal Load Participation Ratios
B9: OutputCase | C9: ItemType | D9: Item | E9: Static | F9: Dynamic
B10: Text | C10: Text | D10: Text | E10: Percent | F10: Percent
B11: MODAL | C11: Acceleration | D11: UX | E11: 100 | F11: 98.208 | G11: =IF(F11>90,"OK","ERROR") -> OK
B12: MODAL | C12: Acceleration | D12: UY | E12: 100 | F12: 97.4525 | G12: =IF(F12>90,"OK","ERROR") -> OK
B13: MODAL | C13: Acceleration | D13: UZ | E13: 0 | F13: 0
A16: 2 | B16: VERIFICACIÓN DE DESPLAZAMIENTOS LATERALES
B35: DIRECCIÓN X
B37: EJES | C37: N° PISO | D37: DESP. ABS. | E37: Δi | F37: hei | G37: DISTORSIÓN
B38: EJE A Y EJE 1 | C38: PISO 6 | D38: 9.972119 | E38: =D38-D39 -> 1.96879 | F38: 300 | G38: =E38/F38 -> 0.0065626333 | H38: =IF(G38<0.007,"OK","ERROR") -> OK
C39: PISO 5 | D39: 8.003329 | E39: =D39-D40 -> 1.946674 | F39: 300 | G39: =E39/F39 -> 0.0064889133 | H39: =IF(G39<0.007,"OK","ERROR") -> OK
C40: PISO 4 | D40: 6.056655 | E40: =D40-D41 -> 1.867993 | F40: 300 | G40: =E40/F40 -> 0.0062266433 | H40: =IF(G40<0.007,"OK","ERROR") -> OK
C41: PISO 3 | D41: 4.188662 | E41: =D41-D42 -> 1.707759 | F41: 300 | G41: =E41/F41 -> 0.00569253 | H41: =IF(G41<0.007,"OK","ERROR") -> OK
C42: PISO 2 | D42: 2.480903 | E42: =D42-D43 -> 1.429107 | F42: 300 | G42: =E42/F42 -> 0.00476369 | H42: =IF(G42<0.007,"OK","ERROR") -> OK
C43: PISO 1 | D43: 1.051796 | E43: =D43-D44 -> 0.958583 | F43: 300 | G43: =E43/F43 -> 0.0031952767 | H43: =IF(G43<0.007,"OK","ERROR") -> OK
C44: SEMISÓTANO | D44: 0.093213 | E44: =D44-D45 -> 0.093213 | F44: 280 | G44: =E44/F44 -> 0.00033290357 | H44: =IF(G44<0.007,"OK","ERROR") -> OK
C45: SÓTANO | D45: 0 | E45: =D45-D46 -> 0 | F45: 280 | G45: =E45/F45 -> 0 | H45: =IF(G45<0.007,"OK","ERROR") -> OK
C46: BASE | D46: 0
B47: EJE A Y EJE 3 | C47: PISO 10 | D47: 16.478506 | E47: =D47-D48 -> 1.766289 | F47: 300 | G47: =E47/F47 -> 0.00588763 | H47: =IF(G47<0.007,"OK","ERROR") -> OK
C48: PISO 9 | D48: 14.712217 | E48: =D48-D49 -> 1.812626 | F48: 300 | G48: =E48/F48 -> 0.0060420867 | H48: =IF(G48<0.007,"OK","ERROR") -> OK
C49: PISO 8 | D49: 12.899591 | E49: =D49-D50 -> 1.846858 | F49: 300 | G49: =E49/F49 -> 0.0061561933 | H49: =IF(G49<0.007,"OK","ERROR") -> OK
C50: PISO 7 | D50: 11.052733 | E50: =D50-D51 -> 1.855454 | F50: 300 | G50: =E50/F50 -> 0.0061848467 | H50: =IF(G50<0.007,"OK","ERROR") -> OK
C51: PISO 6 | D51: 9.197279 | E51: =D51-D52 -> 1.821895 | F51: 300 | G51: =E51/F51 -> 0.0060729833 | H51: =IF(G51<0.007,"OK","ERROR") -> OK
C52: PISO 5 | D52: 7.375384 | E52: =D52-D53 -> 1.798122 | F52: 300 | G52: =E52/F52 -> 0.00599374 | H52: =IF(G52<0.007,"OK","ERROR") -> OK
C53: PISO 4 | D53: 5.577262 | E53: =D53-D54 -> 1.722415 | F53: 300 | G53: =E53/F53 -> 0.0057413833 | H53: =IF(G53<0.007,"OK","ERROR") -> OK
C54: PISO 3 | D54: 3.854847 | E54: =D54-D55 -> 1.571917 | F54: 300 | G54: =E54/F54 -> 0.0052397233 | H54: =IF(G54<0.007,"OK","ERROR") -> OK
C55: PISO 2 | D55: 2.28293 | E55: =D55-D56 -> 1.313002 | F55: 300 | G55: =E55/F55 -> 0.0043766733 | H55: =IF(G55<0.007,"OK","ERROR") -> OK
C56: PISO 1 | D56: 0.969928 | E56: =D56-D57 -> 0.87936 | F56: 300 | G56: =E56/F56 -> 0.0029312 | H56: =IF(G56<0.007,"OK","ERROR") -> OK
C57: SEMISÓTANO | D57: 0.090568 | E57: =D57-D58 -> 0.090568 | F57: 280 | G57: =E57/F57 -> 0.00032345714 | H57: =IF(G57<0.007,"OK","ERROR") -> OK
C58: SÓTANO | D58: 0 | E58: =D58-D59 -> 0 | F58: 280 | G58: =E58/F58 -> 0 | H58: =IF(G58<0.007,"OK","ERROR") -> OK
C59: BASE | D59: 0
B60: EJE A Y EJE 8 | C60: PISO 10 | D60: 16.505414 | E60: =D60-D61 -> 1.773582 | F60: 300 | G60: =E60/F60 -> 0.00591194 | H60: =IF(G60<0.007,"OK","ERROR") -> OK
C61: PISO 9 | D61: 14.731832 | E61: =D61-D62 -> 1.819025 | F61: 300 | G61: =E61/F61 -> 0.0060634167 | H61: =IF(G61<0.007,"OK","ERROR") -> OK
C62: PISO 8 | D62: 12.912807 | E62: =D62-D63 -> 1.852222 | F62: 300 | G62: =E62/F62 -> 0.0061740733 | H62: =IF(G62<0.007,"OK","ERROR") -> OK
C63: PISO 7 | D63: 11.060585 | E63: =D63-D64 -> 1.859748 | F63: 300 | G63: =E63/F63 -> 0.00619916 | H63: =IF(G63<0.007,"OK","ERROR") -> OK
C64: PISO 6 | D64: 9.200837 | E64: =D64-D65 -> 1.82496 | F64: 300 | G64: =E64/F64 -> 0.0060832 | H64: =IF(G64<0.007,"OK","ERROR") -> OK
C65: PISO 5 | D65: 7.375877 | E65: =D65-D66 -> 1.800276 | F65: 300 | G65: =E65/F65 -> 0.00600092 | H65: =IF(G65<0.007,"OK","ERROR") -> OK
C66: PISO 4 | D66: 5.575601 | E66: =D66-D67 -> 1.723529 | F66: 300 | G66: =E66/F66 -> 0.0057450967 | H66: =IF(G66<0.007,"OK","ERROR") -> OK
C67: PISO 3 | D67: 3.852072 | E67: =D67-D68 -> 1.571982 | F67: 300 | G67: =E67/F67 -> 0.00523994 | H67: =IF(G67<0.007,"OK","ERROR") -> OK
...

Sheet PESO
B2: PISO 1 - 2 | C2: =I21+I23+0.25*I25 -> 850.99903 | D2: Ton
B4: DEAD | C4: COLUNAS | D4: 58 | E4: 3 | F4: 0.4 | G4: 0.5 | H4: 2.4028 | I4: =D4*E4*F4*G4*H4 -> 83.61744 | J4: Ton
C5: VIGAS | D5: 2 | E5: =3.5*3 -> 10.5 | F5: 0.25 | G5: 0.4 | H5: 2.4028 | I5: =D5*E5*F5*G5*H5 -> 5.04588 | J5: Ton
D6: 4 | E6: =3.5*3+5 -> 15.5 | F6: 0.25 | G6: 0.4 | H6: 2.4028 | I6: =D6*E6*F6*G6*H6 -> 14.89736 | J6: Ton
D7: 4 | E7: =3.5*3+5*2 -> 20.5 | F7: 0.25 | G7: 0.4 | H7: 2.4028 | I7: =D7*E7*F7*G7*H7 -> 19.70296 | J7: Ton
D8: 2 | E8: =4*5+2*4 -> 28 | F8: 0.25 | G8: 0.4 | H8: 2.4028 | I8: =D8*E8*F8*G8*H8 -> 13.45568 | J8: Ton
D9: 2 | E9: =41-4 -> 37 | F9: 0.25 | G9: 0.4 | H9: 2.4028 | I9: =D9*E9*F9*G9*H9 -> 17.78072 | J9: Ton
D10: 2 | E10: 41 | F10: 0.25 | G10: 0.4 | H10: 2.4028 | I10: =D10*E10*F10*G10*H10 -> 19.70296 | J10: Ton
C11: MUROS | D11: 6 | E11: 5 | F11: 0.25 | G11: 3 | H11: 2.4028 | I11: =D11*E11*F11*G11*H11 -> 54.063 | J11: Ton
D12: 2 | E12: 4 | F12: 0.25 | G12: 3 | H12: 2.4028 | I12: =D12*E12*F12*G12*H12 -> 14.4168 | J12: Ton
D13: 4 | E13: 6 | F13: 0.25 | G13: 3 | H13: 2.4028 | I13: =D13*E13*F13*G13*H13 -> 43.2504 | J13: Ton
C14: ESCALERA | D14: 3 | E14: 3.3541 | F14: 0.15 | G14: 1 | H14: 2.4028 | I14: =D14*E14*F14*G14*H14 -> 3.6266542 | J14: Ton
D15: 2 | E15: 2.25 | F15: 0.15 | G15: 1 | H15: 2.4028 | I15: =D15*E15*F15*G15*H15 -> 1.62189 | J15: Ton
C16: LOSA 5cm | D16: 1 | E16: =(41*20.5)-(80+(3.5*5*4)+(1.5*5*2)) -> 675.5 | F16: 0.05 | G16: 1 | H16: 2.4028 | I16: =D16*E16*F16*G16*H16 -> 81.15457 | J16: Ton
C17: VIGUETAS | D17: 132 | E17: 5 | F17: 0.1 | G17: 0.15 | H17: 2.4028 | I17: =D17*E17*F17*G17*H17 -> 23.78772 | J17: Ton
D18: 264 | E18: 3.5 | F18: 0.1 | G18: 0.15 | H18: 2.4028 | I18: =D18*E18*F18*G18*H18 -> 33.302808 | J18: Ton
D19: 144 | E19: 4 | F19: 0.1 | G19: 0.15 | H19: 2.4028 | I19: =D19*E19*F19*G19*H19 -> 20.760192 | J19: Ton
D20: 200 | E20: 5 | F20: 0.1 | G20: 0.15 | H20: 2.4028 | I20: =D20*E20*F20*G20*H20 -> 36.042 | J20: Ton
I21: =SUM(I4:I20) -> 486.22903 | J21: Ton
B23: CM | C23: LOSA | D23: 1 | E23: =E16 -> 675.5 | F23: 1 | G23: 1 | H23: =0.1+0.09+0.25 -> 0.44 | I23: =D23*E23*F23*G23*H23 -> 297.22 | J23: Ton
B25: LIVE | C25: LOSA | D25: 1 | E25: =E16 -> 675.5 | F25: 1 | G25: 1 | H25: 0.4 | I25: =D25*E25*F25*G25*H25 -> 270.2 | J25: Ton
B28: PISO 3 - 6 | C28: =I47+I49+0.25*I51 -> 817.22403 | D28: Ton
B30: DEAD | C30: COLUNAS | D30: 58 | E30: 3 | F30: 0.4 | G30: 0.5 | H30: 2.4028 | I30: =D30*E30*F30*G30*H30 -> 83.61744 | J30: Ton
C31: VIGAS | D31: 2 | E31: =3.5*3 -> 10.5 | F31: 0.25 | G31: 0.4 | H31: 2.4028 | I31: =D31*E31*F31*G31*H31 -> 5.04588 | J31: Ton
D32: 4 | E32: =3.5*3+5 -> 15.5 | F32: 0.25 | G32: 0.4 | H32: 2.4028 | I32: =D32*E32*F32*G32*H32 -> 14.89736 | J32: Ton
D33: 4 | E33: =3.5*3+5*2 -> 20.5 | F33: 0.25 | G33: 0.4 | H33: 2.4028 | I33: =D33*E33*F33*G33*H33 -> 19.70296 | J33: Ton
D34: 2 | E34: =4*5+2*4 -> 28 | F34: 0.25 | G34: 0.4 | H34: 2.4028 | I34: =D34*E34*F34*G34*H34 -> 13.45568 | J34: Ton
D35: 2 | E35: =41-4 -> 37 | F35: 0.25 | G35: 0.4 | H35: 2.4028 | I35: =D35*E35*F35*G35*H35 -> 17.78072 | J35: Ton
D36: 2 | E36: 41 | F36: 0.25 | G36: 0.4 | H36: 2.4028 | I36: =D36*E36*F36*G36*H36 -> 19.70296 | J36: Ton
C37: MUROS | D37: 6 | E37: 5 | F37: 0.25 | G37: 3 | H37: 2.4028 | I37: =D37*E37*F37*G37*H37 -> 54.063 | J37: Ton
D38: 2 | E38: 4 | F38: 0.25 | G38: 3 | H38: 2.4028 | I38: =D38*E38*F38*G38*H38 -> 14.4168 | J38: Ton
D39: 4 | E39: 6 | F39: 0.25 | G39: 3 | H39: 2.4028 | I39: =D39*E39*F39*G39*H39 -> 43.2504 | J39: Ton
C40: ESCALERA | D40: 3 | E40: 3.3541 | F40: 0.15 | G40: 1 | H40: 2.4028 | I40: =D40*E40*F40*G40*H40 -> 3.6266542 | J40: Ton
D41: 2 | E41: 2.25 | F41: 0.15 | G41: 1 | H41: 2.4028 | I41: =D41*E41*F41*G41*H41 -> 1.62189 | J41: Ton
C42: LOSA 5cm | D42: 1 | E42: =(41*20.5)-(80+(3.5*5*4)+(1.5*5*2)) -> 675.5 | F42: 0.05 | G42: 1 | H42: 2.4028 | I42: =D42*E42*F42*G42*H42 -> 81.15457 | J42: Ton
C43: VIGUETAS | D43: 132 | E43: 5 | F43: 0.1 | G43: 0.15 | H43: 2.4028 | I43: =D43*E43*F43*G43*H43 -> 23.78772 | J43: Ton
D44: 264 | E44: 3.5 | F44: 0.1 | G44: 0.15 | H44: 2.4028 | I44: =D44*E44*F44*G44*H44 -> 33.302808 | J44: Ton
D45: 144 | E45: 4 | F45: 0.1 | G45: 0.15 | H45: 2.4028 | I45: =D45*E45*F45*G45*H45 -> 20.760192 | J45: Ton
D46: 200 | E46: 5 | F46: 0.1 | G46: 0.15 | H46: 2.4028 | I46: =D46*E46*F46*G46*H46 -> 36.042 | J46: Ton
I47: =SUM(I30:I46) -> 486.22903 | J47: Ton
...
