Workbook

Sheet PRESUPUESTOS
A1: ANALISIS DE PRESUPUESTOS
A3: PROYECTO: | B3: I.E. N° 1182 "EL BOSQUE" - CERCO + INGRESOS Y CASETAS
A5: PC | B5: ITEM | C5: DESCRIPCION | D5: UND | E5: CONTRACTUAL | I5: META INICIAL -MES ANTERIOR | M5: META ACTUALIZADO
E6: METRADO | F6: P.U. (S/.) | G6: PARCIAL (S/.) | I6: METRADO | J6: P.U. (S/.) | K6: PARCIAL (S/.) | M6: METRADO | N6: P.U. (S/.) | O6: MANO DE OBRA | P6: MATERIALES | Q6: EQUIPOS | R6: SERVICIOS | S6: SUBCONTRATOS | T6: PARCIAL (S/.)
B7: 01 | C7: OBRAS PROVISIONALES, TRABAJOS PRELIMINARES, SEGURIDAD Y SALUD
B8: 01.02 | C8: Trabajos Preliminares
B9: 01.02.04 | C9: Trazo, Niveles y Replanteo
A10: 100 | B10: 01.02.04.01 | C10: TRAZO Y REPLANTEO PRELIMINAR | D10: M2 | E10: 897.34 | F10: 2.04 | G10: =ROUND(E10*F10,2) -> 1830.57 | I10: 942.21 | J10: 1.33 | K10: =ROUND(I10*J10,2) -> 1253.14 | M10: 935 | N10: =SUM(O10:S10) -> 1.47 | O10: 0.52 | P10: 0.7 | Q10: 0.25 | T10: =ROUND(M10*N10,2) -> 1374.45
A11: 100 | B11: 01.02.04.02 | C11: TRAZO Y REPLANTEO DURANTE EL PROCESO | D11: m2 | E11: 897.34 | F11: 2.04 | G11: =ROUND(E11*F11,2) -> 1830.57 | I11: 942.21 | J11: 1.33 | K11: =ROUND(I11*J11,2) -> 1253.14 | N11: =SUM(O11:S11) -> 0
B12: 02 | C12: ESTRUCTURAS
B13: 02.01 | C13: Movimiento de Tierras
B14: 02.01.01 | C14: Excavaciones
A15: 200 | B15: 02.01.01.01 | C15: EXCAV.ZANJAS Y ZAPATA RT>2kg/cm2 H=1.5m | D15: m3 | E15: 41.9 | F15: 46.74 | G15: =ROUND(E15*F15,2) -> 1958.41 | I15: 39.81 | J15: 29.22 | K15: =ROUND(I15*J15,2) -> 1163.25 | N15: =SUM(O15:S15) -> 0
A16: 200 | B16: 02.01.01.02 | C16: EXCAV.ZANJAS Y ZAPATA RT>2kg/cm2 H=2.0m | D16: m3 | E16: 1975.16 | F16: 50.99 | G16: =ROUND(E16*F16,2) -> 100713.41 | I16: 1876.4 | J16: 33.36 | K16: =ROUND(I16*J16,2) -> 62596.7 | N16: =SUM(O16:S16) -> 0
B17: 02.01.03 | C17: Rellenos
A18: 200 | B18: 02.01.03.01 | C18: RELLENO COMPACTADO C/EQUIPO MAT/PROPIO | D18: m3 | E18: 1197.91 | F18: 26.01 | G18: =ROUND(E18*F18,2) -> 31157.64 | I18: 1138.01 | J18: 15 | K18: =ROUND(I18*J18,2) -> 17070.15 | N18: =SUM(O18:S18) -> 0
B19: 02.01.04 | C19: Eliminacion de Material Excedente
A20: 200 | B20: 02.01.04.01 | C20: ACARREO INTERNO, MATERIAL PROCEDENTE DE EXCAVACIONES | D20: m3 | E20: 68.91 | F20: 17.53 | G20: =ROUND(E20*F20,2) -> 1207.99
A21: 200 | B21: 02.01.04.02 | C21: ELIMINACION MATERIAL EXCEDENTE ACARREADO | D21: M3 | E21: 68.91 | F21: 16.02 | G21: =ROUND(E21*F21,2) -> 1103.94
A22: 200 | B22: 02.01.04.03 | C22: ELIMINACION MATERIAL EXCEDENTE C/MAQUINA | D22: m3 | E22: 995.9 | F22: 21.84 | G22: =ROUND(E22*F22,2) -> 21750.46 | I22: 1118.06 | J22: 18.27 | K22: =ROUND(I22*J22,2) -> 20426.96 | N22: =SUM(O22:S22) -> 0
B23: 02.01.05 | C23: Nivelacion Interior y Apisonado
A24: 200 | B24: 02.01.05.01 | C24: ESCARIFICADO Y COMPACTACION CON PLANCHA COMPACTADORA e = 30 cm | D24: m2 | E24: 68.95 | F24: 4.72 | G24: =ROUND(E24*F24,2) -> 325.44 | I24: 70.33 | J24: 4.36 | K24: =ROUND(I24*J24,2) -> 306.64 | N24: =SUM(O24:S24) -> 0
A25: 200 | B25: 02.01.05.02 | C25: ESCARIFICADO Y COMPACTACION CON PLANCHA COMPACTADORA H=0.60m (02 CAPAS 30cm c/u) | D25: m2 | E25: 8.56 | F25: 7.85 | G25: =ROUND(E25*F25,2) -> 67.2 | I25: 8.73 | J25: 7.37 | K25: =ROUND(I25*J25,2) -> 64.34 | N25: =SUM(O25:S25) -> 0
A26: 200 | B26: 02.01.05.05 | C26: AFIRMADO DE 8" PARA PISOS,PATIOS Y VEREDAS,COMPACTADO. | D26: m2 | E26: 68.95 | F26: 15.19 | G26: =ROUND(E26*F26,2) -> 1047.35 | I26: 70.33 | J26: 11.5 | K26: =ROUND(I26*J26,2) -> 808.8 | N26: =SUM(O26:S26) -> 0
A27: 200 | B27: 02.01.05.06 | C27: AFIRMADO DE 12" EN PISOS INTERIOR/EXTERIOR,COMPACTADO. | D27: m2 | E27: 8.56 | F27: 21.79 | G27: =ROUND(E27*F27,2) -> 186.52 | I27: 8.73 | J27: 14.5 | K27: =ROUND(I27*J27,2) -> 126.59 | N27: =SUM(O27:S27) -> 0
B28: 02.02 | C28: Obras de Concreto Simple
B29: 02.02.01 | C29: Falsos Cimientos
A30: 300 | B30: 02.02.01.01 | C30: SUBCIMIENTO, SUBZAPATA MEZCLA 1:12 + 30 % P.G. | D30: m3 | E30: 323.69 | F30: 173.72 | G30: =ROUND(E30*F30,2) -> 56231.43 | I30: 330.16 | J30: 184.1 | K30: =ROUND(I30*J30,2) -> 60782.46 | N30: =SUM(O30:S30) -> 0
B31: 02.02.02 | C31: Cimientos
A32: 300 | B32: 02.02.02.02 | C32: CIMIENTOS CORRIDOS 1:10 + 30 % P.G. f'c >=100Kg/cm2 | D32: m3 | E32: 24.73 | F32: 179.78 | G32: =ROUND(E32*F32,2) -> 4445.96 | I32: 24.24 | J32: 182.46 | K32: =ROUND(I32*J32,2) -> 4422.83 | N32: =SUM(O32:S32) -> 0
A33: 400 | B33: 02.02.02.03 | C33: CIMIENTO CORRIDO - ENCOFRADO Y DESENCOFRADO | D33: m2 | E33: 23.09 | F33: 46.17 | G33: =ROUND(E33*F33,2) -> 1066.07 | I33: 22.63 | J33: 23.83 | K33: =ROUND(I33*J33,2) -> 539.27 | N33: =SUM(O33:S33) -> 0
A34: 300 | B34: 02.02.02.04 | C34: CALZADURA: CONCRETO C:H 1:10 + 30 % P.G. | D34: m3 | E34: 163.82 | F34: 179.78 | G34: =ROUND(E34*F34,2) -> 29451.56 | I34: 160.54 | J34: 207.85 | K34: =ROUND(I34*J34,2) -> 33368.24 | N34: =SUM(O34:S34) -> 0
A35: 400 | B35: 02.02.02.05 | C35: CALZADURA: ENCOFRADO Y DESENCOFRADO | D35: m2 | E35: 327.63 | F35: 37.47 | G35: =ROUND(E35*F35,2) -> 12276.3 | I35: 321.08 | J35: 26.53 | K35: =ROUND(I35*J35,2) -> 8518.25 | N35: =SUM(O35:S35) -> 0
B36: 02.02.03 | C36: Sobrecimientos
A37: 300 | B37: 02.02.03.01 | C37: SOBRECIMIENTO, CONCRETO 1:8 + 25% P.M. f'c >=100Kg/cm2 | D37: m3 | E37: 3.21 | F37: 260.59 | G37: =ROUND(E37*F37,2) -> 836.49 | I37: 3.15 | J37: 201.22 | K37: =ROUND(I37*J37,2) -> 633.84 | N37: =SUM(O37:S37) -> 0
A38: 400 | B38: 02.02.03.02 | C38: SOBRECIMIENTO, ENCOFRADO Y DESENCOFRADO | D38: m2 | E38: 43.95 | F38: 37.7 | G38: =ROUND(E38*F38,2) -> 1656.92 | I38: 43.07 | J38: 24.18 | K38: =ROUND(I38*J38,2) -> 1041.43 | N38: =SUM(O38:S38) -> 0
B39: 02.03 | C39: Obras de Concreto Armado
B40: 02.03.02 | C40: Zapatas
A41: 300 | B41: 02.03.02.01 | C41: ZAPATAS.- CONCRETO 210 kg/cm2 | D41: m3 | E41: 396.75 | F41: 292.79 | G41: =ROUND(E41*F41,2) -> 116164.43 | I41: 412.62 | J41: 286.6 | K41: =ROUND(I41*J41,2) -> 118256.89 | N41: =SUM(O41:S41) -> 0
A42: 500 | B42: 02.03.02.03 | C42: ZAPATAS.- ACERO Fy=4200 kg/cm2 | D42: KG | E42: 17534.91 | F42: 4.02 | G42: =ROUND(E42*F42,2) -> 70490.34 | I42: 17359.56 | J42: 3.4 | K42: =ROUND(I42*J42,2) -> 59022.5 | N42: =SUM(O42:S42) -> 0
...

Sheet COMPARATIVO
A1: ANALISIS DE AVANCE
A3: PROYECTO: | B3: I.E. N° 1182 "EL BOSQUE" - CERCO + INGRESOS Y CASETAS
E4: ANALISIS DE PRECIOS VENTA | L4: COSTO PREVISTO
A5: PC | B5: ITEM | C5: DESCRIPCION | D5: UND | E5: CONTRACTUAL | F5: VENTA ACTUAL | H5: VENTA PENDIENTE | J5: VENTA TOTAL | L5: PREVISTO | M5: PREVISTO ACTUAL | O5: PREVISTO PENDIENTE | Q5: PREVISTO TOTAL
E6: P.U. (S/.) | F6: METRADO EJECUTADO | G6: PARCIAL (S/.) | H6: METRADO POR EJECUT | I6: PARCIAL (S/.) | J6: METRADO CONTRATO | K6: PARCIAL (S/.) | L6: P.U. (S/.) | M6: METRADO EJECUTADO | N6: PARCIAL (S/.) | O6: METRADO POR EJECUT | P6: PARCIAL (S/.) | Q6: METRADO REAL | R6: PARCIAL (S/.)
B7: 01 | C7: OBRAS PROVISIONALES, TRABAJOS PRELIMINARES, SEGURIDAD Y SALUD
B8: 01.02 | C8: Trabajos Preliminares
B9: 01.02.04 | C9: Trazo, Niveles y Replanteo
A10: 100 | B10: 01.02.04.01 | C10: TRAZO Y REPLANTEO PRELIMINAR | D10: M2 | E10: =PRESUPUESTOS!F10 -> 2.04 | F10: =IF(Q10=0,0,((M10/Q10)*J10)) -> 0 | G10: =ROUND(E10*F10,2) -> 0 | H10: =J10-F10 -> 897.34 | I10: =ROUND(E10*H10,2) -> 1830.57 | J10: =PRESUPUESTOS!E10 -> 897.34 | K10: =ROUND(E10*J10,2) -> 1830.57 | L10: =PRESUPUESTOS!N10 -> 1.47 | N10: =ROUND(M10*L10,2) -> 0 | O10: =Q10-M10 -> 935 | P10: =ROUND(O10*L10,2) -> 1374.45 | Q10: =PRESUPUESTOS!M10 -> 935 | R10: =ROUND(Q10*L10,2) -> 1374.45
A11: 100 | B11: 01.02.04.02 | C11: TRAZO Y REPLANTEO DURANTE EL PROCESO | D11: m2 | E11: =PRESUPUESTOS!F11 -> 2.04 | F11: =IF(Q11=0,0,((M11/Q11)*J11)) -> 0 | G11: =ROUND(E11*F11,2) -> 0 | H11: =J11-F11 -> 897.34 | I11: =ROUND(E11*H11,2) -> 1830.57 | J11: =PRESUPUESTOS!E11 -> 897.34 | K11: =ROUND(E11*J11,2) -> 1830.57 | L11: =PRESUPUESTOS!N11 -> 0 | N11: =ROUND(M11*L11,2) -> 0 | O11: =Q11-M11 -> 0 | P11: =ROUND(O11*L11,2) -> 0 | Q11: =PRESUPUESTOS!M11 -> 0 | R11: =ROUND(Q11*L11,2) -> 0
B12: 02 | C12: ESTRUCTURAS
B13: 02.01 | C13: Movimiento de Tierras
B14: 02.01.01 | C14: Excavaciones
A15: 200 | B15: 02.01.01.01 | C15: EXCAV.ZANJAS Y ZAPATA RT>2kg/cm2 H=1.5m | D15: m3 | E15: =PRESUPUESTOS!F15 -> 46.74 | F15: =IF(Q15=0,0,((M15/Q15)*J15)) -> 0 | G15: =ROUND(E15*F15,2) -> 0 | H15: =J15-F15 -> 41.9 | I15: =ROUND(E15*H15,2) -> 1958.41 | J15: =PRESUPUESTOS!E15 -> 41.9 | K15: =ROUND(E15*J15,2) -> 1958.41 | L15: =PRESUPUESTOS!N15 -> 0 | N15: =ROUND(M15*L15,2) -> 0 | O15: =Q15-M15 -> 0 | P15: =ROUND(O15*L15,2) -> 0 | Q15: =PRESUPUESTOS!M15 -> 0 | R15: =ROUND(Q15*L15,2) -> 0
A16: 200 | B16: 02.01.01.02 | C16: EXCAV.ZANJAS Y ZAPATA RT>2kg/cm2 H=2.0m | D16: m3 | E16: =PRESUPUESTOS!F16 -> 50.99 | F16: =IF(Q16=0,0,((M16/Q16)*J16)) -> 0 | G16: =ROUND(E16*F16,2) -> 0 | H16: =J16-F16 -> 1975.16 | I16: =ROUND(E16*H16,2) -> 100713.41 | J16: =PRESUPUESTOS!E16 -> 1975.16 | K16: =ROUND(E16*J16,2) -> 100713.41 | L16: =PRESUPUESTOS!N16 -> 0 | N16: =ROUND(M16*L16,2) -> 0 | O16: =Q16-M16 -> 0 | P16: =ROUND(O16*L16,2) -> 0 | Q16: =PRESUPUESTOS!M16 -> 0 | R16: =ROUND(Q16*L16,2) -> 0
B17: 02.01.03 | C17: Rellenos
A18: 200 | B18: 02.01.03.01 | C18: RELLENO COMPACTADO C/EQUIPO MAT/PROPIO | D18: m3 | E18: =PRESUPUESTOS!F18 -> 26.01 | F18: =IF(Q18=0,0,((M18/Q18)*J18)) -> 0 | G18: =ROUND(E18*F18,2) -> 0 | H18: =J18-F18 -> 1197.91 | I18: =ROUND(E18*H18,2) -> 31157.64 | J18: =PRESUPUESTOS!E18 -> 1197.91 | K18: =ROUND(E18*J18,2) -> 31157.64 | L18: =PRESUPUESTOS!N18 -> 0 | N18: =ROUND(M18*L18,2) -> 0 | O18: =Q18-M18 -> 0 | P18: =ROUND(O18*L18,2) -> 0 | Q18: =PRESUPUESTOS!M18 -> 0 | R18: =ROUND(Q18*L18,2) -> 0
B19: 02.01.04 | C19: Eliminacion de Material Excedente
A20: 200 | B20: 02.01.04.01 | C20: ACARREO INTERNO, MATERIAL PROCEDENTE DE EXCAVACIONES | D20: m3 | E20: =PRESUPUESTOS!F20 -> 17.53 | F20: =IF(Q20=0,0,((M20/Q20)*J20)) -> 0 | G20: =ROUND(E20*F20,2) -> 0 | H20: =J20-F20 -> 68.91 | I20: =ROUND(E20*H20,2) -> 1207.99 | J20: =PRESUPUESTOS!E20 -> 68.91 | K20: =ROUND(E20*J20,2) -> 1207.99 | L20: =PRESUPUESTOS!N20 -> 0 | N20: =ROUND(M20*L20,2) -> 0 | O20: =Q20-M20 -> 0 | P20: =ROUND(O20*L20,2) -> 0 | Q20: =PRESUPUESTOS!M20 -> 0 | R20: =ROUND(Q20*L20,2) -> 0
A21: 200 | B21: 02.01.04.02 | C21: ELIMINACION MATERIAL EXCEDENTE ACARREADO | D21: M3 | E21: =PRESUPUESTOS!F21 -> 16.02 | F21: =IF(Q21=0,0,((M21/Q21)*J21)) -> 0 | G21: =ROUND(E21*F21,2) -> 0 | H21: =J21-F21 -> 68.91 | I21: =ROUND(E21*H21,2) -> 1103.94 | J21: =PRESUPUESTOS!E21 -> 68.91 | K21: =ROUND(E21*J21,2) -> 1103.94 | L21: =PRESUPUESTOS!N21 -> 0 | N21: =ROUND(M21*L21,2) -> 0 | O21: =Q21-M21 -> 0 | P21: =ROUND(O21*L21,2) -> 0 | Q21: =PRESUPUESTOS!M21 -> 0 | R21: =ROUND(Q21*L21,2) -> 0
A22: 200 | B22: 02.01.04.03 | C22: ELIMINACION MATERIAL EXCEDENTE C/MAQUINA | D22: m3 | E22: =PRESUPUESTOS!F22 -> 21.84 | F22: =IF(Q22=0,0,((M22/Q22)*J22)) -> 0 | G22: =ROUND(E22*F22,2) -> 0 | H22: =J22-F22 -> 995.9 | I22: =ROUND(E22*H22,2) -> 21750.46 | J22: =PRESUPUESTOS!E22 -> 995.9 | K22: =ROUND(E22*J22,2) -> 21750.46 | L22: =PRESUPUESTOS!N22 -> 0 | N22: =ROUND(M22*L22,2) -> 0 | O22: =Q22-M22 -> 0 | P22: =ROUND(O22*L22,2) -> 0 | Q22: =PRESUPUESTOS!M22 -> 0 | R22: =ROUND(Q22*L22,2) -> 0
B23: 02.01.05 | C23: Nivelacion Interior y Apisonado | E23: =PRESUPUESTOS!F23 -> 0 | F23: =IF(Q23=0,0,((M23/Q23)*J23)) -> 0 | G23: =ROUND(E23*F23,2) -> 0 | H23: =J23-F23 -> 0 | I23: =ROUND(E23*H23,2) -> 0 | J23: =PRESUPUESTOS!E23 -> 0 | K23: =ROUND(E23*J23,2) -> 0 | L23: =PRESUPUESTOS!N23 -> 0 | N23: =ROUND(M23*L23,2) -> 0 | O23: =Q23-M23 -> 0 | P23: =ROUND(O23*L23,2) -> 0 | Q23: =PRESUPUESTOS!M23 -> 0 | R23: =ROUND(Q23*L23,2) -> 0
A24: 200 | B24: 02.01.05.01 | C24: ESCARIFICADO Y COMPACTACION CON PLANCHA COMPACTADORA e = 30 cm | D24: m2 | E24: =PRESUPUESTOS!F24 -> 4.72 | F24: =IF(Q24=0,0,((M24/Q24)*J24)) -> 0 | G24: =ROUND(E24*F24,2) -> 0 | H24: =J24-F24 -> 68.95 | I24: =ROUND(E24*H24,2) -> 325.44 | J24: =PRESUPUESTOS!E24 -> 68.95 | K24: =ROUND(E24*J24,2) -> 325.44 | L24: =PRESUPUESTOS!N24 -> 0 | N24: =ROUND(M24*L24,2) -> 0 | O24: =Q24-M24 -> 0 | P24: =ROUND(O24*L24,2) -> 0 | Q24: =PRESUPUESTOS!M24 -> 0 | R24: =ROUND(Q24*L24,2) -> 0
A25: 200 | B25: 02.01.05.02 | C25: ESCARIFICADO Y COMPACTACION CON PLANCHA COMPACTADORA H=0.60m (02 CAPAS 30cm c/u) | D25: m2 | E25: =PRESUPUESTOS!F25 -> 7.85 | F25: =IF(Q25=0,0,((M25/Q25)*J25)) -> 0 | G25: =ROUND(E25*F25,2) -> 0 | H25: =J25-F25 -> 8.56 | I25: =ROUND(E25*H25,2) -> 67.2 | J25: =PRESUPUESTOS!E25 -> 8.56 | K25: =ROUND(E25*J25,2) -> 67.2 | L25: =PRESUPUESTOS!N25 -> 0 | N25: =ROUND(M25*L25,2) -> 0 | O25: =Q25-M25 -> 0 | P25: =ROUND(O25*L25,2) -> 0 | Q25: =PRESUPUESTOS!M25 -> 0 | R25: =ROUND(Q25*L25,2) -> 0
A26: 200 | B26: 02.01.05.05 | C26: AFIRMADO DE 8" PARA PISOS,PATIOS Y VEREDAS,COMPACTADO. | D26: m2 | E26: =PRESUPUESTOS!F26 -> 15.19 | F26: =IF(Q26=0,0,((M26/Q26)*J26)) -> 0 | G26: =ROUND(E26*F26,2) -> 0 | H26: =J26-F26 -> 68.95 | I26: =ROUND(E26*H26,2) -> 1047.35 | J26: =PRESUPUESTOS!E26 -> 68.95 | K26: =ROUND(E26*J26,2) -> 1047.35 | L26: =PRESUPUESTOS!N26 -> 0 | N26: =ROUND(M26*L26,2) -> 0 | O26: =Q26-M26 -> 0 | P26: =ROUND(O26*L26,2) -> 0 | Q26: =PRESUPUESTOS!M26 -> 0 | R26: =ROUND(Q26*L26,2) -> 0
A27: 200 | B27: 02.01.05.06 | C27: AFIRMADO DE 12" EN PISOS INTERIOR/EXTERIOR,COMPACTADO. | D27: m2 | E27: =PRESUPUESTOS!F27 -> 21.79 | F27: =IF(Q27=0,0,((M27/Q27)*J27)) -> 0 | G27: =ROUND(E27*F27,2) -> 0 | H27: =J27-F27 -> 8.56 | I27: =ROUND(E27*H27,2) -> 186.52 | J27: =PRESUPUESTOS!E27 -> 8.56 | K27: =ROUND(E27*J27,2) -> 186.52 | L27: =PRESUPUESTOS!N27 -> 0 | N27: =ROUND(M27*L27,2) -> 0 | O27: =Q27-M27 -> 0 | P27: =ROUND(O27*L27,2) -> 0 | Q27: =PRESUPUESTOS!M27 -> 0 | R27: =ROUND(Q27*L27,2) -> 0
B28: 02.02 | C28: Obras de Concreto Simple | E28: =PRESUPUESTOS!F28 -> 0 | F28: =IF(Q28=0,0,((M28/Q28)*J28)) -> 0 | G28: =ROUND(E28*F28,2) -> 0 | H28: =J28-F28 -> 0 | I28: =ROUND(E28*H28,2) -> 0 | J28: =PRESUPUESTOS!E28 -> 0 | K28: =ROUND(E28*J28,2) -> 0 | L28: =PRESUPUESTOS!N28 -> 0 | N28: =ROUND(M28*L28,2) -> 0 | O28: =Q28-M28 -> 0 | P28: =ROUND(O28*L28,2) -> 0 | Q28: =PRESUPUESTOS!M28 -> 0 | R28: =ROUND(Q28*L28,2) -> 0
B29: 02.02.01 | C29: Falsos Cimientos | E29: =PRESUPUESTOS!F29 -> 0 | F29: =IF(Q29=0,0,((M29/Q29)*J29)) -> 0 | G29: =ROUND(E29*F29,2) -> 0 | H29: =J29-F29 -> 0 | I29: =ROUND(E29*H29,2) -> 0 | J29: =PRESUPUESTOS!E29 -> 0 | K29: =ROUND(E29*J29,2) -> 0 | L29: =PRESUPUESTOS!N29 -> 0 | N29: =ROUND(M29*L29,2) -> 0 | O29: =Q29-M29 -> 0 | P29: =ROUND(O29*L29,2) -> 0 | Q29: =PRESUPUESTOS!M29 -> 0 | R29: =ROUND(Q29*L29,2) -> 0
A30: 300 | B30: 02.02.01.01 | C30: SUBCIMIENTO, SUBZAPATA MEZCLA 1:12 + 30 % P.G. | D30: m3 | E30: =PRESUPUESTOS!F30 -> 173.72 | F30: =IF(Q30=0,0,((M30/Q30)*J30)) -> 0 | G30: =ROUND(E30*F30,2) -> 0 | H30: =J30-F30 -> 323.69 | I30: =ROUND(E30*H30,2) -> 56231.43 | J30: =PRESUPUESTOS!E30 -> 323.69 | K30: =ROUND(E30*J30,2) -> 56231.43 | L30: =PRESUPUESTOS!N30 -> 0 | N30: =ROUND(M30*L30,2) -> 0 | O30: =Q30-M30 -> 0 | P30: =ROUND(O30*L30,2) -> 0 | Q30: =PRESUPUESTOS!M30 -> 0 | R30: =ROUND(Q30*L30,2) -> 0
B31: 02.02.02 | C31: Cimientos | E31: =PRESUPUESTOS!F31 -> 0 | F31: =IF(Q31=0,0,((M31/Q31)*J31)) -> 0 | G31: =ROUND(E31*F31,2) -> 0 | H31: =J31-F31 -> 0 | I31: =ROUND(E31*H31,2) -> 0 | J31: =PRESUPUESTOS!E31 -> 0 | K31: =ROUND(E31*J31,2) -> 0 | L31: =PRESUPUESTOS!N31 -> 0 | N31: =ROUND(M31*L31,2) -> 0 | O31: =Q31-M31 -> 0 | P31: =ROUND(O31*L31,2) -> 0 | Q31: =PRESUPUESTOS!M31 -> 0 | R31: =ROUND(Q31*L31,2) -> 0
A32: 300 | B32: 02.02.02.02 | C32: CIMIENTOS CORRIDOS 1:10 + 30 % P.G. f'c >=100Kg/cm2 | D32: m3 | E32: =PRESUPUESTOS!F32 -> 179.78 | F32: =IF(Q32=0,0,((M32/Q32)*J32)) -> 0 | G32: =ROUND(E32*F32,2) -> 0 | H32: =J32-F32 -> 24.73 | I32: =ROUND(E32*H32,2) -> 4445.96 | J32: =PRESUPUESTOS!E32 -> 24.73 | K32: =ROUND(E32*J32,2) -> 4445.96 | L32: =PRESUPUESTOS!N32 -> 0 | N32: =ROUND(M32*L32,2) -> 0 | O32: =Q32-M32 -> 0 | P32: =ROUND(O32*L32,2) -> 0 | Q32: =PRESUPUESTOS!M32 -> 0 | R32: =ROUND(Q32*L32,2) -> 0
A33: 400 | B33: 02.02.02.03 | C33: CIMIENTO CORRIDO - ENCOFRADO Y DESENCOFRADO | D33: m2 | E33: =PRESUPUESTOS!F33 -> 46.17 | F33: =IF(Q33=0,0,((M33/Q33)*J33)) -> 0 | G33: =ROUND(E33*F33,2) -> 0 | H33: =J33-F33 -> 23.09 | I33: =ROUND(E33*H33,2) -> 1066.07 | J33: =PRESUPUESTOS!E33 -> 23.09 | K33: =ROUND(E33*J33,2) -> 1066.07 | L33: =PRESUPUESTOS!N33 -> 0 | N33: =ROUND(M33*L33,2) -> 0 | O33: =Q33-M33 -> 0 | P33: =ROUND(O33*L33,2) -> 0 | Q33: =PRESUPUESTOS!M33 -> 0 | R33: =ROUND(Q33*L33,2) -> 0
A34: 300 | B34: 02.02.02.04 | C34: CALZADURA: CONCRETO C:H 1:10 + 30 % P.G. | D34: m3 | E34: =PRESUPUESTOS!F34 -> 179.78 | F34: =IF(Q34=0,0,((M34/Q34)*J34)) -> 0 | G34: =ROUND(E34*F34,2) -> 0 | H34: =J34-F34 -> 163.82 | I34: =ROUND(E34*H34,2) -> 29451.56 | J34: =PRESUPUESTOS!E34 -> 163.82 | K34: =ROUND(E34*J34,2) -> 29451.56 | L34: =PRESUPUESTOS!N34 -> 0 | N34: =ROUND(M34*L34,2) -> 0 | O34: =Q34-M34 -> 0 | P34: =ROUND(O34*L34,2) -> 0 | Q34: =PRESUPUESTOS!M34 -> 0 | R34: =ROUND(Q34*L34,2) -> 0
A35: 400 | B35: 02.02.02.05 | C35: CALZADURA: ENCOFRADO Y DESENCOFRADO | D35: m2 | E35: =PRESUPUESTOS!F35 -> 37.47 | F35: =IF(Q35=0,0,((M35/Q35)*J35)) -> 0 | G35: =ROUND(E35*F35,2) -> 0 | H35: =J35-F35 -> 327.63 | I35: =ROUND(E35*H35,2) -> 12276.3 | J35: =PRESUPUESTOS!E35 -> 327.63 | K35: =ROUND(E35*J35,2) -> 12276.3 | L35: =PRESUPUESTOS!N35 -> 0 | N35: =ROUND(M35*L35,2) -> 0 | O35: =Q35-M35 -> 0 | P35: =ROUND(O35*L35,2) -> 0 | Q35: =PRESUPUESTOS!M35 -> 0 | R35: =ROUND(Q35*L35,2) -> 0
B36: 02.02.03 | C36: Sobrecimientos | E36: =PRESUPUESTOS!F36 -> 0 | F36: =IF(Q36=0,0,((M36/Q36)*J36)) -> 0 | G36: =ROUND(E36*F36,2) -> 0 | H36: =J36-F36 -> 0 | I36: =ROUND(E36*H36,2) -> 0 | J36: =PRESUPUESTOS!E36 -> 0 | K36: =ROUND(E36*J36,2) -> 0 | L36: =PRESUPUESTOS!N36 -> 0 | N36: =ROUND(M36*L36,2) -> 0 | O36: =Q36-M36 -> 0 | P36: =ROUND(O36*L36,2) -> 0 | Q36: =PRESUPUESTOS!M36 -> 0 | R36: =ROUND(Q36*L36,2) -> 0
A37: 300 | B37: 02.02.03.01 | C37: SOBRECIMIENTO, CONCRETO 1:8 + 25% P.M. f'c >=100Kg/cm2 | D37: m3 | E37: =PRESUPUESTOS!F37 -> 260.59 | F37: =IF(Q37=0,0,((M37/Q37)*J37)) -> 0 | G37: =ROUND(E37*F37,2) -> 0 | H37: =J37-F37 -> 3.21 | I37: =ROUND(E37*H37,2) -> 836.49 | J37: =PRESUPUESTOS!E37 -> 3.21 | K37: =ROUND(E37*J37,2) -> 836.49 | L37: =PRESUPUESTOS!N37 -> 0 | N37: =ROUND(M37*L37,2) -> 0 | O37: =Q37-M37 -> 0 | P37: =ROUND(O37*L37,2) -> 0 | Q37: =PRESUPUESTOS!M37 -> 0 | R37: =ROUND(Q37*L37,2) -> 0
A38: 400 | B38: 02.02.03.02 | C38: SOBRECIMIENTO, ENCOFRADO Y DESENCOFRADO | D38: m2 | E38: =PRESUPUESTOS!F38 -> 37.7 | F38: =IF(Q38=0,0,((M38/Q38)*J38)) -> 0 | G38: =ROUND(E38*F38,2) -> 0 | H38: =J38-F38 -> 43.95 | I38: =ROUND(E38*H38,2) -> 1656.92 | J38: =PRESUPUESTOS!E38 -> 43.95 | K38: =ROUND(E38*J38,2) -> 1656.92 | L38: =PRESUPUESTOS!N38 -> 0 | N38: =ROUND(M38*L38,2) -> 0 | O38: =Q38-M38 -> 0 | P38: =ROUND(O38*L38,2) -> 0 | Q38: =PRESUPUESTOS!M38 -> 0 | R38: =ROUND(Q38*L38,2) -> 0
B39: 02.03 | C39: Obras de Concreto Armado | E39: =PRESUPUESTOS!F39 -> 0 | F39: =IF(Q39=0,0,((M39/Q39)*J39)) -> 0 | G39: =ROUND(E39*F39,2) -> 0 | H39: =J39-F39 -> 0 | I39: =ROUND(E39*H39,2) -> 0 | J39: =PRESUPUESTOS!E39 -> 0 | K39: =ROUND(E39*J39,2) -> 0 | L39: =PRESUPUESTOS!N39 -> 0 | N39: =ROUND(M39*L39,2) -> 0 | O39: =Q39-M39 -> 0 | P39: =ROUND(O39*L39,2) -> 0 | Q39: =PRESUPUESTOS!M39 -> 0 | R39: =ROUND(Q39*L39,2) -> 0
B40: 02.03.02 | C40: Zapatas | E40: =PRESUPUESTOS!F40 -> 0 | F40: =IF(Q40=0,0,((M40/Q40)*J40)) -> 0 | G40: =ROUND(E40*F40,2) -> 0 | H40: =J40-F40 -> 0 | I40: =ROUND(E40*H40,2) -> 0 | J40: =PRESUPUESTOS!E40 -> 0 | K40: =ROUND(E40*J40,2) -> 0 | L40: =PRESUPUESTOS!N40 -> 0 | N40: =ROUND(M40*L40,2) -> 0 | O40: =Q40-M40 -> 0 | P40: =ROUND(O40*L40,2) -> 0 | Q40: =PRESUPUESTOS!M40 -> 0 | R40: =ROUND(Q40*L40,2) -> 0
A41: 300 | B41: 02.03.02.01 | C41: ZAPATAS.- CONCRETO 210 kg/cm2 | D41: m3 | E41: =PRESUPUESTOS!F41 -> 292.79 | F41: =IF(Q41=0,0,((M41/Q41)*J41)) -> 0 | G41: =ROUND(E41*F41,2) -> 0 | H41: =J41-F41 -> 396.75 | I41: =ROUND(E41*H41,2) -> 116164.43 | J41: =PRESUPUESTOS!E41 -> 396.75 | K41: =ROUND(E41*J41,2) -> 116164.43 | L41: =PRESUPUESTOS!N41 -> 0 | N41: =ROUND(M41*L41,2) -> 0 | O41: =Q41-M41 -> 0 | P41: =ROUND(O41*L41,2) -> 0 | Q41: =PRESUPUESTOS!M41 -> 0 | R41: =ROUND(Q41*L41,2) -> 0
...

Sheet RESUMEN - ANALISIS
A1: RESUMEN
A3: PROYECTO: | B3: I.E. N° 1182 "EL BOSQUE" - CERCO + INGRESOS Y CASETAS
C4: ANALISIS DE PRECIOS VENTA | F4: COSTO PREVISTO | I4: COSTO REAL
A5: CODIGO | B5: PARTIDA DE CONTROL | C5: COSTO TOTAL VENTA | D5: % | E5: COSTO EJECUTADO VENTA | F5: COSTO TOTAL META | G5: % | H5: COSTO EJECUTADO META | I5: COSTO EJECUTADO REAL | J5: MANO DE OBRA | K5: MATERIALES | L5: EQUIPOS | M5: SERVICIOS | N5: SUBCONTRATOS | O5: BRECHA (META - REAL)
B6: PRESUPUESTO CONTRACTUAL
A7: 100 | B7: OBRAS PROVISIONALES | C7: =SUMIF(COMPARATIVO!$A$7:$A$70,'RESUMEN - ANALISIS'!A7,COMPARATIVO!$K$7:$K$70) -> 3661.14 | D7: =E7/C7 -> 0 | E7: =SUMIF(COMPARATIVO!$A$7:$A$70,'RESUMEN - ANALISIS'!A7,COMPARATIVO!$G$7:$G$70) -> 0 | F7: =SUMIF(COMPARATIVO!$A$7:$A$70,'RESUMEN - ANALISIS'!A7,COMPARATIVO!$R$7:$R$70) -> 1374.45 | G7: =H7/F7 -> 0 | H7: =SUMIF(COMPARATIVO!$A$7:$A$70,'RESUMEN - ANALISIS'!A7,COMPARATIVO!$N$7:$N$70) -> 0 | I7: =SUM(J7:N7) -> 229.25 | N7: 229.25 | O7: =H7-I7 -> -229.25
A8: 200 | B8: MOVIMIENTO DE TIERRAS | C8: =SUMIF(COMPARATIVO!$A$7:$A$70,'RESUMEN - ANALISIS'!A8,COMPARATIVO!$K$7:$K$70) -> 159518.36 | D8: =E8/C8 -> 0 | E8: =SUMIF(COMPARATIVO!$A$7:$A$70,'RESUMEN - ANALISIS'!A8,COMPARATIVO!$G$7:$G$70) -> 0 | F8: =SUMIF(COMPARATIVO!$A$7:$A$70,'RESUMEN - ANALISIS'!A8,COMPARATIVO!$R$7:$R$70) -> 0 | G8: =H8/F8 -> #DIV/0! | H8: =SUMIF(COMPARATIVO!$A$7:$A$70,'RESUMEN - ANALISIS'!A8,COMPARATIVO!$N$7:$N$70) -> 0 | I8: =SUM(J8:N8) -> 7319.59 | J8: 200 | N8: 7119.59 | O8: =H8-I8 -> -7319.59
A9: 300 | B9: CONCRETO | C9: =SUMIF(COMPARATIVO!$A$7:$A$70,'RESUMEN - ANALISIS'!A9,COMPARATIVO!$K$7:$K$70) -> 360886.42 | D9: =E9/C9 -> 0 | E9: =SUMIF(COMPARATIVO!$A$7:$A$70,'RESUMEN - ANALISIS'!A9,COMPARATIVO!$G$7:$G$70) -> 0 | F9: =SUMIF(COMPARATIVO!$A$7:$A$70,'RESUMEN - ANALISIS'!A9,COMPARATIVO!$R$7:$R$70) -> 0 | G9: =H9/F9 -> #DIV/0! | H9: =SUMIF(COMPARATIVO!$A$7:$A$70,'RESUMEN - ANALISIS'!A9,COMPARATIVO!$N$7:$N$70) -> 0 | I9: =SUM(J9:N9) -> 17915.1 | N9: 17915.1 | O9: =H9-I9 -> -17915.1
A10: 400 | B10: ENCOFRADO | C10: =SUMIF(COMPARATIVO!$A$7:$A$70,'RESUMEN - ANALISIS'!A10,COMPARATIVO!$K$7:$K$70) -> 221395.36 | D10: =E10/C10 -> 0 | E10: =SUMIF(COMPARATIVO!$A$7:$A$70,'RESUMEN - ANALISIS'!A10,COMPARATIVO!$G$7:$G$70) -> 0 | F10: =SUMIF(COMPARATIVO!$A$7:$A$70,'RESUMEN - ANALISIS'!A10,COMPARATIVO!$R$7:$R$70) -> 0 | G10: =H10/F10 -> #DIV/0! | H10: =SUMIF(COMPARATIVO!$A$7:$A$70,'RESUMEN - ANALISIS'!A10,COMPARATIVO!$N$7:$N$70) -> 0 | I10: =SUM(J10:N10) -> 0
A11: 500 | B11: ACERO | C11: =SUMIF(COMPARATIVO!$A$7:$A$70,'RESUMEN - ANALISIS'!A11,COMPARATIVO!$K$7:$K$70) -> 215263.24 | D11: =E11/C11 -> 0 | E11: =SUMIF(COMPARATIVO!$A$7:$A$70,'RESUMEN - ANALISIS'!A11,COMPARATIVO!$G$7:$G$70) -> 0 | F11: =SUMIF(COMPARATIVO!$A$7:$A$70,'RESUMEN - ANALISIS'!A11,COMPARATIVO!$R$7:$R$70) -> 0 | G11: =H11/F11 -> #DIV/0! | H11: =SUMIF(COMPARATIVO!$A$7:$A$70,'RESUMEN - ANALISIS'!A11,COMPARATIVO!$N$7:$N$70) -> 0 | I11: =SUM(J11:N11) -> 696.08 | J11: 55 | N11: 641.08 | O11: =H11-I11 -> -696.08
B12: TOTALES | C12: =SUM(C7:C11) -> 960724.52 | E12: =SUM(E7:E11) -> 0 | F12: =SUM(F7:F11) -> 1374.45 | H12: =SUM(H7:H11) -> 0 | I12: =SUM(I7:I11) -> 26160.02 | J12: =SUM(J7:J11) -> 255 | K12: =SUM(K7:K11) -> 0 | L12: =SUM(L7:L11) -> 0 | M12: =SUM(M7:M11) -> 0 | N12: =SUM(N7:N11) -> 25905.02 | O12: =SUM(O7:O11) -> -26160.02
B15: RESUMEN | C15: ACUM A MARZO 2023 | E15: META TOTAL | F15: META ANTERIOR | H15: DIFERENCIA
B17: TOTAL COSTO REAL | C17: =I12 -> 26160.02 | E17: =F12 -> 1374.45 | H17: =+F17-E17 -> -1374.45
B19: TOTAL COSTO VENTA | C19: =E12 -> 0 | E19: =C12 -> 960724.52 | H19: =+F19-E19 -> -960724.52
B21: RESULTADO OPERATIVO | C21: =C19-C17 -> -26160.02 | E21: =E19-E17 -> 959350.07 | F21: =F19-F17 -> 0
B22: MARGEN DE UTILIDAD | C22: =C21/C19 -> #DIV/0! | E22: =E21/E19 -> 0.99856936 | F22: =F21/F19 -> #DIV/0!

Sheet DIFERENCIAS
C3: VENTA (S/) | E3: META TOTAL (S/) | I3: META TOTAL (MES ANTERIOR) (S/) | M3: META INICIAL (S/)
A4: UC | B4: DESCRIPCIÓN | C4: INGRESO PREVISTO TOTAL | E4: COSTO PREVISTO | F4: RENTABILIDAD | I4: COSTO PREVISTO | J4: RENTABILIDAD | M4: COSTO PREVISTO | N4: RENTABILIDAD | Q4: DESVIACIONES (META INICIAL TOTAL- META TOTAL)
B5: PRESUPUESTO CONTRACTUAL
A6: 100 | B6: OBRAS PROVISIONALES | C6: =+'RESUMEN - ANALISIS'!C7 -> 3661.14 | E6: =+'RESUMEN - ANALISIS'!F7 -> 1374.45 | F6: =C6-E6 -> 2286.69 | G6: =+F6/C6 -> 0.62458415 | J6: =C6-I6 -> 3661.14 | K6: =J6/C6 -> 1 | N6: =C6-M6 -> 3661.14 | O6: =N6/C6 -> 1 | Q6: =E6-M6 -> 1374.45 | R6: =M6/E6 -> 0
A7: 200 | B7: MOVIMIENTO DE TIERRAS | C7: =+'RESUMEN - ANALISIS'!C8 -> 159518.36 | E7: =+'RESUMEN - ANALISIS'!F8 -> 0 | F7: =C7-E7 -> 159518.36 | G7: =+F7/C7 -> 1 | J7: =C7-I7 -> 159518.36 | K7: =J7/C7 -> 1 | N7: =C7-M7 -> 159518.36 | O7: =N7/C7 -> 1 | Q7: =E7-M7 -> 0 | R7: =M7/E7 -> #DIV/0!
A8: 300 | B8: CONCRETO | C8: =+'RESUMEN - ANALISIS'!C9 -> 360886.42 | E8: =+'RESUMEN - ANALISIS'!F9 -> 0 | F8: =C8-E8 -> 360886.42 | G8: =+F8/C8 -> 1 | J8: =C8-I8 -> 360886.42 | K8: =J8/C8 -> 1 | N8: =C8-M8 -> 360886.42 | O8: =N8/C8 -> 1 | Q8: =E8-M8 -> 0 | R8: =M8/E8 -> #DIV/0!
A9: 400 | B9: ENCOFRADO | C9: =+'RESUMEN - ANALISIS'!C10 -> 221395.36 | E9: =+'RESUMEN - ANALISIS'!F10 -> 0 | F9: =C9-E9 -> 221395.36 | G9: =+F9/C9 -> 1 | J9: =C9-I9 -> 221395.36 | K9: =J9/C9 -> 1 | N9: =C9-M9 -> 221395.36 | O9: =N9/C9 -> 1 | Q9: =E9-M9 -> 0 | R9: =M9/E9 -> #DIV/0!
A10: 500 | B10: ACERO | C10: =+'RESUMEN - ANALISIS'!C11 -> 215263.24 | E10: =+'RESUMEN - ANALISIS'!F11 -> 0 | F10: =C10-E10 -> 215263.24 | G10: =+F10/C10 -> 1 | J10: =C10-I10 -> 215263.24 | K10: =J10/C10 -> 1 | N10: =C10-M10 -> 215263.24 | O10: =N10/C10 -> 1 | Q10: =E10-M10 -> 0 | R10: =M10/E10 -> #DIV/0!
A11: TOTALES VENTA Y COSTE DIRECTO | C11: =SUM(C5:C10) -> 960724.52 | E11: =SUM(E5:E10) -> 1374.45 | F11: =C11-E11 -> 959350.07 | G11: =F11/C11 -> 0.99856936 | I11: =SUM(I5:I10) -> 0 | J11: =C11-I11 -> 960724.52 | K11: =J11/C11 -> 1 | M11: =SUM(M5:M10) -> 0 | N11: =C11-M11 -> 960724.52 | O11: =N11/C11 -> 1 | Q11: =SUM(Q5:Q10) -> 1374.45 | R11: =E11/M11 -> #DIV/0!

Sheet COSTOS INCURRIDOS
A2: ITEM | B2: DESCRIPCION | C2: PROVEEDOR | D2: UNIDAD | E2: CANTIDAD | F2: P.U. | G2: SUBTOTAL | H2: PARTIDA DE CONTROL | I2: TIPO DE COSTO | J2: METRADO UTILIZADO | K2: SUB TOTAL
B3: ORDENES DE COMPRA
A4: 1 | B4: MATERIAL AFIRMADO | C4: CANTERA ECONOMICA | D4: m3 | E4: 500 | F4: 120 | G4: =+E4*F4 -> 60000 | H4: 200 | I4: MATERIALES | J4: 130 | K4: =+J4*F4 -> 15600
B11: ORDENES DE SERVICIO
A12: 1 | B12: ALQUILER DE VOLQUETES | C12: NEGOCIOS DIAZ | D12: hm | E12: 50 | F12: 180 | G12: =+E12*F12 -> 9000 | H12: 200 | I12: SERVICIOS | J12: 35 | K12: =+J12*F12 -> 6300

Sheet CRONOG CONT VENTA
A1: CRONOGRAMA VALORIZADO DE OBRA - PROGRAMACION VENTA
A3: PROYECTO: | B3: I.E. N° 1182 "EL BOSQUE" - CERCO + INGRESOS Y CASETAS
A5: ITEM | B5: DESCRIPCION | C5: UND | D5: CONTRACTUAL | G5: PROGRAMACION
D6: METRADO | E6: P.U. (S/.) | F6: PARCIAL (S/.) | G6: 45474 | H6: 45505 | I6: 45536 | J6: 45566 | K6: 45597
A7: 01 | B7: OBRAS PROVISIONALES, TRABAJOS PRELIMINARES, SEGURIDAD Y SALUD
A8: 01.02 | B8: Trabajos Preliminares
A9: 01.02.04 | B9: Trazo, Niveles y Replanteo
A10: 01.02.04.01 | B10: TRAZO Y REPLANTEO PRELIMINAR | C10: M2 | D10: 897.34 | E10: 2.04 | F10: 1830.57 | G10: =$F10*N10 -> 915.285 | H10: =$F10*O10 -> 915.285 | I10: =$F10*P10 -> 0 | J10: =$F10*Q10 -> 0 | K10: =$F10*R10 -> 0 | L10: =F10-SUM(G10:K10) -> 0 | N10: 0.5 | O10: 0.5
A11: 01.02.04.02 | B11: TRAZO Y REPLANTEO DURANTE EL PROCESO | C11: m2 | D11: 897.34 | E11: 2.04 | F11: 1830.57 | G11: =$F11*N11 -> 457.6425 | H11: =$F11*O11 -> 457.6425 | I11: =$F11*P11 -> 457.6425 | J11: =$F11*Q11 -> 457.6425 | K11: =$F11*R11 -> 0 | L11: =F11-SUM(G11:K11) -> 0 | N11: 0.25 | O11: 0.25 | P11: 0.25 | Q11: 0.25
A12: 02 | B12: ESTRUCTURAS
A13: 02.01 | B13: Movimiento de Tierras
A14: 02.01.01 | B14: Excavaciones
A15: 02.01.01.01 | B15: EXCAV.ZANJAS Y ZAPATA RT>2kg/cm2 H=1.5m | C15: m3 | D15: 41.9 | E15: 46.74 | F15: 1958.41 | G15: =$F15*N15 -> 979.205 | H15: =$F15*O15 -> 979.205 | I15: =$F15*P15 -> 0 | J15: =$F15*Q15 -> 0 | K15: =$F15*R15 -> 0 | L15: =F15-SUM(G15:K15) -> 0 | N15: 0.5 | O15: 0.5
A16: 02.01.01.02 | B16: EXCAV.ZANJAS Y ZAPATA RT>2kg/cm2 H=2.0m | C16: m3 | D16: 1975.16 | E16: 50.99 | F16: 100713.41 | G16: =$F16*N16 -> 50356.705 | H16: =$F16*O16 -> 50356.705 | I16: =$F16*P16 -> 0 | J16: =$F16*Q16 -> 0 | K16: =$F16*R16 -> 0 | L16: =F16-SUM(G16:K16) -> 0 | N16: 0.5 | O16: 0.5
A17: 02.01.03 | B17: Rellenos
A18: 02.01.03.01 | B18: RELLENO COMPACTADO C/EQUIPO MAT/PROPIO | C18: m3 | D18: 1197.91 | E18: 26.01 | F18: 31157.64 | G18: =$F18*N18 -> 0 | H18: =$F18*O18 -> 15578.82 | I18: =$F18*P18 -> 15578.82 | J18: =$F18*Q18 -> 0 | K18: =$F18*R18 -> 0 | L18: =F18-SUM(G18:K18) -> 0 | O18: 0.5 | P18: 0.5
A19: 02.01.04 | B19: Eliminacion de Material Excedente
A20: 02.01.04.01 | B20: ACARREO INTERNO, MATERIAL PROCEDENTE DE EXCAVACIONES | C20: m3 | D20: 68.91 | E20: 17.53 | F20: 1207.99 | G20: =$F20*N20 -> 362.397 | H20: =$F20*O20 -> 603.995 | I20: =$F20*P20 -> 241.598 | J20: =$F20*Q20 -> 0 | K20: =$F20*R20 -> 0 | L20: =F20-SUM(G20:K20) -> 0 | N20: 0.3 | O20: 0.5 | P20: 0.2
A21: 02.01.04.02 | B21: ELIMINACION MATERIAL EXCEDENTE ACARREADO | C21: M3 | D21: 68.91 | E21: 16.02 | F21: 1103.94 | G21: =$F21*N21 -> 331.182 | H21: =$F21*O21 -> 331.182 | I21: =$F21*P21 -> 441.576 | J21: =$F21*Q21 -> 0 | K21: =$F21*R21 -> 0 | L21: =F21-SUM(G21:K21) -> 0 | N21: 0.3 | O21: 0.3 | P21: 0.4
A22: 02.01.04.03 | B22: ELIMINACION MATERIAL EXCEDENTE C/MAQUINA | C22: m3 | D22: 995.9 | E22: 21.84 | F22: 21750.46 | G22: =$F22*N22 -> 6525.138 | H22: =$F22*O22 -> 6525.138 | I22: =$F22*P22 -> 8700.184 | J22: =$F22*Q22 -> 0 | K22: =$F22*R22 -> 0 | L22: =F22-SUM(G22:K22) -> 0 | N22: 0.3 | O22: 0.3 | P22: 0.4
A23: 02.01.05 | B23: Nivelacion Interior y Apisonado
A24: 02.01.05.01 | B24: ESCARIFICADO Y COMPACTACION CON PLANCHA COMPACTADORA e = 30 cm | C24: m2 | D24: 68.95 | E24: 4.72 | F24: 325.44 | G24: =$F24*N24 -> 65.088 | H24: =$F24*O24 -> 130.176 | I24: =$F24*P24 -> 130.176 | J24: =$F24*Q24 -> 0 | K24: =$F24*R24 -> 0 | L24: =F24-SUM(G24:K24) -> 0 | N24: 0.2 | O24: 0.4 | P24: 0.4
A25: 02.01.05.02 | B25: ESCARIFICADO Y COMPACTACION CON PLANCHA COMPACTADORA H=0.60m (02 CAPAS 30cm c/u) | C25: m2 | D25: 8.56 | E25: 7.85 | F25: 67.2 | G25: =$F25*N25 -> 13.44 | H25: =$F25*O25 -> 26.88 | I25: =$F25*P25 -> 26.88 | J25: =$F25*Q25 -> 0 | K25: =$F25*R25 -> 0 | L25: =F25-SUM(G25:K25) -> 0 | N25: 0.2 | O25: 0.4 | P25: 0.4
A26: 02.01.05.05 | B26: AFIRMADO DE 8" PARA PISOS,PATIOS Y VEREDAS,COMPACTADO. | C26: m2 | D26: 68.95 | E26: 15.19 | F26: 1047.35 | G26: =$F26*N26 -> 209.47 | H26: =$F26*O26 -> 418.94 | I26: =$F26*P26 -> 418.94 | J26: =$F26*Q26 -> 0 | K26: =$F26*R26 -> 0 | L26: =F26-SUM(G26:K26) -> 0 | N26: 0.2 | O26: 0.4 | P26: 0.4
A27: 02.01.05.06 | B27: AFIRMADO DE 12" EN PISOS INTERIOR/EXTERIOR,COMPACTADO. | C27: m2 | D27: 8.56 | E27: 21.79 | F27: 186.52 | G27: =$F27*N27 -> 37.304 | H27: =$F27*O27 -> 74.608 | I27: =$F27*P27 -> 74.608 | J27: =$F27*Q27 -> 0 | K27: =$F27*R27 -> 0 | L27: =F27-SUM(G27:K27) -> 0 | N27: 0.2 | O27: 0.4 | P27: 0.4
A28: 02.02 | B28: Obras de Concreto Simple
A29: 02.02.01 | B29: Falsos Cimientos
A30: 02.02.01.01 | B30: SUBCIMIENTO, SUBZAPATA MEZCLA 1:12 + 30 % P.G. | C30: m3 | D30: 323.69 | E30: 173.72 | F30: 56231.43 | G30: =$F30*N30 -> 0 | H30: =$F30*O30 -> 28115.715 | I30: =$F30*P30 -> 28115.715 | J30: =$F30*Q30 -> 0 | K30: =$F30*R30 -> 0 | L30: =F30-SUM(G30:K30) -> 0 | O30: 0.5 | P30: 0.5
A31: 02.02.02 | B31: Cimientos
A32: 02.02.02.02 | B32: CIMIENTOS CORRIDOS 1:10 + 30 % P.G. f'c >=100Kg/cm2 | C32: m3 | D32: 24.73 | E32: 179.78 | F32: 4445.96 | G32: =$F32*N32 -> 0 | H32: =$F32*O32 -> 0 | I32: =$F32*P32 -> 2222.98 | J32: =$F32*Q32 -> 2222.98 | K32: =$F32*R32 -> 0 | L32: =F32-SUM(G32:K32) -> 0 | P32: 0.5 | Q32: 0.5
A33: 02.02.02.03 | B33: CIMIENTO CORRIDO - ENCOFRADO Y DESENCOFRADO | C33: m2 | D33: 23.09 | E33: 46.17 | F33: 1066.07 | G33: =$F33*N33 -> 0 | H33: =$F33*O33 -> 426.428 | I33: =$F33*P33 -> 426.428 | J33: =$F33*Q33 -> 213.214 | K33: =$F33*R33 -> 0 | L33: =F33-SUM(G33:K33) -> 0 | O33: 0.4 | P33: 0.4 | Q33: 0.2
A34: 02.02.02.04 | B34: CALZADURA: CONCRETO C:H 1:10 + 30 % P.G. | C34: m3 | D34: 163.82 | E34: 179.78 | F34: 29451.56 | G34: =$F34*N34 -> 29451.56 | H34: =$F34*O34 -> 0 | I34: =$F34*P34 -> 0 | J34: =$F34*Q34 -> 0 | K34: =$F34*R34 -> 0 | L34: =F34-SUM(G34:K34) -> 0 | N34: 1
A35: 02.02.02.05 | B35: CALZADURA: ENCOFRADO Y DESENCOFRADO | C35: m2 | D35: 327.63 | E35: 37.47 | F35: 12276.3 | G35: =$F35*N35 -> 12276.3 | H35: =$F35*O35 -> 0 | I35: =$F35*P35 -> 0 | J35: =$F35*Q35 -> 0 | K35: =$F35*R35 -> 0 | L35: =F35-SUM(G35:K35) -> 0 | N35: 1
A36: 02.02.03 | B36: Sobrecimientos
A37: 02.02.03.01 | B37: SOBRECIMIENTO, CONCRETO 1:8 + 25% P.M. f'c >=100Kg/cm2 | C37: m3 | D37: 3.21 | E37: 260.59 | F37: 836.49 | G37: =$F37*N37 -> 0 | H37: =$F37*O37 -> 0 | I37: =$F37*P37 -> 418.245 | J37: =$F37*Q37 -> 418.245 | K37: =$F37*R37 -> 0 | L37: =F37-SUM(G37:K37) -> 0 | P37: 0.5 | Q37: 0.5
A38: 02.02.03.02 | B38: SOBRECIMIENTO, ENCOFRADO Y DESENCOFRADO | C38: m2 | D38: 43.95 | E38: 37.7 | F38: 1656.92 | G38: =$F38*N38 -> 0 | H38: =$F38*O38 -> 662.768 | I38: =$F38*P38 -> 662.768 | J38: =$F38*Q38 -> 331.384 | K38: =$F38*R38 -> 0 | L38: =F38-SUM(G38:K38) -> 0 | O38: 0.4 | P38: 0.4 | Q38: 0.2
A39: 02.03 | B39: Obras de Concreto Armado
A40: 02.03.02 | B40: Zapatas
A41: 02.03.02.01 | B41: ZAPATAS.- CONCRETO 210 kg/cm2 | C41: m3 | D41: 396.75 | E41: 292.79 | F41: 116164.43 | G41: =$F41*N41 -> 34849.329 | H41: =$F41*O41 -> 81315.101 | I41: =$F41*P41 -> 0 | J41: =$F41*Q41 -> 0 | K41: =$F41*R41 -> 0 | L41: =F41-SUM(G41:K41) -> 0 | N41: 0.3 | O41: 0.7
A42: 02.03.02.03 | B42: ZAPATAS.- ACERO Fy=4200 kg/cm2 | C42: KG | D42: 17534.91 | E42: 4.02 | F42: 70490.34 | G42: =$F42*N42 -> 21147.102 | H42: =$F42*O42 -> 49343.238 | I42: =$F42*P42 -> 0 | J42: =$F42*Q42 -> 0 | K42: =$F42*R42 -> 0 | L42: =F42-SUM(G42:K42) -> 0 | N42: 0.3 | O42: 0.7
...

Sheet CRONOG CONT META
A1: CRONOGRAMA VALORIZADO DE OBRA - PROGRAMACION VENTA CON COSTOS META
A3: PROYECTO: | B3: I.E. N° 1182 "EL BOSQUE" - CERCO + INGRESOS Y CASETAS
A5: ITEM | B5: DESCRIPCION | C5: UND | D5: CONTRACTUAL | G5: PROGRAMACION
D6: METRADO | E6: P.U. (S/.) | F6: PARCIAL (S/.) | G6: 45474 | H6: 45505 | I6: 45536 | J6: 45566 | K6: 45597
A7: 01 | B7: OBRAS PROVISIONALES, TRABAJOS PRELIMINARES, SEGURIDAD Y SALUD
A8: 01.02 | B8: Trabajos Preliminares
A9: 01.02.04 | B9: Trazo, Niveles y Replanteo
A10: 01.02.04.01 | B10: TRAZO Y REPLANTEO PRELIMINAR | C10: M2 | D10: 942.21 | E10: 1.33 | F10: 1253.14 | G10: =$F10*N10 -> 626.57 | H10: =$F10*O10 -> 626.57 | I10: =$F10*P10 -> 0 | J10: =$F10*Q10 -> 0 | K10: =$F10*R10 -> 0 | L10: =F10-SUM(G10:K10) -> 0 | N10: 0.5 | O10: 0.5
A11: 01.02.04.02 | B11: TRAZO Y REPLANTEO DURANTE EL PROCESO | C11: m2 | D11: 942.21 | E11: 1.33 | F11: 1253.14 | G11: =$F11*N11 -> 313.285 | H11: =$F11*O11 -> 313.285 | I11: =$F11*P11 -> 313.285 | J11: =$F11*Q11 -> 313.285 | K11: =$F11*R11 -> 0 | L11: =F11-SUM(G11:K11) -> 0 | N11: 0.25 | O11: 0.25 | P11: 0.25 | Q11: 0.25
A12: 02 | B12: ESTRUCTURAS
A13: 02.01 | B13: Movimiento de Tierras
A14: 02.01.01 | B14: Excavaciones
A15: 02.01.01.01 | B15: EXCAV.ZANJAS Y ZAPATA RT>2kg/cm2 H=1.5m | C15: m3 | D15: 39.81 | E15: 29.22 | F15: 1163.25 | G15: =$F15*N15 -> 581.625 | H15: =$F15*O15 -> 581.625 | I15: =$F15*P15 -> 0 | J15: =$F15*Q15 -> 0 | K15: =$F15*R15 -> 0 | L15: =F15-SUM(G15:K15) -> 0 | N15: 0.5 | O15: 0.5
A16: 02.01.01.02 | B16: EXCAV.ZANJAS Y ZAPATA RT>2kg/cm2 H=2.0m | C16: m3 | D16: 1876.4 | E16: 33.36 | F16: 62596.7 | G16: =$F16*N16 -> 31298.35 | H16: =$F16*O16 -> 31298.35 | I16: =$F16*P16 -> 0 | J16: =$F16*Q16 -> 0 | K16: =$F16*R16 -> 0 | L16: =F16-SUM(G16:K16) -> 0 | N16: 0.5 | O16: 0.5
A17: 02.01.03 | B17: Rellenos
A18: 02.01.03.01 | B18: RELLENO COMPACTADO C/EQUIPO MAT/PROPIO | C18: m3 | D18: 1138.01 | E18: 15 | F18: 17070.15 | G18: =$F18*N18 -> 0 | H18: =$F18*O18 -> 8535.075 | I18: =$F18*P18 -> 8535.075 | J18: =$F18*Q18 -> 0 | K18: =$F18*R18 -> 0 | L18: =F18-SUM(G18:K18) -> 0 | O18: 0.5 | P18: 0.5
A19: 02.01.04 | B19: Eliminacion de Material Excedente
A20: 02.01.04.01 | B20: ACARREO INTERNO, MATERIAL PROCEDENTE DE EXCAVACIONES | C20: m3 | D20: 1118.06 | E20: 18.27 | F20: 20426.96 | G20: =$F20*N20 -> 6128.088 | H20: =$F20*O20 -> 10213.48 | I20: =$F20*P20 -> 4085.392 | J20: =$F20*Q20 -> 0 | K20: =$F20*R20 -> 0 | L20: =F20-SUM(G20:K20) -> 0 | N20: 0.3 | O20: 0.5 | P20: 0.2
A21: 02.01.04.02 | B21: ELIMINACION MATERIAL EXCEDENTE ACARREADO | C21: M3 | G21: =$F21*N21 -> 0 | H21: =$F21*O21 -> 0 | I21: =$F21*P21 -> 0 | J21: =$F21*Q21 -> 0 | K21: =$F21*R21 -> 0 | L21: =F21-SUM(G21:K21) -> 0 | N21: 0.3 | O21: 0.3 | P21: 0.4
A22: 02.01.04.03 | B22: ELIMINACION MATERIAL EXCEDENTE C/MAQUINA | C22: m3 | G22: =$F22*N22 -> 0 | H22: =$F22*O22 -> 0 | I22: =$F22*P22 -> 0 | J22: =$F22*Q22 -> 0 | K22: =$F22*R22 -> 0 | L22: =F22-SUM(G22:K22) -> 0 | N22: 0.3 | O22: 0.3 | P22: 0.4
A23: 02.01.05 | B23: Nivelacion Interior y Apisonado
A24: 02.01.05.01 | B24: ESCARIFICADO Y COMPACTACION CON PLANCHA COMPACTADORA e = 30 cm | C24: m2 | D24: 70.33 | E24: 4.36 | F24: 306.64 | G24: =$F24*N24 -> 61.328 | H24: =$F24*O24 -> 122.656 | I24: =$F24*P24 -> 122.656 | J24: =$F24*Q24 -> 0 | K24: =$F24*R24 -> 0 | L24: =F24-SUM(G24:K24) -> 0 | N24: 0.2 | O24: 0.4 | P24: 0.4
A25: 02.01.05.02 | B25: ESCARIFICADO Y COMPACTACION CON PLANCHA COMPACTADORA H=0.60m (02 CAPAS 30cm c/u) | C25: m2 | D25: 8.73 | E25: 7.37 | F25: 64.34 | G25: =$F25*N25 -> 12.868 | H25: =$F25*O25 -> 25.736 | I25: =$F25*P25 -> 25.736 | J25: =$F25*Q25 -> 0 | K25: =$F25*R25 -> 0 | L25: =F25-SUM(G25:K25) -> 0 | N25: 0.2 | O25: 0.4 | P25: 0.4
A26: 02.01.05.05 | B26: AFIRMADO DE 8" PARA PISOS,PATIOS Y VEREDAS,COMPACTADO. | C26: m2 | D26: 70.33 | E26: 11.5 | F26: 808.8 | G26: =$F26*N26 -> 161.76 | H26: =$F26*O26 -> 323.52 | I26: =$F26*P26 -> 323.52 | J26: =$F26*Q26 -> 0 | K26: =$F26*R26 -> 0 | L26: =F26-SUM(G26:K26) -> 0 | N26: 0.2 | O26: 0.4 | P26: 0.4
A27: 02.01.05.06 | B27: AFIRMADO DE 12" EN PISOS INTERIOR/EXTERIOR,COMPACTADO. | C27: m2 | D27: 8.73 | E27: 14.5 | F27: 126.59 | G27: =$F27*N27 -> 25.318 | H27: =$F27*O27 -> 50.636 | I27: =$F27*P27 -> 50.636 | J27: =$F27*Q27 -> 0 | K27: =$F27*R27 -> 0 | L27: =F27-SUM(G27:K27) -> 0 | N27: 0.2 | O27: 0.4 | P27: 0.4
A28: 02.02 | B28: Obras de Concreto Simple
A29: 02.02.01 | B29: Falsos Cimientos
A30: 02.02.01.01 | B30: SUBCIMIENTO, SUBZAPATA MEZCLA 1:12 + 30 % P.G. | C30: m3 | D30: 330.16 | E30: 184.1 | F30: 60782.46 | G30: =$F30*N30 -> 0 | H30: =$F30*O30 -> 30391.23 | I30: =$F30*P30 -> 30391.23 | J30: =$F30*Q30 -> 0 | K30: =$F30*R30 -> 0 | L30: =F30-SUM(G30:K30) -> 0 | O30: 0.5 | P30: 0.5
A31: 02.02.02 | B31: Cimientos
A32: 02.02.02.02 | B32: CIMIENTOS CORRIDOS 1:10 + 30 % P.G. f'c >=100Kg/cm2 | C32: m3 | D32: 24.24 | E32: 182.46 | F32: 4422.83 | G32: =$F32*N32 -> 0 | H32: =$F32*O32 -> 0 | I32: =$F32*P32 -> 2211.415 | J32: =$F32*Q32 -> 2211.415 | K32: =$F32*R32 -> 0 | L32: =F32-SUM(G32:K32) -> 0 | P32: 0.5 | Q32: 0.5
A33: 02.02.02.03 | B33: CIMIENTO CORRIDO - ENCOFRADO Y DESENCOFRADO | C33: m2 | D33: 22.63 | E33: 23.83 | F33: 539.27 | G33: =$F33*N33 -> 0 | H33: =$F33*O33 -> 215.708 | I33: =$F33*P33 -> 215.708 | J33: =$F33*Q33 -> 107.854 | K33: =$F33*R33 -> 0 | L33: =F33-SUM(G33:K33) -> 0 | O33: 0.4 | P33: 0.4 | Q33: 0.2
A34: 02.02.02.04 | B34: CALZADURA: CONCRETO C:H 1:10 + 30 % P.G. | C34: m3 | D34: 160.54 | E34: 207.85 | F34: 33368.24 | G34: =$F34*N34 -> 33368.24 | H34: =$F34*O34 -> 0 | I34: =$F34*P34 -> 0 | J34: =$F34*Q34 -> 0 | K34: =$F34*R34 -> 0 | L34: =F34-SUM(G34:K34) -> 0 | N34: 1
A35: 02.02.02.05 | B35: CALZADURA: ENCOFRADO Y DESENCOFRADO | C35: m2 | D35: 321.08 | E35: 26.53 | F35: 8518.25 | G35: =$F35*N35 -> 8518.25 | H35: =$F35*O35 -> 0 | I35: =$F35*P35 -> 0 | J35: =$F35*Q35 -> 0 | K35: =$F35*R35 -> 0 | L35: =F35-SUM(G35:K35) -> 0 | N35: 1
A36: 02.02.03 | B36: Sobrecimientos
A37: 02.02.03.01 | B37: SOBRECIMIENTO, CONCRETO 1:8 + 25% P.M. f'c >=100Kg/cm2 | C37: m3 | D37: 3.15 | E37: 201.22 | F37: 633.84 | G37: =$F37*N37 -> 0 | H37: =$F37*O37 -> 0 | I37: =$F37*P37 -> 316.92 | J37: =$F37*Q37 -> 316.92 | K37: =$F37*R37 -> 0 | L37: =F37-SUM(G37:K37) -> 0 | P37: 0.5 | Q37: 0.5
A38: 02.02.03.02 | B38: SOBRECIMIENTO, ENCOFRADO Y DESENCOFRADO | C38: m2 | D38: 43.07 | E38: 24.18 | F38: 1041.43 | G38: =$F38*N38 -> 0 | H38: =$F38*O38 -> 416.572 | I38: =$F38*P38 -> 416.572 | J38: =$F38*Q38 -> 208.286 | K38: =$F38*R38 -> 0 | L38: =F38-SUM(G38:K38) -> 0 | O38: 0.4 | P38: 0.4 | Q38: 0.2
A39: 02.03 | B39: Obras de Concreto Armado
A40: 02.03.02 | B40: Zapatas
A41: 02.03.02.01 | B41: ZAPATAS.- CONCRETO 210 kg/cm2 | C41: m3 | D41: 412.62 | E41: 286.6 | F41: 118256.89 | G41: =$F41*N41 -> 35477.067 | H41: =$F41*O41 -> 82779.823 | I41: =$F41*P41 -> 0 | J41: =$F41*Q41 -> 0 | K41: =$F41*R41 -> 0 | L41: =F41-SUM(G41:K41) -> 0 | N41: 0.3 | O41: 0.7
A42: 02.03.02.03 | B42: ZAPATAS.- ACERO Fy=4200 kg/cm2 | C42: KG | D42: 17359.56 | E42: 3.4 | F42: 59022.5 | G42: =$F42*N42 -> 17706.75 | H42: =$F42*O42 -> 41315.75 | I42: =$F42*P42 -> 0 | J42: =$F42*Q42 -> 0 | K42: =$F42*R42 -> 0 | L42: =F42-SUM(G42:K42) -> 0 | N42: 0.3 | O42: 0.7
...

Sheet CRONOG INTERNO VENTA
A1: CRONOGRAMA VALORIZADO DE OBRA - PROGRAMACION VENTA
A3: PROYECTO: | B3: I.E. N° 1182 "EL BOSQUE" - CERCO + INGRESOS Y CASETAS
A5: ITEM | B5: DESCRIPCION | C5: UND | D5: CONTRACTUAL | G5: PROGRAMACION
D6: METRADO | E6: P.U. (S/.) | F6: PARCIAL (S/.) | G6: 45474 | H6: 45505 | I6: 45536 | J6: 45566 | K6: 45597
A7: 01 | B7: OBRAS PROVISIONALES, TRABAJOS PRELIMINARES, SEGURIDAD Y SALUD
A8: 01.02 | B8: Trabajos Preliminares
A9: 01.02.04 | B9: Trazo, Niveles y Replanteo
A10: 01.02.04.01 | B10: TRAZO Y REPLANTEO PRELIMINAR | C10: M2 | D10: 897.34 | E10: 2.04 | F10: 1830.57 | G10: =$F10*N10 -> 915.285 | H10: =$F10*O10 -> 915.285 | I10: =$F10*P10 -> 0 | J10: =$F10*Q10 -> 0 | K10: =$F10*R10 -> 0 | L10: =F10-SUM(G10:K10) -> 0 | N10: 0.5 | O10: 0.5
A11: 01.02.04.02 | B11: TRAZO Y REPLANTEO DURANTE EL PROCESO | C11: m2 | D11: 897.34 | E11: 2.04 | F11: 1830.57 | G11: =$F11*N11 -> 457.6425 | H11: =$F11*O11 -> 457.6425 | I11: =$F11*P11 -> 457.6425 | J11: =$F11*Q11 -> 457.6425 | K11: =$F11*R11 -> 0 | L11: =F11-SUM(G11:K11) -> 0 | N11: 0.25 | O11: 0.25 | P11: 0.25 | Q11: 0.25
A12: 02 | B12: ESTRUCTURAS
A13: 02.01 | B13: Movimiento de Tierras
A14: 02.01.01 | B14: Excavaciones
A15: 02.01.01.01 | B15: EXCAV.ZANJAS Y ZAPATA RT>2kg/cm2 H=1.5m | C15: m3 | D15: 41.9 | E15: 46.74 | F15: 1958.41 | G15: =$F15*N15 -> 1370.887 | H15: =$F15*O15 -> 587.523 | I15: =$F15*P15 -> 0 | J15: =$F15*Q15 -> 0 | K15: =$F15*R15 -> 0 | L15: =F15-SUM(G15:K15) -> 0 | N15: 0.7 | O15: 0.3
A16: 02.01.01.02 | B16: EXCAV.ZANJAS Y ZAPATA RT>2kg/cm2 H=2.0m | C16: m3 | D16: 1975.16 | E16: 50.99 | F16: 100713.41 | G16: =$F16*N16 -> 70499.387 | H16: =$F16*O16 -> 30214.023 | I16: =$F16*P16 -> 0 | J16: =$F16*Q16 -> 0 | K16: =$F16*R16 -> 0 | L16: =F16-SUM(G16:K16) -> 0 | N16: 0.7 | O16: 0.3
A17: 02.01.03 | B17: Rellenos
A18: 02.01.03.01 | B18: RELLENO COMPACTADO C/EQUIPO MAT/PROPIO | C18: m3 | D18: 1197.91 | E18: 26.01 | F18: 31157.64 | G18: =$F18*N18 -> 0 | H18: =$F18*O18 -> 9347.292 | I18: =$F18*P18 -> 21810.348 | J18: =$F18*Q18 -> 0 | K18: =$F18*R18 -> 0 | L18: =F18-SUM(G18:K18) -> 0 | O18: 0.3 | P18: 0.7
A19: 02.01.04 | B19: Eliminacion de Material Excedente
A20: 02.01.04.01 | B20: ACARREO INTERNO, MATERIAL PROCEDENTE DE EXCAVACIONES | C20: m3 | D20: 68.91 | E20: 17.53 | F20: 1207.99 | G20: =$F20*N20 -> 603.995 | H20: =$F20*O20 -> 603.995 | I20: =$F20*P20 -> 0 | J20: =$F20*Q20 -> 0 | K20: =$F20*R20 -> 0 | L20: =F20-SUM(G20:K20) -> 0 | N20: 0.5 | O20: 0.5
A21: 02.01.04.02 | B21: ELIMINACION MATERIAL EXCEDENTE ACARREADO | C21: M3 | D21: 68.91 | E21: 16.02 | F21: 1103.94 | G21: =$F21*N21 -> 551.97 | H21: =$F21*O21 -> 551.97 | I21: =$F21*P21 -> 0 | J21: =$F21*Q21 -> 0 | K21: =$F21*R21 -> 0 | L21: =F21-SUM(G21:K21) -> 0 | N21: 0.5 | O21: 0.5
A22: 02.01.04.03 | B22: ELIMINACION MATERIAL EXCEDENTE C/MAQUINA | C22: m3 | D22: 995.9 | E22: 21.84 | F22: 21750.46 | G22: =$F22*N22 -> 10875.23 | H22: =$F22*O22 -> 10875.23 | I22: =$F22*P22 -> 0 | J22: =$F22*Q22 -> 0 | K22: =$F22*R22 -> 0 | L22: =F22-SUM(G22:K22) -> 0 | N22: 0.5 | O22: 0.5
A23: 02.01.05 | B23: Nivelacion Interior y Apisonado
A24: 02.01.05.01 | B24: ESCARIFICADO Y COMPACTACION CON PLANCHA COMPACTADORA e = 30 cm | C24: m2 | D24: 68.95 | E24: 4.72 | F24: 325.44 | G24: =$F24*N24 -> 0 | H24: =$F24*O24 -> 0 | I24: =$F24*P24 -> 0 | J24: =$F24*Q24 -> 162.72 | K24: =$F24*R24 -> 162.72 | L24: =F24-SUM(G24:K24) -> 0 | Q24: 0.5 | R24: 0.5
A25: 02.01.05.02 | B25: ESCARIFICADO Y COMPACTACION CON PLANCHA COMPACTADORA H=0.60m (02 CAPAS 30cm c/u) | C25: m2 | D25: 8.56 | E25: 7.85 | F25: 67.2 | G25: =$F25*N25 -> 0 | H25: =$F25*O25 -> 0 | I25: =$F25*P25 -> 40.32 | J25: =$F25*Q25 -> 26.88 | K25: =$F25*R25 -> 0 | L25: =F25-SUM(G25:K25) -> 0 | P25: 0.6 | Q25: 0.4
A26: 02.01.05.05 | B26: AFIRMADO DE 8" PARA PISOS,PATIOS Y VEREDAS,COMPACTADO. | C26: m2 | D26: 68.95 | E26: 15.19 | F26: 1047.35 | G26: =$F26*N26 -> 0 | H26: =$F26*O26 -> 0 | I26: =$F26*P26 -> 0 | J26: =$F26*Q26 -> 418.94 | K26: =$F26*R26 -> 628.41 | L26: =F26-SUM(G26:K26) -> 0 | Q26: 0.4 | R26: 0.6
A27: 02.01.05.06 | B27: AFIRMADO DE 12" EN PISOS INTERIOR/EXTERIOR,COMPACTADO. | C27: m2 | D27: 8.56 | E27: 21.79 | F27: 186.52 | G27: =$F27*N27 -> 0 | H27: =$F27*O27 -> 0 | I27: =$F27*P27 -> 93.26 | J27: =$F27*Q27 -> 93.26 | K27: =$F27*R27 -> 0 | L27: =F27-SUM(G27:K27) -> 0 | P27: 0.5 | Q27: 0.5
A28: 02.02 | B28: Obras de Concreto Simple
A29: 02.02.01 | B29: Falsos Cimientos
A30: 02.02.01.01 | B30: SUBCIMIENTO, SUBZAPATA MEZCLA 1:12 + 30 % P.G. | C30: m3 | D30: 323.69 | E30: 173.72 | F30: 56231.43 | G30: =$F30*N30 -> 0 | H30: =$F30*O30 -> 39362.001 | I30: =$F30*P30 -> 16869.429 | J30: =$F30*Q30 -> 0 | K30: =$F30*R30 -> 0 | L30: =F30-SUM(G30:K30) -> 0 | O30: 0.7 | P30: 0.3
A31: 02.02.02 | B31: Cimientos
A32: 02.02.02.02 | B32: CIMIENTOS CORRIDOS 1:10 + 30 % P.G. f'c >=100Kg/cm2 | C32: m3 | D32: 24.73 | E32: 179.78 | F32: 4445.96 | G32: =$F32*N32 -> 0 | H32: =$F32*O32 -> 1333.788 | I32: =$F32*P32 -> 3112.172 | J32: =$F32*Q32 -> 0 | K32: =$F32*R32 -> 0 | L32: =F32-SUM(G32:K32) -> 0 | O32: 0.3 | P32: 0.7
A33: 02.02.02.03 | B33: CIMIENTO CORRIDO - ENCOFRADO Y DESENCOFRADO | C33: m2 | D33: 23.09 | E33: 46.17 | F33: 1066.07 | G33: =$F33*N33 -> 0 | H33: =$F33*O33 -> 426.428 | I33: =$F33*P33 -> 639.642 | J33: =$F33*Q33 -> 0 | K33: =$F33*R33 -> 0 | L33: =F33-SUM(G33:K33) -> 0 | O33: 0.4 | P33: 0.6
A34: 02.02.02.04 | B34: CALZADURA: CONCRETO C:H 1:10 + 30 % P.G. | C34: m3 | D34: 163.82 | E34: 179.78 | F34: 29451.56 | G34: =$F34*N34 -> 29451.56 | H34: =$F34*O34 -> 0 | I34: =$F34*P34 -> 0 | J34: =$F34*Q34 -> 0 | K34: =$F34*R34 -> 0 | L34: =F34-SUM(G34:K34) -> 0 | N34: 1
A35: 02.02.02.05 | B35: CALZADURA: ENCOFRADO Y DESENCOFRADO | C35: m2 | D35: 327.63 | E35: 37.47 | F35: 12276.3 | G35: =$F35*N35 -> 12276.3 | H35: =$F35*O35 -> 0 | I35: =$F35*P35 -> 0 | J35: =$F35*Q35 -> 0 | K35: =$F35*R35 -> 0 | L35: =F35-SUM(G35:K35) -> 0 | N35: 1
A36: 02.02.03 | B36: Sobrecimientos
A37: 02.02.03.01 | B37: SOBRECIMIENTO, CONCRETO 1:8 + 25% P.M. f'c >=100Kg/cm2 | C37: m3 | D37: 3.21 | E37: 260.59 | F37: 836.49 | G37: =$F37*N37 -> 0 | H37: =$F37*O37 -> 0 | I37: =$F37*P37 -> 418.245 | J37: =$F37*Q37 -> 418.245 | K37: =$F37*R37 -> 0 | L37: =F37-SUM(G37:K37) -> 0 | P37: 0.5 | Q37: 0.5
A38: 02.02.03.02 | B38: SOBRECIMIENTO, ENCOFRADO Y DESENCOFRADO | C38: m2 | D38: 43.95 | E38: 37.7 | F38: 1656.92 | G38: =$F38*N38 -> 0 | H38: =$F38*O38 -> 662.768 | I38: =$F38*P38 -> 662.768 | J38: =$F38*Q38 -> 331.384 | K38: =$F38*R38 -> 0 | L38: =F38-SUM(G38:K38) -> 0 | O38: 0.4 | P38: 0.4 | Q38: 0.2
A39: 02.03 | B39: Obras de Concreto Armado
A40: 02.03.02 | B40: Zapatas
A41: 02.03.02.01 | B41: ZAPATAS.- CONCRETO 210 kg/cm2 | C41: m3 | D41: 396.75 | E41: 292.79 | F41: 116164.43 | G41: =$F41*N41 -> 0 | H41: =$F41*O41 -> 58082.215 | I41: =$F41*P41 -> 58082.215 | J41: =$F41*Q41 -> 0 | K41: =$F41*R41 -> 0 | L41: =F41-SUM(G41:K41) -> 0 | O41: 0.5 | P41: 0.5
A42: 02.03.02.03 | B42: ZAPATAS.- ACERO Fy=4200 kg/cm2 | C42: KG | D42: 17534.91 | E42: 4.02 | F42: 70490.34 | G42: =$F42*N42 -> 0 | H42: =$F42*O42 -> 35245.17 | I42: =$F42*P42 -> 35245.17 | J42: =$F42*Q42 -> 0 | K42: =$F42*R42 -> 0 | L42: =F42-SUM(G42:K42) -> 0 | O42: 0.5 | P42: 0.5
...

Sheet CRONOG INTERNO META
A1: CRONOGRAMA VALORIZADO DE OBRA - PROGRAMACION VENTA CON COSTOS META
A3: PROYECTO: | B3: I.E. N° 1182 "EL BOSQUE" - CERCO + INGRESOS Y CASETAS
A5: ITEM | B5: DESCRIPCION | C5: UND | D5: CONTRACTUAL | G5: PROGRAMACION
D6: METRADO | E6: P.U. (S/.) | F6: PARCIAL (S/.) | G6: 45474 | H6: 45505 | I6: 45536 | J6: 45566 | K6: 45597
A7: 01 | B7: OBRAS PROVISIONALES, TRABAJOS PRELIMINARES, SEGURIDAD Y SALUD
A8: 01.02 | B8: Trabajos Preliminares
A9: 01.02.04 | B9: Trazo, Niveles y Replanteo
A10: 01.02.04.01 | B10: TRAZO Y REPLANTEO PRELIMINAR | C10: M2 | D10: 942.21 | E10: 1.33 | F10: 1253.14 | G10: =$F10*N10 -> 626.57 | H10: =$F10*O10 -> 626.57 | I10: =$F10*P10 -> 0 | J10: =$F10*Q10 -> 0 | K10: =$F10*R10 -> 0 | L10: =F10-SUM(G10:K10) -> 0 | N10: 0.5 | O10: 0.5
A11: 01.02.04.02 | B11: TRAZO Y REPLANTEO DURANTE EL PROCESO | C11: m2 | D11: 942.21 | E11: 1.33 | F11: 1253.14 | G11: =$F11*N11 -> 313.285 | H11: =$F11*O11 -> 313.285 | I11: =$F11*P11 -> 313.285 | J11: =$F11*Q11 -> 313.285 | K11: =$F11*R11 -> 0 | L11: =F11-SUM(G11:K11) -> 0 | N11: 0.25 | O11: 0.25 | P11: 0.25 | Q11: 0.25
A12: 02 | B12: ESTRUCTURAS
A13: 02.01 | B13: Movimiento de Tierras
A14: 02.01.01 | B14: Excavaciones
A15: 02.01.01.01 | B15: EXCAV.ZANJAS Y ZAPATA RT>2kg/cm2 H=1.5m | C15: m3 | D15: 39.81 | E15: 29.22 | F15: 1163.25 | G15: =$F15*N15 -> 814.275 | H15: =$F15*O15 -> 348.975 | I15: =$F15*P15 -> 0 | J15: =$F15*Q15 -> 0 | K15: =$F15*R15 -> 0 | L15: =F15-SUM(G15:K15) -> 0 | N15: 0.7 | O15: 0.3
A16: 02.01.01.02 | B16: EXCAV.ZANJAS Y ZAPATA RT>2kg/cm2 H=2.0m | C16: m3 | D16: 1876.4 | E16: 33.36 | F16: 62596.7 | G16: =$F16*N16 -> 43817.69 | H16: =$F16*O16 -> 18779.01 | I16: =$F16*P16 -> 0 | J16: =$F16*Q16 -> 0 | K16: =$F16*R16 -> 0 | L16: =F16-SUM(G16:K16) -> 0 | N16: 0.7 | O16: 0.3
A17: 02.01.03 | B17: Rellenos
A18: 02.01.03.01 | B18: RELLENO COMPACTADO C/EQUIPO MAT/PROPIO | C18: m3 | D18: 1138.01 | E18: 15 | F18: 17070.15 | G18: =$F18*N18 -> 0 | H18: =$F18*O18 -> 5121.045 | I18: =$F18*P18 -> 11949.105 | J18: =$F18*Q18 -> 0 | K18: =$F18*R18 -> 0 | L18: =F18-SUM(G18:K18) -> 0 | O18: 0.3 | P18: 0.7
A19: 02.01.04 | B19: Eliminacion de Material Excedente
A20: 02.01.04.01 | B20: ACARREO INTERNO, MATERIAL PROCEDENTE DE EXCAVACIONES | C20: m3 | D20: 1118.06 | E20: 18.27 | F20: 20426.96 | G20: =$F20*N20 -> 10213.48 | H20: =$F20*O20 -> 10213.48 | I20: =$F20*P20 -> 0 | J20: =$F20*Q20 -> 0 | K20: =$F20*R20 -> 0 | L20: =F20-SUM(G20:K20) -> 0 | N20: 0.5 | O20: 0.5
A21: 02.01.04.02 | B21: ELIMINACION MATERIAL EXCEDENTE ACARREADO | C21: M3 | G21: =$F21*N21 -> 0 | H21: =$F21*O21 -> 0 | I21: =$F21*P21 -> 0 | J21: =$F21*Q21 -> 0 | K21: =$F21*R21 -> 0 | L21: =F21-SUM(G21:K21) -> 0 | N21: 0.5 | O21: 0.5
A22: 02.01.04.03 | B22: ELIMINACION MATERIAL EXCEDENTE C/MAQUINA | C22: m3 | G22: =$F22*N22 -> 0 | H22: =$F22*O22 -> 0 | I22: =$F22*P22 -> 0 | J22: =$F22*Q22 -> 0 | K22: =$F22*R22 -> 0 | L22: =F22-SUM(G22:K22) -> 0 | N22: 0.5 | O22: 0.5
A23: 02.01.05 | B23: Nivelacion Interior y Apisonado
A24: 02.01.05.01 | B24: ESCARIFICADO Y COMPACTACION CON PLANCHA COMPACTADORA e = 30 cm | C24: m2 | D24: 70.33 | E24: 4.36 | F24: 306.64 | G24: =$F24*N24 -> 0 | H24: =$F24*O24 -> 0 | I24: =$F24*P24 -> 0 | J24: =$F24*Q24 -> 153.32 | K24: =$F24*R24 -> 153.32 | L24: =F24-SUM(G24:K24) -> 0 | Q24: 0.5 | R24: 0.5
A25: 02.01.05.02 | B25: ESCARIFICADO Y COMPACTACION CON PLANCHA COMPACTADORA H=0.60m (02 CAPAS 30cm c/u) | C25: m2 | D25: 8.73 | E25: 7.37 | F25: 64.34 | G25: =$F25*N25 -> 0 | H25: =$F25*O25 -> 0 | I25: =$F25*P25 -> 38.604 | J25: =$F25*Q25 -> 25.736 | K25: =$F25*R25 -> 0 | L25: =F25-SUM(G25:K25) -> 0 | P25: 0.6 | Q25: 0.4
A26: 02.01.05.05 | B26: AFIRMADO DE 8" PARA PISOS,PATIOS Y VEREDAS,COMPACTADO. | C26: m2 | D26: 70.33 | E26: 11.5 | F26: 808.8 | G26: =$F26*N26 -> 0 | H26: =$F26*O26 -> 0 | I26: =$F26*P26 -> 0 | J26: =$F26*Q26 -> 323.52 | K26: =$F26*R26 -> 485.28 | L26: =F26-SUM(G26:K26) -> 0 | Q26: 0.4 | R26: 0.6
A27: 02.01.05.06 | B27: AFIRMADO DE 12" EN PISOS INTERIOR/EXTERIOR,COMPACTADO. | C27: m2 | D27: 8.73 | E27: 14.5 | F27: 126.59 | G27: =$F27*N27 -> 0 | H27: =$F27*O27 -> 0 | I27: =$F27*P27 -> 63.295 | J27: =$F27*Q27 -> 63.295 | K27: =$F27*R27 -> 0 | L27: =F27-SUM(G27:K27) -> 0 | P27: 0.5 | Q27: 0.5
A28: 02.02 | B28: Obras de Concreto Simple
A29: 02.02.01 | B29: Falsos Cimientos
A30: 02.02.01.01 | B30: SUBCIMIENTO, SUBZAPATA MEZCLA 1:12 + 30 % P.G. | C30: m3 | D30: 330.16 | E30: 184.1 | F30: 60782.46 | G30: =$F30*N30 -> 0 | H30: =$F30*O30 -> 42547.722 | I30: =$F30*P30 -> 18234.738 | J30: =$F30*Q30 -> 0 | K30: =$F30*R30 -> 0 | L30: =F30-SUM(G30:K30) -> 0 | O30: 0.7 | P30: 0.3
A31: 02.02.02 | B31: Cimientos
A32: 02.02.02.02 | B32: CIMIENTOS CORRIDOS 1:10 + 30 % P.G. f'c >=100Kg/cm2 | C32: m3 | D32: 24.24 | E32: 182.46 | F32: 4422.83 | G32: =$F32*N32 -> 0 | H32: =$F32*O32 -> 1326.849 | I32: =$F32*P32 -> 3095.981 | J32: =$F32*Q32 -> 0 | K32: =$F32*R32 -> 0 | L32: =F32-SUM(G32:K32) -> 0 | O32: 0.3 | P32: 0.7
A33: 02.02.02.03 | B33: CIMIENTO CORRIDO - ENCOFRADO Y DESENCOFRADO | C33: m2 | D33: 22.63 | E33: 23.83 | F33: 539.27 | G33: =$F33*N33 -> 0 | H33: =$F33*O33 -> 215.708 | I33: =$F33*P33 -> 323.562 | J33: =$F33*Q33 -> 0 | K33: =$F33*R33 -> 0 | L33: =F33-SUM(G33:K33) -> 0 | O33: 0.4 | P33: 0.6
A34: 02.02.02.04 | B34: CALZADURA: CONCRETO C:H 1:10 + 30 % P.G. | C34: m3 | D34: 160.54 | E34: 207.85 | F34: 33368.24 | G34: =$F34*N34 -> 33368.24 | H34: =$F34*O34 -> 0 | I34: =$F34*P34 -> 0 | J34: =$F34*Q34 -> 0 | K34: =$F34*R34 -> 0 | L34: =F34-SUM(G34:K34) -> 0 | N34: 1
A35: 02.02.02.05 | B35: CALZADURA: ENCOFRADO Y DESENCOFRADO | C35: m2 | D35: 321.08 | E35: 26.53 | F35: 8518.25 | G35: =$F35*N35 -> 8518.25 | H35: =$F35*O35 -> 0 | I35: =$F35*P35 -> 0 | J35: =$F35*Q35 -> 0 | K35: =$F35*R35 -> 0 | L35: =F35-SUM(G35:K35) -> 0 | N35: 1
A36: 02.02.03 | B36: Sobrecimientos
A37: 02.02.03.01 | B37: SOBRECIMIENTO, CONCRETO 1:8 + 25% P.M. f'c >=100Kg/cm2 | C37: m3 | D37: 3.15 | E37: 201.22 | F37: 633.84 | G37: =$F37*N37 -> 0 | H37: =$F37*O37 -> 0 | I37: =$F37*P37 -> 316.92 | J37: =$F37*Q37 -> 316.92 | K37: =$F37*R37 -> 0 | L37: =F37-SUM(G37:K37) -> 0 | P37: 0.5 | Q37: 0.5
A38: 02.02.03.02 | B38: SOBRECIMIENTO, ENCOFRADO Y DESENCOFRADO | C38: m2 | D38: 43.07 | E38: 24.18 | F38: 1041.43 | G38: =$F38*N38 -> 0 | H38: =$F38*O38 -> 416.572 | I38: =$F38*P38 -> 416.572 | J38: =$F38*Q38 -> 208.286 | K38: =$F38*R38 -> 0 | L38: =F38-SUM(G38:K38) -> 0 | O38: 0.4 | P38: 0.4 | Q38: 0.2
A39: 02.03 | B39: Obras de Concreto Armado
A40: 02.03.02 | B40: Zapatas
A41: 02.03.02.01 | B41: ZAPATAS.- CONCRETO 210 kg/cm2 | C41: m3 | D41: 412.62 | E41: 286.6 | F41: 118256.89 | G41: =$F41*N41 -> 0 | H41: =$F41*O41 -> 59128.445 | I41: =$F41*P41 -> 59128.445 | J41: =$F41*Q41 -> 0 | K41: =$F41*R41 -> 0 | L41: =F41-SUM(G41:K41) -> 0 | O41: 0.5 | P41: 0.5
A42: 02.03.02.03 | B42: ZAPATAS.- ACERO Fy=4200 kg/cm2 | C42: KG | D42: 17359.56 | E42: 3.4 | F42: 59022.5 | G42: =$F42*N42 -> 0 | H42: =$F42*O42 -> 29511.25 | I42: =$F42*P42 -> 29511.25 | J42: =$F42*Q42 -> 0 | K42: =$F42*R42 -> 0 | L42: =F42-SUM(G42:K42) -> 0 | O42: 0.5 | P42: 0.5
...

Sheet CRONOG COSTOS REALES
A1: CRONOGRAMA VALORIZADO DE OBRA - PROGRAMACION VENTA CON COSTOS META
A3: PROYECTO: | B3: I.E. N° 1182 "EL BOSQUE" - CERCO + INGRESOS Y CASETAS
A5: ITEM | B5: DESCRIPCION | C5: UND | D5: CONTRACTUAL | G5: PROGRAMACION
D6: METRADO | E6: P.U. (S/.) | F6: PARCIAL (S/.) | G6: 45474 | H6: 45505 | I6: 45536 | J6: 45566 | K6: 45597
A7: 01 | B7: OBRAS PROVISIONALES, TRABAJOS PRELIMINARES, SEGURIDAD Y SALUD
A8: 01.02 | B8: Trabajos Preliminares
A9: 01.02.04 | B9: Trazo, Niveles y Replanteo
A10: 01.02.04.01 | B10: TRAZO Y REPLANTEO PRELIMINAR | C10: M2 | G10: =$F10*N10 -> 0 | H10: =$F10*O10 -> 0 | I10: =$F10*P10 -> 0 | J10: =$F10*Q10 -> 0 | K10: =$F10*R10 -> 0 | L10: =F10-SUM(G10:K10) -> 0
A11: 01.02.04.02 | B11: TRAZO Y REPLANTEO DURANTE EL PROCESO | C11: m2 | G11: =$F11*N11 -> 0 | H11: =$F11*O11 -> 0 | I11: =$F11*P11 -> 0 | J11: =$F11*Q11 -> 0 | K11: =$F11*R11 -> 0 | L11: =F11-SUM(G11:K11) -> 0
A12: 02 | B12: ESTRUCTURAS
A13: 02.01 | B13: Movimiento de Tierras
A14: 02.01.01 | B14: Excavaciones
A15: 02.01.01.01 | B15: EXCAV.ZANJAS Y ZAPATA RT>2kg/cm2 H=1.5m | C15: m3 | G15: =$F15*N15 -> 0 | H15: =$F15*O15 -> 0 | I15: =$F15*P15 -> 0 | J15: =$F15*Q15 -> 0 | K15: =$F15*R15 -> 0 | L15: =F15-SUM(G15:K15) -> 0
A16: 02.01.01.02 | B16: EXCAV.ZANJAS Y ZAPATA RT>2kg/cm2 H=2.0m | C16: m3 | G16: =$F16*N16 -> 0 | H16: =$F16*O16 -> 0 | I16: =$F16*P16 -> 0 | J16: =$F16*Q16 -> 0 | K16: =$F16*R16 -> 0 | L16: =F16-SUM(G16:K16) -> 0
A17: 02.01.03 | B17: Rellenos
A18: 02.01.03.01 | B18: RELLENO COMPACTADO C/EQUIPO MAT/PROPIO | C18: m3 | G18: =$F18*N18 -> 0 | H18: =$F18*O18 -> 0 | I18: =$F18*P18 -> 0 | J18: =$F18*Q18 -> 0 | K18: =$F18*R18 -> 0 | L18: =F18-SUM(G18:K18) -> 0
A19: 02.01.04 | B19: Eliminacion de Material Excedente
A20: 02.01.04.01 | B20: ACARREO INTERNO, MATERIAL PROCEDENTE DE EXCAVACIONES | C20: m3 | G20: =$F20*N20 -> 0 | H20: =$F20*O20 -> 0 | I20: =$F20*P20 -> 0 | J20: =$F20*Q20 -> 0 | K20: =$F20*R20 -> 0 | L20: =F20-SUM(G20:K20) -> 0
A21: 02.01.04.02 | B21: ELIMINACION MATERIAL EXCEDENTE ACARREADO | C21: M3 | G21: =$F21*N21 -> 0 | H21: =$F21*O21 -> 0 | I21: =$F21*P21 -> 0 | J21: =$F21*Q21 -> 0 | K21: =$F21*R21 -> 0 | L21: =F21-SUM(G21:K21) -> 0
A22: 02.01.04.03 | B22: ELIMINACION MATERIAL EXCEDENTE C/MAQUINA | C22: m3 | G22: =$F22*N22 -> 0 | H22: =$F22*O22 -> 0 | I22: =$F22*P22 -> 0 | J22: =$F22*Q22 -> 0 | K22: =$F22*R22 -> 0 | L22: =F22-SUM(G22:K22) -> 0
A23: 02.01.05 | B23: Nivelacion Interior y Apisonado
A24: 02.01.05.01 | B24: ESCARIFICADO Y COMPACTACION CON PLANCHA COMPACTADORA e = 30 cm | C24: m2 | G24: =$F24*N24 -> 0 | H24: =$F24*O24 -> 0 | I24: =$F24*P24 -> 0 | J24: =$F24*Q24 -> 0 | K24: =$F24*R24 -> 0 | L24: =F24-SUM(G24:K24) -> 0
A25: 02.01.05.02 | B25: ESCARIFICADO Y COMPACTACION CON PLANCHA COMPACTADORA H=0.60m (02 CAPAS 30cm c/u) | C25: m2 | G25: =$F25*N25 -> 0 | H25: =$F25*O25 -> 0 | I25: =$F25*P25 -> 0 | J25: =$F25*Q25 -> 0 | K25: =$F25*R25 -> 0 | L25: =F25-SUM(G25:K25) -> 0
A26: 02.01.05.05 | B26: AFIRMADO DE 8" PARA PISOS,PATIOS Y VEREDAS,COMPACTADO. | C26: m2 | G26: =$F26*N26 -> 0 | H26: =$F26*O26 -> 0 | I26: =$F26*P26 -> 0 | J26: =$F26*Q26 -> 0 | K26: =$F26*R26 -> 0 | L26: =F26-SUM(G26:K26) -> 0
A27: 02.01.05.06 | B27: AFIRMADO DE 12" EN PISOS INTERIOR/EXTERIOR,COMPACTADO. | C27: m2 | G27: =$F27*N27 -> 0 | H27: =$F27*O27 -> 0 | I27: =$F27*P27 -> 0 | J27: =$F27*Q27 -> 0 | K27: =$F27*R27 -> 0 | L27: =F27-SUM(G27:K27) -> 0
A28: 02.02 | B28: Obras de Concreto Simple
A29: 02.02.01 | B29: Falsos Cimientos
A30: 02.02.01.01 | B30: SUBCIMIENTO, SUBZAPATA MEZCLA 1:12 + 30 % P.G. | C30: m3 | G30: =$F30*N30 -> 0 | H30: =$F30*O30 -> 0 | I30: =$F30*P30 -> 0 | J30: =$F30*Q30 -> 0 | K30: =$F30*R30 -> 0 | L30: =F30-SUM(G30:K30) -> 0
A31: 02.02.02 | B31: Cimientos
A32: 02.02.02.02 | B32: CIMIENTOS CORRIDOS 1:10 + 30 % P.G. f'c >=100Kg/cm2 | C32: m3 | G32: =$F32*N32 -> 0 | H32: =$F32*O32 -> 0 | I32: =$F32*P32 -> 0 | J32: =$F32*Q32 -> 0 | K32: =$F32*R32 -> 0 | L32: =F32-SUM(G32:K32) -> 0
A33: 02.02.02.03 | B33: CIMIENTO CORRIDO - ENCOFRADO Y DESENCOFRADO | C33: m2 | G33: =$F33*N33 -> 0 | H33: =$F33*O33 -> 0 | I33: =$F33*P33 -> 0 | J33: =$F33*Q33 -> 0 | K33: =$F33*R33 -> 0 | L33: =F33-SUM(G33:K33) -> 0
A34: 02.02.02.04 | B34: CALZADURA: CONCRETO C:H 1:10 + 30 % P.G. | C34: m3 | G34: =$F34*N34 -> 0 | H34: =$F34*O34 -> 0 | I34: =$F34*P34 -> 0 | J34: =$F34*Q34 -> 0 | K34: =$F34*R34 -> 0 | L34: =F34-SUM(G34:K34) -> 0
